package com.draco18s.artifacts.worldgen;
import java.io.ByteArrayOutputStream;
import java.io.DataOutputStream;
import java.io.IOException;
import java.util.Random;

import com.draco18s.artifacts.api.ArtifactsAPI;
import com.draco18s.artifacts.block.*;
import com.draco18s.artifacts.entity.TileEntityDisplayPedestal;
import com.draco18s.artifacts.entity.TileEntityTrap;
import com.draco18s.artifacts.item.*;

import net.minecraft.block.Block;
import net.minecraft.entity.item.EntityItemFrame;
import net.minecraft.entity.item.EntityPainting;
import net.minecraft.init.Blocks;
import net.minecraft.init.Items;
import net.minecraft.item.Item;
import net.minecraft.item.ItemStack;
import net.minecraft.nbt.NBTTagCompound;
import net.minecraft.tileentity.*;
import net.minecraft.util.WeightedRandomChestContent;
import net.minecraft.world.World;
import net.minecraft.world.gen.feature.WorldGenerator;
import net.minecraftforge.common.ChestGenHooks;

public class StructureMasterTower extends WorldGenerator
{
	public StructureMasterTower() { }

	@Override
	public boolean generate(World world, Random random, int x, int y, int z) {
		for (z -= 8; y > 5 && (!world.getBlock(x, y, z).isOpaqueCube() || world.getBlock(x, y, z) == Blocks.leaves); --y)
        {
            ;
        }

        if (y <= 61)
        {
            return false;
        }
        else
        {
        	build(world, random, x-6, y-2, z-13);
        }
		return false;
	}
	
	public static boolean build(World world, Random rand, int i, int j, int k) {
		//System.out.println("Master tower at (" + i + "," + k + ")");
		world.setBlock(i + 0, j + 18, k + 9, Blocks.oak_stairs, 4, 2);
		world.setBlock(i + 0, j + 18, k + 10, Blocks.oak_stairs, 4, 2);
		world.setBlock(i + 0, j + 18, k + 11, Blocks.oak_stairs, 4, 2);
		world.setBlock(i + 0, j + 18, k + 12, Blocks.oak_stairs, 4, 2);
		world.setBlock(i + 0, j + 19, k + 9, Blocks.planks, 0, 2);
		world.setBlock(i + 0, j + 19, k + 10, Blocks.planks, 0, 2);
		world.setBlock(i + 0, j + 19, k + 11, Blocks.planks, 0, 2);
		world.setBlock(i + 0, j + 19, k + 12, Blocks.planks, 0, 2);
		world.setBlock(i + 0, j + 20, k + 9, Blocks.planks, 0, 2);
		world.setBlock(i + 0, j + 20, k + 10, Blocks.glass_pane, 0, 2);
		world.setBlock(i + 0, j + 20, k + 11, Blocks.glass_pane, 0, 2);
		world.setBlock(i + 0, j + 20, k + 12, Blocks.planks, 0, 2);
		world.setBlock(i + 0, j + 21, k + 9, Blocks.planks, 0, 2);
		world.setBlock(i + 0, j + 21, k + 10, Blocks.planks, 0, 2);
		world.setBlock(i + 0, j + 21, k + 11, Blocks.planks, 0, 2);
		world.setBlock(i + 0, j + 21, k + 12, Blocks.planks, 0, 2);
		world.setBlock(i + 0, j + 22, k + 9, Blocks.oak_stairs, 2, 2);
		world.setBlock(i + 0, j + 22, k + 10, Blocks.oak_stairs, 0, 2);
		world.setBlock(i + 0, j + 22, k + 11, Blocks.oak_stairs, 0, 2);
		world.setBlock(i + 0, j + 22, k + 12, Blocks.oak_stairs, 0, 2);
		world.setBlock(i + 1, j + 0, k + 6, Blocks.stonebrick, StructureGenHelper.stoneBrickMeta(rand), 2);
		world.setBlock(i + 1, j + 0, k + 7, Blocks.stonebrick, StructureGenHelper.stoneBrickMeta(rand), 2);
		world.setBlock(i + 1, j + 0, k + 8, Blocks.stonebrick, StructureGenHelper.stoneBrickMeta(rand), 2);
		world.setBlock(i + 1, j + 1, k + 6, Blocks.stonebrick, StructureGenHelper.stoneBrickMeta(rand), 2);
		world.setBlock(i + 1, j + 1, k + 7, Blocks.stonebrick, StructureGenHelper.stoneBrickMeta(rand), 2);
		world.setBlock(i + 1, j + 1, k + 8, Blocks.stonebrick, StructureGenHelper.stoneBrickMeta(rand), 2);
		world.setBlock(i + 1, j + 2, k + 6, Blocks.stonebrick, StructureGenHelper.stoneBrickMeta(rand), 2);
		world.setBlock(i + 1, j + 2, k + 7, Blocks.stonebrick, StructureGenHelper.stoneBrickMeta(rand), 2);
		world.setBlock(i + 1, j + 2, k + 8, Blocks.stonebrick, StructureGenHelper.stoneBrickMeta(rand), 2);
		world.setBlock(i + 1, j + 3, k + 6, Blocks.stonebrick, StructureGenHelper.stoneBrickMeta(rand), 2);
		world.setBlock(i + 1, j + 3, k + 7, Blocks.stonebrick, StructureGenHelper.stoneBrickMeta(rand), 2);
		world.setBlock(i + 1, j + 3, k + 8, Blocks.stonebrick, StructureGenHelper.stoneBrickMeta(rand), 2);
		world.setBlock(i + 1, j + 4, k + 6, Blocks.stonebrick, StructureGenHelper.stoneBrickMeta(rand), 2);
		world.setBlock(i + 1, j + 4, k + 7, Blocks.iron_bars, 0, 2);
		world.setBlock(i + 1, j + 4, k + 8, Blocks.stonebrick, StructureGenHelper.stoneBrickMeta(rand), 2);
		world.setBlock(i + 1, j + 5, k + 6, Blocks.stonebrick, StructureGenHelper.stoneBrickMeta(rand), 2);
		world.setBlock(i + 1, j + 5, k + 7, Blocks.stonebrick, StructureGenHelper.stoneBrickMeta(rand), 2);
		world.setBlock(i + 1, j + 5, k + 8, Blocks.stonebrick, StructureGenHelper.stoneBrickMeta(rand), 2);
		world.setBlock(i + 1, j + 6, k + 6, Blocks.stonebrick, StructureGenHelper.stoneBrickMeta(rand), 2);
		world.setBlock(i + 1, j + 6, k + 7, Blocks.stonebrick, StructureGenHelper.stoneBrickMeta(rand), 2);
		world.setBlock(i + 1, j + 6, k + 8, Blocks.stonebrick, StructureGenHelper.stoneBrickMeta(rand), 2);
		world.setBlock(i + 1, j + 7, k + 6, Blocks.stonebrick, StructureGenHelper.stoneBrickMeta(rand), 2);
		world.setBlock(i + 1, j + 7, k + 7, Blocks.stonebrick, StructureGenHelper.stoneBrickMeta(rand), 2);
		world.setBlock(i + 1, j + 7, k + 8, Blocks.stonebrick, StructureGenHelper.stoneBrickMeta(rand), 2);
		world.setBlock(i + 1, j + 8, k + 6, Blocks.stonebrick, StructureGenHelper.stoneBrickMeta(rand), 2);
		world.setBlock(i + 1, j + 8, k + 7, Blocks.stonebrick, StructureGenHelper.stoneBrickMeta(rand), 2);
		world.setBlock(i + 1, j + 8, k + 8, Blocks.stonebrick, StructureGenHelper.stoneBrickMeta(rand), 2);
		world.setBlock(i + 1, j + 9, k + 6, Blocks.stonebrick, StructureGenHelper.stoneBrickMeta(rand), 2);
		world.setBlock(i + 1, j + 9, k + 7, Blocks.stonebrick, StructureGenHelper.stoneBrickMeta(rand), 2);
		world.setBlock(i + 1, j + 9, k + 8, Blocks.stonebrick, StructureGenHelper.stoneBrickMeta(rand), 2);
		world.setBlock(i + 1, j + 10, k + 7, Blocks.stonebrick, StructureGenHelper.stoneBrickMeta(rand), 2);
		world.setBlock(i + 1, j + 11, k + 2, Blocks.oak_stairs, 4, 2);
		world.setBlock(i + 1, j + 11, k + 3, Blocks.oak_stairs, 4, 2);
		world.setBlock(i + 1, j + 11, k + 4, Blocks.oak_stairs, 4, 2);
		world.setBlock(i + 1, j + 11, k + 7, Blocks.stone_brick_stairs, 0, 2);
		world.setBlock(i + 1, j + 12, k + 2, Blocks.planks, 0, 2);
		world.setBlock(i + 1, j + 12, k + 3, Blocks.planks, 0, 2);
		world.setBlock(i + 1, j + 12, k + 4, Blocks.planks, 0, 2);
		world.setBlock(i + 1, j + 13, k + 2, Blocks.planks, 0, 2);
		world.setBlock(i + 1, j + 13, k + 3, Blocks.planks, 0, 2);
		world.setBlock(i + 1, j + 13, k + 4, Blocks.planks, 0, 2);
		world.setBlock(i + 1, j + 14, k + 2, Blocks.planks, 0, 2);
		world.setBlock(i + 1, j + 14, k + 3, Blocks.planks, 0, 2);
		world.setBlock(i + 1, j + 14, k + 4, Blocks.planks, 0, 2);
		world.setBlock(i + 1, j + 15, k + 1, Blocks.oak_stairs, 2, 2);
		world.setBlock(i + 1, j + 15, k + 2, Blocks.oak_stairs, 0, 2);
		world.setBlock(i + 1, j + 15, k + 3, Blocks.oak_stairs, 0, 2);
		world.setBlock(i + 1, j + 15, k + 4, Blocks.oak_stairs, 0, 2);
		world.setBlock(i + 1, j + 15, k + 5, Blocks.oak_stairs, 3, 2);
		world.setBlock(i + 1, j + 17, k + 9, Blocks.oak_stairs, 4, 2);
		world.setBlock(i + 1, j + 17, k + 10, Blocks.oak_stairs, 4, 2);
		world.setBlock(i + 1, j + 17, k + 11, Blocks.oak_stairs, 4, 2);
		world.setBlock(i + 1, j + 17, k + 12, Blocks.oak_stairs, 4, 2);
		world.setBlock(i + 1, j + 18, k + 8, Blocks.oak_stairs, 6, 2);
		world.setBlock(i + 1, j + 18, k + 9, Blocks.planks, 0, 2);
		world.setBlock(i + 1, j + 18, k + 10, Blocks.planks, 0, 2);
		world.setBlock(i + 1, j + 18, k + 11, Blocks.planks, 0, 2);
		world.setBlock(i + 1, j + 18, k + 12, Blocks.planks, 0, 2);
		world.setBlock(i + 1, j + 18, k + 13, Blocks.oak_stairs, 7, 2);
		world.setBlock(i + 1, j + 19, k + 8, Blocks.planks, 0, 2);
		world.setBlock(i + 1, j + 19, k + 9, Blocks.air);
		world.setBlock(i + 1, j + 19, k + 10, Blocks.air);
		world.setBlock(i + 1, j + 19, k + 11, Blocks.air);
		world.setBlock(i + 1, j + 19, k + 12, Blocks.air);
		world.setBlock(i + 1, j + 19, k + 13, Blocks.planks, 0, 2);
		world.setBlock(i + 1, j + 20, k + 8, Blocks.planks, 0, 2);
		world.setBlock(i + 1, j + 20, k + 9, Blocks.air);
		world.setBlock(i + 1, j + 20, k + 10, Blocks.air);
		world.setBlock(i + 1, j + 20, k + 11, Blocks.air);
		world.setBlock(i + 1, j + 20, k + 12, Blocks.air);
		world.setBlock(i + 1, j + 20, k + 13, Blocks.planks, 0, 2);
		world.setBlock(i + 1, j + 21, k + 8, Blocks.planks, 0, 2);
		world.setBlock(i + 1, j + 21, k + 9, Blocks.planks, 0, 2);
		world.setBlock(i + 1, j + 21, k + 10, Blocks.planks, 0, 2);
		world.setBlock(i + 1, j + 21, k + 11, Blocks.planks, 0, 2);
		world.setBlock(i + 1, j + 21, k + 12, Blocks.planks, 0, 2);
		world.setBlock(i + 1, j + 21, k + 13, Blocks.planks, 0, 2);
		world.setBlock(i + 1, j + 22, k + 8, Blocks.oak_stairs, 2, 2);
		world.setBlock(i + 1, j + 22, k + 9, Blocks.oak_stairs, 0, 2);
		world.setBlock(i + 1, j + 22, k + 10, Blocks.planks, 0, 2);
		world.setBlock(i + 1, j + 22, k + 11, Blocks.planks, 0, 2);
		world.setBlock(i + 1, j + 22, k + 12, Blocks.oak_stairs, 3, 2);
		world.setBlock(i + 1, j + 22, k + 13, Blocks.oak_stairs, 0, 2);
		world.setBlock(i + 1, j + 23, k + 10, Blocks.wooden_slab, 0, 2);
		world.setBlock(i + 1, j + 23, k + 11, Blocks.oak_stairs, 0, 2);
		world.setBlock(i + 2, j + 0, k + 4, Blocks.stonebrick, StructureGenHelper.stoneBrickMeta(rand), 2);
		world.setBlock(i + 2, j + 0, k + 5, Blocks.stonebrick, StructureGenHelper.stoneBrickMeta(rand), 2);
		world.setBlock(i + 2, j + 0, k + 6, Blocks.stonebrick, StructureGenHelper.stoneBrickMeta(rand), 2);
		world.setBlock(i + 2, j + 0, k + 7, Blocks.stonebrick, StructureGenHelper.stoneBrickMeta(rand), 2);
		world.setBlock(i + 2, j + 0, k + 8, Blocks.stonebrick, StructureGenHelper.stoneBrickMeta(rand), 2);
		world.setBlock(i + 2, j + 0, k + 9, Blocks.stonebrick, StructureGenHelper.stoneBrickMeta(rand), 2);
		world.setBlock(i + 2, j + 0, k + 10, Blocks.stonebrick, StructureGenHelper.stoneBrickMeta(rand), 2);
		world.setBlock(i + 2, j + 1, k + 4, Blocks.stonebrick, StructureGenHelper.stoneBrickMeta(rand), 2);
		world.setBlock(i + 2, j + 1, k + 5, Blocks.stonebrick, StructureGenHelper.stoneBrickMeta(rand), 2);
		world.setBlock(i + 2, j + 1, k + 6, Blocks.stonebrick, StructureGenHelper.stoneBrickMeta(rand), 2);
		world.setBlock(i + 2, j + 1, k + 7, Blocks.stonebrick, StructureGenHelper.stoneBrickMeta(rand), 2);
		world.setBlock(i + 2, j + 1, k + 8, Blocks.stonebrick, StructureGenHelper.stoneBrickMeta(rand), 2);
		world.setBlock(i + 2, j + 1, k + 9, Blocks.stonebrick, StructureGenHelper.stoneBrickMeta(rand), 2);
		world.setBlock(i + 2, j + 1, k + 10, Blocks.stonebrick, StructureGenHelper.stoneBrickMeta(rand), 2);
		world.setBlock(i + 2, j + 2, k + 4, Blocks.stonebrick, StructureGenHelper.stoneBrickMeta(rand), 2);
		world.setBlock(i + 2, j + 2, k + 5, Blocks.stonebrick, StructureGenHelper.stoneBrickMeta(rand), 2);
		world.setBlock(i + 2, j + 2, k + 6, Blocks.stonebrick, StructureGenHelper.stoneBrickMeta(rand), 2);
		world.setBlock(i + 2, j + 2, k + 7, Blocks.stonebrick, StructureGenHelper.stoneBrickMeta(rand), 2);
		world.setBlock(i + 2, j + 2, k + 8, Blocks.stonebrick, StructureGenHelper.stoneBrickMeta(rand), 2);
		world.setBlock(i + 2, j + 2, k + 9, Blocks.stonebrick, StructureGenHelper.stoneBrickMeta(rand), 2);
		world.setBlock(i + 2, j + 2, k + 10, Blocks.stonebrick, StructureGenHelper.stoneBrickMeta(rand), 2);
		world.setBlock(i + 2, j + 3, k + 4, Blocks.stonebrick, StructureGenHelper.stoneBrickMeta(rand), 2);
		world.setBlock(i + 2, j + 3, k + 5, Blocks.stonebrick, StructureGenHelper.stoneBrickMeta(rand), 2);
		world.setBlock(i + 2, j + 3, k + 7, Blocks.air);
		world.setBlock(i + 2, j + 3, k + 8, Blocks.stonebrick, StructureGenHelper.stoneBrickMeta(rand), 2);
		world.setBlock(i + 2, j + 3, k + 9, Blocks.stonebrick, StructureGenHelper.stoneBrickMeta(rand), 2);
		world.setBlock(i + 2, j + 3, k + 10, Blocks.stonebrick, StructureGenHelper.stoneBrickMeta(rand), 2);
		world.setBlock(i + 2, j + 4, k + 4, Blocks.stonebrick, StructureGenHelper.stoneBrickMeta(rand), 2);
		world.setBlock(i + 2, j + 4, k + 5, Blocks.stonebrick, StructureGenHelper.stoneBrickMeta(rand), 2);
		world.setBlock(i + 2, j + 4, k + 7, Blocks.air);
		world.setBlock(i + 2, j + 4, k + 8, Blocks.stonebrick, StructureGenHelper.stoneBrickMeta(rand), 2);
		world.setBlock(i + 2, j + 4, k + 9, Blocks.stonebrick, StructureGenHelper.stoneBrickMeta(rand), 2);
		world.setBlock(i + 2, j + 4, k + 10, Blocks.stonebrick, StructureGenHelper.stoneBrickMeta(rand), 2);
		world.setBlock(i + 2, j + 5, k + 4, Blocks.stonebrick, StructureGenHelper.stoneBrickMeta(rand), 2);
		world.setBlock(i + 2, j + 5, k + 5, Blocks.stonebrick, StructureGenHelper.stoneBrickMeta(rand), 2);
		world.setBlock(i + 2, j + 5, k + 7, Blocks.air);
		world.setBlock(i + 2, j + 5, k + 8, Blocks.stonebrick, StructureGenHelper.stoneBrickMeta(rand), 2);
		world.setBlock(i + 2, j + 5, k + 9, Blocks.stonebrick, StructureGenHelper.stoneBrickMeta(rand), 2);
		world.setBlock(i + 2, j + 5, k + 10, Blocks.stonebrick, StructureGenHelper.stoneBrickMeta(rand), 2);
		world.setBlock(i + 2, j + 6, k + 4, Blocks.stonebrick, StructureGenHelper.stoneBrickMeta(rand), 2);
		world.setBlock(i + 2, j + 6, k + 5, Blocks.stonebrick, StructureGenHelper.stoneBrickMeta(rand), 2);
		world.setBlock(i + 2, j + 6, k + 7, Blocks.air);
		world.setBlock(i + 2, j + 6, k + 8, Blocks.stonebrick, StructureGenHelper.stoneBrickMeta(rand), 2);
		world.setBlock(i + 2, j + 6, k + 9, Blocks.stonebrick, StructureGenHelper.stoneBrickMeta(rand), 2);
		world.setBlock(i + 2, j + 6, k + 10, Blocks.stonebrick, StructureGenHelper.stoneBrickMeta(rand), 2);
		world.setBlock(i + 2, j + 7, k + 4, Blocks.stonebrick, StructureGenHelper.stoneBrickMeta(rand), 2);
		world.setBlock(i + 2, j + 7, k + 5, Blocks.stonebrick, StructureGenHelper.stoneBrickMeta(rand), 2);
		world.setBlock(i + 2, j + 7, k + 7, Blocks.stonebrick, StructureGenHelper.stoneBrickMeta(rand), 2);
		world.setBlock(i + 2, j + 7, k + 8, Blocks.stonebrick, StructureGenHelper.stoneBrickMeta(rand), 2);
		world.setBlock(i + 2, j + 7, k + 9, Blocks.stonebrick, StructureGenHelper.stoneBrickMeta(rand), 2);
		world.setBlock(i + 2, j + 7, k + 10, Blocks.stonebrick, StructureGenHelper.stoneBrickMeta(rand), 2);
		world.setBlock(i + 2, j + 8, k + 5, Blocks.stonebrick, StructureGenHelper.stoneBrickMeta(rand), 2);
		world.setBlock(i + 2, j + 8, k + 6, Blocks.air);
		world.setBlock(i + 2, j + 8, k + 7, Blocks.stonebrick, StructureGenHelper.stoneBrickMeta(rand), 2);
		world.setBlock(i + 2, j + 8, k + 8, Blocks.stonebrick, StructureGenHelper.stoneBrickMeta(rand), 2);
		world.setBlock(i + 2, j + 8, k + 9, Blocks.stonebrick, StructureGenHelper.stoneBrickMeta(rand), 2);
		world.setBlock(i + 2, j + 9, k + 5, Blocks.stonebrick, StructureGenHelper.stoneBrickMeta(rand), 2);
		world.setBlock(i + 2, j + 9, k + 6, Blocks.air);
		world.setBlock(i + 2, j + 9, k + 7, Blocks.glowstone, 0, 2);
		world.setBlock(i + 2, j + 9, k + 8, Blocks.stonebrick, StructureGenHelper.stoneBrickMeta(rand), 2);
		world.setBlock(i + 2, j + 9, k + 9, Blocks.stonebrick, StructureGenHelper.stoneBrickMeta(rand), 2);
		world.setBlock(i + 2, j + 10, k + 2, Blocks.oak_stairs, 6, 2);
		world.setBlock(i + 2, j + 10, k + 3, Blocks.oak_stairs, 4, 2);
		world.setBlock(i + 2, j + 10, k + 4, Blocks.oak_stairs, 4, 2);
		world.setBlock(i + 2, j + 10, k + 5, Blocks.stonebrick, StructureGenHelper.stoneBrickMeta(rand), 2);
		world.setBlock(i + 2, j + 10, k + 6, Blocks.stonebrick, StructureGenHelper.stoneBrickMeta(rand), 2);
		world.setBlock(i + 2, j + 10, k + 7, Blocks.stonebrick, StructureGenHelper.stoneBrickMeta(rand), 2);
		world.setBlock(i + 2, j + 10, k + 8, Blocks.stonebrick, StructureGenHelper.stoneBrickMeta(rand), 2);
		world.setBlock(i + 2, j + 10, k + 9, Blocks.stonebrick, StructureGenHelper.stoneBrickMeta(rand), 2);
		world.setBlock(i + 2, j + 11, k + 1, Blocks.oak_stairs, 6, 2);
		world.setBlock(i + 2, j + 11, k + 2, Blocks.planks, 0, 2);
		world.setBlock(i + 2, j + 11, k + 3, Blocks.planks, 0, 2);
		world.setBlock(i + 2, j + 11, k + 4, Blocks.planks, 0, 2);
		world.setBlock(i + 2, j + 11, k + 5, Blocks.stonebrick, StructureGenHelper.stoneBrickMeta(rand), 2);
		world.setBlock(i + 2, j + 11, k + 6, Blocks.stonebrick, StructureGenHelper.stoneBrickMeta(rand), 2);
		world.setBlock(i + 2, j + 11, k + 7, Blocks.stonebrick, StructureGenHelper.stoneBrickMeta(rand), 2);
		world.setBlock(i + 2, j + 11, k + 8, Blocks.stonebrick, StructureGenHelper.stoneBrickMeta(rand), 2);
		world.setBlock(i + 2, j + 11, k + 9, Blocks.stonebrick, StructureGenHelper.stoneBrickMeta(rand), 2);
		world.setBlock(i + 2, j + 12, k + 1, Blocks.planks, 0, 2);
		world.setBlock(i + 2, j + 12, k + 2, Blocks.planks, 0, 2);
		world.setBlock(i + 2, j + 12, k + 3, BlockPedestal.instance, 0, 2);
		TileEntityDisplayPedestal tedd;
		TileEntity te = world.getTileEntity(i + 2, j + 12, k + 3); 
		if(te instanceof TileEntityDisplayPedestal) {
			tedd = (TileEntityDisplayPedestal)te;
			tedd.setInventorySlotContents(0, ArtifactsAPI.artifacts.generateRandomArtifact());
			tedd.rotation = 90;
		}
		world.setBlock(i + 2, j + 12, k + 4, Blocks.air);
		world.setBlock(i + 2, j + 12, k + 5, Blocks.planks, 0, 2);
		world.setBlock(i + 2, j + 12, k + 6, Blocks.stonebrick, StructureGenHelper.stoneBrickMeta(rand), 2);
		world.setBlock(i + 2, j + 12, k + 7, Blocks.stonebrick, StructureGenHelper.stoneBrickMeta(rand), 2);
		world.setBlock(i + 2, j + 12, k + 8, Blocks.stonebrick, StructureGenHelper.stoneBrickMeta(rand), 2);
		world.setBlock(i + 2, j + 13, k + 1, Blocks.planks, 0, 2);
		world.setBlock(i + 2, j + 13, k + 2, Blocks.planks, 0, 2);
		world.setBlock(i + 2, j + 13, k + 3, Blocks.air);
		world.setBlock(i + 2, j + 13, k + 4, Blocks.air);
		world.setBlock(i + 2, j + 13, k + 5, Blocks.planks, 0, 2);
		world.setBlock(i + 2, j + 13, k + 6, Blocks.stonebrick, StructureGenHelper.stoneBrickMeta(rand), 2);
		world.setBlock(i + 2, j + 13, k + 7, Blocks.stonebrick, StructureGenHelper.stoneBrickMeta(rand), 2);
		world.setBlock(i + 2, j + 13, k + 8, Blocks.stonebrick, StructureGenHelper.stoneBrickMeta(rand), 2);
		world.setBlock(i + 2, j + 14, k + 1, Blocks.planks, 0, 2);
		world.setBlock(i + 2, j + 14, k + 2, Blocks.planks, 0, 2);
		world.setBlock(i + 2, j + 14, k + 3, Blocks.air);
		world.setBlock(i + 2, j + 14, k + 4, Blocks.air);
		world.setBlock(i + 2, j + 14, k + 5, Blocks.planks, 0, 2);
		world.setBlock(i + 2, j + 14, k + 6, Blocks.stonebrick, StructureGenHelper.stoneBrickMeta(rand), 2);
		world.setBlock(i + 2, j + 14, k + 7, Blocks.stonebrick, StructureGenHelper.stoneBrickMeta(rand), 2);
		world.setBlock(i + 2, j + 14, k + 8, Blocks.stonebrick, StructureGenHelper.stoneBrickMeta(rand), 2);
		world.setBlock(i + 2, j + 15, k + 0, Blocks.oak_stairs, 0, 2);
		world.setBlock(i + 2, j + 15, k + 1, Blocks.oak_stairs, 0, 2);
		world.setBlock(i + 2, j + 15, k + 2, Blocks.planks, 0, 2);
		world.setBlock(i + 2, j + 15, k + 3, Blocks.planks, 0, 2);
		world.setBlock(i + 2, j + 15, k + 4, Blocks.planks, 0, 2);
		world.setBlock(i + 2, j + 15, k + 5, Blocks.oak_stairs, 3, 2);
		world.setBlock(i + 2, j + 15, k + 7, Blocks.stonebrick, StructureGenHelper.stoneBrickMeta(rand), 2);
		world.setBlock(i + 2, j + 16, k + 2, Blocks.oak_stairs, 2, 2);
		world.setBlock(i + 2, j + 16, k + 3, Blocks.oak_stairs, 0, 2);
		world.setBlock(i + 2, j + 16, k + 4, Blocks.oak_stairs, 0, 2);
		world.setBlock(i + 2, j + 16, k + 7, Blocks.stone_brick_stairs, 0, 2);
		world.setBlock(i + 2, j + 17, k + 9, Blocks.oak_stairs, 6, 2);
		world.setBlock(i + 2, j + 17, k + 10, Blocks.planks, 0, 2);
		world.setBlock(i + 2, j + 17, k + 11, Blocks.planks, 0, 2);
		world.setBlock(i + 2, j + 17, k + 12, Blocks.oak_stairs, 7, 2);
		world.setBlock(i + 2, j + 18, k + 8, Blocks.oak_stairs, 6, 2);
		world.setBlock(i + 2, j + 18, k + 9, Blocks.planks, 0, 2);
		world.setBlock(i + 2, j + 18, k + 10, Blocks.planks, 0, 2);
		world.setBlock(i + 2, j + 18, k + 11, Blocks.planks, 0, 2);
		world.setBlock(i + 2, j + 18, k + 12, Blocks.planks, 0, 2);
		world.setBlock(i + 2, j + 18, k + 13, Blocks.oak_stairs, 7, 2);
		world.setBlock(i + 2, j + 19, k + 8, Blocks.planks, 0, 2);
		world.setBlock(i + 2, j + 19, k + 9, Blocks.air);
		world.setBlock(i + 2, j + 19, k + 10, Blocks.air);
		world.setBlock(i + 2, j + 19, k + 11, Blocks.air);
		world.setBlock(i + 2, j + 19, k + 12, Blocks.chest, 2, 2);
		world.setBlockMetadataWithNotify(i + 2, j + 19, k + 12, 2, 2);
		te = world.getTileEntity(i + 2, j + 19, k + 12);
		if(te instanceof TileEntityChest) {
			TileEntityChest tec = (TileEntityChest)te;
			ChestGenHooks info = ChestGenHooks.getInfo(ChestGenHooks.PYRAMID_DESERT_CHEST);
            WeightedRandomChestContent.generateChestContents(rand, info.getItems(rand), tec, info.getCount(rand));
		}
		world.setBlock(i + 2, j + 19, k + 13, Blocks.planks, 0, 2);
		world.setBlock(i + 2, j + 20, k + 8, Blocks.planks, 0, 2);
		world.setBlock(i + 2, j + 20, k + 9, Blocks.air);
		world.setBlock(i + 2, j + 20, k + 10, Blocks.air);
		world.setBlock(i + 2, j + 20, k + 11, Blocks.air);
		world.setBlock(i + 2, j + 20, k + 12, Blocks.air);
		world.setBlock(i + 2, j + 20, k + 13, Blocks.planks, 0, 2);
		world.setBlock(i + 2, j + 21, k + 8, Blocks.planks, 0, 2);
		world.setBlock(i + 2, j + 21, k + 9, Blocks.planks, 0, 2);
		world.setBlock(i + 2, j + 21, k + 10, Blocks.redstone_lamp, 0, 2);
		world.setBlock(i + 2, j + 21, k + 11, Blocks.planks, 0, 2);
		world.setBlock(i + 2, j + 21, k + 12, Blocks.planks, 0, 2);
		world.setBlock(i + 2, j + 21, k + 13, Blocks.planks, 0, 2);
		world.setBlock(i + 2, j + 22, k + 8, Blocks.oak_stairs, 2, 2);
		world.setBlock(i + 2, j + 22, k + 9, Blocks.planks, 0, 2);
		world.setBlock(i + 2, j + 22, k + 11, Blocks.planks, 0, 2);
		world.setBlock(i + 2, j + 22, k + 12, Blocks.planks, 0, 2);
		world.setBlock(i + 2, j + 22, k + 13, Blocks.oak_stairs, 3, 2);
		world.setBlock(i + 2, j + 23, k + 9, Blocks.wooden_slab, 0, 2);
		world.setBlock(i + 2, j + 23, k + 10, Blocks.oak_stairs, 7, 2);
		world.setBlock(i + 2, j + 23, k + 12, Blocks.oak_stairs, 3, 2);
		//world.scheduleBlockUpdate(i + 2, j + 24, k + 11, Blocks.daylight_detector, 10);
		world.setBlock(i + 3, j + 0, k + 4, Blocks.stonebrick, StructureGenHelper.stoneBrickMeta(rand), 2);
		world.setBlock(i + 3, j + 0, k + 5, Blocks.stonebrick, StructureGenHelper.stoneBrickMeta(rand), 2);
		world.setBlock(i + 3, j + 0, k + 6, Blocks.stonebrick, StructureGenHelper.stoneBrickMeta(rand), 2);
		world.setBlock(i + 3, j + 0, k + 7, Blocks.stonebrick, StructureGenHelper.stoneBrickMeta(rand), 2);
		world.setBlock(i + 3, j + 0, k + 8, Blocks.stonebrick, StructureGenHelper.stoneBrickMeta(rand), 2);
		world.setBlock(i + 3, j + 0, k + 9, Blocks.stonebrick, StructureGenHelper.stoneBrickMeta(rand), 2);
		world.setBlock(i + 3, j + 0, k + 10, Blocks.stonebrick, StructureGenHelper.stoneBrickMeta(rand), 2);
		world.setBlock(i + 3, j + 1, k + 3, Blocks.stonebrick, StructureGenHelper.stoneBrickMeta(rand), 2);
		world.setBlock(i + 3, j + 1, k + 4, Blocks.stonebrick, StructureGenHelper.stoneBrickMeta(rand), 2);
		world.setBlock(i + 3, j + 1, k + 5, BlockSpikes.instance, 0, 2);
		world.setBlock(i + 3, j + 1, k + 6, BlockSpikes.instance, 0, 2);
		world.setBlock(i + 3, j + 1, k + 7, BlockSpikes.instance, 0, 2);
		world.setBlock(i + 3, j + 1, k + 8, Blocks.stonebrick, StructureGenHelper.stoneBrickMeta(rand), 2);
		world.setBlock(i + 3, j + 1, k + 9, Blocks.stonebrick, StructureGenHelper.stoneBrickMeta(rand), 2);
		world.setBlock(i + 3, j + 1, k + 10, Blocks.stonebrick, StructureGenHelper.stoneBrickMeta(rand), 2);
		world.setBlock(i + 3, j + 1, k + 11, Blocks.stonebrick, StructureGenHelper.stoneBrickMeta(rand), 2);
		world.setBlock(i + 3, j + 2, k + 3, Blocks.stonebrick, StructureGenHelper.stoneBrickMeta(rand), 2);
		world.setBlock(i + 3, j + 2, k + 4, Blocks.stonebrick, StructureGenHelper.stoneBrickMeta(rand), 2);
		world.setBlock(i + 3, j + 2, k + 5, BlockIllusionary.instance, 0, 2);
		world.setBlock(i + 3, j + 2, k + 6, BlockIllusionary.instance, 0, 2);
		world.setBlock(i + 3, j + 2, k + 7, BlockIllusionary.instance, 0, 2);
		world.setBlock(i + 3, j + 2, k + 8, Blocks.stonebrick, StructureGenHelper.stoneBrickMeta(rand), 2);
		world.setBlock(i + 3, j + 2, k + 9, Blocks.stonebrick, StructureGenHelper.stoneBrickMeta(rand), 2);
		world.setBlock(i + 3, j + 2, k + 10, Blocks.stonebrick, StructureGenHelper.stoneBrickMeta(rand), 2);
		world.setBlock(i + 3, j + 2, k + 11, Blocks.stonebrick, StructureGenHelper.stoneBrickMeta(rand), 2);
		world.setBlock(i + 3, j + 0, k + 3, Blocks.stonebrick, StructureGenHelper.stoneBrickMeta(rand), 2);
		world.setBlock(i + 3, j + 3, k + 4, BlockTrap.instance, 3, 2);
		te = world.getTileEntity(i + 3, j + 3, k + 4); 
		TileEntityTrap ted;
		if(te instanceof TileEntityTrap) {
			ted = (TileEntityTrap)te;
			ted.func_146019_a/*addItem*/(new ItemStack(Items.diamond_sword, 1, 1000));
		}
		world.setBlockMetadataWithNotify(i + 3, j + 3, k + 4, 3, 2);
		world.setBlock(i + 3, j + 3, k + 5, Blocks.air);
		world.setBlock(i + 3, j + 3, k + 6, Blocks.air);
		world.setBlock(i + 3, j + 3, k + 7, Blocks.air);
		world.setBlock(i + 3, j + 3, k + 8, BlockTrap.instance, 2, 2);
		te = world.getTileEntity(i + 3, j + 3, k + 8); 
		if(te instanceof TileEntityTrap) {
			ted = (TileEntityTrap)te;
			ted.func_146019_a/*addItem*/(new ItemStack(Items.diamond_sword, 1, 1000));
		}
		world.setBlockMetadataWithNotify(i + 3, j + 3, k + 8, 2, 2);
		world.setBlock(i + 3, j + 3, k + 9, Blocks.stonebrick, StructureGenHelper.stoneBrickMeta(rand), 2);
		world.setBlock(i + 3, j + 3, k + 10, Blocks.stonebrick, StructureGenHelper.stoneBrickMeta(rand), 2);
		world.setBlock(i + 3, j + 0, k + 11, Blocks.stonebrick, StructureGenHelper.stoneBrickMeta(rand), 2);
		world.setBlock(i + 3, j + 4, k + 3, Blocks.stonebrick, StructureGenHelper.stoneBrickMeta(rand), 2);
		world.setBlock(i + 3, j + 4, k + 4, Blocks.stonebrick, StructureGenHelper.stoneBrickMeta(rand), 2);
		world.setBlock(i + 3, j + 4, k + 5, Blocks.air);
		world.setBlock(i + 3, j + 4, k + 6, Blocks.air);
		world.setBlock(i + 3, j + 4, k + 7, Blocks.air);
		world.setBlock(i + 3, j + 4, k + 8, Blocks.stonebrick, StructureGenHelper.stoneBrickMeta(rand), 2);
		world.setBlock(i + 3, j + 4, k + 9, Blocks.stonebrick, StructureGenHelper.stoneBrickMeta(rand), 2);
		world.setBlock(i + 3, j + 4, k + 10, Blocks.stonebrick, StructureGenHelper.stoneBrickMeta(rand), 2);
		world.setBlock(i + 3, j + 4, k + 11, Blocks.stonebrick, StructureGenHelper.stoneBrickMeta(rand), 2);
		world.setBlock(i + 3, j + 5, k + 3, Blocks.stonebrick, StructureGenHelper.stoneBrickMeta(rand), 2);
		world.setBlock(i + 3, j + 5, k + 4, Blocks.stonebrick, StructureGenHelper.stoneBrickMeta(rand), 2);
		world.setBlock(i + 3, j + 5, k + 5, Blocks.air);
		world.setBlock(i + 3, j + 5, k + 6, Blocks.air);
		world.setBlock(i + 3, j + 5, k + 7, Blocks.air);
		world.setBlock(i + 3, j + 5, k + 8, Blocks.stonebrick, StructureGenHelper.stoneBrickMeta(rand), 2);
		world.setBlock(i + 3, j + 5, k + 9, Blocks.stonebrick, StructureGenHelper.stoneBrickMeta(rand), 2);
		world.setBlock(i + 3, j + 5, k + 10, Blocks.stonebrick, StructureGenHelper.stoneBrickMeta(rand), 2);
		world.setBlock(i + 3, j + 5, k + 11, Blocks.stonebrick, StructureGenHelper.stoneBrickMeta(rand), 2);
		world.setBlock(i + 3, j + 6, k + 3, Blocks.stonebrick, StructureGenHelper.stoneBrickMeta(rand), 2);
		world.setBlock(i + 3, j + 6, k + 4, Blocks.stonebrick, StructureGenHelper.stoneBrickMeta(rand), 2);
		world.setBlock(i + 3, j + 6, k + 5, Blocks.air);
		world.setBlock(i + 3, j + 6, k + 6, Blocks.air);
		world.setBlock(i + 3, j + 6, k + 7, Blocks.air);
		world.setBlock(i + 3, j + 6, k + 8, Blocks.stonebrick, StructureGenHelper.stoneBrickMeta(rand), 2);
		world.setBlock(i + 3, j + 6, k + 9, Blocks.stonebrick, StructureGenHelper.stoneBrickMeta(rand), 2);
		world.setBlock(i + 3, j + 6, k + 10, Blocks.stonebrick, StructureGenHelper.stoneBrickMeta(rand), 2);
		world.setBlock(i + 3, j + 6, k + 11, Blocks.stonebrick, StructureGenHelper.stoneBrickMeta(rand), 2);
		world.setBlock(i + 3, j + 7, k + 3, Blocks.stonebrick, StructureGenHelper.stoneBrickMeta(rand), 2);
		world.setBlock(i + 3, j + 7, k + 4, Blocks.stonebrick, StructureGenHelper.stoneBrickMeta(rand), 2);
		world.setBlock(i + 3, j + 7, k + 5, Blocks.stonebrick, StructureGenHelper.stoneBrickMeta(rand), 2);
		world.setBlock(i + 3, j + 7, k + 6, Blocks.stonebrick, StructureGenHelper.stoneBrickMeta(rand), 2);
		world.setBlock(i + 3, j + 7, k + 7, BlockTrap.instance, 1, 2);
		world.setBlockMetadataWithNotify(i + 3, j + 7, k + 7, 1, 2);
		te = world.getTileEntity(i + 3, j + 7, k + 7); 
		if(te instanceof TileEntityTrap) {
			ted = (TileEntityTrap)te;
			ted.func_146019_a/*addItem*/(new ItemStack(Items.arrow, 32));
		}
		world.setBlock(i + 3, j + 8, k + 7, StructureGenHelper.randomBlock(rand, new Block[]{BlockArtifactsPressurePlate.invisObsidian, BlockArtifactsPressurePlate.invisObsidian, BlockArtifactsPressurePlate.invisObsidian, BlockArtifactsPressurePlate.invisObsidian, BlockArtifactsPressurePlate.invisObsidian, BlockArtifactsPressurePlate.invisObsidian, BlockArtifactsPressurePlate.invisObsidian, BlockArtifactsPressurePlate.camoObsidian}), 0, 2);
		world.setBlock(i + 3, j + 7, k + 8, Blocks.stonebrick, StructureGenHelper.stoneBrickMeta(rand), 2);
		world.setBlock(i + 3, j + 7, k + 9, Blocks.stonebrick, StructureGenHelper.stoneBrickMeta(rand), 2);
		world.setBlock(i + 3, j + 7, k + 10, Blocks.stonebrick, StructureGenHelper.stoneBrickMeta(rand), 2);
		world.setBlock(i + 3, j + 7, k + 11, Blocks.stonebrick, StructureGenHelper.stoneBrickMeta(rand), 2);
		world.setBlock(i + 3, j + 8, k + 4, Blocks.stonebrick, StructureGenHelper.stoneBrickMeta(rand), 2);
		world.setBlock(i + 3, j + 8, k + 5, Blocks.stonebrick, StructureGenHelper.stoneBrickMeta(rand), 2);
		world.setBlock(i + 3, j + 8, k + 6, Blocks.air);
		//world.setBlock(i + 3, j + 8, k + 7, Blocks.air);
		world.setBlock(i + 3, j + 8, k + 9, Blocks.stonebrick, StructureGenHelper.stoneBrickMeta(rand), 2);
		world.setBlock(i + 3, j + 8, k + 10, Blocks.stonebrick, StructureGenHelper.stoneBrickMeta(rand), 2);
		world.setBlock(i + 3, j + 9, k + 4, Blocks.stonebrick, StructureGenHelper.stoneBrickMeta(rand), 2);
		world.setBlock(i + 3, j + 9, k + 5, Blocks.stonebrick, StructureGenHelper.stoneBrickMeta(rand), 2);
		world.setBlock(i + 3, j + 9, k + 6, Blocks.air);
		world.setBlock(i + 3, j + 9, k + 7, Blocks.air);
		world.setBlock(i + 3, j + 9, k + 9, Blocks.stonebrick, StructureGenHelper.stoneBrickMeta(rand), 2);
		world.setBlock(i + 3, j + 9, k + 10, Blocks.stonebrick, StructureGenHelper.stoneBrickMeta(rand), 2);
		world.setBlock(i + 3, j + 10, k + 1, Blocks.oak_stairs, 4, 2);
		world.setBlock(i + 3, j + 10, k + 2, Blocks.oak_stairs, 4, 2);
		world.setBlock(i + 3, j + 10, k + 3, Blocks.planks, 0, 2);
		world.setBlock(i + 3, j + 10, k + 4, Blocks.stonebrick, StructureGenHelper.stoneBrickMeta(rand), 2);
		world.setBlock(i + 3, j + 10, k + 5, Blocks.stonebrick, StructureGenHelper.stoneBrickMeta(rand), 2);
		world.setBlock(i + 3, j + 10, k + 6, Blocks.air);
		world.setBlock(i + 3, j + 10, k + 7, Blocks.air);
		world.setBlock(i + 3, j + 10, k + 9, Blocks.stonebrick, StructureGenHelper.stoneBrickMeta(rand), 2);
		world.setBlock(i + 3, j + 10, k + 10, Blocks.stonebrick, StructureGenHelper.stoneBrickMeta(rand), 2);
		world.setBlock(i + 3, j + 11, k + 0, Blocks.oak_stairs, 6, 2);
		world.setBlock(i + 3, j + 11, k + 1, Blocks.planks, 0, 2);
		world.setBlock(i + 3, j + 11, k + 2, Blocks.planks, 0, 2);
		world.setBlock(i + 3, j + 11, k + 3, Blocks.planks, 0, 2);
		world.setBlock(i + 3, j + 11, k + 5, Blocks.stonebrick, StructureGenHelper.stoneBrickMeta(rand), 2);
		world.setBlock(i + 3, j + 11, k + 6, Blocks.stonebrick, StructureGenHelper.stoneBrickMeta(rand), 2);
		world.setBlock(i + 3, j + 11, k + 7, Blocks.stonebrick, StructureGenHelper.stoneBrickMeta(rand), 2);
		world.setBlock(i + 3, j + 11, k + 9, Blocks.stonebrick, StructureGenHelper.stoneBrickMeta(rand), 2);
		world.setBlock(i + 3, j + 12, k + 0, Blocks.planks, 0, 2);
		world.setBlock(i + 3, j + 12, k + 1, Blocks.stonebrick, StructureGenHelper.stoneBrickMeta(rand), 2);
		world.setBlock(i + 3, j + 12, k + 2, Blocks.planks, 0, 2);
		world.setBlock(i + 3, j + 12, k + 3, Blocks.air);
		world.setBlock(i + 3, j + 12, k + 4, Blocks.air);
		world.setBlock(i + 3, j + 12, k + 5, Blocks.stonebrick, StructureGenHelper.stoneBrickMeta(rand), 2);
		world.setBlock(i + 3, j + 12, k + 6, Blocks.stonebrick, StructureGenHelper.stoneBrickMeta(rand), 2);
		world.setBlock(i + 3, j + 12, k + 7, Blocks.air);
		world.setBlock(i + 3, j + 12, k + 8, Blocks.air);
		world.setBlock(i + 3, j + 12, k + 9, Blocks.stonebrick, StructureGenHelper.stoneBrickMeta(rand), 2);
		world.setBlock(i + 3, j + 13, k + 0, Blocks.planks, 0, 2);
		world.setBlock(i + 3, j + 13, k + 1, Blocks.stonebrick, StructureGenHelper.stoneBrickMeta(rand), 2);
		world.setBlock(i + 3, j + 13, k + 2, Blocks.planks, 0, 2);
		world.setBlock(i + 3, j + 13, k + 3, Blocks.air);
		world.setBlock(i + 3, j + 13, k + 4, Blocks.air);
		world.setBlock(i + 3, j + 13, k + 5, Blocks.stonebrick, StructureGenHelper.stoneBrickMeta(rand), 2);
		world.setBlock(i + 3, j + 13, k + 6, Blocks.stonebrick, StructureGenHelper.stoneBrickMeta(rand), 2);
		world.setBlock(i + 3, j + 13, k + 7, Blocks.air);
		//world.setBlock(i + 3, j + 13, k + 8, Blocks.stonebrick, StructureGenHelper.stoneBrickMeta(rand), 2);
		world.setBlock(i + 3, j + 13, k + 9, Blocks.stonebrick, StructureGenHelper.stoneBrickMeta(rand), 2);
		world.setBlock(i + 3, j + 14, k + 0, Blocks.planks, 0, 2);
		world.setBlock(i + 3, j + 14, k + 2, Blocks.planks, 0, 2);
		world.setBlock(i + 3, j + 14, k + 3, Blocks.air);
		world.setBlock(i + 3, j + 14, k + 4, Blocks.air);
		world.setBlock(i + 3, j + 14, k + 5, Blocks.stonebrick, StructureGenHelper.stoneBrickMeta(rand), 2);
		world.setBlock(i + 3, j + 14, k + 6, Blocks.stonebrick, StructureGenHelper.stoneBrickMeta(rand), 2);
		world.setBlock(i + 3, j + 14, k + 7, Blocks.air);
		world.setBlock(i + 3, j + 14, k + 8, Blocks.air);
		world.setBlock(i + 3, j + 14, k + 9, Blocks.stonebrick, StructureGenHelper.stoneBrickMeta(rand), 2);
		world.setBlock(i + 3, j + 15, k + 0, Blocks.oak_stairs, 2, 2);
		world.setBlock(i + 3, j + 14, k + 1, Blocks.planks, 15, 2);
		world.setBlock(i + 3, j + 15, k + 1, Blocks.redstone_wire, 0, 2);
		//world.scheduleBlockUpdate(i + 3, j + 15, k + 1, Blocks.daylight_detector, 10);
		world.setBlock(i + 4, j + 15, k + 2, Blocks.planks, 0, 2);
		world.setBlock(i + 4, j + 16, k + 2, Blocks.redstone_wire, 0, 2);
		world.setBlock(i + 3, j + 15, k + 2, Blocks.unlit_redstone_torch, 2, 2);
		world.setBlock(i + 3, j + 15, k + 3, Blocks.planks, 0, 2);
		world.setBlock(i + 3, j + 15, k + 4, Blocks.planks, 0, 2);
		world.setBlock(i + 3, j + 15, k + 5, Blocks.stonebrick, StructureGenHelper.stoneBrickMeta(rand), 2);
		world.setBlock(i + 3, j + 15, k + 6, Blocks.stonebrick, StructureGenHelper.stoneBrickMeta(rand), 2);
		world.setBlock(i + 3, j + 15, k + 7, Blocks.stonebrick, StructureGenHelper.stoneBrickMeta(rand), 2);
		world.setBlock(i + 3, j + 15, k + 8, Blocks.stonebrick, StructureGenHelper.stoneBrickMeta(rand), 2);
		world.setBlock(i + 3, j + 15, k + 9, Blocks.stonebrick, StructureGenHelper.stoneBrickMeta(rand), 2);
		world.setBlock(i + 3, j + 16, k + 1, Blocks.oak_stairs, 2, 2);
		world.setBlock(i + 3, j + 16, k + 2, Blocks.oak_stairs, 0, 2);
		world.setBlock(i + 3, j + 16, k + 3, Blocks.planks, 0, 2);
		world.setBlock(i + 3, j + 16, k + 4, Blocks.oak_stairs, 3, 2);
		world.setBlock(i + 3, j + 16, k + 5, Blocks.oak_stairs, 0, 2);
		world.setBlock(i + 3, j + 16, k + 6, Blocks.stonebrick, StructureGenHelper.stoneBrickMeta(rand), 2);
		world.setBlock(i + 3, j + 16, k + 7, Blocks.stonebrick, StructureGenHelper.stoneBrickMeta(rand), 2);
		world.setBlock(i + 3, j + 16, k + 8, Blocks.stonebrick, StructureGenHelper.stoneBrickMeta(rand), 2);
		world.setBlock(i + 3, j + 17, k + 3, Blocks.oak_stairs, 0, 2);
		world.setBlock(i + 3, j + 17, k + 6, Blocks.stonebrick, StructureGenHelper.stoneBrickMeta(rand), 2);
		world.setBlock(i + 3, j + 17, k + 7, Blocks.stonebrick, StructureGenHelper.stoneBrickMeta(rand), 2);
		world.setBlock(i + 3, j + 17, k + 8, Blocks.stonebrick, StructureGenHelper.stoneBrickMeta(rand), 2);
		world.setBlock(i + 3, j + 17, k + 9, Blocks.oak_stairs, 6, 2);
		world.setBlock(i + 3, j + 17, k + 10, Blocks.oak_stairs, 5, 2);
		world.setBlock(i + 3, j + 17, k + 11, Blocks.oak_stairs, 5, 2);
		world.setBlock(i + 3, j + 17, k + 12, Blocks.oak_stairs, 7, 2);
		world.setBlock(i + 3, j + 18, k + 7, Blocks.stonebrick, StructureGenHelper.stoneBrickMeta(rand), 2);
		world.setBlock(i + 3, j + 18, k + 8, Blocks.planks, 0, 2);
		world.setBlock(i + 3, j + 18, k + 9, Blocks.planks, 0, 2);
		world.setBlock(i + 3, j + 18, k + 10, Blocks.planks, 0, 2);
		world.setBlock(i + 3, j + 18, k + 11, Blocks.planks, 0, 2);
		world.setBlock(i + 3, j + 18, k + 12, Blocks.planks, 0, 2);
		world.setBlock(i + 3, j + 18, k + 13, Blocks.oak_stairs, 7, 2);
		world.setBlock(i + 3, j + 19, k + 7, Blocks.planks, 0, 2);
		world.setBlock(i + 3, j + 19, k + 8, Blocks.planks, 0, 2);
		world.setBlock(i + 3, j + 19, k + 9, Blocks.air);
		world.setBlock(i + 3, j + 19, k + 10, Blocks.air);
		world.setBlock(i + 3, j + 19, k + 11, Blocks.air);
		world.setBlock(i + 3, j + 19, k + 12, Blocks.air);
		world.setBlock(i + 3, j + 19, k + 13, Blocks.planks, 0, 2);
		world.setBlock(i + 3, j + 20, k + 7, Blocks.planks, 0, 2);
		world.setBlock(i + 3, j + 20, k + 8, Blocks.planks, 0, 2);
		world.setBlock(i + 3, j + 20, k + 9, Blocks.air);
		world.setBlock(i + 3, j + 20, k + 10, Blocks.air);
		world.setBlock(i + 3, j + 20, k + 11, Blocks.air);
		world.setBlock(i + 3, j + 20, k + 12, Blocks.air);
		world.setBlock(i + 3, j + 20, k + 13, Blocks.planks, 0, 2);
		world.setBlock(i + 3, j + 21, k + 7, Blocks.oak_stairs, 2, 2);
		world.setBlock(i + 3, j + 21, k + 8, Blocks.planks, 0, 2);
		world.setBlock(i + 3, j + 21, k + 9, Blocks.planks, 0, 2);
		world.setBlock(i + 3, j + 21, k + 10, Blocks.planks, 0, 2);
		world.setBlock(i + 3, j + 21, k + 11, Blocks.planks, 0, 2);
		world.setBlock(i + 3, j + 21, k + 12, Blocks.planks, 0, 2);
		world.setBlock(i + 3, j + 21, k + 13, Blocks.planks, 0, 2);
		world.setBlock(i + 3, j + 22, k + 8, Blocks.oak_stairs, 2, 2);
		world.setBlock(i + 3, j + 22, k + 9, Blocks.oak_stairs, 1, 2);
		world.setBlock(i + 3, j + 22, k + 10, Blocks.planks, 0, 2);
		world.setBlock(i + 3, j + 22, k + 11, Blocks.planks, 0, 2);
		world.setBlock(i + 3, j + 22, k + 12, Blocks.oak_stairs, 1, 2);
		world.setBlock(i + 3, j + 22, k + 13, Blocks.oak_stairs, 3, 2);
		world.setBlock(i + 3, j + 23, k + 10, Blocks.oak_stairs, 1, 2);
		world.setBlock(i + 3, j + 23, k + 11, Blocks.oak_stairs, 1, 2);
		world.setBlock(i + 3, j + 28, k + 6, Blocks.stone_brick_stairs, 4, 2);
		world.setBlock(i + 3, j + 28, k + 7, Blocks.stone_brick_stairs, 4, 2);
		world.setBlock(i + 3, j + 28, k + 8, Blocks.stone_brick_stairs, 4, 2);
		world.setBlock(i + 3, j + 29, k + 6, Blocks.stonebrick, StructureGenHelper.stoneBrickMeta(rand), 2);
		world.setBlock(i + 3, j + 29, k + 7, Blocks.stonebrick, StructureGenHelper.stoneBrickMeta(rand), 2);
		world.setBlock(i + 3, j + 29, k + 8, Blocks.stonebrick, StructureGenHelper.stoneBrickMeta(rand), 2);
		world.setBlock(i + 3, j + 30, k + 6, Blocks.stone_brick_stairs, 3, 2);
		world.setBlock(i + 3, j + 30, k + 8, Blocks.stone_brick_stairs, 2, 2);
		world.setBlock(i + 4, j + 0, k + 3, Blocks.stonebrick, StructureGenHelper.stoneBrickMeta(rand), 2);
		world.setBlock(i + 4, j + 0, k + 4, Blocks.stonebrick, StructureGenHelper.stoneBrickMeta(rand), 2);
		world.setBlock(i + 4, j + 0, k + 5, Blocks.stonebrick, StructureGenHelper.stoneBrickMeta(rand), 2);
		world.setBlock(i + 4, j + 0, k + 6, Blocks.stonebrick, StructureGenHelper.stoneBrickMeta(rand), 2);
		world.setBlock(i + 4, j + 0, k + 7, Blocks.stonebrick, StructureGenHelper.stoneBrickMeta(rand), 2);
		world.setBlock(i + 4, j + 0, k + 8, Blocks.stonebrick, StructureGenHelper.stoneBrickMeta(rand), 2);
		world.setBlock(i + 4, j + 0, k + 9, Blocks.stonebrick, StructureGenHelper.stoneBrickMeta(rand), 2);
		world.setBlock(i + 4, j + 0, k + 10, Blocks.stonebrick, StructureGenHelper.stoneBrickMeta(rand), 2);
		world.setBlock(i + 4, j + 0, k + 11, Blocks.stonebrick, StructureGenHelper.stoneBrickMeta(rand), 2);
		world.setBlock(i + 4, j + 1, k + 3, Blocks.stonebrick, StructureGenHelper.stoneBrickMeta(rand), 2);
		world.setBlock(i + 4, j + 1, k + 4, Blocks.stonebrick, StructureGenHelper.stoneBrickMeta(rand), 2);
		world.setBlock(i + 4, j + 1, k + 5, BlockSpikes.instance, 0, 2);
		world.setBlock(i + 4, j + 1, k + 6, BlockSpikes.instance, 0, 2);
		world.setBlock(i + 4, j + 1, k + 7, BlockSpikes.instance, 0, 2);
		world.setBlock(i + 4, j + 1, k + 8, Blocks.stonebrick, StructureGenHelper.stoneBrickMeta(rand), 2);
		world.setBlock(i + 4, j + 1, k + 9, Blocks.stonebrick, StructureGenHelper.stoneBrickMeta(rand), 2);
		world.setBlock(i + 4, j + 1, k + 10, Blocks.stonebrick, StructureGenHelper.stoneBrickMeta(rand), 2);
		world.setBlock(i + 4, j + 1, k + 11, Blocks.stonebrick, StructureGenHelper.stoneBrickMeta(rand), 2);
		world.setBlock(i + 4, j + 2, k + 3, Blocks.stonebrick, StructureGenHelper.stoneBrickMeta(rand), 2);
		world.setBlock(i + 4, j + 2, k + 4, BlockIllusionary.instance, 0, 2);
		world.setBlock(i + 4, j + 2, k + 5, BlockIllusionary.instance, 0, 2);
		world.setBlock(i + 4, j + 2, k + 6, BlockIllusionary.instance, 0, 2);
		world.setBlock(i + 4, j + 2, k + 7, BlockIllusionary.instance, 0, 2);
		world.setBlock(i + 4, j + 2, k + 8, BlockIllusionary.instance, 0, 2);
		world.setBlock(i + 4, j + 2, k + 9, Blocks.stonebrick, StructureGenHelper.stoneBrickMeta(rand), 2);
		world.setBlock(i + 4, j + 2, k + 10, Blocks.stonebrick, StructureGenHelper.stoneBrickMeta(rand), 2);
		world.setBlock(i + 4, j + 2, k + 11, Blocks.stonebrick, StructureGenHelper.stoneBrickMeta(rand), 2);
		world.setBlock(i + 4, j + 3, k + 3, Blocks.stonebrick, StructureGenHelper.stoneBrickMeta(rand), 2);
		world.setBlock(i + 4, j + 3, k + 4, Blocks.tripwire_hook, 0, 2);
		world.setBlock(i + 4, j + 3, k + 8, Blocks.tripwire_hook, 2, 2);
		world.setBlock(i + 4, j + 3, k + 9, Blocks.stonebrick, StructureGenHelper.stoneBrickMeta(rand), 2);
		world.setBlock(i + 4, j + 3, k + 10, Blocks.stonebrick, StructureGenHelper.stoneBrickMeta(rand), 2);
		world.setBlock(i + 4, j + 3, k + 11, Blocks.stonebrick, StructureGenHelper.stoneBrickMeta(rand), 2);
		world.setBlock(i + 4, j + 4, k + 3, Blocks.stonebrick, StructureGenHelper.stoneBrickMeta(rand), 2);
		world.setBlock(i + 4, j + 4, k + 4, BlockTrap.instance, 3, 2);
		te = world.getTileEntity(i + 4, j + 4, k + 4); 
		if(te instanceof TileEntityTrap) {
			ted = (TileEntityTrap)te;
			ted.func_146019_a/*addItem*/(new ItemStack(Items.potionitem, 8, 16384+8204));
		}
		world.setBlockMetadataWithNotify(i + 4, j + 4, k + 4, 3, 2);
		world.setBlock(i + 4, j + 4, k + 5, Blocks.air);
		world.setBlock(i + 4, j + 4, k + 6, Blocks.air);
		world.setBlock(i + 4, j + 4, k + 7, Blocks.air);
		world.setBlock(i + 4, j + 4, k + 8, BlockTrap.instance, 2, 2);
		te = world.getTileEntity(i + 4, j + 4, k + 8); 
		if(te instanceof TileEntityTrap) {
			ted = (TileEntityTrap)te;
			ted.func_146019_a/*addItem*/(new ItemStack(Items.potionitem, 8, 16384+8234));
		}
		world.setBlockMetadataWithNotify(i + 4, j + 4, k + 8, 2, 2);
		world.setBlock(i + 4, j + 4, k + 9, Blocks.stonebrick, StructureGenHelper.stoneBrickMeta(rand), 2);
		world.setBlock(i + 4, j + 4, k + 10, Blocks.stonebrick, StructureGenHelper.stoneBrickMeta(rand), 2);
		world.setBlock(i + 4, j + 4, k + 11, Blocks.stonebrick, StructureGenHelper.stoneBrickMeta(rand), 2);
		world.setBlock(i + 4, j + 5, k + 3, Blocks.stonebrick, StructureGenHelper.stoneBrickMeta(rand), 2);
		world.setBlock(i + 4, j + 5, k + 4, Blocks.stonebrick, StructureGenHelper.stoneBrickMeta(rand), 2);
		world.setBlock(i + 4, j + 5, k + 5, Blocks.air);
		world.setBlock(i + 4, j + 5, k + 6, Blocks.air);
		world.setBlock(i + 4, j + 5, k + 7, Blocks.air);
		world.setBlock(i + 4, j + 5, k + 8, Blocks.stonebrick, StructureGenHelper.stoneBrickMeta(rand), 2);
		world.setBlock(i + 4, j + 5, k + 9, Blocks.stonebrick, StructureGenHelper.stoneBrickMeta(rand), 2);
		world.setBlock(i + 4, j + 5, k + 10, Blocks.stonebrick, StructureGenHelper.stoneBrickMeta(rand), 2);
		world.setBlock(i + 4, j + 5, k + 11, Blocks.stonebrick, StructureGenHelper.stoneBrickMeta(rand), 2);
		world.setBlock(i + 4, j + 6, k + 3, Blocks.stonebrick, StructureGenHelper.stoneBrickMeta(rand), 2);
		world.setBlock(i + 4, j + 6, k + 4, Blocks.stonebrick, StructureGenHelper.stoneBrickMeta(rand), 2);
		world.setBlock(i + 4, j + 6, k + 5, Blocks.air);
		world.setBlock(i + 4, j + 6, k + 6, Blocks.air);
		world.setBlock(i + 4, j + 6, k + 7, Blocks.air);
		world.setBlock(i + 4, j + 6, k + 8, Blocks.stonebrick, StructureGenHelper.stoneBrickMeta(rand), 2);
		world.setBlock(i + 4, j + 6, k + 9, Blocks.stonebrick, StructureGenHelper.stoneBrickMeta(rand), 2);
		world.setBlock(i + 4, j + 6, k + 10, Blocks.stonebrick, StructureGenHelper.stoneBrickMeta(rand), 2);
		world.setBlock(i + 4, j + 6, k + 11, Blocks.stonebrick, StructureGenHelper.stoneBrickMeta(rand), 2);
		world.setBlock(i + 4, j + 7, k + 3, Blocks.stonebrick, StructureGenHelper.stoneBrickMeta(rand), 2);
		world.setBlock(i + 4, j + 7, k + 4, Blocks.stonebrick, StructureGenHelper.stoneBrickMeta(rand), 2);
		world.setBlock(i + 4, j + 7, k + 5, Blocks.stonebrick, StructureGenHelper.stoneBrickMeta(rand), 2);
		world.setBlock(i + 4, j + 7, k + 6, Blocks.stonebrick, StructureGenHelper.stoneBrickMeta(rand), 2);
		world.setBlock(i + 4, j + 7, k + 7, Blocks.stonebrick, StructureGenHelper.stoneBrickMeta(rand), 2);
		world.setBlock(i + 4, j + 7, k + 8, Blocks.stonebrick, StructureGenHelper.stoneBrickMeta(rand), 2);
		world.setBlock(i + 4, j + 7, k + 9, Blocks.stonebrick, StructureGenHelper.stoneBrickMeta(rand), 2);
		world.setBlock(i + 4, j + 7, k + 10, Blocks.stonebrick, StructureGenHelper.stoneBrickMeta(rand), 2);
		world.setBlock(i + 4, j + 7, k + 11, Blocks.stonebrick, StructureGenHelper.stoneBrickMeta(rand), 2);
		world.setBlock(i + 4, j + 8, k + 3, Blocks.stonebrick, StructureGenHelper.stoneBrickMeta(rand), 2);
		world.setBlock(i + 4, j + 8, k + 4, Blocks.stonebrick, StructureGenHelper.stoneBrickMeta(rand), 2);
		world.setBlock(i + 4, j + 8, k + 5, Blocks.stonebrick, StructureGenHelper.stoneBrickMeta(rand), 2);
		world.setBlock(i + 4, j + 8, k + 6, Blocks.stonebrick, StructureGenHelper.stoneBrickMeta(rand), 2);
		world.setBlock(i + 4, j + 8, k + 7, Blocks.stonebrick, StructureGenHelper.stoneBrickMeta(rand), 2);
		world.setBlock(i + 4, j + 8, k + 8, Blocks.stonebrick, StructureGenHelper.stoneBrickMeta(rand), 2);
		world.setBlock(i + 4, j + 8, k + 9, Blocks.stonebrick, StructureGenHelper.stoneBrickMeta(rand), 2);
		world.setBlock(i + 4, j + 8, k + 10, Blocks.stonebrick, StructureGenHelper.stoneBrickMeta(rand), 2);
		world.setBlock(i + 4, j + 8, k + 11, Blocks.stonebrick, StructureGenHelper.stoneBrickMeta(rand), 2);
		world.setBlock(i + 4, j + 9, k + 3, Blocks.stonebrick, StructureGenHelper.stoneBrickMeta(rand), 2);
		world.setBlock(i + 4, j + 9, k + 4, Blocks.stonebrick, StructureGenHelper.stoneBrickMeta(rand), 2);
		world.setBlock(i + 4, j + 9, k + 5, Blocks.stonebrick, StructureGenHelper.stoneBrickMeta(rand), 2);
		world.setBlock(i + 4, j + 9, k + 6, Blocks.stonebrick, StructureGenHelper.stoneBrickMeta(rand), 2);
		world.setBlock(i + 4, j + 9, k + 7, Blocks.stonebrick, StructureGenHelper.stoneBrickMeta(rand), 2);
		world.setBlock(i + 4, j + 9, k + 8, Blocks.stonebrick, StructureGenHelper.stoneBrickMeta(rand), 2);
		world.setBlock(i + 4, j + 9, k + 9, Blocks.stonebrick, StructureGenHelper.stoneBrickMeta(rand), 2);
		world.setBlock(i + 4, j + 9, k + 10, Blocks.stonebrick, StructureGenHelper.stoneBrickMeta(rand), 2);
		world.setBlock(i + 4, j + 9, k + 11, Blocks.stonebrick, StructureGenHelper.stoneBrickMeta(rand), 2);
		world.setBlock(i + 4, j + 10, k + 1, Blocks.oak_stairs, 6, 2);
		world.setBlock(i + 4, j + 10, k + 2, Blocks.planks, 0, 2);
		world.setBlock(i + 4, j + 10, k + 3, Blocks.stonebrick, StructureGenHelper.stoneBrickMeta(rand), 2);
		world.setBlock(i + 4, j + 10, k + 4, Blocks.stonebrick, StructureGenHelper.stoneBrickMeta(rand), 2);
		world.setBlock(i + 4, j + 10, k + 5, Blocks.stonebrick, StructureGenHelper.stoneBrickMeta(rand), 2);
		world.setBlock(i + 4, j + 10, k + 6, Blocks.stonebrick, StructureGenHelper.stoneBrickMeta(rand), 2);
		world.setBlock(i + 4, j + 10, k + 7, Blocks.stonebrick, StructureGenHelper.stoneBrickMeta(rand), 2);
		world.setBlock(i + 4, j + 10, k + 8, Blocks.stonebrick, StructureGenHelper.stoneBrickMeta(rand), 2);
		world.setBlock(i + 4, j + 10, k + 9, Blocks.stonebrick, StructureGenHelper.stoneBrickMeta(rand), 2);
		world.setBlock(i + 4, j + 10, k + 10, Blocks.stonebrick, StructureGenHelper.stoneBrickMeta(rand), 2);
		world.setBlock(i + 4, j + 10, k + 11, Blocks.stonebrick, StructureGenHelper.stoneBrickMeta(rand), 2);
		world.setBlock(i + 4, j + 11, k + 0, Blocks.oak_stairs, 6, 2);
		world.setBlock(i + 4, j + 11, k + 1, Blocks.planks, 0, 2);
		world.setBlock(i + 4, j + 11, k + 2, Blocks.planks, 0, 2);
		world.setBlock(i + 4, j + 11, k + 3, Blocks.stonebrick, StructureGenHelper.stoneBrickMeta(rand), 2);
		world.setBlock(i + 4, j + 11, k + 4, Blocks.stonebrick, StructureGenHelper.stoneBrickMeta(rand), 2);
		world.setBlock(i + 4, j + 11, k + 5, Blocks.stonebrick, StructureGenHelper.stoneBrickMeta(rand), 2);
		world.setBlock(i + 4, j + 11, k + 6, Blocks.stonebrick, StructureGenHelper.stoneBrickMeta(rand), 2);
		world.setBlock(i + 4, j + 11, k + 7, Blocks.stonebrick, StructureGenHelper.stoneBrickMeta(rand), 2);
		world.setBlock(i + 4, j + 11, k + 8, Blocks.stonebrick, StructureGenHelper.stoneBrickMeta(rand), 2);
		world.setBlock(i + 4, j + 11, k + 9, Blocks.stonebrick, StructureGenHelper.stoneBrickMeta(rand), 2);
		world.setBlock(i + 4, j + 11, k + 10, Blocks.stonebrick, StructureGenHelper.stoneBrickMeta(rand), 2);
		world.setBlock(i + 4, j + 11, k + 11, Blocks.stonebrick, StructureGenHelper.stoneBrickMeta(rand), 2);
		world.setBlock(i + 4, j + 12, k + 0, Blocks.planks, 0, 2);
		world.setBlock(i + 4, j + 12, k + 1, Blocks.stonebrick, StructureGenHelper.stoneBrickMeta(rand), 2);
		world.setBlock(i + 4, j + 12, k + 2, Blocks.planks, 0, 2);
		world.setBlock(i + 4, j + 12, k + 3, Blocks.air);
		world.setBlock(i + 4, j + 12, k + 4, Blocks.stonebrick, StructureGenHelper.stoneBrickMeta(rand), 2);
		world.setBlock(i + 4, j + 12, k + 5, Blocks.stonebrick, StructureGenHelper.stoneBrickMeta(rand), 2);
		world.setBlock(i + 4, j + 12, k + 6, Blocks.stonebrick, StructureGenHelper.stoneBrickMeta(rand), 2);
		world.setBlock(i + 4, j + 12, k + 8, Blocks.glowstone, 0, 2);
		world.setBlock(i + 4, j + 12, k + 9, Blocks.stonebrick, StructureGenHelper.stoneBrickMeta(rand), 2);
		world.setBlock(i + 4, j + 12, k + 10, Blocks.stonebrick, StructureGenHelper.stoneBrickMeta(rand), 2);
		world.setBlock(i + 4, j + 13, k + 0, Blocks.planks, 0, 2);
		world.setBlock(i + 4, j + 13, k + 2, Blocks.planks, 0, 2);
		world.setBlock(i + 4, j + 13, k + 3, Blocks.air);
		world.setBlock(i + 4, j + 13, k + 4, Blocks.redstone_lamp, 0, 2);
		world.setBlock(i + 4, j + 13, k + 5, Blocks.stonebrick, StructureGenHelper.stoneBrickMeta(rand), 2);
		world.setBlock(i + 4, j + 13, k + 6, Blocks.stonebrick, StructureGenHelper.stoneBrickMeta(rand), 2);
		world.setBlock(i + 4, j + 13, k + 9, Blocks.stonebrick, StructureGenHelper.stoneBrickMeta(rand), 2);
		world.setBlock(i + 4, j + 13, k + 10, Blocks.stonebrick, StructureGenHelper.stoneBrickMeta(rand), 2);
		world.setBlock(i + 4, j + 14, k + 0, Blocks.planks, 0, 2);
		world.setBlock(i + 4, j + 14, k + 1, Blocks.unlit_redstone_torch, 1, 2);
		world.setBlock(i + 4, j + 14, k + 2, Blocks.planks, 0, 2);
		world.setBlock(i + 4, j + 14, k + 3, Blocks.air);
		world.setBlock(i + 4, j + 14, k + 4, Blocks.stonebrick, StructureGenHelper.stoneBrickMeta(rand), 2);
		world.setBlock(i + 4, j + 14, k + 5, Blocks.stonebrick, StructureGenHelper.stoneBrickMeta(rand), 2);
		world.setBlock(i + 4, j + 14, k + 6, Blocks.stonebrick, StructureGenHelper.stoneBrickMeta(rand), 2);
		world.setBlock(i + 4, j + 14, k + 8, Blocks.stonebrick, StructureGenHelper.stoneBrickMeta(rand), 2);
		world.setBlock(i + 4, j + 14, k + 9, Blocks.stonebrick, StructureGenHelper.stoneBrickMeta(rand), 2);
		world.setBlock(i + 4, j + 14, k + 10, Blocks.stonebrick, StructureGenHelper.stoneBrickMeta(rand), 2);
		world.setBlock(i + 4, j + 15, k + 0, Blocks.oak_stairs, 2, 2);
		world.setBlock(i + 4, j + 15, k + 1, Blocks.air);
		world.setBlock(i + 4, j + 15, k + 3, Blocks.planks, 0, 2);
		world.setBlock(i + 4, j + 15, k + 4, Blocks.stonebrick, StructureGenHelper.stoneBrickMeta(rand), 2);
		world.setBlock(i + 4, j + 15, k + 5, Blocks.stonebrick, StructureGenHelper.stoneBrickMeta(rand), 2);
		world.setBlock(i + 4, j + 15, k + 6, Blocks.stonebrick, StructureGenHelper.stoneBrickMeta(rand), 2);
		world.setBlock(i + 4, j + 15, k + 8, Blocks.stonebrick, StructureGenHelper.stoneBrickMeta(rand), 2);
		world.setBlock(i + 4, j + 15, k + 9, Blocks.stonebrick, StructureGenHelper.stoneBrickMeta(rand), 2);
		world.setBlock(i + 4, j + 15, k + 10, Blocks.stonebrick, StructureGenHelper.stoneBrickMeta(rand), 2);
		world.setBlock(i + 4, j + 16, k + 1, Blocks.oak_stairs, 2, 2);
		world.setBlock(i + 4, j + 16, k + 3, Blocks.planks, 0, 2);
		world.setBlock(i + 4, j + 16, k + 4, Blocks.planks, 0, 2);
		world.setBlock(i + 4, j + 16, k + 5, Blocks.stonebrick, StructureGenHelper.stoneBrickMeta(rand), 2);
		world.setBlock(i + 4, j + 16, k + 6, Blocks.air);
		world.setBlock(i + 4, j + 16, k + 7, Blocks.air);
		world.setBlock(i + 4, j + 16, k + 8, Blocks.air);
		world.setBlock(i + 4, j + 16, k + 9, Blocks.stonebrick, StructureGenHelper.stoneBrickMeta(rand), 2);
		world.setBlock(i + 4, j + 17, k + 2, Blocks.daylight_detector, 0, 2);
		world.setBlock(i + 4, j + 17, k + 3, Blocks.planks, 0, 2);
		world.setBlock(i + 4, j + 17, k + 4, Blocks.planks, 0, 2);
		world.setBlock(i + 4, j + 17, k + 5, Blocks.stonebrick, StructureGenHelper.stoneBrickMeta(rand), 2);
		world.setBlock(i + 4, j + 17, k + 6, Blocks.air);
		world.setBlock(i + 4, j + 17, k + 7, Blocks.air);
		world.setBlock(i + 4, j + 17, k + 8, Blocks.air);
		world.setBlock(i + 4, j + 17, k + 9, Blocks.stonebrick, StructureGenHelper.stoneBrickMeta(rand), 2);
		world.setBlock(i + 4, j + 18, k + 3, Blocks.wooden_slab, 0, 2);
		world.setBlock(i + 4, j + 18, k + 5, Blocks.stonebrick, StructureGenHelper.stoneBrickMeta(rand), 2);
		world.setBlock(i + 4, j + 18, k + 6, Blocks.stonebrick, StructureGenHelper.stoneBrickMeta(rand), 2);
		world.setBlock(i + 4, j + 18, k + 7, Blocks.stonebrick, StructureGenHelper.stoneBrickMeta(rand), 2);
		world.setBlock(i + 4, j + 18, k + 8, Blocks.stonebrick, StructureGenHelper.stoneBrickMeta(rand), 2);
		world.setBlock(i + 4, j + 18, k + 9, Blocks.stonebrick, StructureGenHelper.stoneBrickMeta(rand), 2);
		world.setBlock(i + 4, j + 18, k + 10, Blocks.oak_stairs, 5, 2);
		world.setBlock(i + 4, j + 18, k + 11, Blocks.oak_stairs, 5, 2);
		world.setBlock(i + 4, j + 18, k + 12, Blocks.oak_stairs, 5, 2);
		world.setBlock(i + 4, j + 19, k + 6, Blocks.stonebrick, StructureGenHelper.stoneBrickMeta(rand), 2);
		world.setBlock(i + 4, j + 19, k + 7, Blocks.air);
		world.setBlock(i + 4, j + 19, k + 8, Blocks.air);
		world.setBlock(i + 4, j + 19, k + 10, Blocks.planks, 0, 2);
		world.setBlock(i + 4, j + 19, k + 11, Blocks.planks, 0, 2);
		world.setBlock(i + 4, j + 19, k + 12, Blocks.planks, 0, 2);
		world.setBlock(i + 4, j + 20, k + 6, Blocks.stonebrick, StructureGenHelper.stoneBrickMeta(rand), 2);
		world.setBlock(i + 4, j + 20, k + 7, Blocks.air);
		world.setBlock(i + 4, j + 20, k + 8, Blocks.air);
		world.setBlock(i + 4, j + 20, k + 10, Blocks.planks, 0, 2);
		world.setBlock(i + 4, j + 20, k + 11, Blocks.planks, 0, 2);
		world.setBlock(i + 4, j + 20, k + 12, Blocks.planks, 0, 2);
		world.setBlock(i + 4, j + 21, k + 6, Blocks.stonebrick, StructureGenHelper.stoneBrickMeta(rand), 2);
		world.setBlock(i + 4, j + 21, k + 7, Blocks.stonebrick, StructureGenHelper.stoneBrickMeta(rand), 2);
		world.setBlock(i + 4, j + 21, k + 8, Blocks.stonebrick, StructureGenHelper.stoneBrickMeta(rand), 2);
		//world.scheduleBlockUpdate(i + 4, j + 21, k + 9, Blocks.daylight_detector, 10);
		world.setBlock(i + 4, j + 21, k + 10, Blocks.planks, 0, 2);
		world.setBlock(i + 4, j + 21, k + 11, Blocks.planks, 0, 2);
		world.setBlock(i + 4, j + 21, k + 12, Blocks.planks, 0, 2);
		world.setBlock(i + 4, j + 22, k + 7, Blocks.stonebrick, StructureGenHelper.stoneBrickMeta(rand), 2);
		world.setBlock(i + 4, j + 22, k + 10, Blocks.oak_stairs, 2, 2);
		world.setBlock(i + 4, j + 22, k + 11, Blocks.oak_stairs, 1, 2);
		world.setBlock(i + 4, j + 22, k + 12, Blocks.oak_stairs, 3, 2);
		world.setBlock(i + 4, j + 23, k + 7, Blocks.stone_brick_stairs, 0, 2);
		world.setBlock(i + 4, j + 27, k + 5, Blocks.stone_brick_stairs, 4, 2);
		world.setBlock(i + 4, j + 27, k + 6, Blocks.stone_brick_stairs, 4, 2);
		world.setBlock(i + 4, j + 27, k + 7, Blocks.stone_brick_stairs, 4, 2);
		world.setBlock(i + 4, j + 27, k + 8, Blocks.stone_brick_stairs, 4, 2);
		world.setBlock(i + 4, j + 27, k + 9, Blocks.stone_brick_stairs, 4, 2);
		world.setBlock(i + 4, j + 28, k + 5, Blocks.stonebrick, StructureGenHelper.stoneBrickMeta(rand), 2);
		world.setBlock(i + 4, j + 28, k + 6, Blocks.stonebrick, StructureGenHelper.stoneBrickMeta(rand), 2);
		world.setBlock(i + 4, j + 28, k + 7, Blocks.stonebrick, StructureGenHelper.stoneBrickMeta(rand), 2);
		world.setBlock(i + 4, j + 28, k + 8, Blocks.stonebrick, StructureGenHelper.stoneBrickMeta(rand), 2);
		world.setBlock(i + 4, j + 28, k + 9, Blocks.stonebrick, StructureGenHelper.stoneBrickMeta(rand), 2);
		world.setBlock(i + 4, j + 29, k + 5, Blocks.stonebrick, StructureGenHelper.stoneBrickMeta(rand), 2);
		world.setBlock(i + 4, j + 29, k + 6, Blocks.air);
		world.setBlock(i + 4, j + 29, k + 7, Blocks.air);
		world.setBlock(i + 4, j + 29, k + 8, Blocks.air);
		world.setBlock(i + 4, j + 29, k + 9, Blocks.stonebrick, StructureGenHelper.stoneBrickMeta(rand), 2);
		world.setBlock(i + 4, j + 30, k + 6, Blocks.air);
		world.setBlock(i + 4, j + 30, k + 7, Blocks.air);
		world.setBlock(i + 4, j + 30, k + 8, Blocks.air);
		world.setBlock(i + 5, j + 0, k + 2, Blocks.stonebrick, StructureGenHelper.stoneBrickMeta(rand), 2);
		world.setBlock(i + 5, j + 0, k + 3, Blocks.stonebrick, StructureGenHelper.stoneBrickMeta(rand), 2);
		world.setBlock(i + 5, j + 0, k + 4, Blocks.stonebrick, StructureGenHelper.stoneBrickMeta(rand), 2);
		world.setBlock(i + 5, j + 0, k + 5, Blocks.stonebrick, StructureGenHelper.stoneBrickMeta(rand), 2);
		world.setBlock(i + 5, j + 0, k + 6, Blocks.stonebrick, StructureGenHelper.stoneBrickMeta(rand), 2);
		world.setBlock(i + 5, j + 0, k + 7, Blocks.stonebrick, StructureGenHelper.stoneBrickMeta(rand), 2);
		world.setBlock(i + 5, j + 0, k + 8, Blocks.stonebrick, StructureGenHelper.stoneBrickMeta(rand), 2);
		world.setBlock(i + 5, j + 0, k + 9, Blocks.stonebrick, StructureGenHelper.stoneBrickMeta(rand), 2);
		world.setBlock(i + 5, j + 0, k + 10, Blocks.stonebrick, StructureGenHelper.stoneBrickMeta(rand), 2);
		world.setBlock(i + 5, j + 0, k + 11, Blocks.stonebrick, StructureGenHelper.stoneBrickMeta(rand), 2);
		world.setBlock(i + 5, j + 0, k + 12, Blocks.stonebrick, StructureGenHelper.stoneBrickMeta(rand), 2);
		world.setBlock(i + 5, j + 1, k + 2, Blocks.stonebrick, StructureGenHelper.stoneBrickMeta(rand), 2);
		world.setBlock(i + 5, j + 1, k + 3, Blocks.stonebrick, StructureGenHelper.stoneBrickMeta(rand), 2);
		world.setBlock(i + 5, j + 1, k + 4, Blocks.stonebrick, StructureGenHelper.stoneBrickMeta(rand), 2);
		world.setBlock(i + 5, j + 1, k + 5, BlockSpikes.instance, 0, 2);
		world.setBlock(i + 5, j + 1, k + 6, BlockSpikes.instance, 0, 2);
		world.setBlock(i + 5, j + 1, k + 7, BlockSpikes.instance, 0, 2);
		world.setBlock(i + 5, j + 1, k + 8, Blocks.stonebrick, StructureGenHelper.stoneBrickMeta(rand), 2);
		world.setBlock(i + 5, j + 1, k + 9, Blocks.stonebrick, StructureGenHelper.stoneBrickMeta(rand), 2);
		world.setBlock(i + 5, j + 1, k + 10, Blocks.stonebrick, StructureGenHelper.stoneBrickMeta(rand), 2);
		world.setBlock(i + 5, j + 1, k + 11, Blocks.stonebrick, StructureGenHelper.stoneBrickMeta(rand), 2);
		world.setBlock(i + 5, j + 1, k + 12, Blocks.stonebrick, StructureGenHelper.stoneBrickMeta(rand), 2);
		world.setBlock(i + 5, j + 2, k + 2, Blocks.stonebrick, StructureGenHelper.stoneBrickMeta(rand), 2);
		world.setBlock(i + 5, j + 2, k + 3, Blocks.stonebrick, StructureGenHelper.stoneBrickMeta(rand), 2);
		world.setBlock(i + 5, j + 2, k + 4, Blocks.stonebrick, StructureGenHelper.stoneBrickMeta(rand), 2);
		world.setBlock(i + 5, j + 2, k + 5, BlockIllusionary.instance, 0, 2);
		world.setBlock(i + 5, j + 2, k + 6, BlockIllusionary.instance, 0, 2);
		world.setBlock(i + 5, j + 2, k + 7, BlockIllusionary.instance, 0, 2);
		world.setBlock(i + 5, j + 2, k + 8, Blocks.stonebrick, StructureGenHelper.stoneBrickMeta(rand), 2);
		world.setBlock(i + 5, j + 2, k + 9, Blocks.stonebrick, StructureGenHelper.stoneBrickMeta(rand), 2);
		world.setBlock(i + 5, j + 2, k + 10, Blocks.stonebrick, StructureGenHelper.stoneBrickMeta(rand), 2);
		world.setBlock(i + 5, j + 2, k + 11, Blocks.stonebrick, StructureGenHelper.stoneBrickMeta(rand), 2);
		world.setBlock(i + 5, j + 2, k + 12, Blocks.stonebrick, StructureGenHelper.stoneBrickMeta(rand), 2);
		world.setBlock(i + 5, j + 3, k + 2, Blocks.stonebrick, StructureGenHelper.stoneBrickMeta(rand), 2);
		world.setBlock(i + 5, j + 3, k + 3, Blocks.stonebrick, StructureGenHelper.stoneBrickMeta(rand), 2);
		world.setBlock(i + 5, j + 3, k + 4, BlockTrap.instance, 3, 2);
		world.setBlockMetadataWithNotify(i + 5, j + 3, k + 4, 3, 2);
		world.setBlock(i + 5, j + 3, k + 5, Blocks.air);
		world.setBlock(i + 5, j + 3, k + 6, Blocks.air);
		world.setBlock(i + 5, j + 3, k + 7, Blocks.air);
		world.setBlock(i + 5, j + 3, k + 8, BlockTrap.instance, 2, 2);
		world.setBlockMetadataWithNotify(i + 5, j + 3, k + 8, 2, 2);
		world.setBlock(i + 5, j + 3, k + 9, Blocks.air);
		world.setBlock(i + 5, j + 3, k + 10, Blocks.air);
		world.setBlock(i + 5, j + 3, k + 11, Blocks.air);
		world.setBlock(i + 5, j + 3, k + 12, Blocks.stonebrick, StructureGenHelper.stoneBrickMeta(rand), 2);
		world.setBlock(i + 5, j + 4, k + 2, Blocks.stonebrick, StructureGenHelper.stoneBrickMeta(rand), 2);
		world.setBlock(i + 5, j + 4, k + 3, Blocks.stonebrick, StructureGenHelper.stoneBrickMeta(rand), 2);
		world.setBlock(i + 5, j + 4, k + 4, Blocks.stonebrick, StructureGenHelper.stoneBrickMeta(rand), 2);
		world.setBlock(i + 5, j + 4, k + 5, Blocks.air);
		world.setBlock(i + 5, j + 4, k + 6, Blocks.air);
		world.setBlock(i + 5, j + 4, k + 7, Blocks.air);
		world.setBlock(i + 5, j + 4, k + 8, Blocks.stonebrick, StructureGenHelper.stoneBrickMeta(rand), 2);
		world.setBlock(i + 5, j + 4, k + 9, Blocks.air);
		world.setBlock(i + 5, j + 4, k + 10, Blocks.air);
		world.setBlock(i + 5, j + 4, k + 11, Blocks.air);
		world.setBlock(i + 5, j + 4, k + 12, Blocks.stonebrick, StructureGenHelper.stoneBrickMeta(rand), 2);
		world.setBlock(i + 5, j + 5, k + 2, Blocks.stonebrick, StructureGenHelper.stoneBrickMeta(rand), 2);
		world.setBlock(i + 5, j + 5, k + 3, Blocks.stonebrick, StructureGenHelper.stoneBrickMeta(rand), 2);
		world.setBlock(i + 5, j + 5, k + 4, Blocks.stonebrick, StructureGenHelper.stoneBrickMeta(rand), 2);
		world.setBlock(i + 5, j + 5, k + 5, Blocks.air);
		world.setBlock(i + 5, j + 5, k + 6, Blocks.air);
		world.setBlock(i + 5, j + 5, k + 7, Blocks.air);
		world.setBlock(i + 5, j + 5, k + 8, Blocks.stonebrick, StructureGenHelper.stoneBrickMeta(rand), 2);
		world.setBlock(i + 5, j + 5, k + 9, Blocks.air);
		world.setBlock(i + 5, j + 5, k + 10, Blocks.air);
		world.setBlock(i + 5, j + 5, k + 11, Blocks.air);
		world.setBlock(i + 5, j + 5, k + 12, Blocks.stonebrick, StructureGenHelper.stoneBrickMeta(rand), 2);
		world.setBlock(i + 5, j + 6, k + 2, Blocks.stonebrick, StructureGenHelper.stoneBrickMeta(rand), 2);
		world.setBlock(i + 5, j + 6, k + 3, Blocks.stonebrick, StructureGenHelper.stoneBrickMeta(rand), 2);
		world.setBlock(i + 5, j + 6, k + 4, Blocks.stonebrick, StructureGenHelper.stoneBrickMeta(rand), 2);
		world.setBlock(i + 5, j + 6, k + 5, Blocks.air);
		world.setBlock(i + 5, j + 6, k + 6, Blocks.air);
		world.setBlock(i + 5, j + 6, k + 7, Blocks.air);
		world.setBlock(i + 5, j + 6, k + 8, Blocks.stonebrick, StructureGenHelper.stoneBrickMeta(rand), 2);
		world.setBlock(i + 5, j + 6, k + 9, Blocks.air);
		world.setBlock(i + 5, j + 6, k + 10, Blocks.air);
		world.setBlock(i + 5, j + 6, k + 11, Blocks.air);
		world.setBlock(i + 5, j + 6, k + 12, Blocks.stonebrick, StructureGenHelper.stoneBrickMeta(rand), 2);
		world.setBlock(i + 5, j + 7, k + 2, Blocks.stonebrick, StructureGenHelper.stoneBrickMeta(rand), 2);
		world.setBlock(i + 5, j + 7, k + 3, Blocks.stonebrick, StructureGenHelper.stoneBrickMeta(rand), 2);
		world.setBlock(i + 5, j + 7, k + 4, Blocks.stonebrick, StructureGenHelper.stoneBrickMeta(rand), 2);
		world.setBlock(i + 5, j + 7, k + 5, Blocks.stonebrick, StructureGenHelper.stoneBrickMeta(rand), 2);
		world.setBlock(i + 5, j + 7, k + 6, Blocks.stonebrick, StructureGenHelper.stoneBrickMeta(rand), 2);
		world.setBlock(i + 5, j + 7, k + 7, Blocks.stonebrick, StructureGenHelper.stoneBrickMeta(rand), 2);
		world.setBlock(i + 5, j + 7, k + 8, Blocks.stonebrick, StructureGenHelper.stoneBrickMeta(rand), 2);
		world.setBlock(i + 5, j + 7, k + 9, Blocks.stonebrick, StructureGenHelper.stoneBrickMeta(rand), 2);
		world.setBlock(i + 5, j + 7, k + 10, Blocks.stonebrick, StructureGenHelper.stoneBrickMeta(rand), 2);
		world.setBlock(i + 5, j + 7, k + 11, Blocks.stonebrick, StructureGenHelper.stoneBrickMeta(rand), 2);
		world.setBlock(i + 5, j + 7, k + 12, Blocks.stonebrick, StructureGenHelper.stoneBrickMeta(rand), 2);
		world.setBlock(i + 5, j + 8, k + 2, Blocks.stonebrick, StructureGenHelper.stoneBrickMeta(rand), 2);
		world.setBlock(i + 5, j + 8, k + 3, Blocks.stonebrick, StructureGenHelper.stoneBrickMeta(rand), 2);
		world.setBlock(i + 5, j + 8, k + 4, Blocks.anvil, 0, 2);
		world.setBlock(i + 5, j + 8, k + 5, Blocks.air);
		world.setBlock(i + 5, j + 8, k + 6, Blocks.air);
		world.setBlock(i + 5, j + 8, k + 8, Blocks.bookshelf, 0, 2);
		world.setBlock(i + 5, j + 8, k + 9, Blocks.bookshelf, 0, 2);
		world.setBlock(i + 5, j + 8, k + 10, Blocks.bookshelf, 0, 2);
		world.setBlock(i + 5, j + 8, k + 11, Blocks.stonebrick, StructureGenHelper.stoneBrickMeta(rand), 2);
		world.setBlock(i + 5, j + 8, k + 12, Blocks.stonebrick, StructureGenHelper.stoneBrickMeta(rand), 2);
		world.setBlock(i + 5, j + 9, k + 2, Blocks.stonebrick, StructureGenHelper.stoneBrickMeta(rand), 2);
		world.setBlock(i + 5, j + 9, k + 3, Blocks.stonebrick, StructureGenHelper.stoneBrickMeta(rand), 2);
		world.setBlock(i + 5, j + 9, k + 4, Blocks.air);
		world.setBlock(i + 5, j + 9, k + 5, Blocks.air);
		world.setBlock(i + 5, j + 9, k + 6, Blocks.air);
		world.setBlock(i + 5, j + 9, k + 8, Blocks.bookshelf, 0, 2);
		world.setBlock(i + 5, j + 9, k + 9, Blocks.bookshelf, 0, 2);
		world.setBlock(i + 5, j + 9, k + 10, Blocks.bookshelf, 0, 2);
		world.setBlock(i + 5, j + 9, k + 11, Blocks.stonebrick, StructureGenHelper.stoneBrickMeta(rand), 2);
		world.setBlock(i + 5, j + 9, k + 12, Blocks.stonebrick, StructureGenHelper.stoneBrickMeta(rand), 2);
		world.setBlock(i + 5, j + 10, k + 1, Blocks.oak_stairs, 6, 2);
		world.setBlock(i + 5, j + 10, k + 2, Blocks.planks, 0, 2);
		world.setBlock(i + 5, j + 10, k + 3, Blocks.stonebrick, StructureGenHelper.stoneBrickMeta(rand), 2);
		world.setBlock(i + 5, j + 10, k + 4, Blocks.stonebrick, StructureGenHelper.stoneBrickMeta(rand), 2);
		world.setBlock(i + 5, j + 10, k + 5, Blocks.stonebrick, StructureGenHelper.stoneBrickMeta(rand), 2);
		world.setBlock(i + 5, j + 10, k + 6, Blocks.stonebrick, StructureGenHelper.stoneBrickMeta(rand), 2);
		world.setBlock(i + 5, j + 10, k + 7, Blocks.stonebrick, StructureGenHelper.stoneBrickMeta(rand), 2);
		world.setBlock(i + 5, j + 10, k + 8, Blocks.stonebrick, StructureGenHelper.stoneBrickMeta(rand), 2);
		world.setBlock(i + 5, j + 10, k + 9, Blocks.stonebrick, StructureGenHelper.stoneBrickMeta(rand), 2);
		world.setBlock(i + 5, j + 10, k + 10, Blocks.stonebrick, StructureGenHelper.stoneBrickMeta(rand), 2);
		world.setBlock(i + 5, j + 10, k + 11, Blocks.stonebrick, StructureGenHelper.stoneBrickMeta(rand), 2);
		world.setBlock(i + 5, j + 11, k + 0, Blocks.oak_stairs, 6, 2);
		world.setBlock(i + 5, j + 11, k + 1, Blocks.planks, 0, 2);
		world.setBlock(i + 5, j + 11, k + 2, Blocks.planks, 0, 2);
		world.setBlock(i + 5, j + 11, k + 3, Blocks.stonebrick, StructureGenHelper.stoneBrickMeta(rand), 2);
		world.setBlock(i + 5, j + 11, k + 4, Blocks.stonebrick, StructureGenHelper.stoneBrickMeta(rand), 2);
		world.setBlock(i + 5, j + 11, k + 5, Blocks.stonebrick, StructureGenHelper.stoneBrickMeta(rand), 2);
		world.setBlock(i + 5, j + 11, k + 6, Blocks.stonebrick, StructureGenHelper.stoneBrickMeta(rand), 2);
		world.setBlock(i + 5, j + 11, k + 7, Blocks.stonebrick, StructureGenHelper.stoneBrickMeta(rand), 2);
		world.setBlock(i + 5, j + 11, k + 8, Blocks.stonebrick, StructureGenHelper.stoneBrickMeta(rand), 2);
		world.setBlock(i + 5, j + 11, k + 9, Blocks.stonebrick, StructureGenHelper.stoneBrickMeta(rand), 2);
		world.setBlock(i + 5, j + 11, k + 10, Blocks.stonebrick, StructureGenHelper.stoneBrickMeta(rand), 2);
		world.setBlock(i + 5, j + 11, k + 11, Blocks.stonebrick, StructureGenHelper.stoneBrickMeta(rand), 2);
		world.setBlock(i + 5, j + 12, k + 0, Blocks.planks, 0, 2);
		world.setBlock(i + 5, j + 12, k + 1, Blocks.sticky_piston, 3, 2);
		//world.setBlock(i + 5, j + 12, k + 2, Blocks.stonebrick, StructureGenHelper.stoneBrickMeta(rand), 2);
		world.setBlock(i + 5, j + 12, k + 3, Blocks.air);
		world.setBlock(i + 5, j + 12, k + 4, Blocks.air);
		world.setBlock(i + 5, j + 12, k + 5, Blocks.air);
		world.setBlock(i + 5, j + 12, k + 6, Blocks.stonebrick, StructureGenHelper.stoneBrickMeta(rand), 2);
		world.setBlock(i + 5, j + 12, k + 7, Blocks.stonebrick, StructureGenHelper.stoneBrickMeta(rand), 2);
		world.setBlock(i + 5, j + 12, k + 8, Blocks.stonebrick, StructureGenHelper.stoneBrickMeta(rand), 2);
		world.setBlock(i + 5, j + 12, k + 9, Blocks.stonebrick, StructureGenHelper.stoneBrickMeta(rand), 2);
		world.setBlock(i + 5, j + 12, k + 10, Blocks.stonebrick, StructureGenHelper.stoneBrickMeta(rand), 2);
		world.setBlock(i + 5, j + 12, k + 11, Blocks.stonebrick, StructureGenHelper.stoneBrickMeta(rand), 2);
		world.setBlock(i + 5, j + 13, k + 0, Blocks.planks, 0, 2);
		world.setBlock(i + 5, j + 13, k + 1, Blocks.sticky_piston, 3, 2);
		//world.setBlock(i + 5, j + 13, k + 2, Blocks.stonebrick, StructureGenHelper.stoneBrickMeta(rand), 2);
		world.setBlock(i + 5, j + 13, k + 3, Blocks.air);
		world.setBlock(i + 5, j + 13, k + 5, Blocks.air);
		world.setBlock(i + 5, j + 13, k + 6, Blocks.stonebrick, StructureGenHelper.stoneBrickMeta(rand), 2);
		world.setBlock(i + 5, j + 13, k + 7, Blocks.stonebrick, StructureGenHelper.stoneBrickMeta(rand), 2);
		world.setBlock(i + 5, j + 13, k + 8, Blocks.sticky_piston, 4, 2);
		world.setBlock(i + 5, j + 13, k + 9, Blocks.stonebrick, StructureGenHelper.stoneBrickMeta(rand), 2);
		world.setBlock(i + 5, j + 13, k + 10, Blocks.stonebrick, StructureGenHelper.stoneBrickMeta(rand), 2);
		world.setBlock(i + 5, j + 13, k + 11, Blocks.stonebrick, StructureGenHelper.stoneBrickMeta(rand), 2);
		world.setBlock(i + 5, j + 14, k + 0, Blocks.planks, 0, 2);
		world.setBlock(i + 5, j + 14, k + 1, Blocks.stonebrick, StructureGenHelper.stoneBrickMeta(rand), 2);
		world.setBlock(i + 5, j + 14, k + 2, Blocks.stonebrick, StructureGenHelper.stoneBrickMeta(rand), 2);
		world.setBlock(i + 5, j + 14, k + 3, Blocks.stonebrick, StructureGenHelper.stoneBrickMeta(rand), 2);
		world.setBlock(i + 5, j + 14, k + 4, Blocks.stonebrick, StructureGenHelper.stoneBrickMeta(rand), 2);
		world.setBlock(i + 5, j + 14, k + 5, Blocks.stonebrick, StructureGenHelper.stoneBrickMeta(rand), 2);
		world.setBlock(i + 5, j + 14, k + 6, Blocks.stonebrick, StructureGenHelper.stoneBrickMeta(rand), 2);
		world.setBlock(i + 5, j + 14, k + 7, Blocks.stonebrick, StructureGenHelper.stoneBrickMeta(rand), 2);
		world.setBlock(i + 5, j + 14, k + 8, Blocks.stonebrick, StructureGenHelper.stoneBrickMeta(rand), 2);
		world.setBlock(i + 5, j + 14, k + 9, Blocks.stonebrick, StructureGenHelper.stoneBrickMeta(rand), 2);
		world.setBlock(i + 5, j + 14, k + 10, Blocks.stonebrick, StructureGenHelper.stoneBrickMeta(rand), 2);
		world.setBlock(i + 5, j + 14, k + 11, Blocks.stonebrick, StructureGenHelper.stoneBrickMeta(rand), 2);
		world.setBlock(i + 5, j + 15, k + 0, Blocks.oak_stairs, 2, 2);
		world.setBlock(i + 5, j + 15, k + 1, Blocks.planks, 0, 2);
		world.setBlock(i + 5, j + 15, k + 2, Blocks.planks, 0, 2);
		world.setBlock(i + 5, j + 15, k + 3, Blocks.stonebrick, StructureGenHelper.stoneBrickMeta(rand), 2);
		world.setBlock(i + 5, j + 15, k + 5, Blocks.stonebrick, StructureGenHelper.stoneBrickMeta(rand), 2);
		world.setBlock(i + 5, j + 15, k + 6, Blocks.stonebrick, StructureGenHelper.stoneBrickMeta(rand), 2);
		world.setBlock(i + 5, j + 15, k + 7, BlockTrap.instance, 1, 2);
		world.setBlockMetadataWithNotify(i + 5, j + 15, k + 7, 1, 2);
		te = world.getTileEntity(i + 5, j + 15, k + 7);
		if(te instanceof TileEntityTrap) {
			ted = (TileEntityTrap)te;
			ted.func_146019_a/*addItem*/(new ItemStack(Items.arrow, 32));
		}
		world.setBlock(i + 5, j + 16, k + 7, StructureGenHelper.randomBlock(rand, new Block[]{BlockArtifactsPressurePlate.invisObsidian, BlockArtifactsPressurePlate.invisObsidian, BlockArtifactsPressurePlate.invisObsidian, BlockArtifactsPressurePlate.invisObsidian, BlockArtifactsPressurePlate.invisObsidian, BlockArtifactsPressurePlate.invisObsidian, BlockArtifactsPressurePlate.invisObsidian, BlockArtifactsPressurePlate.camoObsidian}), 0, 2);
		world.setBlock(i + 5, j + 15, k + 8, Blocks.stonebrick, StructureGenHelper.stoneBrickMeta(rand), 2);
		world.setBlock(i + 5, j + 15, k + 9, Blocks.stonebrick, StructureGenHelper.stoneBrickMeta(rand), 2);
		world.setBlock(i + 5, j + 15, k + 10, Blocks.stonebrick, StructureGenHelper.stoneBrickMeta(rand), 2);
		world.setBlock(i + 5, j + 16, k + 1, Blocks.oak_stairs, 2, 2);
		world.setBlock(i + 5, j + 16, k + 2, Blocks.oak_stairs, 1, 2);
		world.setBlock(i + 5, j + 16, k + 3, Blocks.planks, 0, 2);
		world.setBlock(i + 5, j + 16, k + 4, Blocks.stonebrick, StructureGenHelper.stoneBrickMeta(rand), 2);
		world.setBlock(i + 5, j + 16, k + 5, Blocks.stonebrick, StructureGenHelper.stoneBrickMeta(rand), 2);
		world.setBlock(i + 5, j + 16, k + 6, Blocks.air);
		//world.setBlock(i + 5, j + 16, k + 7, Blocks.air);
		world.setBlock(i + 5, j + 16, k + 9, Blocks.stonebrick, StructureGenHelper.stoneBrickMeta(rand), 2);
		world.setBlock(i + 5, j + 16, k + 10, Blocks.stonebrick, StructureGenHelper.stoneBrickMeta(rand), 2);
		world.setBlock(i + 5, j + 17, k + 3, Blocks.oak_stairs, 1, 2);
		world.setBlock(i + 5, j + 17, k + 4, Blocks.stonebrick, StructureGenHelper.stoneBrickMeta(rand), 2);
		world.setBlock(i + 5, j + 17, k + 5, Blocks.stonebrick, StructureGenHelper.stoneBrickMeta(rand), 2);
		world.setBlock(i + 5, j + 17, k + 6, Blocks.air);
		world.setBlock(i + 5, j + 17, k + 7, Blocks.air);
		world.setBlock(i + 5, j + 17, k + 9, Blocks.stonebrick, StructureGenHelper.stoneBrickMeta(rand), 2);
		world.setBlock(i + 5, j + 17, k + 10, Blocks.stonebrick, StructureGenHelper.stoneBrickMeta(rand), 2);
		world.setBlock(i + 5, j + 18, k + 5, Blocks.stonebrick, StructureGenHelper.stoneBrickMeta(rand), 2);
		world.setBlock(i + 5, j + 18, k + 6, Blocks.stonebrick, StructureGenHelper.stoneBrickMeta(rand), 2);
		world.setBlock(i + 5, j + 18, k + 7, Blocks.stonebrick, StructureGenHelper.stoneBrickMeta(rand), 2);
		world.setBlock(i + 5, j + 18, k + 9, Blocks.stonebrick, StructureGenHelper.stoneBrickMeta(rand), 2);
		world.setBlock(i + 5, j + 19, k + 5, Blocks.stonebrick, StructureGenHelper.stoneBrickMeta(rand), 2);
		world.setBlock(i + 5, j + 19, k + 6, Blocks.air);
		world.setBlock(i + 5, j + 19, k + 7, Blocks.air);
		world.setBlock(i + 5, j + 19, k + 8, Blocks.air);
		world.setBlock(i + 5, j + 19, k + 9, Blocks.stonebrick, StructureGenHelper.stoneBrickMeta(rand), 2);
		world.setBlock(i + 5, j + 20, k + 5, Blocks.stonebrick, StructureGenHelper.stoneBrickMeta(rand), 2);
		world.setBlock(i + 5, j + 20, k + 6, Blocks.air);
		world.setBlock(i + 5, j + 20, k + 7, Blocks.air);
		world.setBlock(i + 5, j + 20, k + 8, Blocks.air);
		world.setBlock(i + 5, j + 20, k + 9, Blocks.stonebrick, StructureGenHelper.stoneBrickMeta(rand), 2);
		world.setBlock(i + 5, j + 21, k + 5, Blocks.stonebrick, StructureGenHelper.stoneBrickMeta(rand), 2);/*set air?*/
		world.setBlock(i + 5, j + 21, k + 6, Blocks.stonebrick, 1, 2);/*set air?*/
		world.setBlock(i + 5, j + 21, k + 7, Blocks.stonebrick, 1, 2);/*set air?*/
		world.setBlock(i + 5, j + 21, k + 8, Blocks.stonebrick, 1, 2);/*set air?*/
		world.setBlock(i + 5, j + 21, k + 9, Blocks.stonebrick, StructureGenHelper.stoneBrickMeta(rand), 2);/*set air?*/
		world.setBlock(i + 5, j + 22, k + 6, Blocks.stonebrick, StructureGenHelper.stoneBrickMeta(rand), 2);
		world.setBlock(i + 5, j + 22, k + 7, Blocks.stonebrick, StructureGenHelper.stoneBrickMeta(rand), 2);
		world.setBlock(i + 5, j + 23, k + 6, Blocks.stonebrick, StructureGenHelper.stoneBrickMeta(rand), 2);
		world.setBlock(i + 5, j + 23, k + 7, Blocks.stonebrick, StructureGenHelper.stoneBrickMeta(rand), 2);
		world.setBlock(i + 5, j + 23, k + 8, Blocks.stonebrick, StructureGenHelper.stoneBrickMeta(rand), 2);
		world.setBlock(i + 5, j + 24, k + 6, Blocks.stonebrick, StructureGenHelper.stoneBrickMeta(rand), 2);
		world.setBlock(i + 5, j + 24, k + 7, Blocks.stonebrick, StructureGenHelper.stoneBrickMeta(rand), 2);
		world.setBlock(i + 5, j + 24, k + 8, Blocks.stonebrick, StructureGenHelper.stoneBrickMeta(rand), 2);
		world.setBlock(i + 5, j + 25, k + 6, Blocks.stonebrick, StructureGenHelper.stoneBrickMeta(rand), 2);
		world.setBlock(i + 5, j + 25, k + 7, Blocks.stonebrick, StructureGenHelper.stoneBrickMeta(rand), 2);
		world.setBlock(i + 5, j + 25, k + 8, Blocks.stonebrick, StructureGenHelper.stoneBrickMeta(rand), 2);
		world.setBlock(i + 5, j + 26, k + 6, Blocks.stonebrick, StructureGenHelper.stoneBrickMeta(rand), 2);
		world.setBlock(i + 5, j + 26, k + 7, Blocks.stonebrick, StructureGenHelper.stoneBrickMeta(rand), 2);
		world.setBlock(i + 5, j + 26, k + 8, Blocks.stonebrick, StructureGenHelper.stoneBrickMeta(rand), 2);
		world.setBlock(i + 5, j + 27, k + 5, Blocks.stone_brick_stairs, 6, 2);
		world.setBlock(i + 5, j + 27, k + 6, Blocks.stonebrick, StructureGenHelper.stoneBrickMeta(rand), 2);
		world.setBlock(i + 5, j + 27, k + 7, Blocks.stonebrick, StructureGenHelper.stoneBrickMeta(rand), 2);
		world.setBlock(i + 5, j + 27, k + 8, Blocks.stonebrick, StructureGenHelper.stoneBrickMeta(rand), 2);
		world.setBlock(i + 5, j + 27, k + 9, Blocks.stone_brick_stairs, 7, 2);
		world.setBlock(i + 5, j + 28, k + 4, Blocks.stone_brick_stairs, 6, 2);
		world.setBlock(i + 5, j + 28, k + 5, Blocks.stonebrick, StructureGenHelper.stoneBrickMeta(rand), 2);
		world.setBlock(i + 5, j + 28, k + 6, Blocks.stonebrick, StructureGenHelper.stoneBrickMeta(rand), 2);
		world.setBlock(i + 5, j + 28, k + 7, Blocks.stonebrick, StructureGenHelper.stoneBrickMeta(rand), 2);
		world.setBlock(i + 5, j + 28, k + 8, Blocks.stonebrick, StructureGenHelper.stoneBrickMeta(rand), 2);
		world.setBlock(i + 5, j + 28, k + 9, Blocks.stonebrick, StructureGenHelper.stoneBrickMeta(rand), 2);
		world.setBlock(i + 5, j + 28, k + 10, Blocks.stone_brick_stairs, 7, 2);
		world.setBlock(i + 5, j + 29, k + 4, Blocks.stonebrick, StructureGenHelper.stoneBrickMeta(rand), 2);
		world.setBlock(i + 5, j + 29, k + 5, Blocks.air);
		world.setBlock(i + 5, j + 29, k + 6, Blocks.fence, 0, 2);
		world.setBlock(i + 5, j + 29, k + 7, Blocks.air);
		world.setBlock(i + 5, j + 29, k + 8, Blocks.fence, 0, 2);
		world.setBlock(i + 5, j + 29, k + 9, Blocks.air);
		world.setBlock(i + 5, j + 29, k + 10, Blocks.stonebrick, StructureGenHelper.stoneBrickMeta(rand), 2);
		world.setBlock(i + 5, j + 30, k + 4, Blocks.stone_brick_stairs, 1, 2);
		world.setBlock(i + 5, j + 30, k + 5, Blocks.air);
		world.setBlock(i + 5, j + 30, k + 6, Blocks.fence, 0, 2);
		world.setBlock(i + 5, j + 30, k + 7, Blocks.air);
		world.setBlock(i + 5, j + 30, k + 8, Blocks.fence, 0, 2);
		world.setBlock(i + 5, j + 30, k + 9, Blocks.air);
		world.setBlock(i + 5, j + 30, k + 10, Blocks.stone_brick_stairs, 1, 2);
		world.setBlock(i + 5, j + 31, k + 6, Blocks.fence, 0, 2);
		world.setBlock(i + 5, j + 31, k + 7, Blocks.air);
		world.setBlock(i + 5, j + 31, k + 8, Blocks.fence, 0, 2);
		world.setBlock(i + 5, j + 32, k + 6, Blocks.oak_stairs, 2, 2);
		world.setBlock(i + 5, j + 32, k + 7, Blocks.oak_stairs, 0, 2);
		world.setBlock(i + 5, j + 32, k + 8, Blocks.oak_stairs, 3, 2);
		world.setBlock(i + 6, j + 0, k + 2, Blocks.stonebrick, StructureGenHelper.stoneBrickMeta(rand), 2);
		world.setBlock(i + 6, j + 0, k + 3, Blocks.stonebrick, StructureGenHelper.stoneBrickMeta(rand), 2);
		world.setBlock(i + 6, j + 0, k + 4, Blocks.stonebrick, StructureGenHelper.stoneBrickMeta(rand), 2);
		world.setBlock(i + 6, j + 0, k + 5, Blocks.stonebrick, StructureGenHelper.stoneBrickMeta(rand), 2);
		world.setBlock(i + 6, j + 0, k + 6, Blocks.stonebrick, StructureGenHelper.stoneBrickMeta(rand), 2);
		world.setBlock(i + 6, j + 0, k + 7, Blocks.stonebrick, StructureGenHelper.stoneBrickMeta(rand), 2);
		world.setBlock(i + 6, j + 0, k + 8, Blocks.stonebrick, StructureGenHelper.stoneBrickMeta(rand), 2);
		world.setBlock(i + 6, j + 0, k + 9, Blocks.stonebrick, StructureGenHelper.stoneBrickMeta(rand), 2);
		world.setBlock(i + 6, j + 0, k + 10, Blocks.stonebrick, StructureGenHelper.stoneBrickMeta(rand), 2);
		world.setBlock(i + 6, j + 0, k + 11, Blocks.stonebrick, StructureGenHelper.stoneBrickMeta(rand), 2);
		world.setBlock(i + 6, j + 0, k + 12, Blocks.stonebrick, StructureGenHelper.stoneBrickMeta(rand), 2);
		world.setBlock(i + 6, j + 1, k + 2, Blocks.stonebrick, StructureGenHelper.stoneBrickMeta(rand), 2);
		world.setBlock(i + 6, j + 1, k + 3, Blocks.stonebrick, StructureGenHelper.stoneBrickMeta(rand), 2);
		world.setBlock(i + 6, j + 1, k + 4, Blocks.stonebrick, StructureGenHelper.stoneBrickMeta(rand), 2);
		world.setBlock(i + 6, j + 1, k + 5, Blocks.stonebrick, StructureGenHelper.stoneBrickMeta(rand), 2);
		world.setBlock(i + 6, j + 1, k + 6, Blocks.stonebrick, StructureGenHelper.stoneBrickMeta(rand), 2);
		world.setBlock(i + 6, j + 1, k + 7, Blocks.stonebrick, StructureGenHelper.stoneBrickMeta(rand), 2);
		world.setBlock(i + 6, j + 1, k + 8, Blocks.stonebrick, StructureGenHelper.stoneBrickMeta(rand), 2);
		world.setBlock(i + 6, j + 1, k + 9, Blocks.stonebrick, StructureGenHelper.stoneBrickMeta(rand), 2);
		world.setBlock(i + 6, j + 1, k + 10, Blocks.stonebrick, StructureGenHelper.stoneBrickMeta(rand), 2);
		world.setBlock(i + 6, j + 1, k + 11, Blocks.stonebrick, StructureGenHelper.stoneBrickMeta(rand), 2);
		world.setBlock(i + 6, j + 1, k + 12, Blocks.stonebrick, StructureGenHelper.stoneBrickMeta(rand), 2);
		world.setBlock(i + 6, j + 2, k + 2, Blocks.stonebrick, StructureGenHelper.stoneBrickMeta(rand), 2);
		world.setBlock(i + 6, j + 2, k + 3, Blocks.stonebrick, StructureGenHelper.stoneBrickMeta(rand), 2);
		world.setBlock(i + 6, j + 2, k + 4, Blocks.stonebrick, StructureGenHelper.stoneBrickMeta(rand), 2);
		world.setBlock(i + 6, j + 2, k + 5, Blocks.stonebrick, StructureGenHelper.stoneBrickMeta(rand), 2);
		world.setBlock(i + 6, j + 2, k + 6, Blocks.stonebrick, StructureGenHelper.stoneBrickMeta(rand), 2);
		world.setBlock(i + 6, j + 2, k + 7, Blocks.stonebrick, StructureGenHelper.stoneBrickMeta(rand), 2);
		world.setBlock(i + 6, j + 2, k + 8, Blocks.stonebrick, StructureGenHelper.stoneBrickMeta(rand), 2);
		world.setBlock(i + 6, j + 2, k + 9, Blocks.stonebrick, StructureGenHelper.stoneBrickMeta(rand), 2);
		world.setBlock(i + 6, j + 2, k + 10, Blocks.stonebrick, StructureGenHelper.stoneBrickMeta(rand), 2);
		world.setBlock(i + 6, j + 2, k + 11, Blocks.stonebrick, StructureGenHelper.stoneBrickMeta(rand), 2);
		world.setBlock(i + 6, j + 2, k + 12, Blocks.stonebrick, StructureGenHelper.stoneBrickMeta(rand), 2);
		world.setBlock(i + 6, j + 3, k + 2, Blocks.stonebrick, StructureGenHelper.stoneBrickMeta(rand), 2);
		world.setBlock(i + 6, j + 3, k + 3, Blocks.stonebrick, StructureGenHelper.stoneBrickMeta(rand), 2);
		world.setBlock(i + 6, j + 3, k + 4, Blocks.stonebrick, StructureGenHelper.stoneBrickMeta(rand), 2);
		world.setBlock(i + 6, j + 3, k + 5, BlockPedestal.instance, 0, 2);
		te = world.getTileEntity(i + 6, j + 3, k + 5); 
		if(te instanceof TileEntityDisplayPedestal) {
			tedd = (TileEntityDisplayPedestal)te;
			tedd.setInventorySlotContents(0, ArtifactsAPI.artifacts.generateRandomArtifact());
			tedd.rotation = 270;
		}
		world.setBlock(i + 6, j + 3, k + 6, BlockPedestal.instance, 0, 2);
		te = world.getTileEntity(i + 6, j + 3, k + 6); 
		if(te instanceof TileEntityDisplayPedestal) {
			tedd = (TileEntityDisplayPedestal)te;
			tedd.setInventorySlotContents(0, ArtifactsAPI.artifacts.generateRandomArtifact());
			tedd.rotation = 270;
		}
		world.setBlock(i + 6, j + 3, k + 7, BlockPedestal.instance, 0, 2);
		te = world.getTileEntity(i + 6, j + 3, k + 7); 
		if(te instanceof TileEntityDisplayPedestal) {
			tedd = (TileEntityDisplayPedestal)te;
			tedd.setInventorySlotContents(0, ArtifactsAPI.artifacts.generateRandomArtifact());
			tedd.rotation = 270;
		}
		world.setBlock(i + 6, j + 3, k + 8, Blocks.stonebrick, StructureGenHelper.stoneBrickMeta(rand), 2);
		world.setBlock(i + 6, j + 3, k + 9, Blocks.air);
		world.setBlock(i + 6, j + 3, k + 10, Blocks.air);
		world.setBlock(i + 6, j + 3, k + 11, Blocks.air);
		world.setBlock(i + 6, j + 4, k + 2, Blocks.stonebrick, StructureGenHelper.stoneBrickMeta(rand), 2);
		world.setBlock(i + 6, j + 4, k + 3, Blocks.stonebrick, StructureGenHelper.stoneBrickMeta(rand), 2);
		world.setBlock(i + 6, j + 4, k + 4, Blocks.stonebrick, StructureGenHelper.stoneBrickMeta(rand), 2);
		world.setBlock(i + 6, j + 4, k + 5, Blocks.air);
		world.setBlock(i + 6, j + 4, k + 6, Blocks.air);
		world.setBlock(i + 6, j + 4, k + 7, Blocks.air);
		world.setBlock(i + 6, j + 4, k + 8, Blocks.stonebrick, StructureGenHelper.stoneBrickMeta(rand), 2);
		world.setBlock(i + 6, j + 4, k + 9, Blocks.air);
		world.setBlock(i + 6, j + 4, k + 10, Blocks.air);
		world.setBlock(i + 6, j + 4, k + 11, Blocks.air);
		world.setBlock(i + 6, j + 5, k + 2, Blocks.stonebrick, StructureGenHelper.stoneBrickMeta(rand), 2);
		world.setBlock(i + 6, j + 5, k + 3, Blocks.stonebrick, StructureGenHelper.stoneBrickMeta(rand), 2);
		world.setBlock(i + 6, j + 5, k + 4, Blocks.stonebrick, StructureGenHelper.stoneBrickMeta(rand), 2);
		world.setBlock(i + 6, j + 5, k + 6, Blocks.air);
		world.setBlock(i + 6, j + 5, k + 8, Blocks.stonebrick, StructureGenHelper.stoneBrickMeta(rand), 2);
		world.setBlock(i + 6, j + 5, k + 9, Blocks.air);
		world.setBlock(i + 6, j + 5, k + 10, Blocks.air);
		world.setBlock(i + 6, j + 5, k + 11, Blocks.air);
		world.setBlock(i + 6, j + 5, k + 12, Blocks.stonebrick, StructureGenHelper.stoneBrickMeta(rand), 2);
		world.setBlock(i + 6, j + 6, k + 2, Blocks.stonebrick, StructureGenHelper.stoneBrickMeta(rand), 2);
		world.setBlock(i + 6, j + 6, k + 3, Blocks.stonebrick, StructureGenHelper.stoneBrickMeta(rand), 2);
		world.setBlock(i + 6, j + 6, k + 4, Blocks.stonebrick, StructureGenHelper.stoneBrickMeta(rand), 2);
		world.setBlock(i + 6, j + 6, k + 5, Blocks.air);
		world.setBlock(i + 6, j + 6, k + 6, Blocks.air);
		world.setBlock(i + 6, j + 6, k + 7, Blocks.air);
		world.setBlock(i + 6, j + 6, k + 8, Blocks.stonebrick, StructureGenHelper.stoneBrickMeta(rand), 2);
		world.setBlock(i + 6, j + 6, k + 9, Blocks.air);
		world.setBlock(i + 6, j + 6, k + 10, Blocks.air);
		world.setBlock(i + 6, j + 6, k + 11, Blocks.air);
		world.setBlock(i + 6, j + 6, k + 12, Blocks.stonebrick, StructureGenHelper.stoneBrickMeta(rand), 2);
		world.setBlock(i + 6, j + 7, k + 2, Blocks.stonebrick, StructureGenHelper.stoneBrickMeta(rand), 2);
		world.setBlock(i + 6, j + 7, k + 3, Blocks.stonebrick, StructureGenHelper.stoneBrickMeta(rand), 2);
		world.setBlock(i + 6, j + 7, k + 4, Blocks.stonebrick, StructureGenHelper.stoneBrickMeta(rand), 2);
		world.setBlock(i + 6, j + 7, k + 5, Blocks.stonebrick, StructureGenHelper.stoneBrickMeta(rand), 2);
		world.setBlock(i + 6, j + 7, k + 6, Blocks.stonebrick, StructureGenHelper.stoneBrickMeta(rand), 2);
		world.setBlock(i + 6, j + 7, k + 7, Blocks.stonebrick, StructureGenHelper.stoneBrickMeta(rand), 2);
		world.setBlock(i + 6, j + 7, k + 8, Blocks.stonebrick, StructureGenHelper.stoneBrickMeta(rand), 2);
		world.setBlock(i + 6, j + 7, k + 9, Blocks.stonebrick, StructureGenHelper.stoneBrickMeta(rand), 2);
		world.setBlock(i + 6, j + 7, k + 10, Blocks.stonebrick, StructureGenHelper.stoneBrickMeta(rand), 2);
		world.setBlock(i + 6, j + 7, k + 11, Blocks.stonebrick, StructureGenHelper.stoneBrickMeta(rand), 2);
		world.setBlock(i + 6, j + 7, k + 12, Blocks.stonebrick, StructureGenHelper.stoneBrickMeta(rand), 2);
		world.setBlock(i + 6, j + 8, k + 2, Blocks.stonebrick, StructureGenHelper.stoneBrickMeta(rand), 2);
		world.setBlock(i + 6, j + 8, k + 3, Blocks.stonebrick, StructureGenHelper.stoneBrickMeta(rand), 2);
		world.setBlock(i + 6, j + 8, k + 4, Blocks.crafting_table, 0, 2);
		world.setBlock(i + 6, j + 8, k + 5, Blocks.air);
		world.setBlock(i + 6, j + 8, k + 6, Blocks.air);
		world.setBlock(i + 6, j + 8, k + 7, Blocks.air);
		world.setBlock(i + 6, j + 8, k + 8, Blocks.air);
		world.setBlock(i + 6, j + 8, k + 9, Blocks.air);
		world.setBlock(i + 6, j + 8, k + 10, Blocks.bookshelf, 0, 2);
		world.setBlock(i + 6, j + 8, k + 11, Blocks.stonebrick, StructureGenHelper.stoneBrickMeta(rand), 2);
		world.setBlock(i + 6, j + 8, k + 12, Blocks.stonebrick, StructureGenHelper.stoneBrickMeta(rand), 2);
		world.setBlock(i + 6, j + 9, k + 2, Blocks.stonebrick, StructureGenHelper.stoneBrickMeta(rand), 2);
		world.setBlock(i + 6, j + 9, k + 3, Blocks.air);
		world.setBlock(i + 6, j + 9, k + 4, Blocks.air);
		world.setBlock(i + 6, j + 9, k + 5, Blocks.air);
		world.setBlock(i + 6, j + 9, k + 6, Blocks.air);
		world.setBlock(i + 6, j + 9, k + 7, Blocks.air);
		world.setBlock(i + 6, j + 9, k + 8, Blocks.air);
		world.setBlock(i + 6, j + 9, k + 9, Blocks.air);
		world.setBlock(i + 6, j + 9, k + 10, Blocks.bookshelf, 0, 2);
		world.setBlock(i + 6, j + 9, k + 11, Blocks.stonebrick, StructureGenHelper.stoneBrickMeta(rand), 2);
		world.setBlock(i + 6, j + 9, k + 12, Blocks.stonebrick, StructureGenHelper.stoneBrickMeta(rand), 2);
		world.setBlock(i + 6, j + 10, k + 2, Blocks.stonebrick, StructureGenHelper.stoneBrickMeta(rand), 2);
		world.setBlock(i + 6, j + 10, k + 3, Blocks.stonebrick, StructureGenHelper.stoneBrickMeta(rand), 2);
		world.setBlock(i + 6, j + 10, k + 4, Blocks.stonebrick, StructureGenHelper.stoneBrickMeta(rand), 2);
		world.setBlock(i + 6, j + 10, k + 5, Blocks.stonebrick, StructureGenHelper.stoneBrickMeta(rand), 2);
		world.setBlock(i + 6, j + 10, k + 6, Blocks.stonebrick, StructureGenHelper.stoneBrickMeta(rand), 2);
		world.setBlock(i + 6, j + 10, k + 7, Blocks.stonebrick, StructureGenHelper.stoneBrickMeta(rand), 2);
		world.setBlock(i + 6, j + 10, k + 8, Blocks.stonebrick, StructureGenHelper.stoneBrickMeta(rand), 2);
		world.setBlock(i + 6, j + 10, k + 9, Blocks.stonebrick, StructureGenHelper.stoneBrickMeta(rand), 2);
		world.setBlock(i + 6, j + 10, k + 10, Blocks.stonebrick, StructureGenHelper.stoneBrickMeta(rand), 2);
		world.setBlock(i + 6, j + 10, k + 11, Blocks.stonebrick, StructureGenHelper.stoneBrickMeta(rand), 2);
		world.setBlock(i + 6, j + 10, k + 12, Blocks.stonebrick, StructureGenHelper.stoneBrickMeta(rand), 2);
		world.setBlock(i + 6, j + 11, k + 1, Blocks.oak_stairs, 5, 2);
		world.setBlock(i + 6, j + 11, k + 2, Blocks.planks, 0, 2);
		world.setBlock(i + 6, j + 11, k + 3, Blocks.stonebrick, StructureGenHelper.stoneBrickMeta(rand), 2);
		world.setBlock(i + 6, j + 11, k + 4, Blocks.stonebrick, StructureGenHelper.stoneBrickMeta(rand), 2);
		world.setBlock(i + 6, j + 11, k + 5, Blocks.stonebrick, StructureGenHelper.stoneBrickMeta(rand), 2);
		world.setBlock(i + 6, j + 11, k + 6, Blocks.stonebrick, StructureGenHelper.stoneBrickMeta(rand), 2);
		world.setBlock(i + 6, j + 11, k + 7, Blocks.stonebrick, StructureGenHelper.stoneBrickMeta(rand), 2);
		world.setBlock(i + 6, j + 11, k + 8, Blocks.stonebrick, StructureGenHelper.stoneBrickMeta(rand), 2);
		world.setBlock(i + 6, j + 11, k + 9, Blocks.stonebrick, StructureGenHelper.stoneBrickMeta(rand), 2);
		world.setBlock(i + 6, j + 11, k + 10, Blocks.stonebrick, StructureGenHelper.stoneBrickMeta(rand), 2);
		world.setBlock(i + 6, j + 11, k + 11, Blocks.stonebrick, StructureGenHelper.stoneBrickMeta(rand), 2);
		world.setBlock(i + 6, j + 11, k + 12, Blocks.stone_brick_stairs, 3, 2);
		world.setBlock(i + 6, j + 12, k + 1, Blocks.planks, 0, 2);
		world.setBlock(i + 6, j + 12, k + 2, Blocks.planks, 0, 2);
		world.setBlock(i + 6, j + 12, k + 3, Blocks.stonebrick, StructureGenHelper.stoneBrickMeta(rand), 2);
		world.setBlock(i + 6, j + 12, k + 4, Blocks.air);
		world.setBlock(i + 6, j + 12, k + 5, Blocks.air);
		world.setBlock(i + 6, j + 12, k + 11, Blocks.stonebrick, StructureGenHelper.stoneBrickMeta(rand), 2);
		world.setBlock(i + 6, j + 13, k + 1, Blocks.planks, 0, 2);
		world.setBlock(i + 6, j + 13, k + 2, Blocks.planks, 0, 2);
		world.setBlock(i + 6, j + 13, k + 3, Blocks.stonebrick, StructureGenHelper.stoneBrickMeta(rand), 2);
		world.setBlock(i + 6, j + 13, k + 4, Blocks.air);
		world.setBlock(i + 6, j + 13, k + 5, Blocks.air);
		world.setBlock(i + 6, j + 13, k + 7, Blocks.air);
		world.setBlock(i + 6, j + 13, k + 8, Blocks.air);
		world.setBlock(i + 6, j + 13, k + 9, Blocks.air);
		world.setBlock(i + 6, j + 13, k + 10, Blocks.air);
		world.setBlock(i + 6, j + 13, k + 11, Blocks.iron_bars, 0, 2);
		world.setBlock(i + 6, j + 14, k + 1, Blocks.planks, 0, 2);
		world.setBlock(i + 6, j + 14, k + 2, Blocks.planks, 0, 2);
		world.setBlock(i + 6, j + 14, k + 3, Blocks.stonebrick, StructureGenHelper.stoneBrickMeta(rand), 2);
		world.setBlock(i + 6, j + 14, k + 4, Blocks.stonebrick, StructureGenHelper.stoneBrickMeta(rand), 2);
		world.setBlock(i + 6, j + 14, k + 5, Blocks.stonebrick, StructureGenHelper.stoneBrickMeta(rand), 2);
		world.setBlock(i + 6, j + 14, k + 6, Blocks.stonebrick, StructureGenHelper.stoneBrickMeta(rand), 2);
		world.setBlock(i + 6, j + 14, k + 7, Blocks.air);
		world.setBlock(i + 6, j + 14, k + 10, Blocks.air);
		world.setBlock(i + 6, j + 14, k + 11, Blocks.iron_bars, 0, 2);
		world.setBlock(i + 6, j + 15, k + 0, Blocks.oak_stairs, 1, 2);
		world.setBlock(i + 6, j + 15, k + 1, Blocks.oak_stairs, 1, 2);
		world.setBlock(i + 6, j + 15, k + 2, Blocks.planks, 0, 2);
		world.setBlock(i + 6, j + 15, k + 3, Blocks.stonebrick, StructureGenHelper.stoneBrickMeta(rand), 2);
		world.setBlock(i + 6, j + 15, k + 6, Blocks.stonebrick, StructureGenHelper.stoneBrickMeta(rand), 2);
		world.setBlock(i + 6, j + 15, k + 7, Blocks.glowstone, 0, 2);
		world.setBlock(i + 6, j + 15, k + 8, Blocks.stonebrick, StructureGenHelper.stoneBrickMeta(rand), 2);
		world.setBlock(i + 6, j + 15, k + 9, Blocks.stonebrick, StructureGenHelper.stoneBrickMeta(rand), 2);
		world.setBlock(i + 6, j + 15, k + 10, Blocks.stonebrick, StructureGenHelper.stoneBrickMeta(rand), 2);
		world.setBlock(i + 6, j + 15, k + 11, Blocks.stonebrick, StructureGenHelper.stoneBrickMeta(rand), 2);
		world.setBlock(i + 6, j + 16, k + 2, Blocks.oak_stairs, 2, 2);
		world.setBlock(i + 6, j + 16, k + 3, Blocks.oak_stairs, 1, 2);
		world.setBlock(i + 6, j + 16, k + 4, Blocks.stonebrick, StructureGenHelper.stoneBrickMeta(rand), 2);
		world.setBlock(i + 6, j + 16, k + 5, Blocks.stonebrick, StructureGenHelper.stoneBrickMeta(rand), 2);
		world.setBlock(i + 6, j + 16, k + 7, Blocks.stonebrick, StructureGenHelper.stoneBrickMeta(rand), 2);
		world.setBlock(i + 6, j + 16, k + 8, Blocks.iron_bars, 0, 2);
		world.setBlock(i + 6, j + 16, k + 9, Blocks.stonebrick, StructureGenHelper.stoneBrickMeta(rand), 2);
		world.setBlock(i + 6, j + 16, k + 10, Blocks.stonebrick, StructureGenHelper.stoneBrickMeta(rand), 2);
		world.setBlock(i + 6, j + 16, k + 11, Blocks.stone_brick_stairs, 3, 2);
		world.setBlock(i + 6, j + 17, k + 4, Blocks.stonebrick, StructureGenHelper.stoneBrickMeta(rand), 2);
		world.setBlock(i + 6, j + 17, k + 5, Blocks.stonebrick, StructureGenHelper.stoneBrickMeta(rand), 2);
		world.setBlock(i + 6, j + 17, k + 7, Blocks.stonebrick, StructureGenHelper.stoneBrickMeta(rand), 2);
		world.setBlock(i + 6, j + 17, k + 8, Blocks.iron_bars, 0, 2);
		world.setBlock(i + 6, j + 17, k + 9, Blocks.stonebrick, StructureGenHelper.stoneBrickMeta(rand), 2);
		world.setBlock(i + 6, j + 17, k + 10, Blocks.stonebrick, StructureGenHelper.stoneBrickMeta(rand), 2);
		world.setBlock(i + 6, j + 18, k + 4, Blocks.stonebrick, StructureGenHelper.stoneBrickMeta(rand), 2);
		world.setBlock(i + 6, j + 18, k + 5, Blocks.stonebrick, StructureGenHelper.stoneBrickMeta(rand), 2);
		world.setBlock(i + 6, j + 18, k + 6, Blocks.stonebrick, StructureGenHelper.stoneBrickMeta(rand), 2);
		world.setBlock(i + 6, j + 18, k + 7, Blocks.stonebrick, StructureGenHelper.stoneBrickMeta(rand), 2);
		world.setBlock(i + 6, j + 18, k + 8, Blocks.stonebrick, StructureGenHelper.stoneBrickMeta(rand), 2);
		world.setBlock(i + 6, j + 18, k + 9, Blocks.stonebrick, StructureGenHelper.stoneBrickMeta(rand), 2);
		world.setBlock(i + 6, j + 18, k + 10, Blocks.stonebrick, StructureGenHelper.stoneBrickMeta(rand), 2);
		world.setBlock(i + 6, j + 19, k + 4, Blocks.stone_brick_stairs, 2, 2);
		world.setBlock(i + 6, j + 19, k + 5, Blocks.stonebrick, StructureGenHelper.stoneBrickMeta(rand), 2);
		world.setBlock(i + 6, j + 19, k + 6, Blocks.air);
		world.setBlock(i + 6, j + 19, k + 8, Blocks.air);
		world.setBlock(i + 6, j + 19, k + 9, Blocks.stonebrick, StructureGenHelper.stoneBrickMeta(rand), 2);
		world.setBlock(i + 6, j + 19, k + 10, Blocks.stone_brick_stairs, 3, 2);
		world.setBlock(i + 6, j + 20, k + 5, Blocks.iron_bars, 0, 2);
		world.setBlock(i + 6, j + 20, k + 6, Blocks.air);
		world.setBlock(i + 6, j + 20, k + 8, Blocks.air);
		world.setBlock(i + 6, j + 20, k + 9, Blocks.iron_bars, 0, 2);
		world.setBlock(i + 6, j + 21, k + 5, Blocks.stonebrick, StructureGenHelper.stoneBrickMeta(rand), 2);/*set air?*/
		world.setBlock(i + 6, j + 21, k + 6, Blocks.stonebrick, 1, 2);/*set air?*/
		world.setBlock(i + 6, j + 21, k + 8, Blocks.stonebrick, 1, 2);/*set air?*/
		world.setBlock(i + 6, j + 21, k + 9, Blocks.stonebrick, StructureGenHelper.stoneBrickMeta(rand), 2);/*set air?*/
		world.setBlock(i + 6, j + 22, k + 5, Blocks.stonebrick, StructureGenHelper.stoneBrickMeta(rand), 2);
		world.setBlock(i + 6, j + 22, k + 6, Blocks.stonebrick, StructureGenHelper.stoneBrickMeta(rand), 2);
		world.setBlock(i + 6, j + 22, k + 8, Blocks.stonebrick, StructureGenHelper.stoneBrickMeta(rand), 2);
		world.setBlock(i + 6, j + 22, k + 9, Blocks.stonebrick, StructureGenHelper.stoneBrickMeta(rand), 2);
		world.setBlock(i + 6, j + 23, k + 5, Blocks.stone_brick_stairs, 2, 2);
		world.setBlock(i + 6, j + 23, k + 6, Blocks.stonebrick, StructureGenHelper.stoneBrickMeta(rand), 2);
		world.setBlock(i + 6, j + 23, k + 8, Blocks.stonebrick, StructureGenHelper.stoneBrickMeta(rand), 2);
		world.setBlock(i + 6, j + 23, k + 9, Blocks.stone_brick_stairs, 3, 2);
		world.setBlock(i + 6, j + 24, k + 6, Blocks.stonebrick, StructureGenHelper.stoneBrickMeta(rand), 2);
