package com.draco18s.artifacts.worldgen;

import java.util.Random;

import com.draco18s.artifacts.api.ArtifactsAPI;
import com.draco18s.artifacts.block.*;
import com.draco18s.artifacts.entity.*;
import com.draco18s.artifacts.item.*;

import net.minecraft.block.Block;
import net.minecraft.entity.item.EntityItemFrame;
import net.minecraft.entity.item.EntityPainting;
import net.minecraft.init.Blocks;
import net.minecraft.init.Items;
import net.minecraft.item.Item;
import net.minecraft.item.ItemStack;
import net.minecraft.nbt.NBTTagCompound;
import net.minecraft.tileentity.TileEntity;
import net.minecraft.tileentity.TileEntityChest;
import net.minecraft.tileentity.TileEntityFlowerPot;
import net.minecraft.tileentity.TileEntityMobSpawner;
import net.minecraft.util.WeightedRandomChestContent;
import net.minecraft.world.World;
import net.minecraft.world.gen.feature.WorldGenerator;
import net.minecraft.world.gen.structure.StructureBoundingBox;
import net.minecraft.world.gen.structure.StructureComponent;
import net.minecraftforge.common.ChestGenHooks;

public class StructureJourneymanTower extends WorldGenerator {

	protected StructureJourneymanTower() {
	}

	@Override
	public boolean generate(World world, Random random, int x, int y, int z) {
		for (z -= 8; y > 5 && (!world.getBlock(x, y, z).isOpaqueCube() || world.getBlock(x, y, z) == Blocks.leaves); --y)
        {
            ;
        }

        if (y <= 61)
        {
            return false;
        }
        else
        {
        	build(world, random, x-5, y, z+1);
        }
		return false;
	}
	
	public static boolean build(World world, Random rand, int i, int j, int k) {
		//System.out.println("Placing journeyman tower at (" + i + "," + k+ ")");
		world.setBlock(i + 0, j + 11, k + 1, Blocks.stone_stairs, 4, 2);
		world.setBlock(i + 0, j + 11, k + 2, Blocks.stone_stairs, 4, 2);
		world.setBlock(i + 0, j + 11, k + 3, Blocks.stone_stairs, 4, 2);
		world.setBlock(i + 0, j + 12, k + 1, StructureGenHelper.cobbleOrMossy(rand), 0, 2);
		world.setBlock(i + 0, j + 12, k + 3, StructureGenHelper.cobbleOrMossy(rand), 0, 2);
		world.setBlock(i + 1, j + 0, k + 3, StructureGenHelper.cobbleOrMossy(rand), 0, 2);
		world.setBlock(i + 1, j + 0, k + 4, StructureGenHelper.cobbleOrMossy(rand), 0, 2);
		world.setBlock(i + 1, j + 0, k + 5, StructureGenHelper.cobbleOrMossy(rand), 0, 2);
		world.setBlock(i + 1, j + 1, k + 3, StructureGenHelper.cobbleOrMossy(rand), 0, 2);
		world.setBlock(i + 1, j + 1, k + 4, StructureGenHelper.cobbleOrMossy(rand), 0, 2);
		world.setBlock(i + 1, j + 1, k + 5, StructureGenHelper.cobbleOrMossy(rand), 0, 2);
		world.setBlock(i + 1, j + 2, k + 3, StructureGenHelper.cobbleOrMossy(rand), 0, 2);
		world.setBlock(i + 1, j + 2, k + 4, StructureGenHelper.cobbleOrMossy(rand), 0, 2);
		world.setBlock(i + 1, j + 2, k + 5, StructureGenHelper.cobbleOrMossy(rand), 0, 2);
		world.setBlock(i + 1, j + 3, k + 3, StructureGenHelper.cobbleOrMossy(rand), 0, 2);
		world.setBlock(i + 1, j + 3, k + 4, StructureGenHelper.cobbleOrMossy(rand), 0, 2);
		world.setBlock(i + 1, j + 3, k + 5, StructureGenHelper.cobbleOrMossy(rand), 0, 2);
		world.setBlock(i + 1, j + 4, k + 3, StructureGenHelper.cobbleOrMossy(rand), 0, 2);
		world.setBlock(i + 1, j + 4, k + 4, StructureGenHelper.cobbleOrMossy(rand), 0, 2);
		world.setBlock(i + 1, j + 4, k + 5, StructureGenHelper.cobbleOrMossy(rand), 0, 2);
		//world.setBlock(i + 1, j + 9, k + 2, Blocks.stone_stairs, 4, 2);
		//world.setBlock(i + 1, j + 9, k + 3, Blocks.stone_stairs, 4, 2);
		world.setBlock(i + 1, j + 10, k + 1, Blocks.stone_stairs, 6, 2);
		world.setBlock(i + 1, j + 10, k + 2, Blocks.stone_stairs, 4, 2);
		world.setBlock(i + 1, j + 10, k + 3, Blocks.stone_stairs, 4, 2);
		world.setBlock(i + 1, j + 11, k + 0, Blocks.stone_stairs, 6, 2);
		world.setBlock(i + 1, j + 11, k + 1, Blocks.air);
		world.setBlock(i + 1, j + 11, k + 2, Blocks.air);
		world.setBlock(i + 1, j + 11, k + 3, Blocks.air);
		world.setBlock(i + 1, j + 11, k + 4, Blocks.stone_stairs, 7, 2);
		world.setBlock(i + 1, j + 12, k + 0, StructureGenHelper.cobbleOrMossy(rand), 0, 2);
		world.setBlock(i + 1, j + 12, k + 1, Blocks.air);
		world.setBlock(i + 1, j + 12, k + 2, Blocks.air);
		world.setBlock(i + 1, j + 12, k + 3, Blocks.air);
		world.setBlock(i + 1, j + 12, k + 4, StructureGenHelper.cobbleOrMossy(rand), 0, 2);
		world.setBlock(i + 1, j + 13, k + 1, Blocks.air);
		world.setBlock(i + 1, j + 13, k + 2, Blocks.air);
		world.setBlock(i + 1, j + 13, k + 3, Blocks.air);
		world.setBlock(i + 2, j + 0, k + 2, StructureGenHelper.cobbleOrMossy(rand), 0, 2);
		world.setBlock(i + 2, j + 0, k + 3, StructureGenHelper.cobbleOrMossy(rand), 0, 2);
		world.setBlock(i + 2, j + 0, k + 4, StructureGenHelper.cobbleOrMossy(rand), 0, 2);
		world.setBlock(i + 2, j + 0, k + 5, StructureGenHelper.cobbleOrMossy(rand), 0, 2);
		world.setBlock(i + 2, j + 0, k + 6, StructureGenHelper.cobbleOrMossy(rand), 0, 2);
		world.setBlock(i + 2, j + 1, k + 2, StructureGenHelper.cobbleOrMossy(rand), 0, 2);
		world.setBlock(i + 2, j + 1, k + 3, Blocks.air);
		world.setBlock(i + 2, j + 1, k + 4, Blocks.air);
		world.setBlock(i + 2, j + 2, k + 5, Blocks.air);
		world.setBlock(i + 2, j + 1, k + 6, StructureGenHelper.cobbleOrMossy(rand), 0, 2);
		world.setBlock(i + 2, j + 2, k + 6, BlockTrap.instance, 4, 2);
		world.setBlockMetadataWithNotify(i + 2, j + 2, k + 6, 2, 2);
		TileEntity te = world.getTileEntity(i + 2, j + 2, k + 6); 
		TileEntityTrap ted;
		if(te instanceof TileEntityTrap) {
			ted = (TileEntityTrap)te;
			//PlaceTraps.addTrapItem(ted);
			ted.func_146019_a/*addItem*/(new ItemStack(Items.iron_sword, 1, 245));
		}
		world.setBlock(i + 2, j + 2, k + 2, StructureGenHelper.cobbleOrMossy(rand), 0, 2);
		world.setBlock(i + 2, j + 2, k + 3, Blocks.air);
		world.setBlock(i + 2, j + 2, k + 4, Blocks.air);
		//world.setBlock(i + 2, j + 2, k + 6, StructureGenHelper.cobbleOrMossy(rand), 0, 2);
		world.setBlock(i + 2, j + 3, k + 2, StructureGenHelper.cobbleOrMossy(rand), 0, 2);
		world.setBlock(i + 2, j + 3, k + 3, StructureGenHelper.randomBlock(rand, new Block[]{Blocks.web, Blocks.air}), 0, 2);
		world.setBlock(i + 2, j + 3, k + 4, Blocks.air);
		world.setBlock(i + 2, j + 3, k + 5, Blocks.air);
		world.setBlock(i + 2, j + 3, k + 6, StructureGenHelper.cobbleOrMossy(rand), 0, 2);
		world.setBlock(i + 2, j + 4, k + 2, StructureGenHelper.cobbleOrMossy(rand), 0, 2);
		world.setBlock(i + 2, j + 4, k + 3, StructureGenHelper.cobbleOrMossy(rand), 0, 2);
		world.setBlock(i + 2, j + 4, k + 4, StructureGenHelper.cobbleOrMossy(rand), 0, 2);
		world.setBlock(i + 2, j + 4, k + 5, StructureGenHelper.cobbleOrMossy(rand), 0, 2);
		world.setBlock(i + 2, j + 4, k + 6, StructureGenHelper.cobbleOrMossy(rand), 0, 2);
		world.setBlock(i + 2, j + 5, k + 2, StructureGenHelper.cobbleOrMossy(rand), 0, 2);
		world.setBlock(i + 2, j + 5, k + 3, StructureGenHelper.cobbleOrMossy(rand), 0, 2);
		world.setBlock(i + 2, j + 5, k + 4, StructureGenHelper.cobbleOrMossy(rand), 0, 2);
		world.setBlock(i + 2, j + 5, k + 5, StructureGenHelper.cobbleOrMossy(rand), 0, 2);
		world.setBlock(i + 2, j + 5, k + 6, StructureGenHelper.cobbleOrMossy(rand), 0, 2);
		world.setBlock(i + 2, j + 6, k + 2, StructureGenHelper.cobbleOrMossy(rand), 0, 2);
		world.setBlock(i + 2, j + 6, k + 3, StructureGenHelper.cobbleOrMossy(rand), 0, 2);
		world.setBlock(i + 2, j + 6, k + 4, StructureGenHelper.cobbleOrMossy(rand), 0, 2);
		world.setBlock(i + 2, j + 6, k + 5, StructureGenHelper.cobbleOrMossy(rand), 0, 2);
		world.setBlock(i + 2, j + 6, k + 6, StructureGenHelper.cobbleOrMossy(rand), 0, 2);
		world.setBlock(i + 2, j + 7, k + 3, StructureGenHelper.cobbleOrMossy(rand), 0, 2);
		world.setBlock(i + 2, j + 7, k + 4, StructureGenHelper.cobbleOrMossy(rand), 0, 2);
		world.setBlock(i + 2, j + 7, k + 5, StructureGenHelper.cobbleOrMossy(rand), 0, 2);
		world.setBlock(i + 2, j + 8, k + 3, StructureGenHelper.cobbleOrMossy(rand), 0, 2);
		world.setBlock(i + 2, j + 8, k + 4, StructureGenHelper.cobbleOrMossy(rand), 0, 2);
		world.setBlock(i + 2, j + 8, k + 5, StructureGenHelper.cobbleOrMossy(rand), 0, 2);
		world.setBlock(i + 2, j + 8, k + 7, Blocks.stone_stairs, 4, 2);
		world.setBlock(i + 2, j + 8, k + 8, Blocks.stone_stairs, 4, 2);
		//world.setBlock(i + 2, j + 9, k + 2, Blocks.stone_stairs, 6, 2);
		world.setBlock(i + 2, j + 9, k + 3, StructureGenHelper.cobbleOrMossy(rand), 0, 2);
		world.setBlock(i + 2, j + 9, k + 7, StructureGenHelper.cobbleOrMossy(rand), 0, 2);
		/*te = world.getTileEntity(i + 2, j + 9, k + 7); 
		if(te instanceof TileEntityTrap) {
			ted = (TileEntityTrap)te;
			PlaceTraps.addTrapItem(ted);
		}*/
		world.setBlock(i + 2, j + 9, k + 8, StructureGenHelper.cobbleOrMossy(rand), 0, 2);
		world.setBlock(i + 2, j + 10, k + 1, Blocks.stone_stairs, 6, 2);
		world.setBlock(i + 2, j + 10, k + 2, StructureGenHelper.cobbleOrMossy(rand), 0, 2);
		world.setBlock(i + 2, j + 10, k + 3, StructureGenHelper.cobbleOrMossy(rand), 0, 2);
		world.setBlock(i + 2, j + 10, k + 7, StructureGenHelper.cobbleOrMossy(rand), 0, 2);
		world.setBlock(i + 2, j + 10, k + 8, StructureGenHelper.cobbleOrMossy(rand), 0, 2);
		world.setBlock(i + 2, j + 11, k + 0, Blocks.stone_stairs, 6, 2);
		world.setBlock(i + 2, j + 11, k + 1, Blocks.air);
		world.setBlock(i + 2, j + 11, k + 2, Blocks.air);
		world.setBlock(i + 2, j + 11, k + 3, Blocks.air);
		world.setBlock(i + 2, j + 11, k + 4, Blocks.stone_stairs, 7, 2);
		world.setBlock(i + 2, j + 11, k + 6, Blocks.birch_stairs, 2, 2);
		world.setBlock(i + 2, j + 11, k + 7, Blocks.birch_stairs, 0, 2);
		world.setBlock(i + 2, j + 11, k + 8, Blocks.birch_stairs, 0, 2);
		world.setBlock(i + 2, j + 11, k + 9, Blocks.birch_stairs, 3, 2);
		world.setBlock(i + 2, j + 12, k + 1, Blocks.air);
		world.setBlock(i + 2, j + 12, k + 2, Blocks.air);
		world.setBlock(i + 2, j + 12, k + 3, Blocks.air);
		world.setBlock(i + 2, j + 13, k + 1, Blocks.air);
		world.setBlock(i + 2, j + 13, k + 2, Blocks.air);
		world.setBlock(i + 2, j + 13, k + 3, Blocks.air);
		world.setBlock(i + 3, j + 0, k + 1, StructureGenHelper.cobbleOrMossy(rand), 0, 2);
		world.setBlock(i + 3, j + 0, k + 2, StructureGenHelper.cobbleOrMossy(rand), 0, 2);
		world.setBlock(i + 3, j + 0, k + 3, StructureGenHelper.cobbleOrMossy(rand), 0, 2);
		world.setBlock(i + 3, j + 0, k + 4, StructureGenHelper.cobbleOrMossy(rand), 0, 2);
		world.setBlock(i + 3, j + 0, k + 5, StructureGenHelper.cobbleOrMossy(rand), 0, 2);
		world.setBlock(i + 3, j + 0, k + 6, StructureGenHelper.cobbleOrMossy(rand), 0, 2);
		world.setBlock(i + 3, j + 0, k + 7, StructureGenHelper.cobbleOrMossy(rand), 0, 2);
		world.setBlock(i + 3, j + 1, k + 1, StructureGenHelper.cobbleOrMossy(rand), 0, 2);
		world.setBlock(i + 3, j + 1, k + 2, Blocks.air);
		world.setBlock(i + 3, j + 1, k + 3, Blocks.air);
		world.setBlock(i + 3, j + 1, k + 4, Blocks.air);
		world.setBlock(i + 3, j + 1, k + 6, BlockInvisibleBlock.instance, 0, 2);
		world.setBlock(i + 3, j + 1, k + 7, StructureGenHelper.cobbleOrMossy(rand), 0, 2);
		world.setBlock(i + 3, j + 2, k + 1, StructureGenHelper.cobbleOrMossy(rand), 0, 2);
		world.setBlock(i + 3, j + 2, k + 2, Blocks.air);
		world.setBlock(i + 3, j + 2, k + 3, Blocks.air);
		world.setBlock(i + 3, j + 2, k + 4, Blocks.air);
		world.setBlock(i + 3, j + 2, k + 6, BlockInvisibleBlock.instance, 0, 2);
		world.setBlock(i + 3, j + 2, k + 7, StructureGenHelper.cobbleOrMossy(rand), 0, 2);
		world.setBlock(i + 3, j + 3, k + 1, StructureGenHelper.cobbleOrMossy(rand), 0, 2);
		world.setBlock(i + 3, j + 3, k + 2, Blocks.air);
		world.setBlock(i + 3, j + 3, k + 3, Blocks.air);
		world.setBlock(i + 3, j + 3, k + 4, Blocks.air);
		world.setBlock(i + 3, j + 3, k + 6, BlockInvisibleBlock.instance, 0, 2);
		world.setBlock(i + 3, j + 3, k + 7, StructureGenHelper.cobbleOrMossy(rand), 0, 2);
		world.setBlock(i + 3, j + 4, k + 1, StructureGenHelper.cobbleOrMossy(rand), 0, 2);
		world.setBlock(i + 3, j + 4, k + 2, StructureGenHelper.cobbleOrMossy(rand), 0, 2);
		world.setBlock(i + 3, j + 4, k + 3, StructureGenHelper.cobbleOrMossy(rand), 0, 2);
		world.setBlock(i + 3, j + 4, k + 4, StructureGenHelper.cobbleOrMossy(rand), 0, 2);
		world.setBlock(i + 3, j + 4, k + 6, StructureGenHelper.cobbleOrMossy(rand), 0, 2);
		world.setBlock(i + 3, j + 4, k + 7, StructureGenHelper.cobbleOrMossy(rand), 0, 2);
		world.setBlock(i + 3, j + 5, k + 1, StructureGenHelper.cobbleOrMossy(rand), 0, 2);
		world.setBlock(i + 3, j + 5, k + 2, StructureGenHelper.cobbleOrMossy(rand), 0, 2);
		world.setBlock(i + 3, j + 5, k + 3, Blocks.air);
		world.setBlock(i + 3, j + 5, k + 4, Blocks.air);
		world.setBlock(i + 3, j + 5, k + 5, Blocks.air);
		world.setBlock(i + 3, j + 5, k + 6, StructureGenHelper.cobbleOrMossy(rand), 0, 2);
		world.setBlock(i + 3, j + 5, k + 7, StructureGenHelper.cobbleOrMossy(rand), 0, 2);
		world.setBlock(i + 3, j + 6, k + 1, StructureGenHelper.cobbleOrMossy(rand), 0, 2);
		world.setBlock(i + 3, j + 6, k + 2, StructureGenHelper.cobbleOrMossy(rand), 0, 2);
		world.setBlock(i + 3, j + 6, k + 3, Blocks.air);
		world.setBlock(i + 3, j + 6, k + 4, Blocks.air);
		world.setBlock(i + 3, j + 6, k + 5, Blocks.air);
		world.setBlock(i + 3, j + 6, k + 6, StructureGenHelper.cobbleOrMossy(rand), 0, 2);
		world.setBlock(i + 3, j + 6, k + 7, StructureGenHelper.cobbleOrMossy(rand), 0, 2);
		world.setBlock(i + 3, j + 7, k + 2, StructureGenHelper.cobbleOrMossy(rand), 0, 2);
		world.setBlock(i + 3, j + 7, k + 3, Blocks.air);
		world.setBlock(i + 3, j + 7, k + 4, Blocks.air);
		world.setBlock(i + 3, j + 7, k + 5, Blocks.air);
		world.setBlock(i + 3, j + 7, k + 6, StructureGenHelper.cobbleOrMossy(rand), 0, 2);
		world.setBlock(i + 3, j + 7, k + 7, StructureGenHelper.cobbleOrMossy(rand), 0, 2);
		world.setBlock(i + 3, j + 7, k + 8, Blocks.stone_stairs, 4, 2);
		world.setBlock(i + 3, j + 8, k + 2, StructureGenHelper.cobbleOrMossy(rand), 0, 2);
		world.setBlock(i + 3, j + 8, k + 3, StructureGenHelper.cobbleOrMossy(rand), 0, 2);
		world.setBlock(i + 3, j + 8, k + 4, StructureGenHelper.cobbleOrMossy(rand), 0, 2);
		world.setBlock(i + 3, j + 8, k + 5, StructureGenHelper.cobbleOrMossy(rand), 0, 2);
		world.setBlock(i + 3, j + 8, k + 6, StructureGenHelper.cobbleOrMossy(rand), 0, 2);
		world.setBlock(i + 3, j + 8, k + 7, StructureGenHelper.cobbleOrMossy(rand), 0, 2);
		world.setBlock(i + 3, j + 8, k + 8, StructureGenHelper.cobbleOrMossy(rand), 0, 2);
		world.setBlock(i + 3, j + 8, k + 9, Blocks.stone_stairs, 7, 2);
		world.setBlock(i + 3, j + 9, k + 2, StructureGenHelper.cobbleOrMossy(rand), 0, 2);
		world.setBlock(i + 3, j + 10, k + 3, BlockTrap.instance, 5, 2);
		world.setBlockMetadataWithNotify(i + 3, j + 10, k + 3, 5, 2);
		te = world.getTileEntity(i + 3, j + 10, k + 3);
		if(te != null && te instanceof TileEntityTrap) {
			ted = (TileEntityTrap)te;
			//PlaceTraps.addTrapItem(ted);
			ted.func_146019_a/*addItem*/(new ItemStack(Items.iron_sword, 1, 245));
		}
		world.setBlock(i + 3, j + 9, k + 4, StructureGenHelper.cobbleOrMossy(rand), 0, 2);
		world.setBlock(i + 3, j + 9, k + 5, StructureGenHelper.cobbleOrMossy(rand), 0, 2);
		world.setBlock(i + 3, j + 9, k + 6, StructureGenHelper.cobbleOrMossy(rand), 0, 2);
		world.setBlock(i + 3, j + 9, k + 7, Blocks.air);
		world.setBlock(i + 3, j + 9, k + 8, StructureGenHelper.randomBlock(rand, new Block[]{Blocks.chest, Blocks.chest, Blocks.air}), 2, 2);//trapped chest
		te = world.getTileEntity(i + 3, j + 9, k + 8);
		if(te != null && te instanceof TileEntityChest) {
			TileEntityChest tec = (TileEntityChest)te;
			ChestGenHooks info = ChestGenHooks.getInfo(ChestGenHooks.DUNGEON_CHEST);
            WeightedRandomChestContent.generateChestContents(rand, info.getItems(rand), tec, info.getCount(rand));
		}
		world.setBlock(i + 3, j + 9, k + 9, StructureGenHelper.cobbleOrMossy(rand), 0, 2);
		world.setBlock(i + 3, j + 10, k + 1, Blocks.stone_stairs, 6, 2);
		world.setBlock(i + 3, j + 10, k + 2, StructureGenHelper.cobbleOrMossy(rand), 0, 2);
		world.setBlock(i + 3, j + 9, k + 3, StructureGenHelper.cobbleOrMossy(rand), 0, 2);
		world.setBlock(i + 3, j + 10, k + 4, StructureGenHelper.cobbleOrMossy(rand), 0, 2);
		world.setBlock(i + 3, j + 10, k + 5, StructureGenHelper.cobbleOrMossy(rand), 0, 2);
		world.setBlock(i + 3, j + 10, k + 6, StructureGenHelper.cobbleOrMossy(rand), 0, 2);
		world.setBlock(i + 3, j + 10, k + 7, Blocks.air);
		world.setBlock(i + 3, j + 10, k + 8, Blocks.air);
		world.setBlock(i + 3, j + 10, k + 9, StructureGenHelper.cobbleOrMossy(rand), 0, 2);
		world.setBlock(i + 3, j + 11, k + 0, Blocks.stone_stairs, 6, 2);
		world.setBlock(i + 3, j + 11, k + 1, Blocks.air);
		world.setBlock(i + 3, j + 11, k + 2, Blocks.stone_stairs, 0, 2);
		world.setBlock(i + 3, j + 11, k + 3, Blocks.stone_stairs, 0, 2);
		world.setBlock(i + 3, j + 11, k + 4, StructureGenHelper.cobbleOrMossy(rand), 0, 2);
		world.setBlock(i + 3, j + 11, k + 5, Blocks.stone_stairs, 0, 2);
		world.setBlock(i + 3, j + 11, k + 6, Blocks.stone_stairs, 0, 2);
		world.setBlock(i + 3, j + 11, k + 7, Blocks.air);
		world.setBlock(i + 3, j + 11, k + 8, Blocks.air);
		world.setBlock(i + 3, j + 11, k + 9, Blocks.birch_stairs, 3, 2);
		world.setBlock(i + 3, j + 12, k + 0, StructureGenHelper.cobbleOrMossy(rand), 0, 2);
		world.setBlock(i + 3, j + 12, k + 1, Blocks.air);
		world.setBlock(i + 3, j + 12, k + 2, Blocks.air);
		world.setBlock(i + 3, j + 12, k + 3, Blocks.air);
		world.setBlock(i + 3, j + 12, k + 4, StructureGenHelper.cobbleOrMossy(rand), 0, 2);
		world.setBlock(i + 3, j + 12, k + 7, Blocks.birch_stairs, 0, 2);
		world.setBlock(i + 3, j + 12, k + 8, Blocks.birch_stairs, 3, 2);
		world.setBlock(i + 3, j + 13, k + 1, Blocks.air);
		world.setBlock(i + 3, j + 13, k + 2, Blocks.air);
		world.setBlock(i + 3, j + 13, k + 3, Blocks.air);
		world.setBlock(i + 3, j + 17, k + 4, StructureGenHelper.cobbleOrMossy(rand), 0, 2);
		world.setBlock(i + 3, j + 17, k + 5, StructureGenHelper.cobbleOrMossy(rand), 0, 2);
		world.setBlock(i + 3, j + 17, k + 6, StructureGenHelper.cobbleOrMossy(rand), 0, 2);
		world.setBlock(i + 3, j + 18, k + 4, StructureGenHelper.cobbleOrMossy(rand), 0, 2);
		world.setBlock(i + 3, j + 18, k + 6, StructureGenHelper.cobbleOrMossy(rand), 0, 2);
		world.setBlock(i + 4, j + 0, k + 0, StructureGenHelper.cobbleOrMossy(rand), 0, 2);
		world.setBlock(i + 4, j + 0, k + 1, StructureGenHelper.cobbleOrMossy(rand), 0, 2);
		world.setBlock(i + 4, j + 0, k + 2, StructureGenHelper.cobbleOrMossy(rand), 0, 2);
		world.setBlock(i + 4, j + 0, k + 3, StructureGenHelper.cobbleOrMossy(rand), 0, 2);
		world.setBlock(i + 4, j + 0, k + 4, StructureGenHelper.cobbleOrMossy(rand), 0, 2);
		world.setBlock(i + 4, j + 0, k + 5, StructureGenHelper.cobbleOrMossy(rand), 0, 2);
		world.setBlock(i + 4, j + 0, k + 6, StructureGenHelper.cobbleOrMossy(rand), 0, 2);
		world.setBlock(i + 4, j + 0, k + 7, StructureGenHelper.cobbleOrMossy(rand), 0, 2);
		world.setBlock(i + 4, j + 0, k + 8, StructureGenHelper.cobbleOrMossy(rand), 0, 2);
		world.setBlock(i + 4, j + 1, k + 0, StructureGenHelper.cobbleOrMossy(rand), 0, 2);
		world.setBlock(i + 4, j + 1, k + 1, StructureGenHelper.randomBlock(rand, new Block[]{Blocks.web, Blocks.air}), 0, 2);
		world.setBlock(i + 4, j + 1, k + 2, Blocks.air);
		world.setBlock(i + 4, j + 1, k + 3, Blocks.air);
		world.setBlock(i + 4, j + 1, k + 4, Blocks.air);
		world.setBlock(i + 4, j + 1, k + 5, Blocks.air);
		world.setBlock(i + 4, j + 1, k + 6, Blocks.air);
		world.setBlock(i + 4, j + 1, k + 7, Blocks.air);
		world.setBlock(i + 4, j + 1, k + 8, StructureGenHelper.cobbleOrMossy(rand), 0, 2);
		world.setBlock(i + 4, j + 2, k + 0, StructureGenHelper.cobbleOrMossy(rand), 0, 2);
		world.setBlock(i + 4, j + 2, k + 1, StructureGenHelper.randomBlock(rand, new Block[]{Blocks.web, Blocks.air}), 0, 2);
		world.setBlock(i + 4, j + 2, k + 2, Blocks.air);
		world.setBlock(i + 4, j + 2, k + 3, Blocks.air);
		world.setBlock(i + 4, j + 2, k + 4, Blocks.air);
		world.setBlock(i + 4, j + 2, k + 5, Blocks.air);
		world.setBlock(i + 4, j + 2, k + 6, Blocks.air);
		world.setBlock(i + 4, j + 2, k + 7, Blocks.air);
		world.setBlock(i + 4, j + 2, k + 8, StructureGenHelper.cobbleOrMossy(rand), 0, 2);
		world.setBlock(i + 4, j + 3, k + 0, StructureGenHelper.cobbleOrMossy(rand), 0, 2);
		world.setBlock(i + 4, j + 3, k + 1, StructureGenHelper.randomBlock(rand, new Block[]{Blocks.web, Blocks.air}), 0, 2);
		world.setBlock(i + 4, j + 3, k + 2, Blocks.air);
		world.setBlock(i + 4, j + 3, k + 3, Blocks.air);
		world.setBlock(i + 4, j + 3, k + 4, Blocks.air);
		world.setBlock(i + 4, j + 3, k + 5, Blocks.air);
		world.setBlock(i + 4, j + 3, k + 6, StructureGenHelper.randomBlock(rand, new Block[]{Blocks.web, Blocks.air}), 0, 2);
		world.setBlock(i + 4, j + 3, k + 7, StructureGenHelper.randomBlock(rand, new Block[]{Blocks.web, Blocks.air}), 0, 2);
		world.setBlock(i + 4, j + 3, k + 8, StructureGenHelper.cobbleOrMossy(rand), 0, 2);
		world.setBlock(i + 4, j + 4, k + 0, StructureGenHelper.cobbleOrMossy(rand), 0, 2);
		world.setBlock(i + 4, j + 4, k + 1, StructureGenHelper.cobbleOrMossy(rand), 0, 2);
		world.setBlock(i + 4, j + 4, k + 2, StructureGenHelper.cobbleOrMossy(rand), 0, 2);
		world.setBlock(i + 4, j + 4, k + 3, StructureGenHelper.cobbleOrMossy(rand), 0, 2);
		world.setBlock(i + 4, j + 4, k + 4, StructureGenHelper.cobbleOrMossy(rand), 0, 2);
		world.setBlock(i + 4, j + 4, k + 5, StructureGenHelper.cobbleOrMossy(rand), 0, 2);
		world.setBlock(i + 4, j + 4, k + 6, StructureGenHelper.cobbleOrMossy(rand), 0, 2);
		world.setBlock(i + 4, j + 4, k + 7, StructureGenHelper.cobbleOrMossy(rand), 0, 2);
		world.setBlock(i + 4, j + 4, k + 8, StructureGenHelper.cobbleOrMossy(rand), 0, 2);
		world.setBlock(i + 4, j + 5, k + 1, StructureGenHelper.cobbleOrMossy(rand), 0, 2);
		world.setBlock(i + 4, j + 5, k + 2, BlockInvisibleBlock.instance, 0, 2);
		world.setBlock(i + 4, j + 5, k + 4, Blocks.air);
		world.setBlock(i + 4, j + 5, k + 5, Blocks.air);
		world.setBlock(i + 4, j + 5, k + 6, StructureGenHelper.randomBlock(rand, new Block[]{Blocks.crafting_table, Blocks.crafting_table, Blocks.crafting_table, Blocks.crafting_table, Blocks.crafting_table, Blocks.air}), 0, 2);
		world.setBlock(i + 4, j + 5, k + 7, StructureGenHelper.cobbleOrMossy(rand), 0, 2);
		world.setBlock(i + 4, j + 6, k + 1, StructureGenHelper.cobbleOrMossy(rand), 0, 2);
		world.setBlock(i + 4, j + 6, k + 2, BlockInvisibleBlock.instance, 0, 2);
		world.setBlock(i + 4, j + 6, k + 4, Blocks.air);
		world.setBlock(i + 4, j + 6, k + 5, Blocks.air);
		world.setBlock(i + 4, j + 6, k + 6, Blocks.air);
		world.setBlock(i + 4, j + 6, k + 7, StructureGenHelper.cobbleOrMossy(rand), 0, 2);
		world.setBlock(i + 4, j + 7, k + 1, StructureGenHelper.cobbleOrMossy(rand), 0, 2);
		world.setBlock(i + 4, j + 7, k + 2, BlockInvisibleBlock.instance, 0, 2);
		world.setBlock(i + 4, j + 7, k + 4, Blocks.air);
		world.setBlock(i + 4, j + 7, k + 5, Blocks.air);
		world.setBlock(i + 4, j + 7, k + 6, Blocks.air);
		world.setBlock(i + 4, j + 7, k + 7, StructureGenHelper.cobbleOrMossy(rand), 0, 2);
		world.setBlock(i + 4, j + 7, k + 8, Blocks.stone_stairs, 7, 2);
		world.setBlock(i + 4, j + 8, k + 1, StructureGenHelper.cobbleOrMossy(rand), 0, 2);
		world.setBlock(i + 4, j + 8, k + 2, StructureGenHelper.cobbleOrMossy(rand), 0, 2);
		world.setBlock(i + 4, j + 8, k + 4, StructureGenHelper.cobbleOrMossy(rand), 0, 2);
		world.setBlock(i + 4, j + 8, k + 5, StructureGenHelper.cobbleOrMossy(rand), 0, 2);
		world.setBlock(i + 4, j + 8, k + 6, StructureGenHelper.cobbleOrMossy(rand), 0, 2);
		world.setBlock(i + 4, j + 8, k + 7, StructureGenHelper.cobbleOrMossy(rand), 0, 2);
		world.setBlock(i + 4, j + 8, k + 8, StructureGenHelper.cobbleOrMossy(rand), 0, 2);
		world.setBlock(i + 4, j + 8, k + 9, Blocks.stone_stairs, 7, 2);
		world.setBlock(i + 4, j + 9, k + 2, StructureGenHelper.cobbleOrMossy(rand), 0, 2);
		world.setBlock(i + 4, j + 9, k + 4, Blocks.air);
		world.setBlock(i + 4, j + 9, k + 5, Blocks.air);
		world.setBlock(i + 4, j + 9, k + 7, Blocks.air);
		world.setBlock(i + 4, j + 9, k + 9, StructureGenHelper.cobbleOrMossy(rand), 0, 2);
		world.setBlock(i + 4, j + 10, k + 2, StructureGenHelper.cobbleOrMossy(rand), 0, 2);
		world.setBlock(i + 4, j + 10, k + 3, Blocks.air);
		world.setBlock(i + 4, j + 10, k + 4, Blocks.air);
		world.setBlock(i + 4, j + 10, k + 5, Blocks.air);
		world.setBlock(i + 4, j + 10, k + 7, Blocks.air);
		world.setBlock(i + 4, j + 10, k + 8, Blocks.air);
		world.setBlock(i + 4, j + 10, k + 9, Blocks.glass_pane, 0, 2);
		world.setBlock(i + 4, j + 11, k + 1, Blocks.stone_stairs, 5, 2);
		world.setBlock(i + 4, j + 11, k + 2, StructureGenHelper.cobbleOrMossy(rand), 0, 2);
		world.setBlock(i + 4, j + 11, k + 3, Blocks.air);
		world.setBlock(i + 4, j + 11, k + 4, Blocks.air);
		world.setBlock(i + 4, j + 11, k + 5, Blocks.air);
		world.setBlock(i + 4, j + 11, k + 6, StructureGenHelper.cobbleOrMossy(rand), 0, 2);
		world.setBlock(i + 4, j + 11, k + 7, Blocks.air);
		world.setBlock(i + 4, j + 11, k + 8, Blocks.air);
		world.setBlock(i + 4, j + 11, k + 9, Blocks.birch_stairs, 3, 2);
		world.setBlock(i + 4, j + 12, k + 1, StructureGenHelper.cobbleOrMossy(rand), 0, 2);
		world.setBlock(i + 4, j + 12, k + 2, Blocks.stone_stairs, 0, 2);
		world.setBlock(i + 4, j + 12, k + 3, Blocks.stone_stairs, 0, 2);
		world.setBlock(i + 4, j + 12, k + 4, StructureGenHelper.cobbleOrMossy(rand), 0, 2);
		world.setBlock(i + 4, j + 12, k + 5, StructureGenHelper.cobbleOrMossy(rand), 0, 2);
		world.setBlock(i + 4, j + 12, k + 6, StructureGenHelper.cobbleOrMossy(rand), 0, 2);
		world.setBlock(i + 4, j + 12, k + 7, Blocks.planks, 2, 2);
		world.setBlock(i + 4, j + 12, k + 8, Blocks.birch_stairs, 3, 2);
		world.setBlock(i + 4, j + 13, k + 1, StructureGenHelper.cobbleOrMossy(rand), 0, 2);
		world.setBlock(i + 4, j + 13, k + 2, Blocks.air);
		world.setBlock(i + 4, j + 13, k + 3, Blocks.air);
		world.setBlock(i + 4, j + 13, k + 4, StructureGenHelper.cobbleOrMossy(rand), 0, 2);
		world.setBlock(i + 4, j + 13, k + 5, StructureGenHelper.cobbleOrMossy(rand), 0, 2);
		world.setBlock(i + 4, j + 13, k + 6, StructureGenHelper.cobbleOrMossy(rand), 0, 2);
		world.setBlock(i + 4, j + 13, k + 7, Blocks.wooden_slab, 2, 2);
		world.setBlock(i + 4, j + 14, k + 2, Blocks.air);
		world.setBlock(i + 4, j + 14, k + 3, Blocks.air);
		world.setBlock(i + 4, j + 14, k + 4, StructureGenHelper.cobbleOrMossy(rand), 0, 2);
		world.setBlock(i + 4, j + 14, k + 5, StructureGenHelper.cobbleOrMossy(rand), 0, 2);
		world.setBlock(i + 4, j + 14, k + 6, StructureGenHelper.cobbleOrMossy(rand), 0, 2);
		world.setBlock(i + 4, j + 15, k + 4, StructureGenHelper.cobbleOrMossy(rand), 0, 2);
		world.setBlock(i + 4, j + 15, k + 5, StructureGenHelper.cobbleOrMossy(rand), 0, 2);
		world.setBlock(i + 4, j + 15, k + 6, StructureGenHelper.cobbleOrMossy(rand), 0, 2);
		world.setBlock(i + 4, j + 16, k + 4, StructureGenHelper.cobbleOrMossy(rand), 0, 2);
		world.setBlock(i + 4, j + 16, k + 5, StructureGenHelper.cobbleOrMossy(rand), 0, 2);
		world.setBlock(i + 4, j + 16, k + 6, StructureGenHelper.cobbleOrMossy(rand), 0, 2);
		world.setBlock(i + 4, j + 17, k + 3, StructureGenHelper.cobbleOrMossy(rand), 0, 2);
		world.setBlock(i + 4, j + 17, k + 4, Blocks.air);
		world.setBlock(i + 4, j + 17, k + 5, Blocks.air);
		world.setBlock(i + 4, j + 17, k + 6, Blocks.air);
		world.setBlock(i + 4, j + 17, k + 7, StructureGenHelper.cobbleOrMossy(rand), 0, 2);
		world.setBlock(i + 4, j + 18, k + 3, StructureGenHelper.cobbleOrMossy(rand), 0, 2);
		world.setBlock(i + 4, j + 18, k + 4, Blocks.air);
		world.setBlock(i + 4, j + 18, k + 5, Blocks.air);
		world.setBlock(i + 4, j + 18, k + 6, Blocks.air);
		world.setBlock(i + 4, j + 18, k + 7, StructureGenHelper.cobbleOrMossy(rand), 0, 2);
		world.setBlock(i + 5, j + 0, k + 0, StructureGenHelper.cobbleOrMossy(rand), 0, 2);
		world.setBlock(i + 5, j + 0, k + 1, StructureGenHelper.cobbleOrMossy(rand), 0, 2);
		world.setBlock(i + 5, j + 0, k + 2, StructureGenHelper.cobbleOrMossy(rand), 0, 2);
		world.setBlock(i + 5, j + 0, k + 3, StructureGenHelper.cobbleOrMossy(rand), 0, 2);
		world.setBlock(i + 5, j + 0, k + 4, StructureGenHelper.cobbleOrMossy(rand), 0, 2);
		world.setBlock(i + 5, j + 0, k + 5, StructureGenHelper.cobbleOrMossy(rand), 0, 2);
		world.setBlock(i + 5, j + 0, k + 6, StructureGenHelper.cobbleOrMossy(rand), 0, 2);
		world.setBlock(i + 5, j + 0, k + 7, StructureGenHelper.cobbleOrMossy(rand), 0, 2);
		world.setBlock(i + 5, j + 0, k + 8, StructureGenHelper.cobbleOrMossy(rand), 0, 2);
		world.setBlock(i + 5, j + 1, k + 1, Blocks.air);
		world.setBlock(i + 5, j + 1, k + 2, Blocks.air);
		world.setBlock(i + 5, j + 1, k + 3, Blocks.air);
		world.setBlock(i + 5, j + 1, k + 4, Blocks.air);
		world.setBlock(i + 5, j + 1, k + 5, Blocks.air);
		world.setBlock(i + 5, j + 1, k + 6, Blocks.air);
		world.setBlock(i + 5, j + 1, k + 7, Blocks.air);
		world.setBlock(i + 5, j + 1, k + 8, StructureGenHelper.cobbleOrMossy(rand), 0, 2);
		world.setBlock(i + 5, j + 2, k + 1, Blocks.air);
		world.setBlock(i + 5, j + 2, k + 2, Blocks.air);
		world.setBlock(i + 5, j + 2, k + 3, Blocks.air);
		world.setBlock(i + 5, j + 2, k + 4, Blocks.air);
		world.setBlock(i + 5, j + 2, k + 5, Blocks.air);
		world.setBlock(i + 5, j + 2, k + 6, Blocks.air);
		world.setBlock(i + 5, j + 2, k + 7, Blocks.air);
		world.setBlock(i + 5, j + 2, k + 8, StructureGenHelper.cobbleOrMossy(rand), 0, 2);
		world.setBlock(i + 5, j + 3, k + 0, StructureGenHelper.cobbleOrMossy(rand), 0, 2);
		world.setBlock(i + 5, j + 3, k + 1, StructureGenHelper.randomBlock(rand, new Block[]{Blocks.web, Blocks.air}), 0, 2);
		world.setBlock(i + 5, j + 3, k + 2, Blocks.air);
		world.setBlock(i + 5, j + 3, k + 3, Blocks.air);
		world.setBlock(i + 5, j + 3, k + 4, Blocks.air);
		world.setBlock(i + 5, j + 3, k + 5, Blocks.air);
		world.setBlock(i + 5, j + 3, k + 6, Blocks.air);
		world.setBlock(i + 5, j + 3, k + 7, Blocks.air);
		world.setBlock(i + 5, j + 3, k + 8, StructureGenHelper.cobbleOrMossy(rand), 0, 2);
		world.setBlock(i + 5, j + 4, k + 0, StructureGenHelper.cobbleOrMossy(rand), 0, 2);
		world.setBlock(i + 5, j + 4, k + 1, StructureGenHelper.cobbleOrMossy(rand), 0, 2);
		world.setBlock(i + 5, j + 4, k + 2, StructureGenHelper.cobbleOrMossy(rand), 0, 2);
		world.setBlock(i + 5, j + 4, k + 3, StructureGenHelper.cobbleOrMossy(rand), 0, 2);
		world.setBlock(i + 5, j + 4, k + 4, StructureGenHelper.cobbleOrMossy(rand), 0, 2);
		world.setBlock(i + 5, j + 4, k + 5, StructureGenHelper.cobbleOrMossy(rand), 0, 2);
		world.setBlock(i + 5, j + 4, k + 6, StructureGenHelper.cobbleOrMossy(rand), 0, 2);
		world.setBlock(i + 5, j + 4, k + 7, StructureGenHelper.cobbleOrMossy(rand), 0, 2);
		world.setBlock(i + 5, j + 4, k + 8, StructureGenHelper.cobbleOrMossy(rand), 0, 2);
		world.setBlock(i + 5, j + 5, k + 1, StructureGenHelper.cobbleOrMossy(rand), 0, 2);
		world.setBlock(i + 5, j + 5, k + 2, Blocks.air);
		world.setBlock(i + 5, j + 5, k + 3, Blocks.air);
		world.setBlock(i + 5, j + 5, k + 4, Blocks.air);
		world.setBlock(i + 5, j + 5, k + 5, Blocks.air);
		world.setBlock(i + 5, j + 5, k + 6, StructureGenHelper.randomBlock(rand, new Block[]{Blocks.anvil, Blocks.air}), 0, 2);
		world.setBlock(i + 5, j + 5, k + 7, StructureGenHelper.cobbleOrMossy(rand), 0, 2);
		world.setBlock(i + 5, j + 6, k + 1, StructureGenHelper.cobbleOrMossy(rand), 0, 2);
		world.setBlock(i + 5, j + 6, k + 2, Blocks.air);
		world.setBlock(i + 5, j + 6, k + 3, Blocks.air);
		world.setBlock(i + 5, j + 6, k + 4, Blocks.air);
		world.setBlock(i + 5, j + 6, k + 5, Blocks.air);
		world.setBlock(i + 5, j + 6, k + 6, Blocks.air);
		world.setBlock(i + 5, j + 6, k + 7, StructureGenHelper.cobbleOrMossy(rand), 0, 2);
		world.setBlock(i + 5, j + 7, k + 1, StructureGenHelper.cobbleOrMossy(rand), 0, 2);
		world.setBlock(i + 5, j + 7, k + 2, Blocks.air);
		world.setBlock(i + 5, j + 7, k + 3, Blocks.air);
		world.setBlock(i + 5, j + 7, k + 4, Blocks.air);
		world.setBlock(i + 5, j + 7, k + 5, Blocks.air);
		world.setBlock(i + 5, j + 7, k + 6, Blocks.air);
		world.setBlock(i + 5, j + 7, k + 7, StructureGenHelper.cobbleOrMossy(rand), 0, 2);
		world.setBlock(i + 5, j + 7, k + 8, Blocks.stone_stairs, 7, 2);
		world.setBlock(i + 5, j + 8, k + 1, StructureGenHelper.cobbleOrMossy(rand), 0, 2);
		world.setBlock(i + 5, j + 8, k + 2, StructureGenHelper.cobbleOrMossy(rand), 0, 2);
		world.setBlock(i + 5, j + 8, k + 3, StructureGenHelper.cobbleOrMossy(rand), 0, 2);
		world.setBlock(i + 5, j + 8, k + 4, StructureGenHelper.cobbleOrMossy(rand), 0, 2);
		world.setBlock(i + 5, j + 8, k + 5, StructureGenHelper.cobbleOrMossy(rand), 0, 2);
		world.setBlock(i + 5, j + 8, k + 6, StructureGenHelper.cobbleOrMossy(rand), 0, 2);
		world.setBlock(i + 5, j + 8, k + 7, StructureGenHelper.cobbleOrMossy(rand), 0, 2);
		world.setBlock(i + 5, j + 8, k + 8, StructureGenHelper.cobbleOrMossy(rand), 0, 2);
		world.setBlock(i + 5, j + 8, k + 9, Blocks.stone_stairs, 7, 2);
		world.setBlock(i + 5, j + 9, k + 2, StructureGenHelper.cobbleOrMossy(rand), 0, 2);
		world.setBlock(i + 5, j + 9, k + 3, Blocks.air);
		world.setBlock(i + 5, j + 9, k + 4, Blocks.air);
		world.setBlock(i + 5, j + 9, k + 6, StructureGenHelper.cobbleOrMossy(rand), 0, 2);
		world.setBlock(i + 5, j + 9, k + 7, Blocks.lit_redstone_lamp, 0, 2);
		world.setBlock(i + 5, j + 9, k + 9, StructureGenHelper.cobbleOrMossy(rand), 0, 2);
		world.setBlock(i + 5, j + 10, k + 2, Blocks.iron_bars, 0, 2);
		world.setBlock(i + 5, j + 10, k + 3, Blocks.air);
		world.setBlock(i + 5, j + 10, k + 4, Blocks.air);
		world.setBlock(i + 5, j + 10, k + 6, StructureGenHelper.cobbleOrMossy(rand), 0, 2);
		world.setBlock(i + 5, j + 10, k + 8, Blocks.air);
		world.setBlock(i + 5, j + 10, k + 9, StructureGenHelper.cobbleOrMossy(rand), 0, 2);
		world.setBlock(i + 5, j + 11, k + 2, StructureGenHelper.cobbleOrMossy(rand), 0, 2);
		world.setBlock(i + 5, j + 11, k + 3, Blocks.air);
		world.setBlock(i + 5, j + 11, k + 4, Blocks.air);
		world.setBlock(i + 5, j + 11, k + 6, StructureGenHelper.cobbleOrMossy(rand), 0, 2);
		world.setBlock(i + 5, j + 11, k + 7, Blocks.air);
		world.setBlock(i + 5, j + 11, k + 8, Blocks.air);
		world.setBlock(i + 5, j + 11, k + 9, Blocks.birch_stairs, 3, 2);
		world.setBlock(i + 5, j + 12, k + 2, StructureGenHelper.cobbleOrMossy(rand), 0, 2);
		world.setBlock(i + 5, j + 12, k + 3, StructureGenHelper.cobbleOrMossy(rand), 0, 2);
		world.setBlock(i + 5, j + 12, k + 4, StructureGenHelper.cobbleOrMossy(rand), 0, 2);
		world.setBlock(i + 5, j + 12, k + 6, StructureGenHelper.cobbleOrMossy(rand), 0, 2);
		world.setBlock(i + 5, j + 12, k + 7, Blocks.birch_stairs, 1, 2);
		world.setBlock(i + 5, j + 12, k + 8, Blocks.birch_stairs, 1, 2);
		world.setBlock(i + 5, j + 13, k + 1, Blocks.stone_stairs, 6, 2);
		world.setBlock(i + 5, j + 13, k + 2, Blocks.air);
		world.setBlock(i + 5, j + 13, k + 3, Blocks.air);
		world.setBlock(i + 5, j + 13, k + 4, Blocks.air);
		world.setBlock(i + 5, j + 13, k + 6, StructureGenHelper.cobbleOrMossy(rand), 0, 2);
		
		world.setBlock(i + 5, j + 14, k + 2, Blocks.air);
		world.setBlock(i + 5, j + 14, k + 3, Blocks.air);
		world.setBlock(i + 5, j + 14, k + 4, Blocks.air);
		world.setBlock(i + 5, j + 14, k + 6, StructureGenHelper.cobbleOrMossy(rand), 0, 2);
		world.setBlock(i + 5, j + 15, k + 4, StructureGenHelper.cobbleOrMossy(rand), 0, 2);
		world.setBlock(i + 5, j + 15, k + 6, StructureGenHelper.cobbleOrMossy(rand), 0, 2);
		world.setBlock(i + 5, j + 16, k + 4, StructureGenHelper.cobbleOrMossy(rand), 0, 2);
		world.setBlock(i + 5, j + 16, k + 5, BlockIllusionary.instance, 0, 2);
		world.setBlock(i + 5, j + 16, k + 6, StructureGenHelper.cobbleOrMossy(rand), 0, 2);
		world.setBlock(i + 5, j + 17, k + 3, StructureGenHelper.cobbleOrMossy(rand), 0, 2);
		world.setBlock(i + 5, j + 17, k + 4, StructureGenHelper.randomBlock(rand, new Block[]{Blocks.chest, Blocks.chest, Blocks.chest, Blocks.air}), 3, 2);
		te = world.getTileEntity(i + 5, j + 17, k + 4);
		if(te != null && te instanceof TileEntityChest) {
			TileEntityChest tec = (TileEntityChest)te;
			ChestGenHooks info = ChestGenHooks.getInfo(ChestGenHooks.PYRAMID_JUNGLE_CHEST);
            WeightedRandomChestContent.generateChestContents(rand, info.getItems(rand), tec, info.getCount(rand));
		}
		world.setBlock(i + 5, j + 17, k + 5, Blocks.air);
		world.setBlock(i + 5, j + 17, k + 6, Blocks.air);
		world.setBlock(i + 5, j + 17, k + 7, StructureGenHelper.cobbleOrMossy(rand), 0, 2);
		world.setBlock(i + 5, j + 18, k + 4, Blocks.air);
		world.setBlock(i + 5, j + 18, k + 5, Blocks.air);
		world.setBlock(i + 5, j + 18, k + 6, Blocks.air);
		world.setBlock(i + 6, j + 0, k + 0, StructureGenHelper.cobbleOrMossy(rand), 0, 2);
		world.setBlock(i + 6, j + 0, k + 1, StructureGenHelper.cobbleOrMossy(rand), 0, 2);
		world.setBlock(i + 6, j + 0, k + 2, StructureGenHelper.cobbleOrMossy(rand), 0, 2);
		world.setBlock(i + 6, j + 0, k + 3, StructureGenHelper.cobbleOrMossy(rand), 0, 2);
		world.setBlock(i + 6, j + 0, k + 4, StructureGenHelper.cobbleOrMossy(rand), 0, 2);
		world.setBlock(i + 6, j + 0, k + 5, StructureGenHelper.cobbleOrMossy(rand), 0, 2);
		world.setBlock(i + 6, j + 0, k + 6, StructureGenHelper.cobbleOrMossy(rand), 0, 2);
		world.setBlock(i + 6, j + 0, k + 7, StructureGenHelper.cobbleOrMossy(rand), 0, 2);
		world.setBlock(i + 6, j + 0, k + 8, StructureGenHelper.cobbleOrMossy(rand), 0, 2);
		world.setBlock(i + 6, j + 1, k + 0, StructureGenHelper.cobbleOrMossy(rand), 0, 2);
		world.setBlock(i + 6, j + 1, k + 1, Blocks.air);
		world.setBlock(i + 6, j + 1, k + 2, Blocks.air);
		world.setBlock(i + 6, j + 1, k + 3, Blocks.air);
		world.setBlock(i + 6, j + 1, k + 4, Blocks.air);
		world.setBlock(i + 6, j + 1, k + 5, Blocks.air);
		world.setBlock(i + 6, j + 1, k + 6, Blocks.air);
		world.setBlock(i + 6, j + 1, k + 7, Blocks.air);
		world.setBlock(i + 6, j + 1, k + 8, StructureGenHelper.cobbleOrMossy(rand), 0, 2);
		world.setBlock(i + 6, j + 2, k + 0, StructureGenHelper.cobbleOrMossy(rand), 0, 2);
		world.setBlock(i + 6, j + 2, k + 1, Blocks.air);
		world.setBlock(i + 6, j + 2, k + 2, Blocks.air);
		world.setBlock(i + 6, j + 2, k + 3, Blocks.air);
		world.setBlock(i + 6, j + 2, k + 4, Blocks.air);
		world.setBlock(i + 6, j + 2, k + 5, Blocks.air);
		world.setBlock(i + 6, j + 2, k + 6, Blocks.air);
		world.setBlock(i + 6, j + 2, k + 7, Blocks.air);
		world.setBlock(i + 6, j + 2, k + 8, StructureGenHelper.cobbleOrMossy(rand), 0, 2);
		world.setBlock(i + 6, j + 3, k + 0, StructureGenHelper.cobbleOrMossy(rand), 0, 2);
		world.setBlock(i + 6, j + 3, k + 1, Blocks.air);
		world.setBlock(i + 6, j + 3, k + 2, Blocks.air);
		world.setBlock(i + 6, j + 3, k + 3, Blocks.air);
		world.setBlock(i + 6, j + 3, k + 4, Blocks.air);
		world.setBlock(i + 6, j + 3, k + 5, Blocks.air);
		world.setBlock(i + 6, j + 3, k + 6, Blocks.air);
		world.setBlock(i + 6, j + 3, k + 7, Blocks.air);
		world.setBlock(i + 6, j + 3, k + 8, StructureGenHelper.cobbleOrMossy(rand), 0, 2);
		world.setBlock(i + 6, j + 4, k + 0, StructureGenHelper.cobbleOrMossy(rand), 0, 2);
		world.setBlock(i + 6, j + 4, k + 1, StructureGenHelper.cobbleOrMossy(rand), 0, 2);
		world.setBlock(i + 6, j + 4, k + 2, StructureGenHelper.cobbleOrMossy(rand), 0, 2);
		world.setBlock(i + 6, j + 4, k + 3, StructureGenHelper.cobbleOrMossy(rand), 0, 2);
		world.setBlock(i + 6, j + 4, k + 4, StructureGenHelper.cobbleOrMossy(rand), 0, 2);
		world.setBlock(i + 6, j + 4, k + 5, StructureGenHelper.cobbleOrMossy(rand), 0, 2);
		world.setBlock(i + 6, j + 4, k + 6, StructureGenHelper.cobbleOrMossy(rand), 0, 2);
		world.setBlock(i + 6, j + 4, k + 7, StructureGenHelper.cobbleOrMossy(rand), 0, 2);
		world.setBlock(i + 6, j + 4, k + 8, StructureGenHelper.cobbleOrMossy(rand), 0, 2);
		world.setBlock(i + 6, j + 5, k + 1, StructureGenHelper.cobbleOrMossy(rand), 0, 2);
		world.setBlock(i + 6, j + 5, k + 2, Blocks.air);
		world.setBlock(i + 6, j + 5, k + 3, Blocks.air);
		world.setBlock(i + 6, j + 5, k + 4, Blocks.air);
		world.setBlock(i + 6, j + 5, k + 5, Blocks.air);
		world.setBlock(i + 6, j + 5, k + 6, Blocks.air);
		world.setBlock(i + 6, j + 5, k + 7, StructureGenHelper.cobbleOrMossy(rand), 0, 2);
		world.setBlock(i + 6, j + 6, k + 1, StructureGenHelper.cobbleOrMossy(rand), 0, 2);
		world.setBlock(i + 6, j + 6, k + 2, Blocks.air);
		world.setBlock(i + 6, j + 6, k + 3, Blocks.air);
		world.setBlock(i + 6, j + 6, k + 4, Blocks.air);
		world.setBlock(i + 6, j + 6, k + 5, Blocks.air);
		world.setBlock(i + 6, j + 6, k + 6, Blocks.air);
		world.setBlock(i + 6, j + 6, k + 7, StructureGenHelper.cobbleOrMossy(rand), 0, 2);
		world.setBlock(i + 6, j + 7, k + 1, StructureGenHelper.cobbleOrMossy(rand), 0, 2);
		world.setBlock(i + 6, j + 7, k + 2, Blocks.air);
		world.setBlock(i + 6, j + 7, k + 3, Blocks.air);
		world.setBlock(i + 6, j + 7, k + 4, Blocks.air);
		world.setBlock(i + 6, j + 7, k + 5, Blocks.air);
		world.setBlock(i + 6, j + 7, k + 6, Blocks.air);
		world.setBlock(i + 6, j + 7, k + 7, StructureGenHelper.cobbleOrMossy(rand), 0, 2);
		world.setBlock(i + 6, j + 8, k + 1, StructureGenHelper.cobbleOrMossy(rand), 0, 2);
		world.setBlock(i + 6, j + 8, k + 2, StructureGenHelper.cobbleOrMossy(rand), 0, 2);
		world.setBlock(i + 6, j + 8, k + 3, StructureGenHelper.cobbleOrMossy(rand), 0, 2);
		world.setBlock(i + 6, j + 8, k + 4, StructureGenHelper.cobbleOrMossy(rand), 0, 2);
		world.setBlock(i + 6, j + 8, k + 5, StructureGenHelper.cobbleOrMossy(rand), 0, 2);
		world.setBlock(i + 6, j + 8, k + 6, StructureGenHelper.cobbleOrMossy(rand), 0, 2);
		world.setBlock(i + 6, j + 8, k + 7, StructureGenHelper.cobbleOrMossy(rand), 0, 2);
		world.setBlock(i + 6, j + 8, k + 8, Blocks.stone_stairs, 5, 2);
		world.setBlock(i + 6, j + 9, k + 2, StructureGenHelper.cobbleOrMossy(rand), 0, 2);
		world.setBlock(i + 6, j + 9, k + 3, Blocks.air);
		world.setBlock(i + 6, j + 9, k + 4, Blocks.air);
		world.setBlock(i + 6, j + 9, k + 6, StructureGenHelper.cobbleOrMossy(rand), 0, 2);
		world.setBlock(i + 6, j + 9, k + 7, StructureGenHelper.cobbleOrMossy(rand), 0, 2);
		world.setBlock(i + 6, j + 9, k + 8, StructureGenHelper.cobbleOrMossy(rand), 0, 2);
		world.setBlock(i + 6, j + 10, k + 2, StructureGenHelper.cobbleOrMossy(rand), 0, 2);
		world.setBlock(i + 6, j + 10, k + 3, Blocks.air);
		world.setBlock(i + 6, j + 10, k + 4, Blocks.air);
		world.setBlock(i + 6, j + 10, k + 5, Blocks.air);
		world.setBlock(i + 6, j + 10, k + 6, BlockTrap.instance, 4, 2);
		world.setBlockMetadataWithNotify(i + 6, j + 10, k + 6, 2, 2);
		te = world.getTileEntity(i + 6, j + 10, k + 6); 
		if(te != null && te instanceof TileEntityTrap) {
			ted = (TileEntityTrap)te;
			//PlaceTraps.addTrapItem(ted);
			ted.func_146019_a/*addItem*/(new ItemStack(Items.iron_sword, 1, 245));
		}
		world.setBlock(i + 6, j + 10, k + 7, StructureGenHelper.cobbleOrMossy(rand), 0, 2);
		world.setBlock(i + 6, j + 10, k + 8, StructureGenHelper.cobbleOrMossy(rand), 0, 2);
		world.setBlock(i + 6, j + 11, k + 2, StructureGenHelper.cobbleOrMossy(rand), 0, 2);
		world.setBlock(i + 6, j + 11, k + 3, Blocks.air);
		world.setBlock(i + 6, j + 11, k + 4, Blocks.air);
		world.setBlock(i + 6, j + 11, k + 5, Blocks.air);
		world.setBlock(i + 6, j + 11, k + 6, StructureGenHelper.cobbleOrMossy(rand), 0, 2);
		world.setBlock(i + 6, j + 11, k + 7, Blocks.birch_stairs, 1, 2);
		world.setBlock(i + 6, j + 11, k + 8, Blocks.birch_stairs, 1, 2);
		world.setBlock(i + 6, j + 11, k + 9, Blocks.birch_stairs, 1, 2);
		world.setBlock(i + 6, j + 12, k + 2, StructureGenHelper.cobbleOrMossy(rand), 0, 2);
		world.setBlock(i + 6, j + 12, k + 3, StructureGenHelper.cobbleOrMossy(rand), 0, 2);
		world.setBlock(i + 6, j + 12, k + 4, StructureGenHelper.cobbleOrMossy(rand), 0, 2);
		world.setBlock(i + 6, j + 12, k + 5, StructureGenHelper.cobbleOrMossy(rand), 0, 2);
		world.setBlock(i + 6, j + 12, k + 6, StructureGenHelper.cobbleOrMossy(rand), 0, 2);
		world.setBlock(i + 6, j + 13, k + 1, Blocks.stone_stairs, 6, 2);
		world.setBlock(i + 6, j + 13, k + 2, Blocks.air);
		world.setBlock(i + 6, j + 13, k + 3, Blocks.air);
		world.setBlock(i + 6, j + 13, k + 4, StructureGenHelper.cobbleOrMossy(rand), 0, 2);
		world.setBlock(i + 6, j + 13, k + 5, StructureGenHelper.cobbleOrMossy(rand), 0, 2);
		world.setBlock(i + 6, j + 13, k + 6, StructureGenHelper.cobbleOrMossy(rand), 0, 2);
		world.setBlock(i + 6, j + 14, k + 2, Blocks.air);
		world.setBlock(i + 6, j + 14, k + 3, Blocks.air);
		world.setBlock(i + 6, j + 14, k + 4, StructureGenHelper.cobbleOrMossy(rand), 0, 2);
		world.setBlock(i + 6, j + 14, k + 5, StructureGenHelper.cobbleOrMossy(rand), 0, 2);
		world.setBlock(i + 6, j + 14, k + 6, StructureGenHelper.cobbleOrMossy(rand), 0, 2);
		world.setBlock(i + 6, j + 15, k + 4, StructureGenHelper.cobbleOrMossy(rand), 0, 2);
		world.setBlock(i + 6, j + 15, k + 5, StructureGenHelper.cobbleOrMossy(rand), 0, 2);
		world.setBlock(i + 6, j + 15, k + 6, StructureGenHelper.cobbleOrMossy(rand), 0, 2);
		world.setBlock(i + 6, j + 16, k + 4, StructureGenHelper.cobbleOrMossy(rand), 0, 2);
		world.setBlock(i + 6, j + 16, k + 5, StructureGenHelper.cobbleOrMossy(rand), 0, 2);
		world.setBlock(i + 6, j + 16, k + 6, StructureGenHelper.cobbleOrMossy(rand), 0, 2);
		world.setBlock(i + 6, j + 17, k + 3, StructureGenHelper.cobbleOrMossy(rand), 0, 2);
		world.setBlock(i + 6, j + 17, k + 4, Blocks.air);
		world.setBlock(i + 6, j + 17, k + 5, Blocks.air);
		world.setBlock(i + 6, j + 17, k + 6, Blocks.air);
		world.setBlock(i + 6, j + 17, k + 7, StructureGenHelper.cobbleOrMossy(rand), 0, 2);
		world.setBlock(i + 6, j + 18, k + 3, StructureGenHelper.cobbleOrMossy(rand), 0, 2);
		world.setBlock(i + 6, j + 18, k + 4, Blocks.air);
		world.setBlock(i + 6, j + 18, k + 5, Blocks.air);
		world.setBlock(i + 6, j + 18, k + 6, Blocks.air);
		world.setBlock(i + 6, j + 18, k + 7, StructureGenHelper.cobbleOrMossy(rand), 0, 2);
		world.setBlock(i + 7, j + 0, k + 1, StructureGenHelper.cobbleOrMossy(rand), 0, 2);
		world.setBlock(i + 7, j + 0, k + 2, StructureGenHelper.cobbleOrMossy(rand), 0, 2);
		world.setBlock(i + 7, j + 0, k + 3, StructureGenHelper.cobbleOrMossy(rand), 0, 2);
		world.setBlock(i + 7, j + 0, k + 4, StructureGenHelper.cobbleOrMossy(rand), 0, 2);
		world.setBlock(i + 7, j + 0, k + 5, StructureGenHelper.cobbleOrMossy(rand), 0, 2);
		world.setBlock(i + 7, j + 0, k + 6, StructureGenHelper.cobbleOrMossy(rand), 0, 2);
		world.setBlock(i + 7, j + 0, k + 7, StructureGenHelper.cobbleOrMossy(rand), 0, 2);
		world.setBlock(i + 7, j + 1, k + 1, StructureGenHelper.cobbleOrMossy(rand), 0, 2);
		world.setBlock(i + 7, j + 1, k + 2, Blocks.air);
		world.setBlock(i + 7, j + 1, k + 3, Blocks.air);
		world.setBlock(i + 7, j + 1, k + 4, Blocks.air);
		world.setBlock(i + 7, j + 1, k + 5, Blocks.air);
		world.setBlock(i + 7, j + 1, k + 6, StructureGenHelper.randomBlock(rand, new Block[]{Blocks.web, Blocks.air}), 0, 2);
		world.setBlock(i + 7, j + 1, k + 7, StructureGenHelper.cobbleOrMossy(rand), 0, 2);
		world.setBlock(i + 7, j + 2, k + 1, StructureGenHelper.cobbleOrMossy(rand), 0, 2);
		world.setBlock(i + 7, j + 2, k + 2, Blocks.air);
		world.setBlock(i + 7, j + 2, k + 3, Blocks.air);
		world.setBlock(i + 7, j + 2, k + 4, Blocks.air);
		world.setBlock(i + 7, j + 2, k + 5, Blocks.air);
		world.setBlock(i + 7, j + 2, k + 6, StructureGenHelper.randomBlock(rand, new Block[]{Blocks.web, Blocks.air}), 0, 2);
		world.setBlock(i + 7, j + 2, k + 7, StructureGenHelper.cobbleOrMossy(rand), 0, 2);
		world.setBlock(i + 7, j + 3, k + 1, StructureGenHelper.cobbleOrMossy(rand), 0, 2);
		world.setBlock(i + 7, j + 3, k + 2, Blocks.air);
		world.setBlock(i + 7, j + 3, k + 3, Blocks.air);
		world.setBlock(i + 7, j + 3, k + 4, Blocks.air);
		world.setBlock(i + 7, j + 3, k + 5, Blocks.air);
		world.setBlock(i + 7, j + 3, k + 6, StructureGenHelper.randomBlock(rand, new Block[]{Blocks.web, Blocks.air}), 0, 2);
		world.setBlock(i + 7, j + 3, k + 7, StructureGenHelper.cobbleOrMossy(rand), 0, 2);
		world.setBlock(i + 7, j + 4, k + 1, StructureGenHelper.cobbleOrMossy(rand), 0, 2);
		world.setBlock(i + 7, j + 4, k + 2, StructureGenHelper.cobbleOrMossy(rand), 0, 2);
		world.setBlock(i + 7, j + 4, k + 3, StructureGenHelper.cobbleOrMossy(rand), 0, 2);
		world.setBlock(i + 7, j + 4, k + 4, StructureGenHelper.cobbleOrMossy(rand), 0, 2);
		world.setBlock(i + 7, j + 4, k + 5, StructureGenHelper.cobbleOrMossy(rand), 0, 2);
		world.setBlock(i + 7, j + 4, k + 6, StructureGenHelper.cobbleOrMossy(rand), 0, 2);
		world.setBlock(i + 7, j + 4, k + 7, StructureGenHelper.cobbleOrMossy(rand), 0, 2);
		world.setBlock(i + 7, j + 5, k + 1, StructureGenHelper.cobbleOrMossy(rand), 0, 2);
		world.setBlock(i + 7, j + 5, k + 2, StructureGenHelper.cobbleOrMossy(rand), 0, 2);
		world.setBlock(i + 7, j + 5, k + 3, BlockPedestal.instance, 0, 2);
		te = world.getTileEntity(i + 7, j + 5, k + 3); 
		if(te instanceof TileEntityDisplayPedestal) {
			TileEntityDisplayPedestal tedd = (TileEntityDisplayPedestal)te;
			tedd.setInventorySlotContents(0, ArtifactsAPI.artifacts.generateRandomArtifact());
			tedd.rotation = 180;
		}
		world.setBlock(i + 7, j + 5, k + 4, Blocks.air);
		world.setBlock(i + 7, j + 5, k + 5, Blocks.air);
		world.setBlock(i + 7, j + 5, k + 6, Blocks.air);
		world.setBlock(i + 7, j + 5, k + 7, StructureGenHelper.cobbleOrMossy(rand), 0, 2);
		world.setBlock(i + 7, j + 6, k + 1, StructureGenHelper.cobbleOrMossy(rand), 0, 2);
		world.setBlock(i + 7, j + 6, k + 2, StructureGenHelper.cobbleOrMossy(rand), 0, 2);
		world.setBlock(i + 7, j + 6, k + 3, Blocks.air);
		world.setBlock(i + 7, j + 6, k + 4, Blocks.air);
		world.setBlock(i + 7, j + 6, k + 5, Blocks.air);
		world.setBlock(i + 7, j + 6, k + 6, Blocks.air);
		world.setBlock(i + 7, j + 6, k + 7, StructureGenHelper.cobbleOrMossy(rand), 0, 2);
		world.setBlock(i + 7, j + 7, k + 2, StructureGenHelper.cobbleOrMossy(rand), 0, 2);
		world.setBlock(i + 7, j + 7, k + 3, Blocks.air);
		world.setBlock(i + 7, j + 7, k + 4, Blocks.air);
		world.setBlock(i + 7, j + 7, k + 5, Blocks.air);
		world.setBlock(i + 7, j + 7, k + 6, Blocks.air);
		world.setBlock(i + 7, j + 7, k + 7, StructureGenHelper.cobbleOrMossy(rand), 0, 2);
		world.setBlock(i + 7, j + 8, k + 2, StructureGenHelper.cobbleOrMossy(rand), 0, 2);
		world.setBlock(i + 7, j + 8, k + 3, StructureGenHelper.cobbleOrMossy(rand), 0, 2);
		world.setBlock(i + 7, j + 8, k + 4, StructureGenHelper.cobbleOrMossy(rand), 0, 2);
		world.setBlock(i + 7, j + 8, k + 5, StructureGenHelper.cobbleOrMossy(rand), 0, 2);
		world.setBlock(i + 7, j + 8, k + 6, StructureGenHelper.cobbleOrMossy(rand), 0, 2);
		world.setBlock(i + 7, j + 9, k + 2, StructureGenHelper.cobbleOrMossy(rand), 0, 2);
		world.setBlock(i + 7, j + 9, k + 3, StructureGenHelper.cobbleOrMossy(rand), 0, 2);
		world.setBlock(i + 7, j + 9, k + 4, StructureGenHelper.cobbleOrMossy(rand), 0, 2);
		world.setBlock(i + 7, j + 9, k + 5, StructureGenHelper.cobbleOrMossy(rand), 0, 2);
		world.setBlock(i + 7, j + 9, k + 6, StructureGenHelper.cobbleOrMossy(rand), 0, 2);
		world.setBlock(i + 7, j + 10, k + 2, StructureGenHelper.cobbleOrMossy(rand), 0, 2);
		world.setBlock(i + 7, j + 10, k + 3, StructureGenHelper.cobbleOrMossy(rand), 0, 2);
		world.setBlock(i + 7, j + 10, k + 4, StructureGenHelper.cobbleOrMossy(rand), 0, 2);
		world.setBlock(i + 7, j + 10, k + 5, StructureGenHelper.cobbleOrMossy(rand), 0, 2);
		world.setBlock(i + 7, j + 10, k + 6, StructureGenHelper.cobbleOrMossy(rand), 0, 2);
		world.setBlock(i + 7, j + 11, k + 3, StructureGenHelper.cobbleOrMossy(rand), 0, 2);
		world.setBlock(i + 7, j + 11, k + 4, StructureGenHelper.cobbleOrMossy(rand), 0, 2);
		world.setBlock(i + 7, j + 11, k + 5, StructureGenHelper.cobbleOrMossy(rand), 0, 2);
		world.setBlock(i + 7, j + 12, k + 3, StructureGenHelper.cobbleOrMossy(rand), 0, 2);
		world.setBlock(i + 7, j + 12, k + 4, StructureGenHelper.cobbleOrMossy(rand), 0, 2);
		world.setBlock(i + 7, j + 12, k + 5, StructureGenHelper.cobbleOrMossy(rand), 0, 2);
		world.setBlock(i + 7, j + 13, k + 2, StructureGenHelper.cobbleOrMossy(rand), 0, 2);
		world.setBlock(i + 7, j + 13, k + 3, Blocks.air);
		world.setBlock(i + 7, j + 13, k + 4, Blocks.air);
		world.setBlock(i + 7, j + 13, k + 5, Blocks.air);
		world.setBlock(i + 7, j + 13, k + 6, Blocks.stone_stairs, 7, 2);
		world.setBlock(i + 7, j + 14, k + 3, Blocks.air);
		world.setBlock(i + 7, j + 14, k + 4, Blocks.air);
		world.setBlock(i + 7, j + 14, k + 5, Blocks.air);
		world.setBlock(i + 7, j + 17, k + 4, StructureGenHelper.cobbleOrMossy(rand), 0, 2);
		world.setBlock(i + 7, j + 17, k + 5, StructureGenHelper.cobbleOrMossy(rand), 0, 2);
		world.setBlock(i + 7, j + 17, k + 6, StructureGenHelper.cobbleOrMossy(rand), 0, 2);
		world.setBlock(i + 7, j + 18, k + 4, StructureGenHelper.cobbleOrMossy(rand), 0, 2);
		world.setBlock(i + 7, j + 18, k + 6, StructureGenHelper.cobbleOrMossy(rand), 0, 2);
		world.setBlock(i + 8, j + 0, k + 2, StructureGenHelper.cobbleOrMossy(rand), 0, 2);
		world.setBlock(i + 8, j + 0, k + 3, StructureGenHelper.cobbleOrMossy(rand), 0, 2);
		world.setBlock(i + 8, j + 0, k + 4, StructureGenHelper.cobbleOrMossy(rand), 0, 2);
		world.setBlock(i + 8, j + 0, k + 5, StructureGenHelper.cobbleOrMossy(rand), 0, 2);
		world.setBlock(i + 8, j + 0, k + 6, StructureGenHelper.cobbleOrMossy(rand), 0, 2);
		world.setBlock(i + 8, j + 1, k + 2, StructureGenHelper.cobbleOrMossy(rand), 0, 2);
		world.setBlock(i + 8, j + 1, k + 3, Blocks.air);
		world.setBlock(i + 8, j + 1, k + 4, Blocks.air);
		world.setBlock(i + 8, j + 1, k + 5, Blocks.air);
		world.setBlock(i + 8, j + 1, k + 6, StructureGenHelper.cobbleOrMossy(rand), 0, 2);
		world.setBlock(i + 8, j + 2, k + 2, StructureGenHelper.cobbleOrMossy(rand), 0, 2);
		world.setBlock(i + 8, j + 2, k + 3, Blocks.air);
		world.setBlock(i + 8, j + 2, k + 4, Blocks.air);
		world.setBlock(i + 8, j + 2, k + 5, Blocks.air);
		world.setBlock(i + 8, j + 2, k + 6, StructureGenHelper.cobbleOrMossy(rand), 0, 2);
		world.setBlock(i + 8, j + 3, k + 2, StructureGenHelper.cobbleOrMossy(rand), 0, 2);
		world.setBlock(i + 8, j + 3, k + 3, Blocks.air);
		world.setBlock(i + 8, j + 3, k + 4, Blocks.air);
		world.setBlock(i + 8, j + 3, k + 5, StructureGenHelper.randomBlock(rand, new Block[]{Blocks.web, Blocks.air}), 0, 2);
		world.setBlock(i + 8, j + 3, k + 6, StructureGenHelper.cobbleOrMossy(rand), 0, 2);
		world.setBlock(i + 8, j + 4, k + 2, StructureGenHelper.cobbleOrMossy(rand), 0, 2);
		world.setBlock(i + 8, j + 4, k + 3, StructureGenHelper.cobbleOrMossy(rand), 0, 2);
		world.setBlock(i + 8, j + 4, k + 4, StructureGenHelper.cobbleOrMossy(rand), 0, 2);
		world.setBlock(i + 8, j + 4, k + 5, StructureGenHelper.cobbleOrMossy(rand), 0, 2);
		world.setBlock(i + 8, j + 4, k + 6, StructureGenHelper.cobbleOrMossy(rand), 0, 2);
		world.setBlock(i + 8, j + 5, k + 2, StructureGenHelper.cobbleOrMossy(rand), 0, 2);
		world.setBlock(i + 8, j + 5, k + 3, StructureGenHelper.cobbleOrMossy(rand), 0, 2);
		world.setBlock(i + 8, j + 5, k + 4, Blocks.air);
		world.setBlock(i + 8, j + 5, k + 5, Blocks.air);
		world.setBlock(i + 8, j + 5, k + 6, Blocks.air);
		world.setBlock(i + 8, j + 5, k + 7, StructureGenHelper.cobbleOrMossy(rand), 0, 2);
		world.setBlock(i + 8, j + 6, k + 2, StructureGenHelper.cobbleOrMossy(rand), 0, 2);
		world.setBlock(i + 8, j + 6, k + 3, StructureGenHelper.cobbleOrMossy(rand), 0, 2);
		world.setBlock(i + 8, j + 6, k + 4, Blocks.air);
		world.setBlock(i + 8, j + 6, k + 5, Blocks.air);
		world.setBlock(i + 8, j + 6, k + 6, Blocks.air);
		world.setBlock(i + 8, j + 6, k + 7, StructureGenHelper.cobbleOrMossy(rand), 0, 2);
		world.setBlock(i + 8, j + 7, k + 3, StructureGenHelper.cobbleOrMossy(rand), 0, 2);
		world.setBlock(i + 8, j + 7, k + 4, Blocks.air);
		world.setBlock(i + 8, j + 7, k + 5, Blocks.air);
		world.setBlock(i + 8, j + 7, k + 6, Blocks.air);
		world.setBlock(i + 8, j + 7, k + 7, StructureGenHelper.cobbleOrMossy(rand), 0, 2);
		world.setBlock(i + 8, j + 8, k + 3, StructureGenHelper.cobbleOrMossy(rand), 0, 2);
		world.setBlock(i + 8, j + 8, k + 4, StructureGenHelper.cobbleOrMossy(rand), 0, 2);
		world.setBlock(i + 8, j + 8, k + 5, StructureGenHelper.cobbleOrMossy(rand), 0, 2);
		world.setBlock(i + 8, j + 8, k + 6, StructureGenHelper.cobbleOrMossy(rand), 0, 2);
		world.setBlock(i + 8, j + 13, k + 3, Blocks.stone_stairs, 5, 2);
		world.setBlock(i + 8, j + 13, k + 4, Blocks.stone_stairs, 5, 2);
		world.setBlock(i + 8, j + 13, k + 5, Blocks.stone_stairs, 5, 2);
		
		world.setBlock(i + 9, j + 0, k + 3, StructureGenHelper.cobbleOrMossy(rand), 0, 2);
		world.setBlock(i + 9, j + 0, k + 4, StructureGenHelper.cobbleOrMossy(rand), 0, 2);
		world.setBlock(i + 9, j + 0, k + 5, StructureGenHelper.cobbleOrMossy(rand), 0, 2);
		world.setBlock(i + 9, j + 1, k + 3, StructureGenHelper.cobbleOrMossy(rand), 0, 2);
		world.setBlock(i + 9, j + 1, k + 4, StructureGenHelper.cobbleOrMossy(rand), 0, 2);
		world.setBlock(i + 9, j + 1, k + 5, StructureGenHelper.cobbleOrMossy(rand), 0, 2);
		world.setBlock(i + 9, j + 2, k + 3, StructureGenHelper.cobbleOrMossy(rand), 0, 2);
		world.setBlock(i + 9, j + 2, k + 4, StructureGenHelper.cobbleOrMossy(rand), 0, 2);
		world.setBlock(i + 9, j + 2, k + 5, StructureGenHelper.cobbleOrMossy(rand), 0, 2);
		world.setBlock(i + 9, j + 3, k + 3, StructureGenHelper.cobbleOrMossy(rand), 0, 2);
		world.setBlock(i + 9, j + 3, k + 4, StructureGenHelper.cobbleOrMossy(rand), 0, 2);
		world.setBlock(i + 9, j + 3, k + 5, StructureGenHelper.cobbleOrMossy(rand), 0, 2);
		world.setBlock(i + 9, j + 4, k + 3, StructureGenHelper.cobbleOrMossy(rand), 0, 2);
		world.setBlock(i + 9, j + 4, k + 4, StructureGenHelper.cobbleOrMossy(rand), 0, 2);
		world.setBlock(i + 9, j + 4, k + 5, StructureGenHelper.cobbleOrMossy(rand), 0, 2);
		world.setBlock(i + 9, j + 4, k + 6, StructureGenHelper.cobbleOrMossy(rand), 0, 2);
		world.setBlock(i + 9, j + 4, k + 7, Blocks.stone_stairs, 7, 2);
		world.setBlock(i + 9, j + 5, k + 4, BlockTrap.instance, 3, 2);
		world.setBlockMetadataWithNotify(i + 9, j + 5, k + 4, 3, 2);
		te = world.getTileEntity(i + 9, j + 5, k + 4); 
		if(te instanceof TileEntityTrap) {
			ted = (TileEntityTrap)te;
			//PlaceTraps.addTrapItem(ted);
			ted.func_146019_a/*addItem*/(new ItemStack(Items.arrow, rand.nextInt(10)));
		}
		world.setBlock(i + 9, j + 5, k + 7, BlockTrap.instance, 2, 2);
		world.setBlockMetadataWithNotify(i + 9, j + 5, k + 7, 2, 2);
		te = world.getTileEntity(i + 9, j + 5, k + 7); 
		if(te instanceof TileEntityTrap) {
			ted = (TileEntityTrap)te;
			//PlaceTraps.addTrapItem(ted);
			ted.func_146019_a/*addItem*/(new ItemStack(Items.arrow, rand.nextInt(10)));
		}
		world.setBlock(i + 9, j + 6, k + 4, StructureGenHelper.cobbleOrMossy(rand), 0, 2);
		world.setBlock(i + 9, j + 6, k + 5, Blocks.air);
		world.setBlock(i + 9, j + 6, k + 6, Blocks.air);
		world.setBlock(i + 9, j + 6, k + 7, StructureGenHelper.cobbleOrMossy(rand), 0, 2);
		world.setBlock(i + 9, j + 7, k + 4, StructureGenHelper.cobbleOrMossy(rand), 0, 2);
		world.setBlock(i + 9, j + 7, k + 5, Blocks.air);
		world.setBlock(i + 9, j + 7, k + 6, Blocks.air);
		world.setBlock(i + 9, j + 7, k + 7, StructureGenHelper.cobbleOrMossy(rand), 0, 2);
		world.setBlock(i + 9, j + 8, k + 5, StructureGenHelper.cobbleOrMossy(rand), 0, 2);
		world.setBlock(i + 9, j + 8, k + 6, StructureGenHelper.cobbleOrMossy(rand), 0, 2);
		world.setBlock(i + 9, j + 8, k + 7, StructureGenHelper.cobbleOrMossy(rand), 0, 2);
		world.setBlock(i + 10, j + 4, k + 5, Blocks.stone_stairs, 6, 2);
		world.setBlock(i + 10, j + 4, k + 6, StructureGenHelper.cobbleOrMossy(rand), 0, 2);
		world.setBlock(i + 10, j + 4, k + 7, Blocks.stone_stairs, 7, 2);
		world.setBlock(i + 10, j + 5, k + 4, Blocks.stone_stairs, 6, 2);
		world.setBlock(i + 10, j + 5, k + 5, Blocks.air);
		world.setBlock(i + 10, j + 5, k + 6, Blocks.air);
		world.setBlock(i + 10, j + 5, k + 7, Blocks.air);
		world.setBlock(i + 10, j + 5, k + 8, Blocks.stone_stairs, 7, 2);
		world.setBlock(i + 10, j + 6, k + 4, StructureGenHelper.cobbleOrMossy(rand), 0, 2);
		world.setBlock(i + 10, j + 6, k + 5, Blocks.air);
		world.setBlock(i + 10, j + 6, k + 6, Blocks.air);
		world.setBlock(i + 10, j + 6, k + 7, Blocks.air);
		world.setBlock(i + 10, j + 6, k + 8, StructureGenHelper.cobbleOrMossy(rand), 0, 2);
		world.setBlock(i + 10, j + 7, k + 4, StructureGenHelper.cobbleOrMossy(rand), 0, 2);
		world.setBlock(i + 10, j + 7, k + 5, Blocks.air);
		world.setBlock(i + 10, j + 7, k + 6, Blocks.air);
		world.setBlock(i + 10, j + 7, k + 7, Blocks.air);
		world.setBlock(i + 10, j + 7, k + 8, StructureGenHelper.cobbleOrMossy(rand), 0, 2);
		world.setBlock(i + 10, j + 8, k + 4, StructureGenHelper.cobbleOrMossy(rand), 0, 2);
		world.setBlock(i + 10, j + 8, k + 5, Blocks.birch_stairs, 5, 2);
		world.setBlock(i + 10, j + 8, k + 6, Blocks.birch_stairs, 5, 2);
		world.setBlock(i + 10, j + 8, k + 7, Blocks.birch_stairs, 5, 2);
		world.setBlock(i + 10, j + 8, k + 8, StructureGenHelper.cobbleOrMossy(rand), 0, 2);
		world.setBlock(i + 10, j + 9, k + 4, Blocks.birch_stairs, 0, 2);
		world.setBlock(i + 10, j + 9, k + 5, Blocks.birch_stairs, 0, 2);
		world.setBlock(i + 10, j + 9, k + 6, Blocks.birch_stairs, 0, 2);
		world.setBlock(i + 10, j + 9, k + 7, Blocks.birch_stairs, 0, 2);
		world.setBlock(i + 10, j + 9, k + 8, Blocks.birch_stairs, 3, 2);
		world.setBlock(i + 11, j + 4, k + 5, Blocks.stone_stairs, 6, 2);
		world.setBlock(i + 11, j + 4, k + 6, StructureGenHelper.cobbleOrMossy(rand), 0, 2);
		world.setBlock(i + 11, j + 4, k + 7, Blocks.stone_stairs, 7, 2);
		world.setBlock(i + 11, j + 5, k + 4, Blocks.stone_stairs, 6, 2);
		world.setBlock(i + 11, j + 5, k + 5, Blocks.air);
		world.setBlock(i + 11, j + 5, k + 6, Blocks.enchanting_table, 0, 2);
		world.setBlock(i + 11, j + 5, k + 7, Blocks.air);
		world.setBlock(i + 11, j + 5, k + 8, Blocks.stone_stairs, 7, 2);
		world.setBlock(i + 11, j + 6, k + 4, Blocks.iron_bars, 0, 2);
		world.setBlock(i + 11, j + 6, k + 5, Blocks.air);
		world.setBlock(i + 11, j + 6, k + 6, Blocks.air);
		world.setBlock(i + 11, j + 6, k + 7, Blocks.air);
		world.setBlock(i + 11, j + 6, k + 8, Blocks.iron_bars, 0, 2);
		world.setBlock(i + 11, j + 7, k + 4, Blocks.iron_bars, 0, 2);
		world.setBlock(i + 11, j + 7, k + 5, Blocks.air);
		world.setBlock(i + 11, j + 7, k + 6, Blocks.air);
		world.setBlock(i + 11, j + 7, k + 7, Blocks.air);
		world.setBlock(i + 11, j + 7, k + 8, Blocks.iron_bars, 0, 2);
		world.setBlock(i + 11, j + 8, k + 4, StructureGenHelper.cobbleOrMossy(rand), 0, 2);
		world.setBlock(i + 11, j + 8, k + 5, Blocks.air);
		world.setBlock(i + 11, j + 8, k + 6, Blocks.air);
		world.setBlock(i + 11, j + 8, k + 7, Blocks.air);
		world.setBlock(i + 11, j + 8, k + 8, StructureGenHelper.cobbleOrMossy(rand), 0, 2);
		world.setBlock(i + 11, j + 9, k + 4, Blocks.birch_stairs, 2, 2);
		world.setBlock(i + 11, j + 9, k + 5, BlockIllusionary.instance, 0, 2);
		world.setBlock(i + 11, j + 9, k + 6, BlockIllusionary.instance, 0, 2);
		world.setBlock(i + 11, j + 9, k + 7, BlockIllusionary.instance, 0, 2);
		world.setBlock(i + 11, j + 9, k + 8, Blocks.birch_stairs, 3, 2);
		world.setBlock(i + 11, j + 10, k + 5, Blocks.birch_stairs, 0, 2);
		world.setBlock(i + 11, j + 10, k + 6, Blocks.birch_stairs, 0, 2);
		world.setBlock(i + 11, j + 10, k + 7, Blocks.birch_stairs, 3, 2);
		world.setBlock(i + 12, j + 4, k + 5, Blocks.stone_stairs, 6, 2);
		world.setBlock(i + 12, j + 4, k + 6, StructureGenHelper.cobbleOrMossy(rand), 0, 2);
		world.setBlock(i + 12, j + 4, k + 7, Blocks.stone_stairs, 7, 2);
		world.setBlock(i + 12, j + 5, k + 4, Blocks.stone_stairs, 6, 2);
		world.setBlock(i + 12, j + 5, k + 5, Blocks.air);
		world.setBlock(i + 12, j + 5, k + 6, Blocks.air);
		world.setBlock(i + 12, j + 5, k + 7, Blocks.air);
		world.setBlock(i + 12, j + 5, k + 8, Blocks.stone_stairs, 7, 2);
		world.setBlock(i + 12, j + 6, k + 4, StructureGenHelper.cobbleOrMossy(rand), 0, 2);
		world.setBlock(i + 12, j + 6, k + 5, Blocks.air);
		world.setBlock(i + 12, j + 6, k + 6, Blocks.air);
		world.setBlock(i + 12, j + 6, k + 7, Blocks.air);
		world.setBlock(i + 12, j + 6, k + 8, StructureGenHelper.cobbleOrMossy(rand), 0, 2);
		world.setBlock(i + 12, j + 7, k + 4, StructureGenHelper.cobbleOrMossy(rand), 0, 2);
		world.setBlock(i + 12, j + 7, k + 5, Blocks.air);
		world.setBlock(i + 12, j + 7, k + 6, Blocks.air);
		world.setBlock(i + 12, j + 7, k + 7, Blocks.air);
		world.setBlock(i + 12, j + 7, k + 8, StructureGenHelper.cobbleOrMossy(rand), 0, 2);
		world.setBlock(i + 12, j + 8, k + 4, StructureGenHelper.cobbleOrMossy(rand), 0, 2);
		world.setBlock(i + 12, j + 8, k + 5, Blocks.air);
		world.setBlock(i + 12, j + 8, k + 6, Blocks.air);
		world.setBlock(i + 12, j + 8, k + 7, Blocks.air);
		world.setBlock(i + 12, j + 8, k + 8, StructureGenHelper.cobbleOrMossy(rand), 0, 2);
		world.setBlock(i + 12, j + 9, k + 4, Blocks.birch_stairs, 2, 2);
		world.setBlock(i + 12, j + 9, k + 5, BlockIllusionary.instance, 0, 2);
		world.setBlock(i + 12, j + 9, k + 6, BlockIllusionary.instance, 0, 2);
		world.setBlock(i + 12, j + 9, k + 7, BlockIllusionary.instance, 0, 2);
		world.setBlock(i + 12, j + 9, k + 8, Blocks.birch_stairs, 3, 2);
		world.setBlock(i + 12, j + 10, k + 5, Blocks.birch_stairs, 2, 2);
		world.setBlock(i + 12, j + 10, k + 6, Blocks.chest, 4, 2);
		te = world.getTileEntity(i + 12, j + 10, k + 6);
		if(te instanceof TileEntityChest) {
			TileEntityChest tec = (TileEntityChest)te;
			ChestGenHooks info = ChestGenHooks.getInfo(ChestGenHooks.PYRAMID_DESERT_CHEST);
            WeightedRandomChestContent.generateChestContents(rand, info.getItems(rand), tec, info.getCount(rand));
		}
		world.setBlock(i + 12, j + 10, k + 7, Blocks.birch_stairs, 3, 2);
		world.setBlock(i + 12, j + 11, k + 6, Blocks.wooden_slab, 2, 2);
		world.setBlock(i + 13, j + 4, k + 5, Blocks.stone_stairs, 5, 2);
		world.setBlock(i + 13, j + 4, k + 6, Blocks.stone_stairs, 5, 2);
		world.setBlock(i + 13, j + 4, k + 7, Blocks.stone_stairs, 7, 2);
		world.setBlock(i + 13, j + 5, k + 4, Blocks.stone_stairs, 6, 2);
		world.setBlock(i + 13, j + 5, k + 5, Blocks.bookshelf, 0, 2);
		world.setBlock(i + 13, j + 5, k + 6, Blocks.bookshelf, 0, 2);
		world.setBlock(i + 13, j + 5, k + 7, Blocks.bookshelf, 0, 2);
		world.setBlock(i + 13, j + 5, k + 8, Blocks.stone_stairs, 7, 2);
		world.setBlock(i + 13, j + 6, k + 4, StructureGenHelper.cobbleOrMossy(rand), 0, 2);
		world.setBlock(i + 13, j + 6, k + 5, Blocks.bookshelf, 0, 2);
		world.setBlock(i + 13, j + 6, k + 6, Blocks.bookshelf, 0, 2);
		world.setBlock(i + 13, j + 6, k + 7, Blocks.bookshelf, 0, 2);
		world.setBlock(i + 13, j + 6, k + 8, StructureGenHelper.cobbleOrMossy(rand), 0, 2);
		world.setBlock(i + 13, j + 7, k + 4, StructureGenHelper.cobbleOrMossy(rand), 0, 2);
		world.setBlock(i + 13, j + 7, k + 5, StructureGenHelper.randomBlock(rand, new Block[]{Blocks.bookshelf, Blocks.bookshelf, Blocks.bookshelf, Blocks.bookshelf, Blocks.web, Blocks.web}), 0, 2);
		world.setBlock(i + 13, j + 7, k + 6, StructureGenHelper.randomBlock(rand, new Block[]{Blocks.bookshelf, Blocks.bookshelf, Blocks.bookshelf, Blocks.bookshelf, Blocks.web, Blocks.web}), 0, 2);
		world.setBlock(i + 13, j + 7, k + 7, StructureGenHelper.randomBlock(rand, new Block[]{Blocks.bookshelf, Blocks.bookshelf, Blocks.bookshelf, Blocks.bookshelf, Blocks.web, Blocks.web}), 0, 2);
		world.setBlock(i + 13, j + 7, k + 8, StructureGenHelper.cobbleOrMossy(rand), 0, 2);
		world.setBlock(i + 13, j + 8, k + 4, StructureGenHelper.cobbleOrMossy(rand), 0, 2);
		world.setBlock(i + 13, j + 8, k + 5, StructureGenHelper.randomBlock(rand, new Block[]{Blocks.bookshelf, Blocks.bookshelf, Blocks.bookshelf, Blocks.web, Blocks.air}), 0, 2);
		world.setBlock(i + 13, j + 8, k + 6, StructureGenHelper.randomBlock(rand, new Block[]{Blocks.bookshelf, Blocks.bookshelf, Blocks.bookshelf, Blocks.web, Blocks.air}), 0, 2);
		world.setBlock(i + 13, j + 8, k + 7, StructureGenHelper.randomBlock(rand, new Block[]{Blocks.bookshelf, Blocks.bookshelf, Blocks.bookshelf, Blocks.web, Blocks.air}), 0, 2);
		world.setBlock(i + 13, j + 8, k + 8, StructureGenHelper.cobbleOrMossy(rand), 0, 2);
		world.setBlock(i + 13, j + 9, k + 4, Blocks.birch_stairs, 2, 2);
		world.setBlock(i + 13, j + 9, k + 5, Blocks.planks, 2, 2);
		world.setBlock(i + 13, j + 9, k + 6, Blocks.planks, 2, 2);
		world.setBlock(i + 13, j + 9, k + 7, Blocks.planks, 2, 2);
		world.setBlock(i + 13, j + 9, k + 8, Blocks.birch_stairs, 3, 2);
		world.setBlock(i + 13, j + 10, k + 5, Blocks.birch_stairs, 2, 2);
		world.setBlock(i + 13, j + 10, k + 6, Blocks.birch_stairs, 1, 2);
		world.setBlock(i + 13, j + 10, k + 7, Blocks.birch_stairs, 1, 2);
		world.setBlock(i + 14, j + 5, k + 5, Blocks.stone_stairs, 5, 2);
		world.setBlock(i + 14, j + 5, k + 6, Blocks.stone_stairs, 5, 2);
		world.setBlock(i + 14, j + 5, k + 7, Blocks.stone_stairs, 5, 2);
		world.setBlock(i + 14, j + 6, k + 5, StructureGenHelper.cobbleOrMossy(rand), 0, 2);
		world.setBlock(i + 14, j + 6, k + 6, StructureGenHelper.cobbleOrMossy(rand), 0, 2);
		world.setBlock(i + 14, j + 6, k + 7, StructureGenHelper.cobbleOrMossy(rand), 0, 2);
		world.setBlock(i + 14, j + 7, k + 5, StructureGenHelper.cobbleOrMossy(rand), 0, 2);
		world.setBlock(i + 14, j + 7, k + 6, StructureGenHelper.cobbleOrMossy(rand), 0, 2);
		world.setBlock(i + 14, j + 7, k + 7, StructureGenHelper.cobbleOrMossy(rand), 0, 2);
		world.setBlock(i + 14, j + 8, k + 5, StructureGenHelper.cobbleOrMossy(rand), 0, 2);
		world.setBlock(i + 14, j + 8, k + 6, StructureGenHelper.cobbleOrMossy(rand), 0, 2);
		world.setBlock(i + 14, j + 8, k + 7, StructureGenHelper.cobbleOrMossy(rand), 0, 2);
		world.setBlock(i + 14, j + 9, k + 4, Blocks.birch_stairs, 2, 2);
		world.setBlock(i + 14, j + 9, k + 5, Blocks.birch_stairs, 1, 2);
		world.setBlock(i + 14, j + 9, k + 6, Blocks.birch_stairs, 1, 2);
		world.setBlock(i + 14, j + 9, k + 7, Blocks.birch_stairs, 1, 2);
		world.setBlock(i + 14, j + 9, k + 8, Blocks.birch_stairs, 1, 2);
		world.setBlock(i + 0, j + 13, k + 1, Blocks.torch, 5, 2);
		world.setBlock(i + 2, j + 1, k + 5, StructureGenHelper.randomBlock(rand, new Block[]{BlockWallPlate.stone, BlockWallPlate.camoStone}), 2, 2);
		world.setBlock(i + 3, j + 1, k + 5, Blocks.ladder, 2, 2);
		world.setBlock(i + 3, j + 2, k + 5, Blocks.ladder, 2, 2);
		world.setBlock(i + 3, j + 3, k + 5, Blocks.ladder, 2, 2);
		world.setBlock(i + 3, j + 4, k + 5, Blocks.ladder, 2, 2);
		world.setBlock(i + 4, j + 5, k + 3, Blocks.ladder, 3, 2);
		world.setBlock(i + 4, j + 6, k + 3, Blocks.ladder, 3, 2);
		world.setBlock(i + 4, j + 7, k + 3, Blocks.ladder, 3, 2);
		world.setBlock(i + 4, j + 8, k + 3, Blocks.ladder, 3, 2);
		world.setBlock(i + 4, j + 9, k + 3, StructureGenHelper.randomBlock(rand, new Block[]{BlockWallPlate.stone, BlockWallPlate.camoStone}), 3, 2);
		world.setBlock(i + 4, j + 9, k + 6, Blocks.wooden_door, 1, 2);
		world.setBlock(i + 4, j + 10, k + 6, Blocks.wooden_door, 8, 2);
		world.setBlock(i + 5, j + 1, k + 0, Blocks.iron_door, 1, 2);
		world.setBlock(i + 5, j + 2, k + 0, Blocks.iron_door, 8, 2);
		world.setBlockToAir(i + 5, j + 1, k - 1);
		world.setBlockToAir(i + 5, j + 21, k - 1);
		world.setBlock(i + 5, j + 9, k + 5, Blocks.ladder, 2, 2);
		world.setBlock(i + 5, j + 10, k + 5, Blocks.ladder, 2, 2);
		world.setBlock(i + 5, j + 10, k + 7, Blocks.lever, 14, 2);
		world.setBlock(i + 5, j + 11, k + 5, Blocks.ladder, 2, 2);
		world.setBlock(i + 5, j + 12, k + 5, Blocks.ladder, 2, 2);
		world.setBlock(i + 5, j + 13, k + 5, Blocks.ladder, 2, 2);
		world.setBlock(i + 5, j + 14, k + 5, Blocks.ladder, 2, 2);
		world.setBlock(i + 5, j + 15, k + 5, Blocks.torch, 4, 2);
		world.setBlock(i + 6, j + 9, k + 5, StructureGenHelper.randomBlock(rand, new Block[]{BlockWallPlate.stone, BlockWallPlate.camoStone}), 2, 2);
		world.setBlock(i + 7, j + 14, k + 2, Blocks.torch, 5, 2);
		world.setBlock(i + 9, j + 5, k + 5, BlockArtifactsPressurePlate.invisObsidian, 0, 2);
		world.setBlock(i + 9, j + 5, k + 6, BlockArtifactsPressurePlate.invisObsidian, 0, 2);

		//Decoration
		
		world.setBlock(i + 4, j + 9, k + 8, Blocks.bed, 3, 2);
		world.setBlock(i + 5, j + 9, k + 8, Blocks.bed, 11, 2);
		
		//Flower Pots
		world.setBlock(i + 5, j + 14, k + 1, StructureGenHelper.randomBlock(rand, new Block[]{Blocks.flower_pot, Blocks.air}), 0, 2);
		te = world.getTileEntity(i + 5, j + 14, k + 1); 
		if(te != null && te instanceof TileEntityFlowerPot) {
			TileEntityFlowerPot tefp = (TileEntityFlowerPot)te;
			StructureGenHelper.generatePotContents(rand, tefp);
		}
		
		world.setBlock(i + 8, j + 14, k + 4, StructureGenHelper.randomBlock(rand, new Block[]{Blocks.flower_pot, Blocks.air}), 0, 2);
		te = world.getTileEntity(i + 8, j + 14, k + 4); 
		if(te != null && te instanceof TileEntityFlowerPot) {
			TileEntityFlowerPot tefp = (TileEntityFlowerPot)te;
			StructureGenHelper.generatePotContents(rand, tefp);
		}
		
		//Tables and chairs
		if(rand.nextInt(10) == 0) {
			world.setBlock(i + 2, j + 1, k + 4, Blocks.nether_brick_fence);
			world.setBlock(i + 2, j + 2, k + 4, BlockArtifactsPressurePlate.obsidian);
			world.setBlock(i + 2, j + 1, k + 3, Blocks.brick_stairs, 3, 2);
		}
		if(rand.nextInt(10) == 0) {
			world.setBlock(i + 4, j + 1, k + 7, Blocks.brick_stairs, 1, 2);
			world.setBlock(i + 5, j + 1, k + 7, Blocks.nether_brick_fence);
			world.setBlock(i + 5, j + 2, k + 7, BlockArtifactsPressurePlate.obsidian);
			world.setBlock(i + 6, j + 1, k + 7, Blocks.brick_stairs, 0, 2);
		}
		if(rand.nextInt(10) == 0) {
			world.setBlock(i + 8, j + 1, k + 5, Blocks.brick_stairs, 2, 2);
			world.setBlock(i + 8, j + 1, k + 4, Blocks.nether_brick_fence);
			world.setBlock(i + 8, j + 2, k + 4, BlockArtifactsPressurePlate.obsidian);
			world.setBlock(i + 8, j + 1, k + 3, Blocks.brick_stairs, 3, 2);
		}
		if(rand.nextInt(10) == 0) {
			world.setBlock(i + 5, j + 5, k + 2, Blocks.nether_brick_fence);
			world.setBlock(i + 5, j + 6, k + 2, BlockArtifactsPressurePlate.obsidian);
			world.setBlock(i + 6, j + 5, k + 2, Blocks.brick_stairs, 0, 2);
		}
		if(rand.nextInt(10) == 0) {
			world.setBlock(i + 6, j + 9, k + 4, Blocks.nether_brick_fence);
			world.setBlock(i + 6, j + 10, k + 4, BlockArtifactsPressurePlate.obsidian);
			world.setBlock(i + 6, j + 9, k + 3, Blocks.brick_stairs, 3, 2);
		}
		if(rand.nextInt(10) == 0) {
			world.setBlock(i + 6, j + 9, k + 4, Blocks.nether_brick_fence);
			world.setBlock(i + 6, j + 10, k + 4, BlockArtifactsPressurePlate.obsidian);
			world.setBlock(i + 6, j + 9, k + 3, Blocks.brick_stairs, 3, 2);
		}
		if(rand.nextInt(10) == 0) {
			world.setBlock(i + 1, j + 11, k + 3, Blocks.brick_stairs, 2, 2);
			world.setBlock(i + 1, j + 11, k + 2, Blocks.nether_brick_fence);
			world.setBlock(i + 1, j + 12, k + 2, BlockArtifactsPressurePlate.obsidian);
			world.setBlock(i + 1, j + 11, k + 1, Blocks.brick_stairs, 3, 2);
		}
		
		//world.setBlock(i + 11, j + 5, k + 6, Block.enchantmentTable.blockID, 0, 2);
		EntityItemFrame e = new EntityItemFrame(world, i + 13, j + 6, k + 6, 1);
		e.setDisplayedItem(new ItemStack(ItemCalendar.instance));
		//NBTTagCompound nbt = new NBTTagCompound();
		//e.writeEntityToNBT(nbt);
		//e.readEntityFromNBT(nbt);
		world.spawnEntityInWorld(e);
		
		basement(world, i, j, k, rand);
		return true;
	}
	
	private static void basement(World world, int i, int j, int k, Random rand) {
		boolean noair = false;
		int y = -1;
		do {
			noair = false;
			for(int x = 1; x <= 9; x++) {
				for(int z = 0; z <= 8; z++) {
					//5,y,4
					int d = (x-5)*(x-5)+(z-4)*(z-4);
					if(d <= 17) {
						if(!world.getBlock(i+x, j+y, z+k).isOpaqueCube() || world.getBlock(i+x, j+y, z+k) == Blocks.leaves) {
							noair=true;
							world.setBlock(i+x, j+y, z+k, StructureGenHelper.cobbleOrMossy(rand), 0, 2);
						}
					}
				}
			}
			y--;
		} while(noair && (j+y) >= 0);
		if(y >= -7 && world.rand.nextBoolean()) {
			y = -8;
		}
		if(y < -7) {
			y++;
			int yy = 3;
			for(; yy <= 5; yy++) {
				for(int x = 3; x <= 7; x++) {
					for(int z = 2; z <= 6; z++) {
						world.setBlockToAir(i+x, j+y+yy, k+z);
					}
				}
			}
			world.setBlock(i+5, j+y+5, k+4, Blocks.mob_spawner, 0, 2);
			TileEntityMobSpawner tileentitymobspawner = (TileEntityMobSpawner)world.getTileEntity(i+5, j+y+5, k+4);

            if (tileentitymobspawner != null)
            {
                tileentitymobspawner.func_145881_a/*getSpawnerLogic*/().setEntityName("ClayGolem");
                NBTTagCompound nbt = new NBTTagCompound();
                tileentitymobspawner.writeToNBT(nbt);
                nbt.setShort("MinSpawnDelay",(short)100);
                nbt.setShort("MaxSpawnDelay",(short)600);
                tileentitymobspawner.readFromNBT(nbt);
            }
            
            world.setBlock(i+5, j+y+4, k+4, StructureGenHelper.randomBlock(rand, new Block[]{Blocks.chest, Blocks.chest, Blocks.air}), 2, 2);
    		TileEntity te = world.getTileEntity(i+5, j+y+4, k+4);
    		if(te != null && te instanceof TileEntityChest) {
    			TileEntityChest tec = (TileEntityChest)te;
    			ChestGenHooks info = ChestGenHooks.getInfo(ChestGenHooks.DUNGEON_CHEST);
                WeightedRandomChestContent.generateChestContents(rand, info.getItems(rand), tec, info.getCount(rand));
    		}
    		
    		world.setBlock(i+5, j+y+3, k+4, StructureGenHelper.cobbleOrMossy(rand), 0, 2);
            
			for(yy=3;yy*-1>y;yy++) {
				world.setBlock(i+7, j+y+yy, k+6, Blocks.ladder, 2, 2);
			}
			world.setBlock(i+7, j+y+yy, k+6, Blocks.ladder, 2, 2);
			world.setBlock(i+7, j+y+yy+1, k+6, Blocks.trapdoor, 2, 2);
		}
	}
}
