package com.draco18s.artifacts.worldgen;

import java.util.Random;

import com.draco18s.artifacts.api.ArtifactsAPI;
import com.draco18s.artifacts.block.*;
import com.draco18s.artifacts.entity.TileEntityDisplayPedestal;
import com.draco18s.artifacts.entity.TileEntityTrap;
import com.draco18s.artifacts.item.ItemArtifact;

import net.minecraft.block.Block;
import net.minecraft.init.Blocks;
import net.minecraft.init.Items;
import net.minecraft.item.Item;
import net.minecraft.item.ItemStack;
import net.minecraft.nbt.NBTTagCompound;
import net.minecraft.tileentity.TileEntity;
import net.minecraft.tileentity.TileEntityChest;
import net.minecraft.tileentity.TileEntityMobSpawner;
import net.minecraft.util.WeightedRandomChestContent;
import net.minecraft.world.World;
import net.minecraft.world.gen.feature.WorldGenerator;
import net.minecraft.world.gen.structure.StructureBoundingBox;
import net.minecraft.world.gen.structure.StructureComponent;
import net.minecraftforge.common.ChestGenHooks;

public class StructureApprenticeTowerAncient extends WorldGenerator {

	protected StructureApprenticeTowerAncient() {
	}

	@Override
	public boolean generate(World world, Random random, int x, int y, int z) {
		for (z -= 8; y > 5 && (!world.getBlock(x, y, z).isOpaqueCube() || world.getBlock(x, y, z) == Blocks.leaves); --y)
        {
            ;
        }

        if (y <= 61)
        {
            return false;
        }
        else
        {
        	build(world, random, x-3, y-2, z+1);
        }
		return false;
	}
	
	public static boolean build(World world, Random rand, int i, int j, int k) {
		//System.out.println("Placing apprentice tower at (" + i + "," + k+ ")");
		world.setBlock(i + 0, j + 0, k + 2, StructureGenHelper.cobbleMossyOrAir(rand), 0, 2);
		world.setBlock(i + 0, j + 0, k + 3, StructureGenHelper.cobbleMossyOrAir(rand), 0, 2);
		world.setBlock(i + 0, j + 0, k + 4, StructureGenHelper.cobbleMossyOrAir(rand), 0, 2);
		world.setBlock(i + 0, j + 1, k + 2, StructureGenHelper.cobbleMossyOrAir(rand), 0, 2);
		world.setBlock(i + 0, j + 1, k + 3, StructureGenHelper.cobbleMossyOrAir(rand), 0, 2);
		world.setBlock(i + 0, j + 1, k + 4, StructureGenHelper.cobbleMossyOrAir(rand), 0, 2);
		world.setBlock(i + 0, j + 2, k + 2, StructureGenHelper.cobbleMossyOrAir(rand), 0, 2);
		world.setBlock(i + 0, j + 2, k + 3, StructureGenHelper.cobbleMossyOrAir(rand), 0, 2);
		world.setBlock(i + 0, j + 2, k + 4, StructureGenHelper.cobbleMossyOrAir(rand), 0, 2);
		world.setBlock(i + 0, j + 3, k + 2, StructureGenHelper.cobbleMossyOrAir(rand), 0, 2);
		world.setBlock(i + 0, j + 3, k + 3, StructureGenHelper.cobbleMossyOrAir(rand), 0, 2);
		world.setBlock(i + 0, j + 3, k + 4, StructureGenHelper.cobbleMossyOrAir(rand), 0, 2);
		world.setBlock(i + 0, j + 4, k + 2, StructureGenHelper.cobbleMossyOrAir(rand), 0, 2);
		world.setBlock(i + 0, j + 4, k + 3, StructureGenHelper.cobbleMossyOrAir(rand), 0, 2);
		world.setBlock(i + 0, j + 4, k + 4, StructureGenHelper.cobbleMossyOrAir(rand), 0, 2);
		world.setBlock(i + 0, j + 5, k + 2, StructureGenHelper.cobbleMossyOrAir(rand), 0, 2);
		world.setBlock(i + 0, j + 5, k + 3, StructureGenHelper.cobbleMossyOrAir(rand), 0, 2);
		world.setBlock(i + 0, j + 5, k + 4, StructureGenHelper.cobbleMossyOrAir(rand), 0, 2);
		world.setBlock(i + 0, j + 6, k + 2, StructureGenHelper.cobbleMossyOrAir(rand), 0, 2);
		world.setBlock(i + 0, j + 6, k + 3, StructureGenHelper.cobbleMossyOrAir(rand), 0, 2);
		world.setBlock(i + 0, j + 6, k + 4, StructureGenHelper.cobbleMossyOrAir(rand), 0, 2);
		world.setBlock(i + 1, j + 0, k + 1, StructureGenHelper.cobbleMossyOrAir(rand), 0, 2);
		world.setBlock(i + 1, j + 0, k + 2, StructureGenHelper.cobbleMossyOrAir(rand), 0, 2);
		world.setBlock(i + 1, j + 0, k + 3, StructureGenHelper.cobbleMossyOrAir(rand), 0, 2);
		world.setBlock(i + 1, j + 0, k + 4, StructureGenHelper.cobbleMossyOrAir(rand), 0, 2);
		world.setBlock(i + 1, j + 0, k + 5, StructureGenHelper.cobbleMossyOrAir(rand), 0, 2);
		world.setBlock(i + 1, j + 1, k + 1, StructureGenHelper.cobbleMossyOrAir(rand), 0, 2);
		world.setBlock(i + 1, j + 1, k + 2, StructureGenHelper.cobbleMossyOrAir(rand), 0, 2);
		world.setBlock(i + 1, j + 1, k + 3, StructureGenHelper.cobbleMossyOrAir(rand), 0, 2);
		world.setBlock(i + 1, j + 1, k + 4, StructureGenHelper.cobbleMossyOrAir(rand), 0, 2);
		world.setBlock(i + 1, j + 1, k + 5, StructureGenHelper.cobbleMossyOrAir(rand), 0, 2);
		world.setBlock(i + 1, j + 2, k + 1, StructureGenHelper.cobbleMossyOrAir(rand), 0, 2);
		world.setBlock(i + 1, j + 2, k + 2, StructureGenHelper.cobbleMossyOrAir(rand), 0, 2);
		world.setBlock(i + 1, j + 2, k + 3, StructureGenHelper.cobbleMossyOrAir(rand), 0, 2);
		world.setBlock(i + 1, j + 2, k + 4, StructureGenHelper.cobbleMossyOrAir(rand), 0, 2);
		world.setBlock(i + 1, j + 2, k + 5, StructureGenHelper.cobbleMossyOrAir(rand), 0, 2);
		world.setBlock(i + 1, j + 3, k + 1, StructureGenHelper.cobbleMossyOrAir(rand), 0, 2);
		world.setBlock(i + 1, j + 3, k + 2, BlockInvisibleBlock.instance, 0, 2);
		world.setBlockToAir(i + 1, j + 3, k + 3);
		world.setBlock(i + 1, j + 3, k + 4, StructureGenHelper.randomBlock(rand, new Block[]{Blocks.bookshelf, Blocks.air, Blocks.web, Blocks.air, Blocks.air}), 0, 2);
		world.setBlock(i + 1, j + 3, k + 5, StructureGenHelper.cobbleMossyOrAir(rand), 0, 2);
		world.setBlock(i + 1, j + 4, k + 1, StructureGenHelper.cobbleMossyOrAir(rand), 0, 2);
		world.setBlock(i + 1, j + 4, k + 2, BlockInvisibleBlock.instance, 0, 2);
		world.setBlockToAir(i + 1, j + 4, k + 3);
		world.setBlock(i + 1, j + 4, k + 4, StructureGenHelper.randomBlock(rand, new Block[]{Blocks.bookshelf, Blocks.air, Blocks.web, Blocks.air, Blocks.air}), 0, 2);
		world.setBlock(i + 1, j + 4, k + 5, StructureGenHelper.cobbleMossyOrAir(rand), 0, 2);
		world.setBlock(i + 1, j + 5, k + 1, StructureGenHelper.cobbleMossyOrAir(rand), 0, 2);
		world.setBlock(i + 1, j + 5, k + 2, BlockInvisibleBlock.instance, 0, 2);
		world.setBlockToAir(i + 1, j + 5, k + 3);
		world.setBlock(i + 1, j + 5, k + 4, StructureGenHelper.randomBlock(rand, new Block[]{Blocks.web, Blocks.air, Blocks.air}), 0, 2);
		world.setBlock(i + 1, j + 5, k + 5, StructureGenHelper.cobbleMossyOrAir(rand), 0, 2);
		world.setBlock(i + 1, j + 6, k + 1, StructureGenHelper.cobbleMossyOrAir(rand), 0, 2);
		world.setBlock(i + 1, j + 6, k + 2, StructureGenHelper.cobbleMossyOrAir(rand), 0, 2);
		world.setBlock(i + 1, j + 6, k + 3, StructureGenHelper.cobbleMossyOrAir(rand), 0, 2);
		world.setBlock(i + 1, j + 6, k + 4, StructureGenHelper.cobbleMossyOrAir(rand), 0, 2);
		world.setBlock(i + 1, j + 6, k + 5, StructureGenHelper.cobbleMossyOrAir(rand), 0, 2);
		world.setBlock(i + 1, j + 7, k + 2, StructureGenHelper.cobbleMossyOrAir(rand), 0, 2);
		world.setBlock(i + 1, j + 7, k + 3, StructureGenHelper.cobbleMossyOrAir(rand), 0, 2);
		world.setBlock(i + 1, j + 7, k + 4, StructureGenHelper.cobbleMossyOrAir(rand), 0, 2);
		world.setBlock(i + 1, j + 8, k + 2, StructureGenHelper.cobbleMossyOrAir(rand), 0, 2);
		world.setBlock(i + 1, j + 8, k + 3, StructureGenHelper.cobbleMossyOrAir(rand), 0, 2);
		world.setBlock(i + 1, j + 8, k + 4, StructureGenHelper.cobbleMossyOrAir(rand), 0, 2);
		world.setBlock(i + 1, j + 9, k + 2, StructureGenHelper.cobbleMossyOrAir(rand), 0, 2);
		world.setBlock(i + 1, j + 9, k + 3, StructureGenHelper.cobbleMossyOrAir(rand), 0, 2);
		world.setBlock(i + 1, j + 9, k + 4, StructureGenHelper.cobbleMossyOrAir(rand), 0, 2);
		world.setBlock(i + 1, j + 10, k + 2, StructureGenHelper.cobbleMossyOrAir(rand), 0, 2);
		world.setBlock(i + 1, j + 10, k + 3, StructureGenHelper.cobbleMossyOrAir(rand), 0, 2);
		world.setBlock(i + 1, j + 10, k + 4, StructureGenHelper.cobbleMossyOrAir(rand), 0, 2);
		world.setBlock(i + 1, j + 14, k + 2, StructureGenHelper.cobbleMossyOrAir(rand), 0, 2);
		world.setBlock(i + 1, j + 14, k + 3, StructureGenHelper.cobbleMossyOrAir(rand), 0, 2);
		world.setBlock(i + 1, j + 14, k + 4, StructureGenHelper.cobbleMossyOrAir(rand), 0, 2);
		world.setBlock(i + 1, j + 15, k + 2, StructureGenHelper.cobbleMossyOrAir(rand), 0, 2);
		world.setBlock(i + 1, j + 15, k + 3, StructureGenHelper.cobbleMossyOrAir(rand), 0, 2);
		world.setBlock(i + 1, j + 15, k + 4, StructureGenHelper.cobbleMossyOrAir(rand), 0, 2);
		world.setBlock(i + 1, j + 16, k + 2, StructureGenHelper.cobbleMossyOrAir(rand), 0, 2);
		world.setBlockToAir(i + 1, j + 16, k + 3);
		world.setBlock(i + 1, j + 16, k + 4, StructureGenHelper.cobbleMossyOrAir(rand), 0, 2);
		world.setBlock(i + 2, j + 0, k + 0, StructureGenHelper.cobbleMossyOrAir(rand), 0, 2);
		world.setBlock(i + 2, j + 0, k + 1, StructureGenHelper.cobbleMossyOrAir(rand), 0, 2);
		world.setBlock(i + 2, j + 0, k + 2, StructureGenHelper.cobbleMossyOrAir(rand), 0, 2);
		world.setBlock(i + 2, j + 0, k + 3, StructureGenHelper.cobbleMossyOrAir(rand), 0, 2);
		world.setBlock(i + 2, j + 0, k + 4, StructureGenHelper.cobbleMossyOrAir(rand), 0, 2);
		world.setBlock(i + 2, j + 0, k + 5, StructureGenHelper.cobbleMossyOrAir(rand), 0, 2);
		world.setBlock(i + 2, j + 0, k + 6, StructureGenHelper.cobbleMossyOrAir(rand), 0, 2);
		world.setBlock(i + 2, j + 1, k + 0, StructureGenHelper.cobbleMossyOrAir(rand), 0, 2);
		world.setBlock(i + 2, j + 1, k + 1, BlockSpikes.instance, 0, 2);
		world.setBlock(i + 2, j + 1, k + 2, BlockSpikes.instance, 0, 2);
		world.setBlock(i + 2, j + 1, k + 3, BlockSpikes.instance, 0, 2);
		world.setBlock(i + 2, j + 1, k + 4, StructureGenHelper.cobbleMossyOrAir(rand), 0, 2);
		world.setBlock(i + 2, j + 1, k + 5, StructureGenHelper.cobbleMossyOrAir(rand), 0, 2);
		world.setBlock(i + 2, j + 1, k + 6, StructureGenHelper.cobbleMossyOrAir(rand), 0, 2);
		world.setBlock(i + 2, j + 2, k + 0, StructureGenHelper.cobbleMossyOrAir(rand), 0, 2);
		world.setBlock(i + 2, j + 2, k + 1, BlockIllusionary.instance, 0, 2);
		world.setBlock(i + 2, j + 2, k + 2, BlockIllusionary.instance, 0, 2);
		world.setBlock(i + 2, j + 2, k + 3, BlockIllusionary.instance, 0, 2);
		world.setBlock(i + 2, j + 2, k + 4, StructureGenHelper.cobbleMossyOrAir(rand), 0, 2);
		world.setBlock(i + 2, j + 2, k + 5, StructureGenHelper.cobbleMossyOrAir(rand), 0, 2);
		world.setBlock(i + 2, j + 2, k + 6, StructureGenHelper.cobbleMossyOrAir(rand), 0, 2);
		world.setBlock(i + 2, j + 3, k + 0, StructureGenHelper.cobbleMossyOrAir(rand), 0, 2);
		world.setBlockToAir(i + 2, j + 3, k + 1);
		world.setBlockToAir(i + 2, j + 3, k + 3);
		world.setBlockToAir(i + 2, j + 3, k + 4);
		world.setBlock(i + 2, j + 3, k + 5, StructureGenHelper.randomBlock(rand, new Block[]{Blocks.bookshelf, Blocks.air, Blocks.web, Blocks.air, Blocks.air}), 0, 2);
		world.setBlock(i + 2, j + 3, k + 6, StructureGenHelper.cobbleMossyOrAir(rand), 0, 2);
		world.setBlock(i + 2, j + 4, k + 0, StructureGenHelper.cobbleMossyOrAir(rand), 0, 2);
		world.setBlockToAir(i + 2, j + 4, k + 1);
		world.setBlockToAir(i + 2, j + 4, k + 3);
		world.setBlockToAir(i + 2, j + 4, k + 4);
		world.setBlock(i + 2, j + 4, k + 5, StructureGenHelper.randomBlock(rand, new Block[]{Blocks.bookshelf, Blocks.air, Blocks.web, Blocks.air, Blocks.air}), 0, 2);
		world.setBlock(i + 2, j + 4, k + 6, StructureGenHelper.cobbleMossyOrAir(rand), 0, 2);
		world.setBlock(i + 2, j + 5, k + 0, StructureGenHelper.cobbleMossyOrAir(rand), 0, 2);
		world.setBlock(i + 2, j + 5, k + 1, Blocks.air);
		world.setBlock(i + 2, j + 5, k + 3, Blocks.air);
		world.setBlock(i + 2, j + 5, k + 4, Blocks.air);
		world.setBlock(i + 2, j + 5, k + 5, StructureGenHelper.randomBlock(rand, new Block[]{Blocks.web, Blocks.air, Blocks.air}), 0, 2);
		world.setBlock(i + 2, j + 5, k + 6, StructureGenHelper.cobbleMossyOrAir(rand), 0, 2);
		world.setBlock(i + 2, j + 6, k + 0, StructureGenHelper.cobbleMossyOrAir(rand), 0, 2);
		world.setBlock(i + 2, j + 6, k + 1, StructureGenHelper.cobbleMossyOrAir(rand), 0, 2);
		world.setBlock(i + 2, j + 6, k + 3, StructureGenHelper.cobbleMossyOrAir(rand), 0, 2);
		world.setBlock(i + 2, j + 6, k + 4, StructureGenHelper.cobbleMossyOrAir(rand), 0, 2);
		world.setBlock(i + 2, j + 6, k + 5, StructureGenHelper.cobbleMossyOrAir(rand), 0, 2);
		world.setBlock(i + 2, j + 6, k + 6, StructureGenHelper.cobbleMossyOrAir(rand), 0, 2);
		world.setBlock(i + 2, j + 7, k + 1, StructureGenHelper.cobbleMossyOrAir(rand), 0, 2);
		world.setBlock(i + 2, j + 7, k + 2, Blocks.air);
		world.setBlock(i + 2, j + 7, k + 3, Blocks.air);
		world.setBlock(i + 2, j + 7, k + 4, Blocks.air);
		world.setBlock(i + 2, j + 7, k + 5, StructureGenHelper.cobbleMossyOrAir(rand), 0, 2);
		world.setBlock(i + 2, j + 8, k + 1, StructureGenHelper.cobbleMossyOrAir(rand), 0, 2);
		world.setBlock(i + 2, j + 8, k + 2, Blocks.air);
		world.setBlock(i + 2, j + 8, k + 3, Blocks.air);
		world.setBlock(i + 2, j + 8, k + 4, Blocks.air);
		world.setBlock(i + 2, j + 8, k + 5, StructureGenHelper.cobbleMossyOrAir(rand), 0, 2);
		world.setBlock(i + 2, j + 9, k + 1, StructureGenHelper.cobbleMossyOrAir(rand), 0, 2);
		world.setBlock(i + 2, j + 9, k + 2, Blocks.air);
		world.setBlock(i + 2, j + 9, k + 3, Blocks.air);
		world.setBlock(i + 2, j + 9, k + 4, StructureGenHelper.randomBlock(rand, new Block[]{Blocks.web, Blocks.air, Blocks.air}), 0, 2);
		world.setBlock(i + 2, j + 9, k + 5, StructureGenHelper.cobbleMossyOrAir(rand), 0, 2);
		world.setBlock(i + 2, j + 10, k + 1, StructureGenHelper.cobbleMossyOrAir(rand), 0, 2);
		world.setBlock(i + 2, j + 10, k + 2, StructureGenHelper.cobbleMossyOrAir(rand), 0, 2);
		world.setBlock(i + 2, j + 10, k + 3, StructureGenHelper.cobbleMossyOrAir(rand), 0, 2);
		world.setBlock(i + 2, j + 10, k + 4, StructureGenHelper.cobbleMossyOrAir(rand), 0, 2);
		world.setBlock(i + 2, j + 10, k + 5, StructureGenHelper.cobbleMossyOrAir(rand), 0, 2);
		world.setBlock(i + 2, j + 11, k + 2, StructureGenHelper.cobbleMossyOrAir(rand), 0, 2);
		world.setBlock(i + 2, j + 11, k + 3, StructureGenHelper.cobbleMossyOrAir(rand), 0, 2);
		world.setBlock(i + 2, j + 11, k + 4, StructureGenHelper.cobbleMossyOrAir(rand), 0, 2);
		world.setBlock(i + 2, j + 12, k + 2, StructureGenHelper.cobbleMossyOrAir(rand), 0, 2);
		world.setBlock(i + 2, j + 12, k + 3, StructureGenHelper.cobbleMossyOrAir(rand), 0, 2);
		world.setBlock(i + 2, j + 12, k + 4, StructureGenHelper.cobbleMossyOrAir(rand), 0, 2);
		world.setBlock(i + 2, j + 13, k + 2, StructureGenHelper.cobbleMossyOrAir(rand), 0, 2);
		world.setBlock(i + 2, j + 13, k + 3, StructureGenHelper.cobbleMossyOrAir(rand), 0, 2);
		world.setBlock(i + 2, j + 13, k + 4, StructureGenHelper.cobbleMossyOrAir(rand), 0, 2);
		world.setBlock(i + 2, j + 14, k + 1, StructureGenHelper.cobbleMossyOrAir(rand), 0, 2);
		world.setBlock(i + 2, j + 14, k + 2, StructureGenHelper.cobbleMossyOrAir(rand), 0, 2);
		world.setBlock(i + 2, j + 14, k + 3, StructureGenHelper.cobbleMossyOrAir(rand), 0, 2);
		world.setBlock(i + 2, j + 14, k + 4, StructureGenHelper.cobbleMossyOrAir(rand), 0, 2);
		world.setBlock(i + 2, j + 14, k + 5, StructureGenHelper.cobbleMossyOrAir(rand), 0, 2);
		world.setBlock(i + 2, j + 15, k + 1, StructureGenHelper.cobbleMossyOrAir(rand), 0, 2);
		world.setBlock(i + 2, j + 15, k + 2, Blocks.air);
		world.setBlock(i + 2, j + 15, k + 3, Blocks.air);
		world.setBlock(i + 2, j + 15, k + 4, Blocks.air);
		world.setBlock(i + 2, j + 15, k + 5, StructureGenHelper.cobbleMossyOrAir(rand), 0, 2);
		world.setBlock(i + 2, j + 16, k + 1, StructureGenHelper.cobbleMossyOrAir(rand), 0, 2);
		world.setBlock(i + 2, j + 16, k + 2, Blocks.air);
		world.setBlock(i + 2, j + 16, k + 3, Blocks.air);
		world.setBlock(i + 2, j + 16, k + 4, Blocks.air);
		world.setBlock(i + 2, j + 16, k + 5, StructureGenHelper.cobbleMossyOrAir(rand), 0, 2);
		world.setBlock(i + 3, j + 0, k + 0, StructureGenHelper.cobbleMossyOrAir(rand), 0, 2);
		world.setBlock(i + 3, j + 0, k + 1, StructureGenHelper.cobbleMossyOrAir(rand), 0, 2);
		world.setBlock(i + 3, j + 0, k + 2, StructureGenHelper.cobbleMossyOrAir(rand), 0, 2);
		world.setBlock(i + 3, j + 0, k + 3, StructureGenHelper.cobbleMossyOrAir(rand), 0, 2);
		world.setBlock(i + 3, j + 0, k + 4, StructureGenHelper.cobbleMossyOrAir(rand), 0, 2);
		world.setBlock(i + 3, j + 0, k + 5, StructureGenHelper.cobbleMossyOrAir(rand), 0, 2);
		world.setBlock(i + 3, j + 0, k + 6, StructureGenHelper.cobbleMossyOrAir(rand), 0, 2);
		world.setBlock(i + 3, j + 1, k + 0, StructureGenHelper.cobbleMossyOrAir(rand), 0, 2);
		world.setBlock(i + 3, j + 1, k + 1, BlockSpikes.instance, 0, 2);
		world.setBlock(i + 3, j + 1, k + 2, BlockSpikes.instance, 0, 2);
		world.setBlock(i + 3, j + 1, k + 3, BlockSpikes.instance, 0, 2);
		world.setBlock(i + 3, j + 1, k + 4, StructureGenHelper.cobbleMossyOrAir(rand), 0, 2);
		world.setBlock(i + 3, j + 1, k + 5, StructureGenHelper.cobbleMossyOrAir(rand), 0, 2);
		world.setBlock(i + 3, j + 1, k + 6, StructureGenHelper.cobbleMossyOrAir(rand), 0, 2);
		world.setBlock(i + 3, j + 2, k + 0, StructureGenHelper.cobbleMossyOrAir(rand), 0, 2);
		world.setBlock(i + 3, j + 2, k + 1, BlockIllusionary.instance, 0, 2);
		world.setBlock(i + 3, j + 2, k + 2, BlockIllusionary.instance, 0, 2);
		world.setBlock(i + 3, j + 2, k + 3, BlockIllusionary.instance, 0, 2);
		world.setBlock(i + 3, j + 2, k + 4, StructureGenHelper.cobbleMossyOrAir(rand), 0, 2);
		world.setBlock(i + 3, j + 2, k + 5, StructureGenHelper.cobbleMossyOrAir(rand), 0, 2);
		world.setBlock(i + 3, j + 2, k + 6, StructureGenHelper.cobbleMossyOrAir(rand), 0, 2);
		world.setBlock(i + 3, j + 3, k + 1, Blocks.air);
		world.setBlock(i + 3, j + 3, k + 2, Blocks.air);
		world.setBlock(i + 3, j + 3, k + 3, Blocks.air);
		world.setBlock(i + 3, j + 3, k + 4, Blocks.air);
		world.setBlock(i + 3, j + 3, k + 5, StructureGenHelper.randomBlock(rand, new Block[]{Blocks.crafting_table, Blocks.air, Blocks.air, Blocks.air}), 0, 2);
		world.setBlock(i + 3, j + 3, k + 6, StructureGenHelper.cobbleMossyOrAir(rand), 0, 2);
		world.setBlock(i + 3, j + 4, k + 1, Blocks.air);
		world.setBlock(i + 3, j + 4, k + 2, Blocks.air);
		world.setBlock(i + 3, j + 4, k + 3, Blocks.air);
		world.setBlock(i + 3, j + 4, k + 4, Blocks.air);
		world.setBlock(i + 3, j + 4, k + 5, Blocks.air);
		world.setBlock(i + 3, j + 4, k + 6, StructureGenHelper.cobbleMossyOrAir(rand), 0, 2);
		world.setBlock(i + 3, j + 5, k + 0, StructureGenHelper.cobbleMossyOrAir(rand), 0, 2);
		world.setBlock(i + 3, j + 5, k + 1, Blocks.air);
		world.setBlock(i + 3, j + 5, k + 2, Blocks.air);
		world.setBlock(i + 3, j + 5, k + 3, Blocks.air);
		world.setBlock(i + 3, j + 5, k + 4, Blocks.air);
		world.setBlock(i + 3, j + 5, k + 5, Blocks.air);
		world.setBlock(i + 3, j + 5, k + 6, StructureGenHelper.cobbleMossyOrAir(rand), 0, 2);
		world.setBlock(i + 3, j + 6, k + 0, StructureGenHelper.cobbleMossyOrAir(rand), 0, 2);
		world.setBlock(i + 3, j + 6, k + 1, StructureGenHelper.cobbleMossyOrAir(rand), 0, 2);
		world.setBlock(i + 3, j + 6, k + 2, StructureGenHelper.cobbleMossyOrAir(rand), 0, 2);
		world.setBlock(i + 3, j + 6, k + 3, StructureGenHelper.cobbleMossyOrAir(rand), 0, 2);
		world.setBlock(i + 3, j + 6, k + 4, StructureGenHelper.cobbleMossyOrAir(rand), 0, 2);
		world.setBlock(i + 3, j + 6, k + 5, StructureGenHelper.cobbleMossyOrAir(rand), 0, 2);
		world.setBlock(i + 3, j + 6, k + 6, StructureGenHelper.cobbleMossyOrAir(rand), 0, 2);
		world.setBlock(i + 3, j + 7, k + 1, StructureGenHelper.cobbleMossyOrAir(rand), 0, 2);
		world.setBlock(i + 3, j + 7, k + 2, Blocks.air);
		world.setBlock(i + 3, j + 7, k + 4, BlockInvisibleBlock.instance, 0, 2);
		world.setBlock(i + 3, j + 7, k + 5, StructureGenHelper.cobbleMossyOrAir(rand), 0, 2);
		world.setBlock(i + 3, j + 8, k + 1, StructureGenHelper.cobbleMossyOrAir(rand), 0, 2);
		world.setBlock(i + 3, j + 8, k + 2, Blocks.air);
		world.setBlock(i + 3, j + 8, k + 4, BlockInvisibleBlock.instance, 0, 2);
		world.setBlock(i + 3, j + 8, k + 5, StructureGenHelper.cobbleMossyOrAir(rand), 0, 2);
		world.setBlock(i + 3, j + 9, k + 1, StructureGenHelper.cobbleMossyOrAir(rand), 0, 2);
		world.setBlock(i + 3, j + 9, k + 2, Blocks.air);
		world.setBlock(i + 3, j + 9, k + 4, BlockInvisibleBlock.instance, 0, 2);
		world.setBlock(i + 3, j + 9, k + 5, StructureGenHelper.cobbleMossyOrAir(rand), 0, 2);
		world.setBlock(i + 3, j + 10, k + 1, StructureGenHelper.cobbleMossyOrAir(rand), 0, 2);
		world.setBlock(i + 3, j + 10, k + 2, StructureGenHelper.cobbleMossyOrAir(rand), 0, 2);
		world.setBlock(i + 3, j + 10, k + 4, StructureGenHelper.cobbleMossyOrAir(rand), 0, 2);
		world.setBlock(i + 3, j + 10, k + 5, StructureGenHelper.cobbleMossyOrAir(rand), 0, 2);
		world.setBlock(i + 3, j + 11, k + 2, StructureGenHelper.cobbleMossyOrAir(rand), 0, 2);
		world.setBlock(i + 3, j + 11, k + 4, StructureGenHelper.cobbleMossyOrAir(rand), 0, 2);
		world.setBlock(i + 3, j + 12, k + 2, StructureGenHelper.cobbleMossyOrAir(rand), 0, 2);
		world.setBlock(i + 3, j + 12, k + 4, StructureGenHelper.cobbleMossyOrAir(rand), 0, 2);
		world.setBlock(i + 3, j + 13, k + 2, StructureGenHelper.cobbleMossyOrAir(rand), 0, 2);
		world.setBlock(i + 3, j + 13, k + 4, StructureGenHelper.cobbleMossyOrAir(rand), 0, 2);
		world.setBlock(i + 3, j + 14, k + 1, StructureGenHelper.cobbleMossyOrAir(rand), 0, 2);
		world.setBlock(i + 3, j + 14, k + 2, StructureGenHelper.cobbleMossyOrAir(rand), 0, 2);
		world.setBlock(i + 3, j + 14, k + 3, BlockIllusionary.instance, 0, 2);
		world.setBlock(i + 3, j + 14, k + 4, StructureGenHelper.cobbleMossyOrAir(rand), 0, 2);
		world.setBlock(i + 3, j + 14, k + 5, StructureGenHelper.cobbleMossyOrAir(rand), 0, 2);
		world.setBlock(i + 3, j + 15, k + 1, StructureGenHelper.cobbleMossyOrAir(rand), 0, 2);
		world.setBlock(i + 3, j + 15, k + 2, Blocks.air);
		world.setBlock(i + 3, j + 15, k + 3, Blocks.air);
		world.setBlock(i + 3, j + 15, k + 5, StructureGenHelper.cobbleMossyOrAir(rand), 0, 2);
		world.setBlock(i + 3, j + 16, k + 1, Blocks.air);
		world.setBlock(i + 3, j + 16, k + 2, Blocks.air);
		world.setBlock(i + 3, j + 16, k + 3, Blocks.air);
		world.setBlock(i + 3, j + 16, k + 4, Blocks.air);
		world.setBlock(i + 3, j + 16, k + 5, Blocks.air);
		world.setBlock(i + 4, j + 0, k + 0, StructureGenHelper.cobbleMossyOrAir(rand), 0, 2);
		world.setBlock(i + 4, j + 0, k + 1, StructureGenHelper.cobbleMossyOrAir(rand), 0, 2);
		world.setBlock(i + 4, j + 0, k + 2, StructureGenHelper.cobbleMossyOrAir(rand), 0, 2);
		world.setBlock(i + 4, j + 0, k + 3, StructureGenHelper.cobbleMossyOrAir(rand), 0, 2);
		world.setBlock(i + 4, j + 0, k + 4, StructureGenHelper.cobbleMossyOrAir(rand), 0, 2);
		world.setBlock(i + 4, j + 0, k + 5, StructureGenHelper.cobbleMossyOrAir(rand), 0, 2);
		world.setBlock(i + 4, j + 0, k + 6, StructureGenHelper.cobbleMossyOrAir(rand), 0, 2);
		world.setBlock(i + 4, j + 1, k + 0, StructureGenHelper.cobbleMossyOrAir(rand), 0, 2);
		world.setBlock(i + 4, j + 1, k + 1, BlockSpikes.instance, 0, 2);
		world.setBlock(i + 4, j + 1, k + 2, BlockSpikes.instance, 0, 2);
		world.setBlock(i + 4, j + 1, k + 3, BlockSpikes.instance, 0, 2);
		world.setBlock(i + 4, j + 1, k + 4, StructureGenHelper.cobbleMossyOrAir(rand), 0, 2);
		world.setBlock(i + 4, j + 1, k + 5, StructureGenHelper.cobbleMossyOrAir(rand), 0, 2);
		world.setBlock(i + 4, j + 1, k + 6, StructureGenHelper.cobbleMossyOrAir(rand), 0, 2);
		world.setBlock(i + 4, j + 2, k + 0, StructureGenHelper.cobbleMossyOrAir(rand), 0, 2);
		world.setBlock(i + 4, j + 2, k + 1, BlockIllusionary.instance, 0, 2);
		world.setBlock(i + 4, j + 2, k + 2, BlockIllusionary.instance, 0, 2);
		world.setBlock(i + 4, j + 2, k + 3, BlockIllusionary.instance, 0, 2);
		world.setBlock(i + 4, j + 2, k + 4, StructureGenHelper.cobbleMossyOrAir(rand), 0, 2);
		world.setBlock(i + 4, j + 2, k + 5, StructureGenHelper.cobbleMossyOrAir(rand), 0, 2);
		world.setBlock(i + 4, j + 2, k + 6, StructureGenHelper.cobbleMossyOrAir(rand), 0, 2);
		world.setBlock(i + 4, j + 3, k + 0, StructureGenHelper.cobbleMossyOrAir(rand), 0, 2);
		world.setBlock(i + 4, j + 3, k + 1, Blocks.air);
		world.setBlock(i + 4, j + 3, k + 2, Blocks.air);
		world.setBlock(i + 4, j + 3, k + 3, Blocks.air);
		world.setBlock(i + 4, j + 3, k + 4, Blocks.air);
		world.setBlock(i + 4, j + 3, k + 5, StructureGenHelper.randomBlock(rand, new Block[]{Blocks.bookshelf, Blocks.air, Blocks.web, Blocks.air, Blocks.air}), 0, 2);
		world.setBlock(i + 4, j + 3, k + 6, StructureGenHelper.cobbleMossyOrAir(rand), 0, 2);
		world.setBlock(i + 4, j + 4, k + 0, StructureGenHelper.cobbleMossyOrAir(rand), 0, 2);
		world.setBlock(i + 4, j + 4, k + 1, Blocks.air);
		world.setBlock(i + 4, j + 4, k + 2, Blocks.air);
		world.setBlock(i + 4, j + 4, k + 3, Blocks.air);
		world.setBlock(i + 4, j + 4, k + 4, Blocks.air);
		world.setBlock(i + 4, j + 4, k + 5, StructureGenHelper.randomBlock(rand, new Block[]{Blocks.bookshelf, Blocks.air, Blocks.web, Blocks.air, Blocks.air}), 0, 2);
		world.setBlock(i + 4, j + 4, k + 6, StructureGenHelper.cobbleMossyOrAir(rand), 0, 2);
		world.setBlock(i + 4, j + 5, k + 0, StructureGenHelper.cobbleMossyOrAir(rand), 0, 2);
		world.setBlock(i + 4, j + 5, k + 1, StructureGenHelper.randomBlock(rand, new Block[]{Blocks.web, Blocks.air, Blocks.air}), 0, 2);
		world.setBlock(i + 4, j + 5, k + 2, Blocks.air);
		world.setBlock(i + 4, j + 5, k + 3, Blocks.air);
		world.setBlock(i + 4, j + 5, k + 4, Blocks.air);
		world.setBlock(i + 4, j + 5, k + 5, Blocks.air);
		world.setBlock(i + 4, j + 5, k + 6, StructureGenHelper.cobbleMossyOrAir(rand), 0, 2);
		world.setBlock(i + 4, j + 6, k + 0, StructureGenHelper.cobbleMossyOrAir(rand), 0, 2);
		world.setBlock(i + 4, j + 6, k + 1, StructureGenHelper.cobbleMossyOrAir(rand), 0, 2);
		world.setBlock(i + 4, j + 6, k + 2, StructureGenHelper.cobbleMossyOrAir(rand), 0, 2);
		world.setBlock(i + 4, j + 6, k + 3, StructureGenHelper.cobbleMossyOrAir(rand), 0, 2);
		world.setBlock(i + 4, j + 6, k + 4, StructureGenHelper.cobbleMossyOrAir(rand), 0, 2);
		world.setBlock(i + 4, j + 6, k + 5, StructureGenHelper.cobbleMossyOrAir(rand), 0, 2);
		world.setBlock(i + 4, j + 6, k + 6, StructureGenHelper.cobbleMossyOrAir(rand), 0, 2);
		world.setBlock(i + 4, j + 7, k + 1, StructureGenHelper.cobbleMossyOrAir(rand), 0, 2);
		world.setBlock(i + 4, j + 7, k + 2, Blocks.air);
		world.setBlock(i + 4, j + 7, k + 3, Blocks.air);
		world.setBlock(i + 4, j + 7, k + 4, Blocks.air);
		world.setBlock(i + 4, j + 7, k + 5, StructureGenHelper.cobbleMossyOrAir(rand), 0, 2);
		world.setBlock(i + 4, j + 8, k + 1, StructureGenHelper.cobbleMossyOrAir(rand), 0, 2);
		world.setBlock(i + 4, j + 8, k + 2, Blocks.air);
		world.setBlock(i + 4, j + 8, k + 3, Blocks.air);
		world.setBlock(i + 4, j + 8, k + 4, Blocks.air);
		world.setBlock(i + 4, j + 8, k + 5, StructureGenHelper.cobbleMossyOrAir(rand), 0, 2);
		world.setBlock(i + 4, j + 9, k + 1, StructureGenHelper.cobbleMossyOrAir(rand), 0, 2);
		world.setBlock(i + 4, j + 9, k + 2, StructureGenHelper.randomBlock(rand, new Block[]{Blocks.web, Blocks.air, Blocks.air}), 0, 2);
		world.setBlock(i + 4, j + 9, k + 3, StructureGenHelper.randomBlock(rand, new Block[]{Blocks.web, Blocks.air, Blocks.air}), 0, 2);
		world.setBlock(i + 4, j + 9, k + 4, Blocks.air);
		world.setBlock(i + 4, j + 9, k + 5, StructureGenHelper.cobbleMossyOrAir(rand), 0, 2);
		world.setBlock(i + 4, j + 10, k + 1, StructureGenHelper.cobbleMossyOrAir(rand), 0, 2);
		world.setBlock(i + 4, j + 10, k + 2, StructureGenHelper.cobbleMossyOrAir(rand), 0, 2);
		world.setBlock(i + 4, j + 10, k + 3, StructureGenHelper.cobbleMossyOrAir(rand), 0, 2);
		world.setBlock(i + 4, j + 10, k + 4, StructureGenHelper.cobbleMossyOrAir(rand), 0, 2);
		world.setBlock(i + 4, j + 10, k + 5, StructureGenHelper.cobbleMossyOrAir(rand), 0, 2);
		world.setBlock(i + 4, j + 11, k + 2, StructureGenHelper.cobbleMossyOrAir(rand), 0, 2);
		world.setBlock(i + 4, j + 11, k + 3, Blocks.air);
		world.setBlock(i + 4, j + 11, k + 4, StructureGenHelper.cobbleMossyOrAir(rand), 0, 2);
		world.setBlock(i + 4, j + 12, k + 2, StructureGenHelper.cobbleMossyOrAir(rand), 0, 2);
		world.setBlock(i + 4, j + 12, k + 3, Blocks.air);
		world.setBlock(i + 4, j + 12, k + 4, StructureGenHelper.cobbleMossyOrAir(rand), 0, 2);
		world.setBlock(i + 4, j + 13, k + 2, StructureGenHelper.cobbleMossyOrAir(rand), 0, 2);
		world.setBlock(i + 4, j + 13, k + 3, StructureGenHelper.cobbleMossyOrAir(rand), 0, 2);
		world.setBlock(i + 4, j + 13, k + 4, StructureGenHelper.cobbleMossyOrAir(rand), 0, 2);
		world.setBlock(i + 4, j + 14, k + 1, StructureGenHelper.cobbleMossyOrAir(rand), 0, 2);
		world.setBlock(i + 4, j + 14, k + 2, StructureGenHelper.cobbleMossyOrAir(rand), 0, 2);
		world.setBlock(i + 4, j + 14, k + 3, StructureGenHelper.cobbleMossyOrAir(rand), 0, 2);
		world.setBlock(i + 4, j + 14, k + 4, StructureGenHelper.cobbleMossyOrAir(rand), 0, 2);
		world.setBlock(i + 4, j + 14, k + 5, StructureGenHelper.cobbleMossyOrAir(rand), 0, 2);
		world.setBlock(i + 4, j + 15, k + 1, StructureGenHelper.cobbleMossyOrAir(rand), 0, 2);
		world.setBlock(i + 4, j + 15, k + 2, Blocks.air);
		world.setBlock(i + 4, j + 15, k + 3, Blocks.air);
		world.setBlock(i + 4, j + 15, k + 4, Blocks.air);
		world.setBlock(i + 4, j + 15, k + 5, StructureGenHelper.cobbleMossyOrAir(rand), 0, 2);
		world.setBlock(i + 4, j + 16, k + 1, StructureGenHelper.cobbleMossyOrAir(rand), 0, 2);
		world.setBlock(i + 4, j + 16, k + 2, Blocks.air);
		world.setBlock(i + 4, j + 16, k + 3, Blocks.air);
		world.setBlock(i + 4, j + 16, k + 4, Blocks.air);
		world.setBlock(i + 4, j + 16, k + 5, StructureGenHelper.cobbleMossyOrAir(rand), 0, 2);
		world.setBlock(i + 5, j + 0, k + 1, StructureGenHelper.cobbleMossyOrAir(rand), 0, 2);
		world.setBlock(i + 5, j + 0, k + 2, StructureGenHelper.cobbleMossyOrAir(rand), 0, 2);
		world.setBlock(i + 5, j + 0, k + 3, StructureGenHelper.cobbleMossyOrAir(rand), 0, 2);
		world.setBlock(i + 5, j + 0, k + 4, StructureGenHelper.cobbleMossyOrAir(rand), 0, 2);
		world.setBlock(i + 5, j + 0, k + 5, StructureGenHelper.cobbleMossyOrAir(rand), 0, 2);
		world.setBlock(i + 5, j + 1, k + 1, StructureGenHelper.cobbleMossyOrAir(rand), 0, 2);
		world.setBlock(i + 5, j + 1, k + 2, StructureGenHelper.cobbleMossyOrAir(rand), 0, 2);
		world.setBlock(i + 5, j + 1, k + 3, StructureGenHelper.cobbleMossyOrAir(rand), 0, 2);
		world.setBlock(i + 5, j + 1, k + 4, StructureGenHelper.cobbleMossyOrAir(rand), 0, 2);
		world.setBlock(i + 5, j + 1, k + 5, StructureGenHelper.cobbleMossyOrAir(rand), 0, 2);
		world.setBlock(i + 5, j + 2, k + 1, StructureGenHelper.cobbleMossyOrAir(rand), 0, 2);
		world.setBlock(i + 5, j + 2, k + 2, StructureGenHelper.cobbleMossyOrAir(rand), 0, 2);
		world.setBlock(i + 5, j + 2, k + 3, StructureGenHelper.cobbleMossyOrAir(rand), 0, 2);
		world.setBlock(i + 5, j + 2, k + 4, StructureGenHelper.cobbleMossyOrAir(rand), 0, 2);
		world.setBlock(i + 5, j + 2, k + 5, StructureGenHelper.cobbleMossyOrAir(rand), 0, 2);
		world.setBlock(i + 5, j + 3, k + 1, StructureGenHelper.cobbleMossyOrAir(rand), 0, 2);
		world.setBlock(i + 5, j + 3, k + 2, Blocks.air);
		world.setBlock(i + 5, j + 3, k + 3, Blocks.air);
		world.setBlock(i + 5, j + 3, k + 4, StructureGenHelper.randomBlock(rand, new Block[]{Blocks.bookshelf, Blocks.air, Blocks.web, Blocks.air, Blocks.air}), 0, 2);
		world.setBlock(i + 5, j + 3, k + 5, StructureGenHelper.cobbleMossyOrAir(rand), 0, 2);
		world.setBlock(i + 5, j + 4, k + 1, StructureGenHelper.cobbleMossyOrAir(rand), 0, 2);
		world.setBlock(i + 5, j + 4, k + 2, Blocks.air);
		world.setBlock(i + 5, j + 4, k + 3, Blocks.air);
		world.setBlock(i + 5, j + 4, k + 4, StructureGenHelper.randomBlock(rand, new Block[]{Blocks.bookshelf, Blocks.air, Blocks.web, Blocks.air, Blocks.air}), 0, 2);
		world.setBlock(i + 5, j + 4, k + 5, StructureGenHelper.cobbleMossyOrAir(rand), 0, 2);
		world.setBlock(i + 5, j + 5, k + 1, StructureGenHelper.cobbleMossyOrAir(rand), 0, 2);
		world.setBlock(i + 5, j + 5, k + 2, Blocks.air);
		world.setBlock(i + 5, j + 5, k + 3, Blocks.air);
		world.setBlock(i + 5, j + 5, k + 4, StructureGenHelper.randomBlock(rand, new Block[]{Blocks.web, Blocks.air, Blocks.air}), 0, 2);
		world.setBlock(i + 5, j + 5, k + 5, StructureGenHelper.cobbleMossyOrAir(rand), 0, 2);
		world.setBlock(i + 5, j + 6, k + 1, StructureGenHelper.cobbleMossyOrAir(rand), 0, 2);
		world.setBlock(i + 5, j + 6, k + 2, StructureGenHelper.cobbleMossyOrAir(rand), 0, 2);
		world.setBlock(i + 5, j + 6, k + 3, StructureGenHelper.cobbleMossyOrAir(rand), 0, 2);
		world.setBlock(i + 5, j + 6, k + 4, StructureGenHelper.cobbleMossyOrAir(rand), 0, 2);
		world.setBlock(i + 5, j + 6, k + 5, StructureGenHelper.cobbleMossyOrAir(rand), 0, 2);
		world.setBlock(i + 5, j + 7, k + 2, StructureGenHelper.cobbleMossyOrAir(rand), 0, 2);
		world.setBlock(i + 5, j + 7, k + 3, StructureGenHelper.cobbleMossyOrAir(rand), 0, 2);
		world.setBlock(i + 5, j + 7, k + 4, StructureGenHelper.cobbleMossyOrAir(rand), 0, 2);
		world.setBlock(i + 5, j + 8, k + 2, StructureGenHelper.cobbleMossyOrAir(rand), 0, 2);
		world.setBlock(i + 5, j + 8, k + 3, StructureGenHelper.cobbleMossyOrAir(rand), 0, 2);
		world.setBlock(i + 5, j + 8, k + 4, StructureGenHelper.cobbleMossyOrAir(rand), 0, 2);
		world.setBlock(i + 5, j + 9, k + 2, StructureGenHelper.cobbleMossyOrAir(rand), 0, 2);
		world.setBlock(i + 5, j + 9, k + 3, StructureGenHelper.cobbleMossyOrAir(rand), 0, 2);
		world.setBlock(i + 5, j + 9, k + 4, StructureGenHelper.cobbleMossyOrAir(rand), 0, 2);
		world.setBlock(i + 5, j + 10, k + 2, StructureGenHelper.cobbleMossyOrAir(rand), 0, 2);
		world.setBlock(i + 5, j + 10, k + 3, StructureGenHelper.cobbleOrMossy(rand), 0, 2);
		world.setBlock(i + 5, j + 10, k + 4, StructureGenHelper.cobbleMossyOrAir(rand), 0, 2);
		world.setBlock(i + 5, j + 11, k + 2, StructureGenHelper.randomBlock(rand, new Block[]{Blocks.fence, Blocks.air}), 0, 2);
		world.setBlock(i + 5, j + 11, k + 3, Blocks.air);
		world.setBlock(i + 5, j + 11, k + 4, StructureGenHelper.randomBlock(rand, new Block[]{Blocks.fence, Blocks.air}), 0, 2);
		world.setBlock(i + 5, j + 12, k + 3, Blocks.air);
		world.setBlock(i + 5, j + 14, k + 2, StructureGenHelper.cobbleMossyOrAir(rand), 0, 2);
		world.setBlock(i + 5, j + 14, k + 3, StructureGenHelper.cobbleMossyOrAir(rand), 0, 2);
		world.setBlock(i + 5, j + 14, k + 4, StructureGenHelper.cobbleMossyOrAir(rand), 0, 2);
		world.setBlock(i + 5, j + 15, k + 2, StructureGenHelper.cobbleMossyOrAir(rand), 0, 2);
		world.setBlock(i + 5, j + 15, k + 3, StructureGenHelper.cobbleMossyOrAir(rand), 0, 2);
		world.setBlock(i + 5, j + 15, k + 4, StructureGenHelper.cobbleMossyOrAir(rand), 0, 2);
		world.setBlock(i + 5, j + 16, k + 2, StructureGenHelper.cobbleMossyOrAir(rand), 0, 2);
		world.setBlock(i + 5, j + 16, k + 3, Blocks.air);
		world.setBlock(i + 5, j + 16, k + 4, StructureGenHelper.cobbleMossyOrAir(rand), 0, 2);
		world.setBlock(i + 6, j + 0, k + 2, StructureGenHelper.cobbleMossyOrAir(rand), 0, 2);
		world.setBlock(i + 6, j + 0, k + 3, StructureGenHelper.cobbleMossyOrAir(rand), 0, 2);
		world.setBlock(i + 6, j + 0, k + 4, StructureGenHelper.cobbleMossyOrAir(rand), 0, 2);
		world.setBlock(i + 6, j + 1, k + 2, StructureGenHelper.cobbleMossyOrAir(rand), 0, 2);
		world.setBlock(i + 6, j + 1, k + 3, StructureGenHelper.cobbleMossyOrAir(rand), 0, 2);
		world.setBlock(i + 6, j + 1, k + 4, StructureGenHelper.cobbleMossyOrAir(rand), 0, 2);
		world.setBlock(i + 6, j + 2, k + 2, StructureGenHelper.cobbleMossyOrAir(rand), 0, 2);
		world.setBlock(i + 6, j + 2, k + 3, StructureGenHelper.cobbleMossyOrAir(rand), 0, 2);
		world.setBlock(i + 6, j + 2, k + 4, StructureGenHelper.cobbleMossyOrAir(rand), 0, 2);
		world.setBlock(i + 6, j + 3, k + 2, StructureGenHelper.cobbleMossyOrAir(rand), 0, 2);
		world.setBlock(i + 6, j + 3, k + 3, StructureGenHelper.cobbleMossyOrAir(rand), 0, 2);
		world.setBlock(i + 6, j + 3, k + 4, StructureGenHelper.cobbleMossyOrAir(rand), 0, 2);
		world.setBlock(i + 6, j + 4, k + 2, StructureGenHelper.cobbleMossyOrAir(rand), 0, 2);
		world.setBlock(i + 6, j + 4, k + 3, StructureGenHelper.cobbleMossyOrAir(rand), 0, 2);
		world.setBlock(i + 6, j + 4, k + 4, StructureGenHelper.cobbleMossyOrAir(rand), 0, 2);
		world.setBlock(i + 6, j + 5, k + 2, StructureGenHelper.cobbleMossyOrAir(rand), 0, 2);
		world.setBlock(i + 6, j + 5, k + 3, StructureGenHelper.cobbleMossyOrAir(rand), 0, 2);
		world.setBlock(i + 6, j + 5, k + 4, StructureGenHelper.cobbleMossyOrAir(rand), 0, 2);
		world.setBlock(i + 6, j + 6, k + 2, StructureGenHelper.cobbleMossyOrAir(rand), 0, 2);
		world.setBlock(i + 6, j + 6, k + 3, StructureGenHelper.cobbleMossyOrAir(rand), 0, 2);
		world.setBlock(i + 6, j + 6, k + 4, StructureGenHelper.cobbleMossyOrAir(rand), 0, 2);
		world.setBlock(i + 6, j + 10, k + 2, Blocks.air);
		world.setBlock(i + 6, j + 10, k + 3, BlockIllusionary.instance, 0, 2);
		world.setBlock(i + 6, j + 10, k + 4, Blocks.air);
		world.setBlock(i + 6, j + 11, k + 2, StructureGenHelper.randomBlock(rand, new Block[]{Blocks.fence, Blocks.air}), 0, 2);
		world.setBlock(i + 6, j + 11, k + 3, Blocks.air);
		world.setBlock(i + 6, j + 11, k + 4, StructureGenHelper.randomBlock(rand, new Block[]{Blocks.fence, Blocks.air}), 0, 2);
		world.setBlock(i + 6, j + 12, k + 3, Blocks.air);
		world.setBlock(i + 7, j + 10, k + 2, Blocks.air);
		world.setBlock(i + 7, j + 10, k + 3, BlockIllusionary.instance, 0, 2);
		world.setBlock(i + 7, j + 10, k + 4, Blocks.air);
		world.setBlock(i + 7, j + 11, k + 2, StructureGenHelper.randomBlock(rand, new Block[]{Blocks.fence, Blocks.air}), 0, 2);
		world.setBlock(i + 7, j + 11, k + 3, Blocks.air);
		world.setBlock(i + 7, j + 11, k + 4, StructureGenHelper.randomBlock(rand, new Block[]{Blocks.fence, Blocks.air}), 0, 2);
		world.setBlock(i + 7, j + 12, k + 0, Blocks.air);
		world.setBlock(i + 7, j + 12, k + 1, Blocks.air);
		world.setBlock(i + 7, j + 12, k + 2, Blocks.air);
		world.setBlock(i + 7, j + 12, k + 3, Blocks.air);
		world.setBlock(i + 7, j + 12, k + 4, Blocks.air);
		world.setBlock(i + 7, j + 12, k + 5, Blocks.air);
		world.setBlock(i + 8, j + 8, k + 1, Blocks.air);
		world.setBlock(i + 8, j + 8, k + 2, Blocks.air);
		world.setBlock(i + 8, j + 8, k + 3, Blocks.air);
		world.setBlock(i + 8, j + 8, k + 4, Blocks.air);
		world.setBlock(i + 8, j + 9, k + 1, Blocks.air);
		world.setBlock(i + 8, j + 9, k + 2, Blocks.air);
		world.setBlock(i + 8, j + 9, k + 3, Blocks.air);
		world.setBlock(i + 8, j + 9, k + 4, Blocks.air);
		world.setBlock(i + 8, j + 10, k + 0, Blocks.air);
		world.setBlock(i + 8, j + 10, k + 1, Blocks.air);
		world.setBlock(i + 8, j + 10, k + 2, Blocks.air);
		world.setBlock(i + 8, j + 10, k + 3, BlockIllusionary.instance, 0, 2);
		world.setBlock(i + 8, j + 10, k + 4, Blocks.air);
		world.setBlock(i + 8, j + 10, k + 5, Blocks.air);
		world.setBlock(i + 8, j + 11, k + 0, Blocks.air);
		world.setBlock(i + 8, j + 11, k + 1, Blocks.air);
		world.setBlock(i + 8, j + 11, k + 2, StructureGenHelper.cobbleMossyOrAir(rand), 0, 2);
		world.setBlock(i + 8, j + 11, k + 3, Blocks.air);
		world.setBlock(i + 8, j + 11, k + 4, StructureGenHelper.randomBlock(rand, new Block[]{Blocks.fence, Blocks.air}), 0, 2);
		world.setBlock(i + 8, j + 11, k + 5, Blocks.air);
		world.setBlock(i + 8, j + 12, k + 0, Blocks.air);
		world.setBlock(i + 8, j + 12, k + 1, Blocks.air);
		world.setBlock(i + 8, j + 12, k + 2, StructureGenHelper.cobbleMossyOrAir(rand), 0, 2);
		world.setBlock(i + 8, j + 12, k + 3, Blocks.air);
		world.setBlock(i + 8, j + 12, k + 4, Blocks.air);
		world.setBlock(i + 8, j + 12, k + 5, Blocks.air);
		world.setBlock(i + 8, j + 13, k + 2, StructureGenHelper.cobbleMossyOrAir(rand), 0, 2);
		world.setBlock(i + 8, j + 13, k + 3, StructureGenHelper.cobbleMossyOrAir(rand), 0, 2);
		world.setBlock(i + 8, j + 14, k + 1, StructureGenHelper.randomBlock(rand, new Block[]{Blocks.oak_stairs, Blocks.air}), 2, 2);
		world.setBlock(i + 8, j + 14, k + 2, StructureGenHelper.randomBlock(rand, new Block[]{Blocks.oak_stairs, Blocks.air}), 0, 2);
		world.setBlock(i + 8, j + 14, k + 3, StructureGenHelper.randomBlock(rand, new Block[]{Blocks.oak_stairs, Blocks.air}), 0, 2);
		world.setBlock(i + 8, j + 14, k + 4, StructureGenHelper.randomBlock(rand, new Block[]{Blocks.oak_stairs, Blocks.air}), 0, 2);
		world.setBlock(i + 9, j + 8, k + 1, Blocks.air);
		world.setBlock(i + 9, j + 8, k + 2, Blocks.air);
		world.setBlock(i + 9, j + 8, k + 3, Blocks.air);
		world.setBlock(i + 9, j + 8, k + 4, Blocks.air);
		world.setBlock(i + 9, j + 9, k + 1, Blocks.air);
		world.setBlock(i + 9, j + 9, k + 2, StructureGenHelper.randomBlock(rand, new Block[]{Blocks.stone_stairs, Blocks.air}), 6, 2);
		world.setBlock(i + 9, j + 9, k + 3, StructureGenHelper.randomBlock(rand, new Block[]{Blocks.stone_stairs, Blocks.air}), 4, 2);
		world.setBlock(i + 9, j + 9, k + 4, Blocks.air);
		world.setBlock(i + 9, j + 10, k + 0, Blocks.air);
		world.setBlock(i + 9, j + 10, k + 1, StructureGenHelper.randomBlock(rand, new Block[]{Blocks.stone_stairs, Blocks.air}), 6, 2);
		world.setBlock(i + 9, j + 10, k + 2, StructureGenHelper.cobbleMossyOrAir(rand), 0, 2);
		world.setBlock(i + 9, j + 10, k + 3, StructureGenHelper.cobbleMossyOrAir(rand), 0, 2);
		world.setBlock(i + 9, j + 10, k + 4, StructureGenHelper.randomBlock(rand, new Block[]{Blocks.stone_stairs, Blocks.air}), 7, 2);
		world.setBlock(i + 9, j + 10, k + 5, Blocks.air);
		world.setBlock(i + 9, j + 11, k + 0, Blocks.air);
		world.setBlock(i + 9, j + 11, k + 1, StructureGenHelper.cobbleMossyOrAir(rand), 0, 2);
		world.setBlock(i + 9, j + 11, k + 2, StructureGenHelper.randomBlock(rand, new Block[]{BlockPedestal.instance, Blocks.air}), 0, 2);
		world.setBlock(i + 9, j + 11, k + 3, Blocks.air);
		world.setBlock(i + 9, j + 11, k + 4, StructureGenHelper.cobbleMossyOrAir(rand), 0, 2);
		world.setBlock(i + 9, j + 11, k + 5, Blocks.air);
		world.setBlock(i + 9, j + 12, k + 0, Blocks.air);
		world.setBlock(i + 9, j + 12, k + 1, StructureGenHelper.cobbleMossyOrAir(rand), 0, 2);
		world.setBlock(i + 9, j + 12, k + 2, Blocks.air);
		world.setBlock(i + 9, j + 12, k + 3, Blocks.air);
		world.setBlock(i + 9, j + 12, k + 4, StructureGenHelper.cobbleMossyOrAir(rand), 0, 2);
		world.setBlock(i + 9, j + 12, k + 5, Blocks.air);
		world.setBlock(i + 9, j + 13, k + 1, StructureGenHelper.cobbleMossyOrAir(rand), 0, 2);
		world.setBlock(i + 9, j + 13, k + 2, StructureGenHelper.cobbleMossyOrAir(rand), 0, 2);
		world.setBlock(i + 9, j + 13, k + 3, StructureGenHelper.cobbleMossyOrAir(rand), 0, 2);
		world.setBlock(i + 9, j + 13, k + 4, StructureGenHelper.cobbleMossyOrAir(rand), 0, 2);
		world.setBlock(i + 9, j + 14, k + 1, StructureGenHelper.randomBlock(rand, new Block[]{Blocks.oak_stairs, Blocks.air}), 2, 2);
		world.setBlock(i + 9, j + 14, k + 2, StructureGenHelper.cobbleMossyOrAir(rand), 0, 2);
		world.setBlock(i + 9, j + 14, k + 3, StructureGenHelper.cobbleMossyOrAir(rand), 0, 2);
		world.setBlock(i + 9, j + 14, k + 4, StructureGenHelper.randomBlock(rand, new Block[]{Blocks.oak_stairs, Blocks.air}), 3, 2);
		world.setBlock(i + 9, j + 15, k + 2, StructureGenHelper.randomBlock(rand, new Block[]{Blocks.oak_stairs, Blocks.air}), 2, 2);
		world.setBlock(i + 9, j + 15, k + 3, StructureGenHelper.randomBlock(rand, new Block[]{Blocks.oak_stairs, Blocks.air}), 0, 2);
		world.setBlock(i + 10, j + 8, k + 1, Blocks.air);
		world.setBlock(i + 10, j + 8, k + 2, Blocks.air);
		world.setBlock(i + 10, j + 8, k + 3, Blocks.air);
		world.setBlock(i + 10, j + 8, k + 4, Blocks.air);
		world.setBlock(i + 10, j + 9, k + 1, Blocks.air);
		world.setBlock(i + 10, j + 9, k + 2, StructureGenHelper.randomBlock(rand, new Block[]{Blocks.stone_stairs, Blocks.air}), 5, 2);
		world.setBlock(i + 10, j + 9, k + 3, StructureGenHelper.randomBlock(rand, new Block[]{Blocks.stone_stairs, Blocks.air}), 7, 2);
		world.setBlock(i + 10, j + 9, k + 4, Blocks.air);
		world.setBlock(i + 10, j + 10, k + 0, Blocks.air);
		world.setBlock(i + 10, j + 10, k + 1, StructureGenHelper.randomBlock(rand, new Block[]{Blocks.stone_stairs, Blocks.air}), 6, 2);
		world.setBlock(i + 10, j + 10, k + 2, StructureGenHelper.cobbleMossyOrAir(rand), 0, 2);
		world.setBlock(i + 10, j + 10, k + 3, StructureGenHelper.cobbleMossyOrAir(rand), 0, 2);
		world.setBlock(i + 10, j + 10, k + 4, StructureGenHelper.randomBlock(rand, new Block[]{Blocks.stone_stairs, Blocks.air}), 7, 2);
		world.setBlock(i + 10, j + 10, k + 5, Blocks.air);
		world.setBlock(i + 10, j + 11, k + 0, Blocks.air);
		world.setBlock(i + 10, j + 11, k + 1, StructureGenHelper.cobbleMossyOrAir(rand), 0, 2);
		world.setBlock(i + 10, j + 11, k + 2, Blocks.air, 10, 2);
		world.setBlock(i + 10, j + 11, k + 3, Blocks.air, 2, 2);
		world.setBlock(i + 10, j + 11, k + 4, StructureGenHelper.cobbleMossyOrAir(rand), 0, 2);
		world.setBlock(i + 10, j + 11, k + 5, Blocks.air);
		world.setBlock(i + 10, j + 12, k + 0, Blocks.air);
		world.setBlock(i + 10, j + 12, k + 1, StructureGenHelper.cobbleMossyOrAir(rand), 0, 2);
		world.setBlock(i + 10, j + 12, k + 2, Blocks.air);
		world.setBlock(i + 10, j + 12, k + 3, Blocks.air);
		world.setBlock(i + 10, j + 12, k + 4, StructureGenHelper.cobbleMossyOrAir(rand), 0, 2);
		world.setBlock(i + 10, j + 12, k + 5, Blocks.air);
		world.setBlock(i + 10, j + 13, k + 1, StructureGenHelper.cobbleMossyOrAir(rand), 0, 2);
		world.setBlock(i + 10, j + 13, k + 2, StructureGenHelper.cobbleMossyOrAir(rand), 0, 2);
		world.setBlock(i + 10, j + 13, k + 3, StructureGenHelper.cobbleMossyOrAir(rand), 0, 2);
		world.setBlock(i + 10, j + 13, k + 4, StructureGenHelper.cobbleMossyOrAir(rand), 0, 2);
		world.setBlock(i + 10, j + 14, k + 1, StructureGenHelper.randomBlock(rand, new Block[]{Blocks.oak_stairs, Blocks.air}), 2, 2);
		world.setBlock(i + 10, j + 14, k + 2, StructureGenHelper.cobbleMossyOrAir(rand), 0, 2);
		world.setBlock(i + 10, j + 14, k + 3, StructureGenHelper.cobbleMossyOrAir(rand), 0, 2);
		world.setBlock(i + 10, j + 14, k + 4, StructureGenHelper.randomBlock(rand, new Block[]{Blocks.oak_stairs, Blocks.air}), 3, 2);
		world.setBlock(i + 10, j + 15, k + 2, StructureGenHelper.randomBlock(rand, new Block[]{Blocks.oak_stairs, Blocks.air}), 1, 2);
		world.setBlock(i + 10, j + 15, k + 3, StructureGenHelper.randomBlock(rand, new Block[]{Blocks.oak_stairs, Blocks.air}), 3, 2);
		world.setBlock(i + 11, j + 8, k + 1, Blocks.air);
		world.setBlock(i + 11, j + 8, k + 2, Blocks.air);
		world.setBlock(i + 11, j + 8, k + 3, Blocks.air);
		world.setBlock(i + 11, j + 8, k + 4, Blocks.air);
		world.setBlock(i + 11, j + 9, k + 1, Blocks.air);
		world.setBlock(i + 11, j + 9, k + 2, Blocks.air);
		world.setBlock(i + 11, j + 9, k + 3, Blocks.air);
		world.setBlock(i + 11, j + 9, k + 4, Blocks.air);
		world.setBlock(i + 11, j + 10, k + 0, Blocks.air);
		world.setBlock(i + 11, j + 10, k + 1, Blocks.air);
		world.setBlock(i + 11, j + 10, k + 2, StructureGenHelper.randomBlock(rand, new Block[]{Blocks.stone_stairs, Blocks.air}), 5, 2);
		world.setBlock(i + 11, j + 10, k + 3, StructureGenHelper.randomBlock(rand, new Block[]{Blocks.stone_stairs, Blocks.air}), 5, 2);
		world.setBlock(i + 11, j + 10, k + 4, Blocks.air);
		world.setBlock(i + 11, j + 10, k + 5, Blocks.air);
		world.setBlock(i + 11, j + 11, k + 0, Blocks.air);
		world.setBlock(i + 11, j + 11, k + 1, Blocks.air);
		world.setBlock(i + 11, j + 11, k + 2, StructureGenHelper.cobbleMossyOrAir(rand), 0, 2);
		world.setBlock(i + 11, j + 11, k + 3, StructureGenHelper.cobbleMossyOrAir(rand), 0, 2);
		world.setBlock(i + 11, j + 11, k + 4, Blocks.air);
		world.setBlock(i + 11, j + 11, k + 5, Blocks.air);
		world.setBlock(i + 11, j + 12, k + 0, Blocks.air);
		world.setBlock(i + 11, j + 12, k + 1, Blocks.air);
		world.setBlock(i + 11, j + 12, k + 2, StructureGenHelper.cobbleMossyOrAir(rand), 0, 2);
		world.setBlock(i + 11, j + 12, k + 3, StructureGenHelper.cobbleMossyOrAir(rand), 0, 2);
		world.setBlock(i + 11, j + 12, k + 4, Blocks.air);
		world.setBlock(i + 11, j + 12, k + 5, Blocks.air);
		world.setBlock(i + 11, j + 13, k + 2, StructureGenHelper.cobbleMossyOrAir(rand), 0, 2);
		world.setBlock(i + 11, j + 13, k + 3, StructureGenHelper.cobbleMossyOrAir(rand), 0, 2);
		world.setBlock(i + 11, j + 14, k + 1, StructureGenHelper.randomBlock(rand, new Block[]{Blocks.oak_stairs, Blocks.air}), 1, 2);
		world.setBlock(i + 11, j + 14, k + 2, StructureGenHelper.randomBlock(rand, new Block[]{Blocks.oak_stairs, Blocks.air}), 1, 2);
		world.setBlock(i + 11, j + 14, k + 3, StructureGenHelper.randomBlock(rand, new Block[]{Blocks.oak_stairs, Blocks.air}), 1, 2);
		world.setBlock(i + 11, j + 14, k + 4, StructureGenHelper.randomBlock(rand, new Block[]{Blocks.oak_stairs, Blocks.air}), 3, 2);
		world.setBlock(i + 2, j + 3, k + 2, StructureGenHelper.randomBlock(rand, new Block[]{Blocks.ladder, Blocks.ladder, Blocks.ladder, Blocks.ladder, Blocks.ladder, Blocks.air}), 5, 2);
		world.setBlock(i + 2, j + 4, k + 2, StructureGenHelper.randomBlock(rand, new Block[]{Blocks.ladder, Blocks.ladder, Blocks.ladder, Blocks.ladder, Blocks.ladder, Blocks.air}), 5, 2);
		world.setBlock(i + 2, j + 5, k + 2, StructureGenHelper.randomBlock(rand, new Block[]{Blocks.ladder, Blocks.ladder, Blocks.ladder, Blocks.ladder, Blocks.ladder, Blocks.air}), 5, 2);
		world.setBlock(i + 2, j + 6, k + 2, StructureGenHelper.randomBlock(rand, new Block[]{Blocks.ladder, Blocks.ladder, Blocks.ladder, Blocks.ladder, Blocks.ladder, Blocks.air}), 5, 2);
		world.setBlock(i + 3, j + 3, k + 0, Blocks.air);
		world.setBlock(i + 3, j + 4, k + 0, Blocks.air);
		world.setBlockToAir(i+3, j+3, k-1);
		world.setBlockToAir(i+3, j+4, k-1);
		world.setBlock(i + 3, j + 7, k + 3, StructureGenHelper.randomBlock(rand, new Block[]{Blocks.ladder, Blocks.ladder, Blocks.ladder, Blocks.ladder, Blocks.ladder, Blocks.air}), 2, 2);
		world.setBlock(i + 3, j + 8, k + 3, StructureGenHelper.randomBlock(rand, new Block[]{Blocks.ladder, Blocks.ladder, Blocks.ladder, Blocks.ladder, Blocks.ladder, Blocks.air}), 2, 2);
		world.setBlock(i + 3, j + 9, k + 3, StructureGenHelper.randomBlock(rand, new Block[]{Blocks.ladder, Blocks.ladder, Blocks.ladder, Blocks.ladder, Blocks.ladder, Blocks.air}), 2, 2);
		world.setBlock(i + 3, j + 10, k + 3, StructureGenHelper.randomBlock(rand, new Block[]{Blocks.ladder, Blocks.ladder, Blocks.ladder, Blocks.ladder, Blocks.ladder, Blocks.air}), 2, 2);
		world.setBlock(i + 3, j + 11, k + 3, StructureGenHelper.randomBlock(rand, new Block[]{Blocks.ladder, Blocks.ladder, Blocks.ladder, Blocks.ladder, Blocks.ladder, Blocks.air}), 2, 2);
		world.setBlock(i + 3, j + 12, k + 3, StructureGenHelper.randomBlock(rand, new Block[]{Blocks.ladder, Blocks.ladder, Blocks.ladder, Blocks.ladder, Blocks.ladder, Blocks.air}), 2, 2);
		world.setBlock(i + 3, j + 13, k + 3, Blocks.air);
		TileEntity te = world.getTileEntity(i + 9, j + 11, k + 2); 
		if(te != null && te instanceof TileEntityDisplayPedestal) {
			TileEntityDisplayPedestal ted = (TileEntityDisplayPedestal)te;
			ted.setInventorySlotContents(0, ArtifactsAPI.artifacts.generateRandomArtifact());
			ted.rotation = 180;
		}
		if(rand.nextBoolean()) {
			world.setBlock(i + 3, j + 15, k + 4, Blocks.air);
		}
		else {
			world.setBlock(i + 3, j + 15, k + 4, BlockTrap.instance, 3, 2);
			TileEntityTrap tileentitychest = (TileEntityTrap)world.getTileEntity(i + 3, j + 15, k + 4);
			if (tileentitychest != null)
	        {
	            ChestGenHooks info = ChestGenHooks.getInfo(ChestGenHooks.PYRAMID_JUNGLE_CHEST);
	            WeightedRandomChestContent.generateChestContents(rand, info.getItems(rand), tileentitychest, info.getCount(rand));
	            tileentitychest.func_146019_a(new ItemStack(Items.iron_sword, 1, 245));
	        }
			world.setBlock(i + 3, j + 15, k + 3, StructureGenHelper.randomBlock(rand, new Block[]{Blocks.stone_pressure_plate, BlockArtifactsPressurePlate.camoStone}), 0, 2);
		}
		basement(world, i, j, k, rand);
		return true;
	}
	
	private static void basement(World world, int i, int j, int k, Random rand) {
		boolean noair = false;
		int y = -1;
		do {
			noair = false;
			for(int x = 0; x <= 6; x++) {
				for(int z = 0; z <= 6; z++) {
					//5,y,4
					int d = (x-3)*(x-3)+(z-3)*(z-3);
					if(d <= 10) {
						if(!world.getBlock(i+x, j+y, z+k).isOpaqueCube() || world.getBlock(i+x, j+y, z+k) == Blocks.leaves) {
							noair=true;
							world.setBlock(i+x, j+y, z+k, StructureGenHelper.cobbleMossyOrAir(rand), 0, 2);
						}
					}
				}
			}
			y--;
		} while(noair && (j+y) >= 0);
	}
}
