package com.draco18s.artifacts.worldgen;
import java.io.ByteArrayOutputStream;
import java.io.DataOutputStream;
import java.io.IOException;
import java.util.Random;

import com.draco18s.artifacts.api.ArtifactsAPI;
import com.draco18s.artifacts.block.*;
import com.draco18s.artifacts.entity.TileEntityDisplayPedestal;
import com.draco18s.artifacts.entity.TileEntityTrap;
import com.draco18s.artifacts.item.*;

import net.minecraft.block.Block;
import net.minecraft.entity.item.EntityItemFrame;
import net.minecraft.entity.item.EntityPainting;
import net.minecraft.init.Blocks;
import net.minecraft.init.Items;
import net.minecraft.item.Item;
import net.minecraft.item.ItemStack;
import net.minecraft.nbt.NBTTagCompound;
import net.minecraft.tileentity.*;
import net.minecraft.util.WeightedRandomChestContent;
import net.minecraft.world.World;
import net.minecraft.world.gen.feature.WorldGenerator;
import net.minecraftforge.common.ChestGenHooks;

public class StructureMasterTowerAncient extends WorldGenerator
{
	public StructureMasterTowerAncient() { }

	@Override
	public boolean generate(World world, Random random, int x, int y, int z) {
		for (z -= 8; y > 5 && (!world.getBlock(x, y, z).isOpaqueCube() || world.getBlock(x, y, z) == Blocks.leaves); --y)
        {
            ;
        }

        if (y <= 61)
        {
            return false;
        }
        else
        {
        	build(world, random, x-6, y-2, z-13);
        }
		return false;
	}
	
	public static boolean build(World world, Random rand, int i, int j, int k) {
		//System.out.println("Master tower at (" + i + "," + k + ")");
		world.setBlock(i + 0, j + 18, k + 9, StructureGenHelper.blockChance90p(rand, Blocks.oak_stairs), 4, 2);
		world.setBlock(i + 0, j + 18, k + 10, StructureGenHelper.blockChance90p(rand, Blocks.oak_stairs), 4, 2);
		world.setBlock(i + 0, j + 18, k + 11, StructureGenHelper.blockChance90p(rand, Blocks.oak_stairs), 4, 2);
		world.setBlock(i + 0, j + 18, k + 12, StructureGenHelper.blockChance90p(rand, Blocks.oak_stairs), 4, 2);
		world.setBlock(i + 0, j + 19, k + 9, StructureGenHelper.blockChance90p(rand, Blocks.planks), 0, 2);
		world.setBlock(i + 0, j + 19, k + 10, StructureGenHelper.blockChance90p(rand, Blocks.planks), 0, 2);
		world.setBlock(i + 0, j + 19, k + 11, StructureGenHelper.blockChance90p(rand, Blocks.planks), 0, 2);
		world.setBlock(i + 0, j + 19, k + 12, StructureGenHelper.blockChance90p(rand, Blocks.planks), 0, 2);
		world.setBlock(i + 0, j + 20, k + 9, StructureGenHelper.blockChance90p(rand, Blocks.planks), 0, 2);
		world.setBlock(i + 0, j + 20, k + 10, Blocks.air, 0, 2);
		world.setBlock(i + 0, j + 20, k + 11, Blocks.air, 0, 2);
		world.setBlock(i + 0, j + 20, k + 12, StructureGenHelper.blockChance90p(rand, Blocks.planks), 0, 2);
		world.setBlock(i + 0, j + 21, k + 9, StructureGenHelper.blockChance90p(rand, Blocks.planks), 0, 2);
		world.setBlock(i + 0, j + 21, k + 10, StructureGenHelper.blockChance90p(rand, Blocks.planks), 0, 2);
		world.setBlock(i + 0, j + 21, k + 11, StructureGenHelper.blockChance90p(rand, Blocks.planks), 0, 2);
		world.setBlock(i + 0, j + 21, k + 12, StructureGenHelper.blockChance90p(rand, Blocks.planks), 0, 2);
		world.setBlock(i + 0, j + 22, k + 9, StructureGenHelper.blockChance90p(rand, Blocks.oak_stairs), 2, 2);
		world.setBlock(i + 0, j + 22, k + 10, StructureGenHelper.blockChance90p(rand, Blocks.oak_stairs), 0, 2);
		world.setBlock(i + 0, j + 22, k + 11, StructureGenHelper.blockChance90p(rand, Blocks.oak_stairs), 0, 2);
		world.setBlock(i + 0, j + 22, k + 12, StructureGenHelper.blockChance90p(rand, Blocks.oak_stairs), 0, 2);
		world.setBlock(i + 1, j + 0, k + 6, StructureGenHelper.blockChance90p(rand, Blocks.stonebrick), StructureGenHelper.stoneBrickMetaAncient(rand), 2);
		world.setBlock(i + 1, j + 0, k + 7, StructureGenHelper.blockChance90p(rand, Blocks.stonebrick), StructureGenHelper.stoneBrickMetaAncient(rand), 2);
		world.setBlock(i + 1, j + 0, k + 8, StructureGenHelper.blockChance90p(rand, Blocks.stonebrick), StructureGenHelper.stoneBrickMetaAncient(rand), 2);
		world.setBlock(i + 1, j + 1, k + 6, StructureGenHelper.blockChance90p(rand, Blocks.stonebrick), StructureGenHelper.stoneBrickMetaAncient(rand), 2);
		world.setBlock(i + 1, j + 1, k + 7, StructureGenHelper.blockChance90p(rand, Blocks.stonebrick), StructureGenHelper.stoneBrickMetaAncient(rand), 2);
		world.setBlock(i + 1, j + 1, k + 8, StructureGenHelper.blockChance90p(rand, Blocks.stonebrick), StructureGenHelper.stoneBrickMetaAncient(rand), 2);
		world.setBlock(i + 1, j + 2, k + 6, StructureGenHelper.blockChance90p(rand, Blocks.stonebrick), StructureGenHelper.stoneBrickMetaAncient(rand), 2);
		world.setBlock(i + 1, j + 2, k + 7, StructureGenHelper.blockChance90p(rand, Blocks.stonebrick), StructureGenHelper.stoneBrickMetaAncient(rand), 2);
		world.setBlock(i + 1, j + 2, k + 8, StructureGenHelper.blockChance90p(rand, Blocks.stonebrick), StructureGenHelper.stoneBrickMetaAncient(rand), 2);
		world.setBlock(i + 1, j + 3, k + 6, StructureGenHelper.blockChance90p(rand, Blocks.stonebrick), StructureGenHelper.stoneBrickMetaAncient(rand), 2);
		world.setBlock(i + 1, j + 3, k + 7, StructureGenHelper.blockChance90p(rand, Blocks.stonebrick), StructureGenHelper.stoneBrickMetaAncient(rand), 2);
		world.setBlock(i + 1, j + 3, k + 8, StructureGenHelper.blockChance90p(rand, Blocks.stonebrick), StructureGenHelper.stoneBrickMetaAncient(rand), 2);
		world.setBlock(i + 1, j + 4, k + 6, StructureGenHelper.blockChance90p(rand, Blocks.stonebrick), StructureGenHelper.stoneBrickMetaAncient(rand), 2);
		world.setBlock(i + 1, j + 4, k + 7, Blocks.air, 0, 2);
		world.setBlock(i + 1, j + 4, k + 8, StructureGenHelper.blockChance90p(rand, Blocks.stonebrick), StructureGenHelper.stoneBrickMetaAncient(rand), 2);
		world.setBlock(i + 1, j + 5, k + 6, StructureGenHelper.blockChance90p(rand, Blocks.stonebrick), StructureGenHelper.stoneBrickMetaAncient(rand), 2);
		world.setBlock(i + 1, j + 5, k + 7, StructureGenHelper.blockChance90p(rand, Blocks.stonebrick), StructureGenHelper.stoneBrickMetaAncient(rand), 2);
		world.setBlock(i + 1, j + 5, k + 8, StructureGenHelper.blockChance90p(rand, Blocks.stonebrick), StructureGenHelper.stoneBrickMetaAncient(rand), 2);
		world.setBlock(i + 1, j + 6, k + 6, StructureGenHelper.blockChance90p(rand, Blocks.stonebrick), StructureGenHelper.stoneBrickMetaAncient(rand), 2);
		world.setBlock(i + 1, j + 6, k + 7, StructureGenHelper.blockChance90p(rand, Blocks.stonebrick), StructureGenHelper.stoneBrickMetaAncient(rand), 2);
		world.setBlock(i + 1, j + 6, k + 8, StructureGenHelper.blockChance90p(rand, Blocks.stonebrick), StructureGenHelper.stoneBrickMetaAncient(rand), 2);
		world.setBlock(i + 1, j + 7, k + 6, StructureGenHelper.blockChance90p(rand, Blocks.stonebrick), StructureGenHelper.stoneBrickMetaAncient(rand), 2);
		world.setBlock(i + 1, j + 7, k + 7, StructureGenHelper.blockChance90p(rand, Blocks.stonebrick), StructureGenHelper.stoneBrickMetaAncient(rand), 2);
		world.setBlock(i + 1, j + 7, k + 8, StructureGenHelper.blockChance90p(rand, Blocks.stonebrick), StructureGenHelper.stoneBrickMetaAncient(rand), 2);
		world.setBlock(i + 1, j + 8, k + 6, StructureGenHelper.blockChance90p(rand, Blocks.stonebrick), StructureGenHelper.stoneBrickMetaAncient(rand), 2);
		world.setBlock(i + 1, j + 8, k + 7, StructureGenHelper.blockChance90p(rand, Blocks.stonebrick), StructureGenHelper.stoneBrickMetaAncient(rand), 2);
		world.setBlock(i + 1, j + 8, k + 8, StructureGenHelper.blockChance90p(rand, Blocks.stonebrick), StructureGenHelper.stoneBrickMetaAncient(rand), 2);
		world.setBlock(i + 1, j + 9, k + 6, StructureGenHelper.blockChance90p(rand, Blocks.stonebrick), StructureGenHelper.stoneBrickMetaAncient(rand), 2);
		world.setBlock(i + 1, j + 9, k + 7, StructureGenHelper.blockChance90p(rand, Blocks.stonebrick), StructureGenHelper.stoneBrickMetaAncient(rand), 2);
		world.setBlock(i + 1, j + 9, k + 8, StructureGenHelper.blockChance90p(rand, Blocks.stonebrick), StructureGenHelper.stoneBrickMetaAncient(rand), 2);
		world.setBlock(i + 1, j + 10, k + 7, StructureGenHelper.blockChance90p(rand, Blocks.stonebrick), StructureGenHelper.stoneBrickMetaAncient(rand), 2);
		world.setBlock(i + 1, j + 11, k + 2, StructureGenHelper.blockChance90p(rand, Blocks.oak_stairs), 4, 2);
		world.setBlock(i + 1, j + 11, k + 3, StructureGenHelper.blockChance90p(rand, Blocks.oak_stairs), 4, 2);
		world.setBlock(i + 1, j + 11, k + 4, StructureGenHelper.blockChance90p(rand, Blocks.oak_stairs), 4, 2);
		world.setBlock(i + 1, j + 11, k + 7, StructureGenHelper.blockChance90p(rand, Blocks.stone_brick_stairs), 0, 2);
		world.setBlock(i + 1, j + 12, k + 2, StructureGenHelper.blockChance90p(rand, Blocks.planks), 0, 2);
		world.setBlock(i + 1, j + 12, k + 3, StructureGenHelper.blockChance90p(rand, Blocks.planks), 0, 2);
		world.setBlock(i + 1, j + 12, k + 4, StructureGenHelper.blockChance90p(rand, Blocks.planks), 0, 2);
		world.setBlock(i + 1, j + 13, k + 2, StructureGenHelper.blockChance90p(rand, Blocks.planks), 0, 2);
		world.setBlock(i + 1, j + 13, k + 3, StructureGenHelper.blockChance90p(rand, Blocks.planks), 0, 2);
		world.setBlock(i + 1, j + 13, k + 4, StructureGenHelper.blockChance90p(rand, Blocks.planks), 0, 2);
		world.setBlock(i + 1, j + 14, k + 2, StructureGenHelper.blockChance90p(rand, Blocks.planks), 0, 2);
		world.setBlock(i + 1, j + 14, k + 3, StructureGenHelper.blockChance90p(rand, Blocks.planks), 0, 2);
		world.setBlock(i + 1, j + 14, k + 4, StructureGenHelper.blockChance90p(rand, Blocks.planks), 0, 2);
		world.setBlock(i + 1, j + 15, k + 1, StructureGenHelper.blockChance90p(rand, Blocks.oak_stairs), 2, 2);
		world.setBlock(i + 1, j + 15, k + 2, StructureGenHelper.blockChance90p(rand, Blocks.oak_stairs), 0, 2);
		world.setBlock(i + 1, j + 15, k + 3, StructureGenHelper.blockChance90p(rand, Blocks.oak_stairs), 0, 2);
		world.setBlock(i + 1, j + 15, k + 4, StructureGenHelper.blockChance90p(rand, Blocks.oak_stairs), 0, 2);
		world.setBlock(i + 1, j + 15, k + 5, StructureGenHelper.blockChance90p(rand, Blocks.oak_stairs), 3, 2);
		world.setBlock(i + 1, j + 17, k + 9, StructureGenHelper.blockChance90p(rand, Blocks.oak_stairs), 4, 2);
		world.setBlock(i + 1, j + 17, k + 10, StructureGenHelper.blockChance90p(rand, Blocks.oak_stairs), 4, 2);
		world.setBlock(i + 1, j + 17, k + 11, StructureGenHelper.blockChance90p(rand, Blocks.oak_stairs), 4, 2);
		world.setBlock(i + 1, j + 17, k + 12, StructureGenHelper.blockChance90p(rand, Blocks.oak_stairs), 4, 2);
		world.setBlock(i + 1, j + 18, k + 8, StructureGenHelper.blockChance90p(rand, Blocks.oak_stairs), 6, 2);
		world.setBlock(i + 1, j + 18, k + 9, StructureGenHelper.blockChance90p(rand, Blocks.planks), 0, 2);
		world.setBlock(i + 1, j + 18, k + 10, StructureGenHelper.blockChance90p(rand, Blocks.planks), 0, 2);
		world.setBlock(i + 1, j + 18, k + 11, StructureGenHelper.blockChance90p(rand, Blocks.planks), 0, 2);
		world.setBlock(i + 1, j + 18, k + 12, StructureGenHelper.blockChance90p(rand, Blocks.planks), 0, 2);
		world.setBlock(i + 1, j + 18, k + 13, StructureGenHelper.blockChance90p(rand, Blocks.oak_stairs), 7, 2);
		world.setBlock(i + 1, j + 19, k + 8, StructureGenHelper.blockChance90p(rand, Blocks.planks), 0, 2);
		world.setBlock(i + 1, j + 19, k + 9, Blocks.air);
		world.setBlock(i + 1, j + 19, k + 10, Blocks.air);
		world.setBlock(i + 1, j + 19, k + 11, Blocks.air);
		world.setBlock(i + 1, j + 19, k + 12, Blocks.air);
		world.setBlock(i + 1, j + 19, k + 13, StructureGenHelper.blockChance90p(rand, Blocks.planks), 0, 2);
		world.setBlock(i + 1, j + 20, k + 8, StructureGenHelper.blockChance90p(rand, Blocks.planks), 0, 2);
		world.setBlock(i + 1, j + 20, k + 9, Blocks.air);
		world.setBlock(i + 1, j + 20, k + 10, Blocks.air);
		world.setBlock(i + 1, j + 20, k + 11, Blocks.air);
		world.setBlock(i + 1, j + 20, k + 12, Blocks.air);
		world.setBlock(i + 1, j + 20, k + 13, StructureGenHelper.blockChance90p(rand, Blocks.planks), 0, 2);
		world.setBlock(i + 1, j + 21, k + 8, StructureGenHelper.blockChance90p(rand, Blocks.planks), 0, 2);
		world.setBlock(i + 1, j + 21, k + 9, StructureGenHelper.blockChance90p(rand, Blocks.planks), 0, 2);
		world.setBlock(i + 1, j + 21, k + 10, StructureGenHelper.blockChance90p(rand, Blocks.planks), 0, 2);
		world.setBlock(i + 1, j + 21, k + 11, StructureGenHelper.blockChance90p(rand, Blocks.planks), 0, 2);
		world.setBlock(i + 1, j + 21, k + 12, StructureGenHelper.blockChance90p(rand, Blocks.planks), 0, 2);
		world.setBlock(i + 1, j + 21, k + 13, StructureGenHelper.blockChance90p(rand, Blocks.planks), 0, 2);
		world.setBlock(i + 1, j + 22, k + 8, StructureGenHelper.blockChance90p(rand, Blocks.oak_stairs), 2, 2);
		world.setBlock(i + 1, j + 22, k + 9, StructureGenHelper.blockChance90p(rand, Blocks.oak_stairs), 0, 2);
		world.setBlock(i + 1, j + 22, k + 10, StructureGenHelper.blockChance90p(rand, Blocks.planks), 0, 2);
		world.setBlock(i + 1, j + 22, k + 11, StructureGenHelper.blockChance90p(rand, Blocks.planks), 0, 2);
		world.setBlock(i + 1, j + 22, k + 12, StructureGenHelper.blockChance90p(rand, Blocks.oak_stairs), 3, 2);
		world.setBlock(i + 1, j + 22, k + 13, StructureGenHelper.blockChance90p(rand, Blocks.oak_stairs), 0, 2);
		world.setBlock(i + 1, j + 23, k + 10, StructureGenHelper.blockChance90p(rand, Blocks.wooden_slab), 0, 2);
		world.setBlock(i + 1, j + 23, k + 11, StructureGenHelper.blockChance90p(rand, Blocks.oak_stairs), 0, 2);
		world.setBlock(i + 2, j + 0, k + 4, StructureGenHelper.blockChance90p(rand, Blocks.stonebrick), StructureGenHelper.stoneBrickMetaAncient(rand), 2);
		world.setBlock(i + 2, j + 0, k + 5, StructureGenHelper.blockChance90p(rand, Blocks.stonebrick), StructureGenHelper.stoneBrickMetaAncient(rand), 2);
		world.setBlock(i + 2, j + 0, k + 6, StructureGenHelper.blockChance90p(rand, Blocks.stonebrick), StructureGenHelper.stoneBrickMetaAncient(rand), 2);
		world.setBlock(i + 2, j + 0, k + 7, StructureGenHelper.blockChance90p(rand, Blocks.stonebrick), StructureGenHelper.stoneBrickMetaAncient(rand), 2);
		world.setBlock(i + 2, j + 0, k + 8, StructureGenHelper.blockChance90p(rand, Blocks.stonebrick), StructureGenHelper.stoneBrickMetaAncient(rand), 2);
		world.setBlock(i + 2, j + 0, k + 9, StructureGenHelper.blockChance90p(rand, Blocks.stonebrick), StructureGenHelper.stoneBrickMetaAncient(rand), 2);
		world.setBlock(i + 2, j + 0, k + 10, StructureGenHelper.blockChance90p(rand, Blocks.stonebrick), StructureGenHelper.stoneBrickMetaAncient(rand), 2);
		world.setBlock(i + 2, j + 1, k + 4, StructureGenHelper.blockChance90p(rand, Blocks.stonebrick), StructureGenHelper.stoneBrickMetaAncient(rand), 2);
		world.setBlock(i + 2, j + 1, k + 5, StructureGenHelper.blockChance90p(rand, Blocks.stonebrick), StructureGenHelper.stoneBrickMetaAncient(rand), 2);
		world.setBlock(i + 2, j + 1, k + 6, StructureGenHelper.blockChance90p(rand, Blocks.stonebrick), StructureGenHelper.stoneBrickMetaAncient(rand), 2);
		world.setBlock(i + 2, j + 1, k + 7, StructureGenHelper.blockChance90p(rand, Blocks.stonebrick), StructureGenHelper.stoneBrickMetaAncient(rand), 2);
		world.setBlock(i + 2, j + 1, k + 8, StructureGenHelper.blockChance90p(rand, Blocks.stonebrick), StructureGenHelper.stoneBrickMetaAncient(rand), 2);
		world.setBlock(i + 2, j + 1, k + 9, StructureGenHelper.blockChance90p(rand, Blocks.stonebrick), StructureGenHelper.stoneBrickMetaAncient(rand), 2);
		world.setBlock(i + 2, j + 1, k + 10, StructureGenHelper.blockChance90p(rand, Blocks.stonebrick), StructureGenHelper.stoneBrickMetaAncient(rand), 2);
		world.setBlock(i + 2, j + 2, k + 4, StructureGenHelper.blockChance90p(rand, Blocks.stonebrick), StructureGenHelper.stoneBrickMetaAncient(rand), 2);
		world.setBlock(i + 2, j + 2, k + 5, StructureGenHelper.blockChance90p(rand, Blocks.stonebrick), StructureGenHelper.stoneBrickMetaAncient(rand), 2);
		world.setBlock(i + 2, j + 2, k + 6, StructureGenHelper.blockChance90p(rand, Blocks.stonebrick), StructureGenHelper.stoneBrickMetaAncient(rand), 2);
		world.setBlock(i + 2, j + 2, k + 7, StructureGenHelper.blockChance90p(rand, Blocks.stonebrick), StructureGenHelper.stoneBrickMetaAncient(rand), 2);
		world.setBlock(i + 2, j + 2, k + 8, StructureGenHelper.blockChance90p(rand, Blocks.stonebrick), StructureGenHelper.stoneBrickMetaAncient(rand), 2);
		world.setBlock(i + 2, j + 2, k + 9, StructureGenHelper.blockChance90p(rand, Blocks.stonebrick), StructureGenHelper.stoneBrickMetaAncient(rand), 2);
		world.setBlock(i + 2, j + 2, k + 10, StructureGenHelper.blockChance90p(rand, Blocks.stonebrick), StructureGenHelper.stoneBrickMetaAncient(rand), 2);
		world.setBlock(i + 2, j + 3, k + 4, StructureGenHelper.blockChance90p(rand, Blocks.stonebrick), StructureGenHelper.stoneBrickMetaAncient(rand), 2);
		world.setBlock(i + 2, j + 3, k + 5, StructureGenHelper.blockChance90p(rand, Blocks.stonebrick), StructureGenHelper.stoneBrickMetaAncient(rand), 2);
		world.setBlock(i + 2, j + 3, k + 7, Blocks.air);
		world.setBlock(i + 2, j + 3, k + 8, StructureGenHelper.blockChance90p(rand, Blocks.stonebrick), StructureGenHelper.stoneBrickMetaAncient(rand), 2);
		world.setBlock(i + 2, j + 3, k + 9, StructureGenHelper.blockChance90p(rand, Blocks.stonebrick), StructureGenHelper.stoneBrickMetaAncient(rand), 2);
		world.setBlock(i + 2, j + 3, k + 10, StructureGenHelper.blockChance90p(rand, Blocks.stonebrick), StructureGenHelper.stoneBrickMetaAncient(rand), 2);
		world.setBlock(i + 2, j + 4, k + 4, StructureGenHelper.blockChance90p(rand, Blocks.stonebrick), StructureGenHelper.stoneBrickMetaAncient(rand), 2);
		world.setBlock(i + 2, j + 4, k + 5, StructureGenHelper.blockChance90p(rand, Blocks.stonebrick), StructureGenHelper.stoneBrickMetaAncient(rand), 2);
		world.setBlock(i + 2, j + 4, k + 7, Blocks.air);
		world.setBlock(i + 2, j + 4, k + 8, StructureGenHelper.blockChance90p(rand, Blocks.stonebrick), StructureGenHelper.stoneBrickMetaAncient(rand), 2);
		world.setBlock(i + 2, j + 4, k + 9, StructureGenHelper.blockChance90p(rand, Blocks.stonebrick), StructureGenHelper.stoneBrickMetaAncient(rand), 2);
		world.setBlock(i + 2, j + 4, k + 10, StructureGenHelper.blockChance90p(rand, Blocks.stonebrick), StructureGenHelper.stoneBrickMetaAncient(rand), 2);
		world.setBlock(i + 2, j + 5, k + 4, StructureGenHelper.blockChance90p(rand, Blocks.stonebrick), StructureGenHelper.stoneBrickMetaAncient(rand), 2);
		world.setBlock(i + 2, j + 5, k + 5, StructureGenHelper.blockChance90p(rand, Blocks.stonebrick), StructureGenHelper.stoneBrickMetaAncient(rand), 2);
		world.setBlock(i + 2, j + 5, k + 7, Blocks.air);
		world.setBlock(i + 2, j + 5, k + 8, StructureGenHelper.blockChance90p(rand, Blocks.stonebrick), StructureGenHelper.stoneBrickMetaAncient(rand), 2);
		world.setBlock(i + 2, j + 5, k + 9, StructureGenHelper.blockChance90p(rand, Blocks.stonebrick), StructureGenHelper.stoneBrickMetaAncient(rand), 2);
		world.setBlock(i + 2, j + 5, k + 10, StructureGenHelper.blockChance90p(rand, Blocks.stonebrick), StructureGenHelper.stoneBrickMetaAncient(rand), 2);
		world.setBlock(i + 2, j + 6, k + 4, StructureGenHelper.blockChance90p(rand, Blocks.stonebrick), StructureGenHelper.stoneBrickMetaAncient(rand), 2);
		world.setBlock(i + 2, j + 6, k + 5, StructureGenHelper.blockChance90p(rand, Blocks.stonebrick), StructureGenHelper.stoneBrickMetaAncient(rand), 2);
		world.setBlock(i + 2, j + 6, k + 7, Blocks.air);
		world.setBlock(i + 2, j + 6, k + 8, StructureGenHelper.blockChance90p(rand, Blocks.stonebrick), StructureGenHelper.stoneBrickMetaAncient(rand), 2);
		world.setBlock(i + 2, j + 6, k + 9, StructureGenHelper.blockChance90p(rand, Blocks.stonebrick), StructureGenHelper.stoneBrickMetaAncient(rand), 2);
		world.setBlock(i + 2, j + 6, k + 10, StructureGenHelper.blockChance90p(rand, Blocks.stonebrick), StructureGenHelper.stoneBrickMetaAncient(rand), 2);
		world.setBlock(i + 2, j + 7, k + 4, StructureGenHelper.blockChance90p(rand, Blocks.stonebrick), StructureGenHelper.stoneBrickMetaAncient(rand), 2);
		world.setBlock(i + 2, j + 7, k + 5, StructureGenHelper.blockChance90p(rand, Blocks.stonebrick), StructureGenHelper.stoneBrickMetaAncient(rand), 2);
		world.setBlock(i + 2, j + 7, k + 7, StructureGenHelper.blockChance90p(rand, Blocks.stonebrick), StructureGenHelper.stoneBrickMetaAncient(rand), 2);
		world.setBlock(i + 2, j + 7, k + 8, StructureGenHelper.blockChance90p(rand, Blocks.stonebrick), StructureGenHelper.stoneBrickMetaAncient(rand), 2);
		world.setBlock(i + 2, j + 7, k + 9, StructureGenHelper.blockChance90p(rand, Blocks.stonebrick), StructureGenHelper.stoneBrickMetaAncient(rand), 2);
		world.setBlock(i + 2, j + 7, k + 10, StructureGenHelper.blockChance90p(rand, Blocks.stonebrick), StructureGenHelper.stoneBrickMetaAncient(rand), 2);
		world.setBlock(i + 2, j + 8, k + 5, StructureGenHelper.blockChance90p(rand, Blocks.stonebrick), StructureGenHelper.stoneBrickMetaAncient(rand), 2);
		world.setBlock(i + 2, j + 8, k + 6, Blocks.air);
		world.setBlock(i + 2, j + 8, k + 7, StructureGenHelper.blockChance90p(rand, Blocks.stonebrick), StructureGenHelper.stoneBrickMetaAncient(rand), 2);
		world.setBlock(i + 2, j + 8, k + 8, StructureGenHelper.blockChance90p(rand, Blocks.stonebrick), StructureGenHelper.stoneBrickMetaAncient(rand), 2);
		world.setBlock(i + 2, j + 8, k + 9, StructureGenHelper.blockChance90p(rand, Blocks.stonebrick), StructureGenHelper.stoneBrickMetaAncient(rand), 2);
		world.setBlock(i + 2, j + 9, k + 5, StructureGenHelper.blockChance90p(rand, Blocks.stonebrick), StructureGenHelper.stoneBrickMetaAncient(rand), 2);
		world.setBlock(i + 2, j + 9, k + 6, Blocks.air);
		world.setBlock(i + 2, j + 9, k + 7, StructureGenHelper.randomBlock(rand, new Block[]{Blocks.glowstone, Blocks.air}), 0, 2);
		world.setBlock(i + 2, j + 9, k + 8, StructureGenHelper.blockChance90p(rand, Blocks.stonebrick), StructureGenHelper.stoneBrickMetaAncient(rand), 2);
		world.setBlock(i + 2, j + 9, k + 9, StructureGenHelper.blockChance90p(rand, Blocks.stonebrick), StructureGenHelper.stoneBrickMetaAncient(rand), 2);
		world.setBlock(i + 2, j + 10, k + 2, StructureGenHelper.blockChance90p(rand, Blocks.oak_stairs), 6, 2);
		world.setBlock(i + 2, j + 10, k + 3, StructureGenHelper.blockChance90p(rand, Blocks.oak_stairs), 4, 2);
		world.setBlock(i + 2, j + 10, k + 4, StructureGenHelper.blockChance90p(rand, Blocks.oak_stairs), 4, 2);
		world.setBlock(i + 2, j + 10, k + 5, StructureGenHelper.blockChance90p(rand, Blocks.stonebrick), StructureGenHelper.stoneBrickMetaAncient(rand), 2);
		world.setBlock(i + 2, j + 10, k + 6, StructureGenHelper.blockChance90p(rand, Blocks.stonebrick), StructureGenHelper.stoneBrickMetaAncient(rand), 2);
		world.setBlock(i + 2, j + 10, k + 7, StructureGenHelper.blockChance90p(rand, Blocks.stonebrick), StructureGenHelper.stoneBrickMetaAncient(rand), 2);
		world.setBlock(i + 2, j + 10, k + 8, StructureGenHelper.blockChance90p(rand, Blocks.stonebrick), StructureGenHelper.stoneBrickMetaAncient(rand), 2);
		world.setBlock(i + 2, j + 10, k + 9, StructureGenHelper.blockChance90p(rand, Blocks.stonebrick), StructureGenHelper.stoneBrickMetaAncient(rand), 2);
		world.setBlock(i + 2, j + 11, k + 1, StructureGenHelper.blockChance90p(rand, Blocks.oak_stairs), 6, 2);
		world.setBlock(i + 2, j + 11, k + 2, StructureGenHelper.blockChance90p(rand, Blocks.planks), 0, 2);
		world.setBlock(i + 2, j + 11, k + 3, StructureGenHelper.blockChance90p(rand, Blocks.planks), 0, 2);
		world.setBlock(i + 2, j + 11, k + 4, StructureGenHelper.blockChance90p(rand, Blocks.planks), 0, 2);
		world.setBlock(i + 2, j + 11, k + 5, StructureGenHelper.blockChance90p(rand, Blocks.stonebrick), StructureGenHelper.stoneBrickMetaAncient(rand), 2);
		world.setBlock(i + 2, j + 11, k + 6, StructureGenHelper.blockChance90p(rand, Blocks.stonebrick), StructureGenHelper.stoneBrickMetaAncient(rand), 2);
		world.setBlock(i + 2, j + 11, k + 7, StructureGenHelper.blockChance90p(rand, Blocks.stonebrick), StructureGenHelper.stoneBrickMetaAncient(rand), 2);
		world.setBlock(i + 2, j + 11, k + 8, StructureGenHelper.blockChance90p(rand, Blocks.stonebrick), StructureGenHelper.stoneBrickMetaAncient(rand), 2);
		world.setBlock(i + 2, j + 11, k + 9, StructureGenHelper.blockChance90p(rand, Blocks.stonebrick), StructureGenHelper.stoneBrickMetaAncient(rand), 2);
		world.setBlock(i + 2, j + 12, k + 1, StructureGenHelper.blockChance90p(rand, Blocks.planks), 0, 2);
		world.setBlock(i + 2, j + 12, k + 2, StructureGenHelper.blockChance90p(rand, Blocks.planks), 0, 2);
		world.setBlock(i + 2, j + 12, k + 3, StructureGenHelper.randomBlock(rand, new Block[]{BlockPedestal.instance, Blocks.air}), 0, 2);
		TileEntityDisplayPedestal tedd;
		TileEntity te = world.getTileEntity(i + 2, j + 12, k + 3); 
		if(te != null && te instanceof TileEntityDisplayPedestal) {
			tedd = (TileEntityDisplayPedestal)te;
			tedd.setInventorySlotContents(0, ArtifactsAPI.artifacts.generateRandomArtifact());
			tedd.rotation = 90;
		}
		world.setBlock(i + 2, j + 12, k + 4, Blocks.air);
		world.setBlock(i + 2, j + 12, k + 5, StructureGenHelper.blockChance90p(rand, Blocks.planks), 0, 2);
		world.setBlock(i + 2, j + 12, k + 6, StructureGenHelper.blockChance90p(rand, Blocks.stonebrick), StructureGenHelper.stoneBrickMetaAncient(rand), 2);
		world.setBlock(i + 2, j + 12, k + 7, StructureGenHelper.blockChance90p(rand, Blocks.stonebrick), StructureGenHelper.stoneBrickMetaAncient(rand), 2);
		world.setBlock(i + 2, j + 12, k + 8, StructureGenHelper.blockChance90p(rand, Blocks.stonebrick), StructureGenHelper.stoneBrickMetaAncient(rand), 2);
		world.setBlock(i + 2, j + 13, k + 1, StructureGenHelper.blockChance90p(rand, Blocks.planks), 0, 2);
		world.setBlock(i + 2, j + 13, k + 2, StructureGenHelper.blockChance90p(rand, Blocks.planks), 0, 2);
		world.setBlock(i + 2, j + 13, k + 3, Blocks.air);
		world.setBlock(i + 2, j + 13, k + 4, Blocks.air);
		world.setBlock(i + 2, j + 13, k + 5, StructureGenHelper.blockChance90p(rand, Blocks.planks), 0, 2);
		world.setBlock(i + 2, j + 13, k + 6, StructureGenHelper.blockChance90p(rand, Blocks.stonebrick), StructureGenHelper.stoneBrickMetaAncient(rand), 2);
		world.setBlock(i + 2, j + 13, k + 7, StructureGenHelper.blockChance90p(rand, Blocks.stonebrick), StructureGenHelper.stoneBrickMetaAncient(rand), 2);
		world.setBlock(i + 2, j + 13, k + 8, StructureGenHelper.blockChance90p(rand, Blocks.stonebrick), StructureGenHelper.stoneBrickMetaAncient(rand), 2);
		world.setBlock(i + 2, j + 14, k + 1, StructureGenHelper.blockChance90p(rand, Blocks.planks), 0, 2);
		world.setBlock(i + 2, j + 14, k + 2, StructureGenHelper.blockChance90p(rand, Blocks.planks), 0, 2);
		world.setBlock(i + 2, j + 14, k + 3, Blocks.air);
		world.setBlock(i + 2, j + 14, k + 4, Blocks.air);
		world.setBlock(i + 2, j + 14, k + 5, StructureGenHelper.blockChance90p(rand, Blocks.planks), 0, 2);
		world.setBlock(i + 2, j + 14, k + 6, StructureGenHelper.blockChance90p(rand, Blocks.stonebrick), StructureGenHelper.stoneBrickMetaAncient(rand), 2);
		world.setBlock(i + 2, j + 14, k + 7, StructureGenHelper.blockChance90p(rand, Blocks.stonebrick), StructureGenHelper.stoneBrickMetaAncient(rand), 2);
		world.setBlock(i + 2, j + 14, k + 8, StructureGenHelper.blockChance90p(rand, Blocks.stonebrick), StructureGenHelper.stoneBrickMetaAncient(rand), 2);
		world.setBlock(i + 2, j + 15, k + 0, StructureGenHelper.blockChance90p(rand, Blocks.oak_stairs), 0, 2);
		world.setBlock(i + 2, j + 15, k + 1, StructureGenHelper.blockChance90p(rand, Blocks.oak_stairs), 0, 2);
		world.setBlock(i + 2, j + 15, k + 2, StructureGenHelper.blockChance90p(rand, Blocks.planks), 0, 2);
		world.setBlock(i + 2, j + 15, k + 3, StructureGenHelper.blockChance90p(rand, Blocks.planks), 0, 2);
		world.setBlock(i + 2, j + 15, k + 4, StructureGenHelper.blockChance90p(rand, Blocks.planks), 0, 2);
		world.setBlock(i + 2, j + 15, k + 5, StructureGenHelper.blockChance90p(rand, Blocks.oak_stairs), 3, 2);
		world.setBlock(i + 2, j + 15, k + 7, StructureGenHelper.blockChance90p(rand, Blocks.stonebrick), StructureGenHelper.stoneBrickMetaAncient(rand), 2);
		world.setBlock(i + 2, j + 16, k + 2, StructureGenHelper.blockChance90p(rand, Blocks.oak_stairs), 2, 2);
		world.setBlock(i + 2, j + 16, k + 3, StructureGenHelper.blockChance90p(rand, Blocks.oak_stairs), 0, 2);
		world.setBlock(i + 2, j + 16, k + 4, StructureGenHelper.blockChance90p(rand, Blocks.oak_stairs), 0, 2);
		world.setBlock(i + 2, j + 16, k + 7, StructureGenHelper.blockChance90p(rand, Blocks.stone_brick_stairs), 0, 2);
		world.setBlock(i + 2, j + 17, k + 9, StructureGenHelper.blockChance90p(rand, Blocks.oak_stairs), 6, 2);
		world.setBlock(i + 2, j + 17, k + 10, StructureGenHelper.blockChance90p(rand, Blocks.planks), 0, 2);
		world.setBlock(i + 2, j + 17, k + 11, StructureGenHelper.blockChance90p(rand, Blocks.planks), 0, 2);
		world.setBlock(i + 2, j + 17, k + 12, StructureGenHelper.blockChance90p(rand, Blocks.oak_stairs), 7, 2);
		world.setBlock(i + 2, j + 18, k + 8, StructureGenHelper.blockChance90p(rand, Blocks.oak_stairs), 6, 2);
		world.setBlock(i + 2, j + 18, k + 9, StructureGenHelper.blockChance90p(rand, Blocks.planks), 0, 2);
		world.setBlock(i + 2, j + 18, k + 10, StructureGenHelper.blockChance90p(rand, Blocks.planks), 0, 2);
		world.setBlock(i + 2, j + 18, k + 11, StructureGenHelper.blockChance90p(rand, Blocks.planks), 0, 2);
		world.setBlock(i + 2, j + 18, k + 12, StructureGenHelper.blockChance90p(rand, Blocks.planks), 0, 2);
		world.setBlock(i + 2, j + 18, k + 13, StructureGenHelper.blockChance90p(rand, Blocks.oak_stairs), 7, 2);
		world.setBlock(i + 2, j + 19, k + 8, StructureGenHelper.blockChance90p(rand, Blocks.planks), 0, 2);
		world.setBlock(i + 2, j + 19, k + 9, Blocks.air);
		world.setBlock(i + 2, j + 19, k + 10, Blocks.air);
		world.setBlock(i + 2, j + 19, k + 11, Blocks.air);
		world.setBlock(i + 2, j + 19, k + 12, StructureGenHelper.randomBlock(rand, new Block[]{Blocks.chest, Blocks.chest, Blocks.air}), 2, 2);
		world.setBlockMetadataWithNotify(i + 2, j + 19, k + 12, 2, 2);
		te = world.getTileEntity(i + 2, j + 19, k + 12);
		if(te != null && te instanceof TileEntityChest) {
			TileEntityChest tec = (TileEntityChest)te;
			ChestGenHooks info = ChestGenHooks.getInfo(ChestGenHooks.PYRAMID_DESERT_CHEST);
            WeightedRandomChestContent.generateChestContents(rand, info.getItems(rand), tec, info.getCount(rand));
		}
		world.setBlock(i + 2, j + 19, k + 13, StructureGenHelper.blockChance90p(rand, Blocks.planks), 0, 2);
		world.setBlock(i + 2, j + 20, k + 8, StructureGenHelper.blockChance90p(rand, Blocks.planks), 0, 2);
		world.setBlock(i + 2, j + 20, k + 9, Blocks.air);
		world.setBlock(i + 2, j + 20, k + 10, Blocks.air);
		world.setBlock(i + 2, j + 20, k + 11, Blocks.air);
		world.setBlock(i + 2, j + 20, k + 12, Blocks.air);
		world.setBlock(i + 2, j + 20, k + 13, StructureGenHelper.blockChance90p(rand, Blocks.planks), 0, 2);
		world.setBlock(i + 2, j + 21, k + 8, StructureGenHelper.blockChance90p(rand, Blocks.planks), 0, 2);
		world.setBlock(i + 2, j + 21, k + 9, StructureGenHelper.blockChance90p(rand, Blocks.planks), 0, 2);
		world.setBlock(i + 2, j + 21, k + 10, Blocks.redstone_lamp, 0, 2);
		world.setBlock(i + 2, j + 21, k + 11, StructureGenHelper.blockChance90p(rand, Blocks.planks), 0, 2);
		world.setBlock(i + 2, j + 21, k + 12, StructureGenHelper.blockChance90p(rand, Blocks.planks), 0, 2);
		world.setBlock(i + 2, j + 21, k + 13, StructureGenHelper.blockChance90p(rand, Blocks.planks), 0, 2);
		world.setBlock(i + 2, j + 22, k + 8, StructureGenHelper.blockChance90p(rand, Blocks.oak_stairs), 2, 2);
		world.setBlock(i + 2, j + 22, k + 9, StructureGenHelper.blockChance90p(rand, Blocks.planks), 0, 2);
		world.setBlock(i + 2, j + 22, k + 11, StructureGenHelper.blockChance90p(rand, Blocks.planks), 0, 2);
		world.setBlock(i + 2, j + 22, k + 12, StructureGenHelper.blockChance90p(rand, Blocks.planks), 0, 2);
		world.setBlock(i + 2, j + 22, k + 13, StructureGenHelper.blockChance90p(rand, Blocks.oak_stairs), 3, 2);
		world.setBlock(i + 2, j + 23, k + 9, StructureGenHelper.blockChance90p(rand, Blocks.wooden_slab), 0, 2);
		world.setBlock(i + 2, j + 23, k + 10, StructureGenHelper.blockChance90p(rand, Blocks.oak_stairs), 7, 2);
		world.setBlock(i + 2, j + 23, k + 12, StructureGenHelper.blockChance90p(rand, Blocks.oak_stairs), 3, 2);
		//world.scheduleBlockUpdate(i + 2, j + 24, k + 11, Blocks.daylight_detector, 10);
		world.setBlock(i + 3, j + 0, k + 4, StructureGenHelper.blockChance90p(rand, Blocks.stonebrick), StructureGenHelper.stoneBrickMetaAncient(rand), 2);
		world.setBlock(i + 3, j + 0, k + 5, StructureGenHelper.blockChance90p(rand, Blocks.stonebrick), StructureGenHelper.stoneBrickMetaAncient(rand), 2);
		world.setBlock(i + 3, j + 0, k + 6, StructureGenHelper.blockChance90p(rand, Blocks.stonebrick), StructureGenHelper.stoneBrickMetaAncient(rand), 2);
		world.setBlock(i + 3, j + 0, k + 7, StructureGenHelper.blockChance90p(rand, Blocks.stonebrick), StructureGenHelper.stoneBrickMetaAncient(rand), 2);
		world.setBlock(i + 3, j + 0, k + 8, StructureGenHelper.blockChance90p(rand, Blocks.stonebrick), StructureGenHelper.stoneBrickMetaAncient(rand), 2);
		world.setBlock(i + 3, j + 0, k + 9, StructureGenHelper.blockChance90p(rand, Blocks.stonebrick), StructureGenHelper.stoneBrickMetaAncient(rand), 2);
		world.setBlock(i + 3, j + 0, k + 10, StructureGenHelper.blockChance90p(rand, Blocks.stonebrick), StructureGenHelper.stoneBrickMetaAncient(rand), 2);
		world.setBlock(i + 3, j + 1, k + 3, StructureGenHelper.blockChance90p(rand, Blocks.stonebrick), StructureGenHelper.stoneBrickMetaAncient(rand), 2);
		world.setBlock(i + 3, j + 1, k + 4, StructureGenHelper.blockChance90p(rand, Blocks.stonebrick), StructureGenHelper.stoneBrickMetaAncient(rand), 2);
		world.setBlock(i + 3, j + 1, k + 5, BlockSpikes.instance, 0, 2);
		world.setBlock(i + 3, j + 1, k + 6, BlockSpikes.instance, 0, 2);
		world.setBlock(i + 3, j + 1, k + 7, BlockSpikes.instance, 0, 2);
		world.setBlock(i + 3, j + 1, k + 8, StructureGenHelper.blockChance90p(rand, Blocks.stonebrick), StructureGenHelper.stoneBrickMetaAncient(rand), 2);
		world.setBlock(i + 3, j + 1, k + 9, StructureGenHelper.blockChance90p(rand, Blocks.stonebrick), StructureGenHelper.stoneBrickMetaAncient(rand), 2);
		world.setBlock(i + 3, j + 1, k + 10, StructureGenHelper.blockChance90p(rand, Blocks.stonebrick), StructureGenHelper.stoneBrickMetaAncient(rand), 2);
		world.setBlock(i + 3, j + 1, k + 11, StructureGenHelper.blockChance90p(rand, Blocks.stonebrick), StructureGenHelper.stoneBrickMetaAncient(rand), 2);
		world.setBlock(i + 3, j + 2, k + 3, StructureGenHelper.blockChance90p(rand, Blocks.stonebrick), StructureGenHelper.stoneBrickMetaAncient(rand), 2);
		world.setBlock(i + 3, j + 2, k + 4, StructureGenHelper.blockChance90p(rand, Blocks.stonebrick), StructureGenHelper.stoneBrickMetaAncient(rand), 2);
		world.setBlock(i + 3, j + 2, k + 5, BlockIllusionary.instance, 0, 2);
		world.setBlock(i + 3, j + 2, k + 6, BlockIllusionary.instance, 0, 2);
		world.setBlock(i + 3, j + 2, k + 7, BlockIllusionary.instance, 0, 2);
		world.setBlock(i + 3, j + 2, k + 8, StructureGenHelper.blockChance90p(rand, Blocks.stonebrick), StructureGenHelper.stoneBrickMetaAncient(rand), 2);
		world.setBlock(i + 3, j + 2, k + 9, StructureGenHelper.blockChance90p(rand, Blocks.stonebrick), StructureGenHelper.stoneBrickMetaAncient(rand), 2);
		world.setBlock(i + 3, j + 2, k + 10, StructureGenHelper.blockChance90p(rand, Blocks.stonebrick), StructureGenHelper.stoneBrickMetaAncient(rand), 2);
		world.setBlock(i + 3, j + 2, k + 11, StructureGenHelper.blockChance90p(rand, Blocks.stonebrick), StructureGenHelper.stoneBrickMetaAncient(rand), 2);
		world.setBlock(i + 3, j + 0, k + 3, StructureGenHelper.blockChance90p(rand, Blocks.stonebrick), StructureGenHelper.stoneBrickMetaAncient(rand), 2);
		world.setBlock(i + 3, j + 3, k + 4, BlockTrap.instance, 3, 2);
		te = world.getTileEntity(i + 3, j + 3, k + 4); 
		TileEntityTrap ted;
		if(te instanceof TileEntityTrap) {
			ted = (TileEntityTrap)te;
			ted.func_146019_a/*addItem*/(new ItemStack(Items.diamond_sword, 1, 1550));
		}
		world.setBlockMetadataWithNotify(i + 3, j + 3, k + 4, 3, 2);
		world.setBlock(i + 3, j + 3, k + 5, Blocks.air);
		world.setBlock(i + 3, j + 3, k + 6, Blocks.air);
		world.setBlock(i + 3, j + 3, k + 7, Blocks.air);
		world.setBlock(i + 3, j + 3, k + 8, BlockTrap.instance, 2, 2);
		te = world.getTileEntity(i + 3, j + 3, k + 8); 
		if(te instanceof TileEntityTrap) {
			ted = (TileEntityTrap)te;
			ted.func_146019_a/*addItem*/(new ItemStack(Items.diamond_sword, 1, 1550));
		}
		world.setBlockMetadataWithNotify(i + 3, j + 3, k + 8, 2, 2);
		world.setBlock(i + 3, j + 3, k + 9, StructureGenHelper.blockChance90p(rand, Blocks.stonebrick), StructureGenHelper.stoneBrickMetaAncient(rand), 2);
		world.setBlock(i + 3, j + 3, k + 10, StructureGenHelper.blockChance90p(rand, Blocks.stonebrick), StructureGenHelper.stoneBrickMetaAncient(rand), 2);
		world.setBlock(i + 3, j + 0, k + 11, StructureGenHelper.blockChance90p(rand, Blocks.stonebrick), StructureGenHelper.stoneBrickMetaAncient(rand), 2);
		world.setBlock(i + 3, j + 4, k + 3, StructureGenHelper.blockChance90p(rand, Blocks.stonebrick), StructureGenHelper.stoneBrickMetaAncient(rand), 2);
		world.setBlock(i + 3, j + 4, k + 4, StructureGenHelper.blockChance90p(rand, Blocks.stonebrick), StructureGenHelper.stoneBrickMetaAncient(rand), 2);
		world.setBlock(i + 3, j + 4, k + 5, Blocks.air);
		world.setBlock(i + 3, j + 4, k + 6, Blocks.air);
		world.setBlock(i + 3, j + 4, k + 7, Blocks.air);
		world.setBlock(i + 3, j + 4, k + 8, StructureGenHelper.blockChance90p(rand, Blocks.stonebrick), StructureGenHelper.stoneBrickMetaAncient(rand), 2);
		world.setBlock(i + 3, j + 4, k + 9, StructureGenHelper.blockChance90p(rand, Blocks.stonebrick), StructureGenHelper.stoneBrickMetaAncient(rand), 2);
		world.setBlock(i + 3, j + 4, k + 10, StructureGenHelper.blockChance90p(rand, Blocks.stonebrick), StructureGenHelper.stoneBrickMetaAncient(rand), 2);
		world.setBlock(i + 3, j + 4, k + 11, StructureGenHelper.blockChance90p(rand, Blocks.stonebrick), StructureGenHelper.stoneBrickMetaAncient(rand), 2);
		world.setBlock(i + 3, j + 5, k + 3, StructureGenHelper.blockChance90p(rand, Blocks.stonebrick), StructureGenHelper.stoneBrickMetaAncient(rand), 2);
		world.setBlock(i + 3, j + 5, k + 4, StructureGenHelper.blockChance90p(rand, Blocks.stonebrick), StructureGenHelper.stoneBrickMetaAncient(rand), 2);
		world.setBlock(i + 3, j + 5, k + 5, Blocks.air);
		world.setBlock(i + 3, j + 5, k + 6, Blocks.air);
		world.setBlock(i + 3, j + 5, k + 7, Blocks.air);
		world.setBlock(i + 3, j + 5, k + 8, StructureGenHelper.blockChance90p(rand, Blocks.stonebrick), StructureGenHelper.stoneBrickMetaAncient(rand), 2);
		world.setBlock(i + 3, j + 5, k + 9, StructureGenHelper.blockChance90p(rand, Blocks.stonebrick), StructureGenHelper.stoneBrickMetaAncient(rand), 2);
		world.setBlock(i + 3, j + 5, k + 10, StructureGenHelper.blockChance90p(rand, Blocks.stonebrick), StructureGenHelper.stoneBrickMetaAncient(rand), 2);
		world.setBlock(i + 3, j + 5, k + 11, StructureGenHelper.blockChance90p(rand, Blocks.stonebrick), StructureGenHelper.stoneBrickMetaAncient(rand), 2);
		world.setBlock(i + 3, j + 6, k + 3, StructureGenHelper.blockChance90p(rand, Blocks.stonebrick), StructureGenHelper.stoneBrickMetaAncient(rand), 2);
		world.setBlock(i + 3, j + 6, k + 4, StructureGenHelper.blockChance90p(rand, Blocks.stonebrick), StructureGenHelper.stoneBrickMetaAncient(rand), 2);
		world.setBlock(i + 3, j + 6, k + 5, Blocks.air);
		world.setBlock(i + 3, j + 6, k + 6, Blocks.air);
		world.setBlock(i + 3, j + 6, k + 7, Blocks.air);
		world.setBlock(i + 3, j + 6, k + 8, StructureGenHelper.blockChance90p(rand, Blocks.stonebrick), StructureGenHelper.stoneBrickMetaAncient(rand), 2);
		world.setBlock(i + 3, j + 6, k + 9, StructureGenHelper.blockChance90p(rand, Blocks.stonebrick), StructureGenHelper.stoneBrickMetaAncient(rand), 2);
		world.setBlock(i + 3, j + 6, k + 10, StructureGenHelper.blockChance90p(rand, Blocks.stonebrick), StructureGenHelper.stoneBrickMetaAncient(rand), 2);
		world.setBlock(i + 3, j + 6, k + 11, StructureGenHelper.blockChance90p(rand, Blocks.stonebrick), StructureGenHelper.stoneBrickMetaAncient(rand), 2);
		world.setBlock(i + 3, j + 7, k + 3, StructureGenHelper.blockChance90p(rand, Blocks.stonebrick), StructureGenHelper.stoneBrickMetaAncient(rand), 2);
		world.setBlock(i + 3, j + 7, k + 4, StructureGenHelper.blockChance90p(rand, Blocks.stonebrick), StructureGenHelper.stoneBrickMetaAncient(rand), 2);
		world.setBlock(i + 3, j + 7, k + 5, StructureGenHelper.blockChance90p(rand, Blocks.stonebrick), StructureGenHelper.stoneBrickMetaAncient(rand), 2);
		world.setBlock(i + 3, j + 7, k + 6, StructureGenHelper.blockChance90p(rand, Blocks.stonebrick), StructureGenHelper.stoneBrickMetaAncient(rand), 2);
		world.setBlock(i + 3, j + 7, k + 7, BlockTrap.instance, 1, 2);
		world.setBlockMetadataWithNotify(i + 3, j + 7, k + 7, 1, 2);
		te = world.getTileEntity(i + 3, j + 7, k + 7); 
		if(te instanceof TileEntityTrap) {
			ted = (TileEntityTrap)te;
			ted.func_146019_a/*addItem*/(new ItemStack(Items.arrow, rand.nextInt(10)));
		}
		world.setBlock(i + 3, j + 8, k + 7, StructureGenHelper.randomBlock(rand, new Block[]{BlockArtifactsPressurePlate.invisObsidian, BlockArtifactsPressurePlate.invisObsidian, BlockArtifactsPressurePlate.invisObsidian, BlockArtifactsPressurePlate.camoObsidian}), 0, 2);
		world.setBlock(i + 3, j + 7, k + 8, StructureGenHelper.blockChance90p(rand, Blocks.stonebrick), StructureGenHelper.stoneBrickMetaAncient(rand), 2);
		world.setBlock(i + 3, j + 7, k + 9, StructureGenHelper.blockChance90p(rand, Blocks.stonebrick), StructureGenHelper.stoneBrickMetaAncient(rand), 2);
		world.setBlock(i + 3, j + 7, k + 10, StructureGenHelper.blockChance90p(rand, Blocks.stonebrick), StructureGenHelper.stoneBrickMetaAncient(rand), 2);
		world.setBlock(i + 3, j + 7, k + 11, StructureGenHelper.blockChance90p(rand, Blocks.stonebrick), StructureGenHelper.stoneBrickMetaAncient(rand), 2);
		world.setBlock(i + 3, j + 8, k + 4, StructureGenHelper.blockChance90p(rand, Blocks.stonebrick), StructureGenHelper.stoneBrickMetaAncient(rand), 2);
		world.setBlock(i + 3, j + 8, k + 5, StructureGenHelper.blockChance90p(rand, Blocks.stonebrick), StructureGenHelper.stoneBrickMetaAncient(rand), 2);
		world.setBlock(i + 3, j + 8, k + 6, Blocks.air);
		//world.setBlock(i + 3, j + 8, k + 7, Blocks.air);
		world.setBlock(i + 3, j + 8, k + 9, StructureGenHelper.blockChance90p(rand, Blocks.stonebrick), StructureGenHelper.stoneBrickMetaAncient(rand), 2);
		world.setBlock(i + 3, j + 8, k + 10, StructureGenHelper.blockChance90p(rand, Blocks.stonebrick), StructureGenHelper.stoneBrickMetaAncient(rand), 2);
		world.setBlock(i + 3, j + 9, k + 4, StructureGenHelper.blockChance90p(rand, Blocks.stonebrick), StructureGenHelper.stoneBrickMetaAncient(rand), 2);
		world.setBlock(i + 3, j + 9, k + 5, StructureGenHelper.blockChance90p(rand, Blocks.stonebrick), StructureGenHelper.stoneBrickMetaAncient(rand), 2);
		world.setBlock(i + 3, j + 9, k + 6, Blocks.air);
		world.setBlock(i + 3, j + 9, k + 7, Blocks.air);
		world.setBlock(i + 3, j + 9, k + 9, StructureGenHelper.blockChance90p(rand, Blocks.stonebrick), StructureGenHelper.stoneBrickMetaAncient(rand), 2);
		world.setBlock(i + 3, j + 9, k + 10, StructureGenHelper.blockChance90p(rand, Blocks.stonebrick), StructureGenHelper.stoneBrickMetaAncient(rand), 2);
		world.setBlock(i + 3, j + 10, k + 1, StructureGenHelper.blockChance90p(rand, Blocks.oak_stairs), 4, 2);
		world.setBlock(i + 3, j + 10, k + 2, StructureGenHelper.blockChance90p(rand, Blocks.oak_stairs), 4, 2);
		world.setBlock(i + 3, j + 10, k + 3, StructureGenHelper.blockChance90p(rand, Blocks.planks), 0, 2);
		world.setBlock(i + 3, j + 10, k + 4, StructureGenHelper.blockChance90p(rand, Blocks.stonebrick), StructureGenHelper.stoneBrickMetaAncient(rand), 2);
		world.setBlock(i + 3, j + 10, k + 5, StructureGenHelper.blockChance90p(rand, Blocks.stonebrick), StructureGenHelper.stoneBrickMetaAncient(rand), 2);
		world.setBlock(i + 3, j + 10, k + 6, Blocks.air);
		world.setBlock(i + 3, j + 10, k + 7, Blocks.air);
		world.setBlock(i + 3, j + 10, k + 9, StructureGenHelper.blockChance90p(rand, Blocks.stonebrick), StructureGenHelper.stoneBrickMetaAncient(rand), 2);
		world.setBlock(i + 3, j + 10, k + 10, StructureGenHelper.blockChance90p(rand, Blocks.stonebrick), StructureGenHelper.stoneBrickMetaAncient(rand), 2);
		world.setBlock(i + 3, j + 11, k + 0, StructureGenHelper.blockChance90p(rand, Blocks.oak_stairs), 6, 2);
		world.setBlock(i + 3, j + 11, k + 1, StructureGenHelper.blockChance90p(rand, Blocks.planks), 0, 2);
		world.setBlock(i + 3, j + 11, k + 2, StructureGenHelper.blockChance90p(rand, Blocks.planks), 0, 2);
		world.setBlock(i + 3, j + 11, k + 3, StructureGenHelper.blockChance90p(rand, Blocks.planks), 0, 2);
		world.setBlock(i + 3, j + 11, k + 5, StructureGenHelper.blockChance90p(rand, Blocks.stonebrick), StructureGenHelper.stoneBrickMetaAncient(rand), 2);
		world.setBlock(i + 3, j + 11, k + 6, StructureGenHelper.blockChance90p(rand, Blocks.stonebrick), StructureGenHelper.stoneBrickMetaAncient(rand), 2);
		world.setBlock(i + 3, j + 11, k + 7, StructureGenHelper.blockChance90p(rand, Blocks.stonebrick), StructureGenHelper.stoneBrickMetaAncient(rand), 2);
		world.setBlock(i + 3, j + 11, k + 9, StructureGenHelper.blockChance90p(rand, Blocks.stonebrick), StructureGenHelper.stoneBrickMetaAncient(rand), 2);
		world.setBlock(i + 3, j + 12, k + 0, StructureGenHelper.blockChance90p(rand, Blocks.planks), 0, 2);
		world.setBlock(i + 3, j + 12, k + 1, StructureGenHelper.blockChance90p(rand, Blocks.stonebrick), StructureGenHelper.stoneBrickMetaAncient(rand), 2);
		world.setBlock(i + 3, j + 12, k + 2, StructureGenHelper.blockChance90p(rand, Blocks.planks), 0, 2);
		world.setBlock(i + 3, j + 12, k + 3, Blocks.air);
		world.setBlock(i + 3, j + 12, k + 4, Blocks.air);
		world.setBlock(i + 3, j + 12, k + 5, StructureGenHelper.blockChance90p(rand, Blocks.stonebrick), StructureGenHelper.stoneBrickMetaAncient(rand), 2);
		world.setBlock(i + 3, j + 12, k + 6, StructureGenHelper.blockChance90p(rand, Blocks.stonebrick), StructureGenHelper.stoneBrickMetaAncient(rand), 2);
		world.setBlock(i + 3, j + 12, k + 7, Blocks.air);
		world.setBlock(i + 3, j + 12, k + 8, Blocks.air);
		world.setBlock(i + 3, j + 12, k + 9, StructureGenHelper.blockChance90p(rand, Blocks.stonebrick), StructureGenHelper.stoneBrickMetaAncient(rand), 2);
		world.setBlock(i + 3, j + 13, k + 0, StructureGenHelper.blockChance90p(rand, Blocks.planks), 0, 2);
		world.setBlock(i + 3, j + 13, k + 1, StructureGenHelper.blockChance90p(rand, Blocks.stonebrick), StructureGenHelper.stoneBrickMetaAncient(rand), 2);
		world.setBlock(i + 3, j + 13, k + 2, StructureGenHelper.blockChance90p(rand, Blocks.planks), 0, 2);
		world.setBlock(i + 3, j + 13, k + 3, Blocks.air);
		world.setBlock(i + 3, j + 13, k + 4, Blocks.air);
		world.setBlock(i + 3, j + 13, k + 5, StructureGenHelper.blockChance90p(rand, Blocks.stonebrick), StructureGenHelper.stoneBrickMetaAncient(rand), 2);
		world.setBlock(i + 3, j + 13, k + 6, StructureGenHelper.blockChance90p(rand, Blocks.stonebrick), StructureGenHelper.stoneBrickMetaAncient(rand), 2);
		world.setBlock(i + 3, j + 13, k + 7, Blocks.air);
		//world.setBlock(i + 3, j + 13, k + 8, StructureGenHelper.blockChance90p(rand, Blocks.stonebrick), StructureGenHelper.stoneBrickMetaAncient(rand), 2);
		world.setBlock(i + 3, j + 13, k + 9, StructureGenHelper.blockChance90p(rand, Blocks.stonebrick), StructureGenHelper.stoneBrickMetaAncient(rand), 2);
		world.setBlock(i + 3, j + 14, k + 0, StructureGenHelper.blockChance90p(rand, Blocks.planks), 0, 2);
		world.setBlock(i + 3, j + 14, k + 2, StructureGenHelper.blockChance90p(rand, Blocks.planks), 0, 2);
		world.setBlock(i + 3, j + 14, k + 3, Blocks.air);
		world.setBlock(i + 3, j + 14, k + 4, Blocks.air);
		world.setBlock(i + 3, j + 14, k + 5, StructureGenHelper.blockChance90p(rand, Blocks.stonebrick), StructureGenHelper.stoneBrickMetaAncient(rand), 2);
		world.setBlock(i + 3, j + 14, k + 6, StructureGenHelper.blockChance90p(rand, Blocks.stonebrick), StructureGenHelper.stoneBrickMetaAncient(rand), 2);
		world.setBlock(i + 3, j + 14, k + 7, Blocks.air);
		world.setBlock(i + 3, j + 14, k + 8, Blocks.air);
		world.setBlock(i + 3, j + 14, k + 9, StructureGenHelper.blockChance90p(rand, Blocks.stonebrick), StructureGenHelper.stoneBrickMetaAncient(rand), 2);
		world.setBlock(i + 3, j + 15, k + 0, StructureGenHelper.blockChance90p(rand, Blocks.oak_stairs), 2, 2);
		world.setBlock(i + 3, j + 14, k + 1, StructureGenHelper.blockChance90p(rand, Blocks.planks), 15, 2);
		world.setBlock(i + 3, j + 15, k + 1, Blocks.air);
		//world.scheduleBlockUpdate(i + 3, j + 15, k + 1, Blocks.daylight_detector, 10);
		world.setBlock(i + 4, j + 15, k + 2, StructureGenHelper.blockChance90p(rand, Blocks.planks), 0, 2);
		world.setBlock(i + 4, j + 16, k + 2, Blocks.air);
		world.setBlock(i + 3, j + 15, k + 2, Blocks.air);
		world.setBlock(i + 3, j + 15, k + 3, StructureGenHelper.blockChance90p(rand, Blocks.planks), 0, 2);
		world.setBlock(i + 3, j + 15, k + 4, StructureGenHelper.blockChance90p(rand, Blocks.planks), 0, 2);
		world.setBlock(i + 3, j + 15, k + 5, StructureGenHelper.blockChance90p(rand, Blocks.stonebrick), StructureGenHelper.stoneBrickMetaAncient(rand), 2);
		world.setBlock(i + 3, j + 15, k + 6, StructureGenHelper.blockChance90p(rand, Blocks.stonebrick), StructureGenHelper.stoneBrickMetaAncient(rand), 2);
		world.setBlock(i + 3, j + 15, k + 7, StructureGenHelper.blockChance90p(rand, Blocks.stonebrick), StructureGenHelper.stoneBrickMetaAncient(rand), 2);
		world.setBlock(i + 3, j + 15, k + 8, StructureGenHelper.blockChance90p(rand, Blocks.stonebrick), StructureGenHelper.stoneBrickMetaAncient(rand), 2);
		world.setBlock(i + 3, j + 15, k + 9, StructureGenHelper.blockChance90p(rand, Blocks.stonebrick), StructureGenHelper.stoneBrickMetaAncient(rand), 2);
		world.setBlock(i + 3, j + 16, k + 1, StructureGenHelper.blockChance90p(rand, Blocks.oak_stairs), 2, 2);
		world.setBlock(i + 3, j + 16, k + 2, StructureGenHelper.blockChance90p(rand, Blocks.oak_stairs), 0, 2);
		world.setBlock(i + 3, j + 16, k + 3, StructureGenHelper.blockChance90p(rand, Blocks.planks), 0, 2);
		world.setBlock(i + 3, j + 16, k + 4, StructureGenHelper.blockChance90p(rand, Blocks.oak_stairs), 3, 2);
		world.setBlock(i + 3, j + 16, k + 5, StructureGenHelper.blockChance90p(rand, Blocks.oak_stairs), 0, 2);
		world.setBlock(i + 3, j + 16, k + 6, StructureGenHelper.blockChance90p(rand, Blocks.stonebrick), StructureGenHelper.stoneBrickMetaAncient(rand), 2);
		world.setBlock(i + 3, j + 16, k + 7, StructureGenHelper.blockChance90p(rand, Blocks.stonebrick), StructureGenHelper.stoneBrickMetaAncient(rand), 2);
		world.setBlock(i + 3, j + 16, k + 8, StructureGenHelper.blockChance90p(rand, Blocks.stonebrick), StructureGenHelper.stoneBrickMetaAncient(rand), 2);
		world.setBlock(i + 3, j + 17, k + 3, StructureGenHelper.blockChance90p(rand, Blocks.oak_stairs), 0, 2);
		world.setBlock(i + 3, j + 17, k + 6, StructureGenHelper.blockChance90p(rand, Blocks.stonebrick), StructureGenHelper.stoneBrickMetaAncient(rand), 2);
		world.setBlock(i + 3, j + 17, k + 7, StructureGenHelper.blockChance90p(rand, Blocks.stonebrick), StructureGenHelper.stoneBrickMetaAncient(rand), 2);
		world.setBlock(i + 3, j + 17, k + 8, StructureGenHelper.blockChance90p(rand, Blocks.stonebrick), StructureGenHelper.stoneBrickMetaAncient(rand), 2);
		world.setBlock(i + 3, j + 17, k + 9, StructureGenHelper.blockChance90p(rand, Blocks.oak_stairs), 6, 2);
		world.setBlock(i + 3, j + 17, k + 10, StructureGenHelper.blockChance90p(rand, Blocks.oak_stairs), 5, 2);
		world.setBlock(i + 3, j + 17, k + 11, StructureGenHelper.blockChance90p(rand, Blocks.oak_stairs), 5, 2);
		world.setBlock(i + 3, j + 17, k + 12, StructureGenHelper.blockChance90p(rand, Blocks.oak_stairs), 7, 2);
		world.setBlock(i + 3, j + 18, k + 7, StructureGenHelper.blockChance90p(rand, Blocks.stonebrick), StructureGenHelper.stoneBrickMetaAncient(rand), 2);
		world.setBlock(i + 3, j + 18, k + 8, StructureGenHelper.blockChance90p(rand, Blocks.planks), 0, 2);
		world.setBlock(i + 3, j + 18, k + 9, StructureGenHelper.blockChance90p(rand, Blocks.planks), 0, 2);
		world.setBlock(i + 3, j + 18, k + 10, StructureGenHelper.blockChance90p(rand, Blocks.planks), 0, 2);
		world.setBlock(i + 3, j + 18, k + 11, StructureGenHelper.blockChance90p(rand, Blocks.planks), 0, 2);
		world.setBlock(i + 3, j + 18, k + 12, StructureGenHelper.blockChance90p(rand, Blocks.planks), 0, 2);
		world.setBlock(i + 3, j + 18, k + 13, StructureGenHelper.blockChance90p(rand, Blocks.oak_stairs), 7, 2);
		world.setBlock(i + 3, j + 19, k + 7, StructureGenHelper.blockChance90p(rand, Blocks.planks), 0, 2);
		world.setBlock(i + 3, j + 19, k + 8, StructureGenHelper.blockChance90p(rand, Blocks.planks), 0, 2);
		world.setBlock(i + 3, j + 19, k + 9, Blocks.air);
		world.setBlock(i + 3, j + 19, k + 10, Blocks.air);
		world.setBlock(i + 3, j + 19, k + 11, Blocks.air);
		world.setBlock(i + 3, j + 19, k + 12, Blocks.air);
		world.setBlock(i + 3, j + 19, k + 13, StructureGenHelper.blockChance90p(rand, Blocks.planks), 0, 2);
		world.setBlock(i + 3, j + 20, k + 7, StructureGenHelper.blockChance90p(rand, Blocks.planks), 0, 2);
		world.setBlock(i + 3, j + 20, k + 8, StructureGenHelper.blockChance90p(rand, Blocks.planks), 0, 2);
		world.setBlock(i + 3, j + 20, k + 9, Blocks.air);
		world.setBlock(i + 3, j + 20, k + 10, Blocks.air);
		world.setBlock(i + 3, j + 20, k + 11, Blocks.air);
		world.setBlock(i + 3, j + 20, k + 12, Blocks.air);
		world.setBlock(i + 3, j + 20, k + 13, StructureGenHelper.blockChance90p(rand, Blocks.planks), 0, 2);
		world.setBlock(i + 3, j + 21, k + 7, StructureGenHelper.blockChance90p(rand, Blocks.oak_stairs), 2, 2);
		world.setBlock(i + 3, j + 21, k + 8, StructureGenHelper.blockChance90p(rand, Blocks.planks), 0, 2);
		world.setBlock(i + 3, j + 21, k + 9, StructureGenHelper.blockChance90p(rand, Blocks.planks), 0, 2);
		world.setBlock(i + 3, j + 21, k + 10, StructureGenHelper.blockChance90p(rand, Blocks.planks), 0, 2);
		world.setBlock(i + 3, j + 21, k + 11, StructureGenHelper.blockChance90p(rand, Blocks.planks), 0, 2);
		world.setBlock(i + 3, j + 21, k + 12, StructureGenHelper.blockChance90p(rand, Blocks.planks), 0, 2);
		world.setBlock(i + 3, j + 21, k + 13, StructureGenHelper.blockChance90p(rand, Blocks.planks), 0, 2);
		world.setBlock(i + 3, j + 22, k + 8, StructureGenHelper.blockChance90p(rand, Blocks.oak_stairs), 2, 2);
		world.setBlock(i + 3, j + 22, k + 9, StructureGenHelper.blockChance90p(rand, Blocks.oak_stairs), 1, 2);
		world.setBlock(i + 3, j + 22, k + 10, StructureGenHelper.blockChance90p(rand, Blocks.planks), 0, 2);
		world.setBlock(i + 3, j + 22, k + 11, StructureGenHelper.blockChance90p(rand, Blocks.planks), 0, 2);
		world.setBlock(i + 3, j + 22, k + 12, StructureGenHelper.blockChance90p(rand, Blocks.oak_stairs), 1, 2);
		world.setBlock(i + 3, j + 22, k + 13, StructureGenHelper.blockChance90p(rand, Blocks.oak_stairs), 3, 2);
		world.setBlock(i + 3, j + 23, k + 10, StructureGenHelper.blockChance90p(rand, Blocks.oak_stairs), 1, 2);
		world.setBlock(i + 3, j + 23, k + 11, StructureGenHelper.blockChance90p(rand, Blocks.oak_stairs), 1, 2);
		world.setBlock(i + 3, j + 28, k + 6, StructureGenHelper.blockChance90p(rand, Blocks.stone_brick_stairs), 4, 2);
		world.setBlock(i + 3, j + 28, k + 7, StructureGenHelper.blockChance90p(rand, Blocks.stone_brick_stairs), 4, 2);
		world.setBlock(i + 3, j + 28, k + 8, StructureGenHelper.blockChance90p(rand, Blocks.stone_brick_stairs), 4, 2);
		world.setBlock(i + 3, j + 29, k + 6, StructureGenHelper.blockChance90p(rand, Blocks.stonebrick), StructureGenHelper.stoneBrickMetaAncient(rand), 2);
		world.setBlock(i + 3, j + 29, k + 7, StructureGenHelper.blockChance90p(rand, Blocks.stonebrick), StructureGenHelper.stoneBrickMetaAncient(rand), 2);
		world.setBlock(i + 3, j + 29, k + 8, StructureGenHelper.blockChance90p(rand, Blocks.stonebrick), StructureGenHelper.stoneBrickMetaAncient(rand), 2);
		world.setBlock(i + 3, j + 30, k + 6, StructureGenHelper.blockChance90p(rand, Blocks.stone_brick_stairs), 3, 2);
		world.setBlock(i + 3, j + 30, k + 8, StructureGenHelper.blockChance90p(rand, Blocks.stone_brick_stairs), 2, 2);
		world.setBlock(i + 4, j + 0, k + 3, StructureGenHelper.blockChance90p(rand, Blocks.stonebrick), StructureGenHelper.stoneBrickMetaAncient(rand), 2);
		world.setBlock(i + 4, j + 0, k + 4, StructureGenHelper.blockChance90p(rand, Blocks.stonebrick), StructureGenHelper.stoneBrickMetaAncient(rand), 2);
		world.setBlock(i + 4, j + 0, k + 5, StructureGenHelper.blockChance90p(rand, Blocks.stonebrick), StructureGenHelper.stoneBrickMetaAncient(rand), 2);
		world.setBlock(i + 4, j + 0, k + 6, StructureGenHelper.blockChance90p(rand, Blocks.stonebrick), StructureGenHelper.stoneBrickMetaAncient(rand), 2);
		world.setBlock(i + 4, j + 0, k + 7, StructureGenHelper.blockChance90p(rand, Blocks.stonebrick), StructureGenHelper.stoneBrickMetaAncient(rand), 2);
		world.setBlock(i + 4, j + 0, k + 8, StructureGenHelper.blockChance90p(rand, Blocks.stonebrick), StructureGenHelper.stoneBrickMetaAncient(rand), 2);
		world.setBlock(i + 4, j + 0, k + 9, StructureGenHelper.blockChance90p(rand, Blocks.stonebrick), StructureGenHelper.stoneBrickMetaAncient(rand), 2);
		world.setBlock(i + 4, j + 0, k + 10, StructureGenHelper.blockChance90p(rand, Blocks.stonebrick), StructureGenHelper.stoneBrickMetaAncient(rand), 2);
		world.setBlock(i + 4, j + 0, k + 11, StructureGenHelper.blockChance90p(rand, Blocks.stonebrick), StructureGenHelper.stoneBrickMetaAncient(rand), 2);
		world.setBlock(i + 4, j + 1, k + 3, StructureGenHelper.blockChance90p(rand, Blocks.stonebrick), StructureGenHelper.stoneBrickMetaAncient(rand), 2);
		world.setBlock(i + 4, j + 1, k + 4, StructureGenHelper.blockChance90p(rand, Blocks.stonebrick), StructureGenHelper.stoneBrickMetaAncient(rand), 2);
		world.setBlock(i + 4, j + 1, k + 5, BlockSpikes.instance, 0, 2);
		world.setBlock(i + 4, j + 1, k + 6, BlockSpikes.instance, 0, 2);
		world.setBlock(i + 4, j + 1, k + 7, BlockSpikes.instance, 0, 2);
		world.setBlock(i + 4, j + 1, k + 8, StructureGenHelper.blockChance90p(rand, Blocks.stonebrick), StructureGenHelper.stoneBrickMetaAncient(rand), 2);
		world.setBlock(i + 4, j + 1, k + 9, StructureGenHelper.blockChance90p(rand, Blocks.stonebrick), StructureGenHelper.stoneBrickMetaAncient(rand), 2);
		world.setBlock(i + 4, j + 1, k + 10, StructureGenHelper.blockChance90p(rand, Blocks.stonebrick), StructureGenHelper.stoneBrickMetaAncient(rand), 2);
		world.setBlock(i + 4, j + 1, k + 11, StructureGenHelper.blockChance90p(rand, Blocks.stonebrick), StructureGenHelper.stoneBrickMetaAncient(rand), 2);
		world.setBlock(i + 4, j + 2, k + 3, StructureGenHelper.blockChance90p(rand, Blocks.stonebrick), StructureGenHelper.stoneBrickMetaAncient(rand), 2);
		world.setBlock(i + 4, j + 2, k + 4, BlockIllusionary.instance, 0, 2);
		world.setBlock(i + 4, j + 2, k + 5, BlockIllusionary.instance, 0, 2);
		world.setBlock(i + 4, j + 2, k + 6, BlockIllusionary.instance, 0, 2);
		world.setBlock(i + 4, j + 2, k + 7, BlockIllusionary.instance, 0, 2);
		world.setBlock(i + 4, j + 2, k + 8, BlockIllusionary.instance, 0, 2);
		world.setBlock(i + 4, j + 2, k + 9, StructureGenHelper.blockChance90p(rand, Blocks.stonebrick), StructureGenHelper.stoneBrickMetaAncient(rand), 2);
		world.setBlock(i + 4, j + 2, k + 10, StructureGenHelper.blockChance90p(rand, Blocks.stonebrick), StructureGenHelper.stoneBrickMetaAncient(rand), 2);
		world.setBlock(i + 4, j + 2, k + 11, StructureGenHelper.blockChance90p(rand, Blocks.stonebrick), StructureGenHelper.stoneBrickMetaAncient(rand), 2);
		world.setBlock(i + 4, j + 3, k + 3, StructureGenHelper.blockChance90p(rand, Blocks.stonebrick), StructureGenHelper.stoneBrickMetaAncient(rand), 2);
		world.setBlock(i + 4, j + 3, k + 4, Blocks.tripwire_hook, 0, 2);
		world.setBlock(i + 4, j + 3, k + 8, Blocks.tripwire_hook, 2, 2);
		world.setBlock(i + 4, j + 3, k + 9, StructureGenHelper.blockChance90p(rand, Blocks.stonebrick), StructureGenHelper.stoneBrickMetaAncient(rand), 2);
		world.setBlock(i + 4, j + 3, k + 10, StructureGenHelper.blockChance90p(rand, Blocks.stonebrick), StructureGenHelper.stoneBrickMetaAncient(rand), 2);
		world.setBlock(i + 4, j + 3, k + 11, StructureGenHelper.blockChance90p(rand, Blocks.stonebrick), StructureGenHelper.stoneBrickMetaAncient(rand), 2);
		world.setBlock(i + 4, j + 4, k + 3, StructureGenHelper.blockChance90p(rand, Blocks.stonebrick), StructureGenHelper.stoneBrickMetaAncient(rand), 2);
		world.setBlock(i + 4, j + 4, k + 4, BlockTrap.instance, 3, 2);
		te = world.getTileEntity(i + 4, j + 4, k + 4); 
		if(te instanceof TileEntityTrap) {
			ted = (TileEntityTrap)te;
			ted.func_146019_a/*addItem*/(new ItemStack(Items.potionitem, 1, 16384+8204));
		}
		world.setBlockMetadataWithNotify(i + 4, j + 4, k + 4, 3, 2);
		world.setBlock(i + 4, j + 4, k + 5, Blocks.air);
		world.setBlock(i + 4, j + 4, k + 6, Blocks.air);
		world.setBlock(i + 4, j + 4, k + 7, Blocks.air);
		world.setBlock(i + 4, j + 4, k + 8, BlockTrap.instance, 2, 2);
		te = world.getTileEntity(i + 4, j + 4, k + 8); 
		if(te instanceof TileEntityTrap) {
			ted = (TileEntityTrap)te;
			ted.func_146019_a/*addItem*/(new ItemStack(Items.potionitem, 1, 16384+8234));
		}
		world.setBlockMetadataWithNotify(i + 4, j + 4, k + 8, 2, 2);
		world.setBlock(i + 4, j + 4, k + 9, StructureGenHelper.blockChance90p(rand, Blocks.stonebrick), StructureGenHelper.stoneBrickMetaAncient(rand), 2);
		world.setBlock(i + 4, j + 4, k + 10, StructureGenHelper.blockChance90p(rand, Blocks.stonebrick), StructureGenHelper.stoneBrickMetaAncient(rand), 2);
		world.setBlock(i + 4, j + 4, k + 11, StructureGenHelper.blockChance90p(rand, Blocks.stonebrick), StructureGenHelper.stoneBrickMetaAncient(rand), 2);
		world.setBlock(i + 4, j + 5, k + 3, StructureGenHelper.blockChance90p(rand, Blocks.stonebrick), StructureGenHelper.stoneBrickMetaAncient(rand), 2);
		world.setBlock(i + 4, j + 5, k + 4, StructureGenHelper.blockChance90p(rand, Blocks.stonebrick), StructureGenHelper.stoneBrickMetaAncient(rand), 2);
		world.setBlock(i + 4, j + 5, k + 5, Blocks.air);
		world.setBlock(i + 4, j + 5, k + 6, Blocks.air);
		world.setBlock(i + 4, j + 5, k + 7, Blocks.air);
		world.setBlock(i + 4, j + 5, k + 8, StructureGenHelper.blockChance90p(rand, Blocks.stonebrick), StructureGenHelper.stoneBrickMetaAncient(rand), 2);
		world.setBlock(i + 4, j + 5, k + 9, StructureGenHelper.blockChance90p(rand, Blocks.stonebrick), StructureGenHelper.stoneBrickMetaAncient(rand), 2);
		world.setBlock(i + 4, j + 5, k + 10, StructureGenHelper.blockChance90p(rand, Blocks.stonebrick), StructureGenHelper.stoneBrickMetaAncient(rand), 2);
		world.setBlock(i + 4, j + 5, k + 11, StructureGenHelper.blockChance90p(rand, Blocks.stonebrick), StructureGenHelper.stoneBrickMetaAncient(rand), 2);
		world.setBlock(i + 4, j + 6, k + 3, StructureGenHelper.blockChance90p(rand, Blocks.stonebrick), StructureGenHelper.stoneBrickMetaAncient(rand), 2);
		world.setBlock(i + 4, j + 6, k + 4, StructureGenHelper.blockChance90p(rand, Blocks.stonebrick), StructureGenHelper.stoneBrickMetaAncient(rand), 2);
		world.setBlock(i + 4, j + 6, k + 5, Blocks.air);
		world.setBlock(i + 4, j + 6, k + 6, Blocks.air);
		world.setBlock(i + 4, j + 6, k + 7, Blocks.air);
		world.setBlock(i + 4, j + 6, k + 8, StructureGenHelper.blockChance90p(rand, Blocks.stonebrick), StructureGenHelper.stoneBrickMetaAncient(rand), 2);
		world.setBlock(i + 4, j + 6, k + 9, StructureGenHelper.blockChance90p(rand, Blocks.stonebrick), StructureGenHelper.stoneBrickMetaAncient(rand), 2);
		world.setBlock(i + 4, j + 6, k + 10, StructureGenHelper.blockChance90p(rand, Blocks.stonebrick), StructureGenHelper.stoneBrickMetaAncient(rand), 2);
		world.setBlock(i + 4, j + 6, k + 11, StructureGenHelper.blockChance90p(rand, Blocks.stonebrick), StructureGenHelper.stoneBrickMetaAncient(rand), 2);
		world.setBlock(i + 4, j + 7, k + 3, StructureGenHelper.blockChance90p(rand, Blocks.stonebrick), StructureGenHelper.stoneBrickMetaAncient(rand), 2);
		world.setBlock(i + 4, j + 7, k + 4, StructureGenHelper.blockChance90p(rand, Blocks.stonebrick), StructureGenHelper.stoneBrickMetaAncient(rand), 2);
		world.setBlock(i + 4, j + 7, k + 5, StructureGenHelper.blockChance90p(rand, Blocks.stonebrick), StructureGenHelper.stoneBrickMetaAncient(rand), 2);
		world.setBlock(i + 4, j + 7, k + 6, StructureGenHelper.blockChance90p(rand, Blocks.stonebrick), StructureGenHelper.stoneBrickMetaAncient(rand), 2);
		world.setBlock(i + 4, j + 7, k + 7, StructureGenHelper.blockChance90p(rand, Blocks.stonebrick), StructureGenHelper.stoneBrickMetaAncient(rand), 2);
		world.setBlock(i + 4, j + 7, k + 8, StructureGenHelper.blockChance90p(rand, Blocks.stonebrick), StructureGenHelper.stoneBrickMetaAncient(rand), 2);
		world.setBlock(i + 4, j + 7, k + 9, StructureGenHelper.blockChance90p(rand, Blocks.stonebrick), StructureGenHelper.stoneBrickMetaAncient(rand), 2);
		world.setBlock(i + 4, j + 7, k + 10, StructureGenHelper.blockChance90p(rand, Blocks.stonebrick), StructureGenHelper.stoneBrickMetaAncient(rand), 2);
		world.setBlock(i + 4, j + 7, k + 11, StructureGenHelper.blockChance90p(rand, Blocks.stonebrick), StructureGenHelper.stoneBrickMetaAncient(rand), 2);
		world.setBlock(i + 4, j + 8, k + 3, StructureGenHelper.blockChance90p(rand, Blocks.stonebrick), StructureGenHelper.stoneBrickMetaAncient(rand), 2);
		world.setBlock(i + 4, j + 8, k + 4, StructureGenHelper.blockChance90p(rand, Blocks.stonebrick), StructureGenHelper.stoneBrickMetaAncient(rand), 2);
		world.setBlock(i + 4, j + 8, k + 5, StructureGenHelper.blockChance90p(rand, Blocks.stonebrick), StructureGenHelper.stoneBrickMetaAncient(rand), 2);
		world.setBlock(i + 4, j + 8, k + 6, StructureGenHelper.blockChance90p(rand, Blocks.stonebrick), StructureGenHelper.stoneBrickMetaAncient(rand), 2);
		world.setBlock(i + 4, j + 8, k + 7, StructureGenHelper.blockChance90p(rand, Blocks.stonebrick), StructureGenHelper.stoneBrickMetaAncient(rand), 2);
		world.setBlock(i + 4, j + 8, k + 8, StructureGenHelper.blockChance90p(rand, Blocks.stonebrick), StructureGenHelper.stoneBrickMetaAncient(rand), 2);
		world.setBlock(i + 4, j + 8, k + 9, StructureGenHelper.blockChance90p(rand, Blocks.stonebrick), StructureGenHelper.stoneBrickMetaAncient(rand), 2);
		world.setBlock(i + 4, j + 8, k + 10, StructureGenHelper.blockChance90p(rand, Blocks.stonebrick), StructureGenHelper.stoneBrickMetaAncient(rand), 2);
		world.setBlock(i + 4, j + 8, k + 11, StructureGenHelper.blockChance90p(rand, Blocks.stonebrick), StructureGenHelper.stoneBrickMetaAncient(rand), 2);
		world.setBlock(i + 4, j + 9, k + 3, StructureGenHelper.blockChance90p(rand, Blocks.stonebrick), StructureGenHelper.stoneBrickMetaAncient(rand), 2);
		world.setBlock(i + 4, j + 9, k + 4, StructureGenHelper.blockChance90p(rand, Blocks.stonebrick), StructureGenHelper.stoneBrickMetaAncient(rand), 2);
		world.setBlock(i + 4, j + 9, k + 5, StructureGenHelper.blockChance90p(rand, Blocks.stonebrick), StructureGenHelper.stoneBrickMetaAncient(rand), 2);
		world.setBlock(i + 4, j + 9, k + 6, StructureGenHelper.blockChance90p(rand, Blocks.stonebrick), StructureGenHelper.stoneBrickMetaAncient(rand), 2);
		world.setBlock(i + 4, j + 9, k + 7, StructureGenHelper.blockChance90p(rand, Blocks.stonebrick), StructureGenHelper.stoneBrickMetaAncient(rand), 2);
		world.setBlock(i + 4, j + 9, k + 8, StructureGenHelper.blockChance90p(rand, Blocks.stonebrick), StructureGenHelper.stoneBrickMetaAncient(rand), 2);
		world.setBlock(i + 4, j + 9, k + 9, StructureGenHelper.blockChance90p(rand, Blocks.stonebrick), StructureGenHelper.stoneBrickMetaAncient(rand), 2);
		world.setBlock(i + 4, j + 9, k + 10, StructureGenHelper.blockChance90p(rand, Blocks.stonebrick), StructureGenHelper.stoneBrickMetaAncient(rand), 2);
		world.setBlock(i + 4, j + 9, k + 11, StructureGenHelper.blockChance90p(rand, Blocks.stonebrick), StructureGenHelper.stoneBrickMetaAncient(rand), 2);
		world.setBlock(i + 4, j + 10, k + 1, StructureGenHelper.blockChance90p(rand, Blocks.oak_stairs), 6, 2);
		world.setBlock(i + 4, j + 10, k + 2, StructureGenHelper.blockChance90p(rand, Blocks.planks), 0, 2);
		world.setBlock(i + 4, j + 10, k + 3, StructureGenHelper.blockChance90p(rand, Blocks.stonebrick), StructureGenHelper.stoneBrickMetaAncient(rand), 2);
		world.setBlock(i + 4, j + 10, k + 4, StructureGenHelper.blockChance90p(rand, Blocks.stonebrick), StructureGenHelper.stoneBrickMetaAncient(rand), 2);
		world.setBlock(i + 4, j + 10, k + 5, StructureGenHelper.blockChance90p(rand, Blocks.stonebrick), StructureGenHelper.stoneBrickMetaAncient(rand), 2);
		world.setBlock(i + 4, j + 10, k + 6, StructureGenHelper.blockChance90p(rand, Blocks.stonebrick), StructureGenHelper.stoneBrickMetaAncient(rand), 2);
		world.setBlock(i + 4, j + 10, k + 7, StructureGenHelper.blockChance90p(rand, Blocks.stonebrick), StructureGenHelper.stoneBrickMetaAncient(rand), 2);
		world.setBlock(i + 4, j + 10, k + 8, StructureGenHelper.blockChance90p(rand, Blocks.stonebrick), StructureGenHelper.stoneBrickMetaAncient(rand), 2);
		world.setBlock(i + 4, j + 10, k + 9, StructureGenHelper.blockChance90p(rand, Blocks.stonebrick), StructureGenHelper.stoneBrickMetaAncient(rand), 2);
		world.setBlock(i + 4, j + 10, k + 10, StructureGenHelper.blockChance90p(rand, Blocks.stonebrick), StructureGenHelper.stoneBrickMetaAncient(rand), 2);
		world.setBlock(i + 4, j + 10, k + 11, StructureGenHelper.blockChance90p(rand, Blocks.stonebrick), StructureGenHelper.stoneBrickMetaAncient(rand), 2);
		world.setBlock(i + 4, j + 11, k + 0, StructureGenHelper.blockChance90p(rand, Blocks.oak_stairs), 6, 2);
		world.setBlock(i + 4, j + 11, k + 1, StructureGenHelper.blockChance90p(rand, Blocks.planks), 0, 2);
		world.setBlock(i + 4, j + 11, k + 2, StructureGenHelper.blockChance90p(rand, Blocks.planks), 0, 2);
		world.setBlock(i + 4, j + 11, k + 3, StructureGenHelper.blockChance90p(rand, Blocks.stonebrick), StructureGenHelper.stoneBrickMetaAncient(rand), 2);
		world.setBlock(i + 4, j + 11, k + 4, StructureGenHelper.blockChance90p(rand, Blocks.stonebrick), StructureGenHelper.stoneBrickMetaAncient(rand), 2);
		world.setBlock(i + 4, j + 11, k + 5, StructureGenHelper.blockChance90p(rand, Blocks.stonebrick), StructureGenHelper.stoneBrickMetaAncient(rand), 2);
		world.setBlock(i + 4, j + 11, k + 6, StructureGenHelper.blockChance90p(rand, Blocks.stonebrick), StructureGenHelper.stoneBrickMetaAncient(rand), 2);
		world.setBlock(i + 4, j + 11, k + 7, StructureGenHelper.blockChance90p(rand, Blocks.stonebrick), StructureGenHelper.stoneBrickMetaAncient(rand), 2);
		world.setBlock(i + 4, j + 11, k + 8, StructureGenHelper.blockChance90p(rand, Blocks.stonebrick), StructureGenHelper.stoneBrickMetaAncient(rand), 2);
		world.setBlock(i + 4, j + 11, k + 9, StructureGenHelper.blockChance90p(rand, Blocks.stonebrick), StructureGenHelper.stoneBrickMetaAncient(rand), 2);
		world.setBlock(i + 4, j + 11, k + 10, StructureGenHelper.blockChance90p(rand, Blocks.stonebrick), StructureGenHelper.stoneBrickMetaAncient(rand), 2);
		world.setBlock(i + 4, j + 11, k + 11, StructureGenHelper.blockChance90p(rand, Blocks.stonebrick), StructureGenHelper.stoneBrickMetaAncient(rand), 2);
		world.setBlock(i + 4, j + 12, k + 0, StructureGenHelper.blockChance90p(rand, Blocks.planks), 0, 2);
		world.setBlock(i + 4, j + 12, k + 1, StructureGenHelper.blockChance90p(rand, Blocks.stonebrick), StructureGenHelper.stoneBrickMetaAncient(rand), 2);
		world.setBlock(i + 4, j + 12, k + 2, StructureGenHelper.blockChance90p(rand, Blocks.planks), 0, 2);
		world.setBlock(i + 4, j + 12, k + 3, Blocks.air);
		world.setBlock(i + 4, j + 12, k + 4, StructureGenHelper.blockChance90p(rand, Blocks.stonebrick), StructureGenHelper.stoneBrickMetaAncient(rand), 2);
		world.setBlock(i + 4, j + 12, k + 5, StructureGenHelper.blockChance90p(rand, Blocks.stonebrick), StructureGenHelper.stoneBrickMetaAncient(rand), 2);
		world.setBlock(i + 4, j + 12, k + 6, StructureGenHelper.blockChance90p(rand, Blocks.stonebrick), StructureGenHelper.stoneBrickMetaAncient(rand), 2);
		world.setBlock(i + 4, j + 12, k + 8, StructureGenHelper.randomBlock(rand, new Block[]{Blocks.glowstone, Blocks.air}), 0, 2);
		world.setBlock(i + 4, j + 12, k + 9, StructureGenHelper.blockChance90p(rand, Blocks.stonebrick), StructureGenHelper.stoneBrickMetaAncient(rand), 2);
		world.setBlock(i + 4, j + 12, k + 10, StructureGenHelper.blockChance90p(rand, Blocks.stonebrick), StructureGenHelper.stoneBrickMetaAncient(rand), 2);
		world.setBlock(i + 4, j + 13, k + 0, StructureGenHelper.blockChance90p(rand, Blocks.planks), 0, 2);
		world.setBlock(i + 4, j + 13, k + 2, StructureGenHelper.blockChance90p(rand, Blocks.planks), 0, 2);
		world.setBlock(i + 4, j + 13, k + 3, Blocks.air);
		world.setBlock(i + 4, j + 13, k + 4, Blocks.redstone_lamp, 0, 2);
		world.setBlock(i + 4, j + 13, k + 5, StructureGenHelper.blockChance90p(rand, Blocks.stonebrick), StructureGenHelper.stoneBrickMetaAncient(rand), 2);
		world.setBlock(i + 4, j + 13, k + 6, StructureGenHelper.blockChance90p(rand, Blocks.stonebrick), StructureGenHelper.stoneBrickMetaAncient(rand), 2);
		world.setBlock(i + 4, j + 13, k + 9, StructureGenHelper.blockChance90p(rand, Blocks.stonebrick), StructureGenHelper.stoneBrickMetaAncient(rand), 2);
		world.setBlock(i + 4, j + 13, k + 10, StructureGenHelper.blockChance90p(rand, Blocks.stonebrick), StructureGenHelper.stoneBrickMetaAncient(rand), 2);
		world.setBlock(i + 4, j + 14, k + 0, StructureGenHelper.blockChance90p(rand, Blocks.planks), 0, 2);
		world.setBlock(i + 4, j + 14, k + 1, Blocks.air);
		world.setBlock(i + 4, j + 14, k + 2, StructureGenHelper.blockChance90p(rand, Blocks.planks), 0, 2);
		world.setBlock(i + 4, j + 14, k + 3, Blocks.air);
		world.setBlock(i + 4, j + 14, k + 4, StructureGenHelper.blockChance90p(rand, Blocks.stonebrick), StructureGenHelper.stoneBrickMetaAncient(rand), 2);
		world.setBlock(i + 4, j + 14, k + 5, StructureGenHelper.blockChance90p(rand, Blocks.stonebrick), StructureGenHelper.stoneBrickMetaAncient(rand), 2);
		world.setBlock(i + 4, j + 14, k + 6, StructureGenHelper.blockChance90p(rand, Blocks.stonebrick), StructureGenHelper.stoneBrickMetaAncient(rand), 2);
		world.setBlock(i + 4, j + 14, k + 8, StructureGenHelper.blockChance90p(rand, Blocks.stonebrick), StructureGenHelper.stoneBrickMetaAncient(rand), 2);
		world.setBlock(i + 4, j + 14, k + 9, StructureGenHelper.blockChance90p(rand, Blocks.stonebrick), StructureGenHelper.stoneBrickMetaAncient(rand), 2);
		world.setBlock(i + 4, j + 14, k + 10, StructureGenHelper.blockChance90p(rand, Blocks.stonebrick), StructureGenHelper.stoneBrickMetaAncient(rand), 2);
		world.setBlock(i + 4, j + 15, k + 0, StructureGenHelper.blockChance90p(rand, Blocks.oak_stairs), 2, 2);
		world.setBlock(i + 4, j + 15, k + 1, Blocks.air);
		world.setBlock(i + 4, j + 15, k + 3, StructureGenHelper.blockChance90p(rand, Blocks.planks), 0, 2);
		world.setBlock(i + 4, j + 15, k + 4, StructureGenHelper.blockChance90p(rand, Blocks.stonebrick), StructureGenHelper.stoneBrickMetaAncient(rand), 2);
		world.setBlock(i + 4, j + 15, k + 5, StructureGenHelper.blockChance90p(rand, Blocks.stonebrick), StructureGenHelper.stoneBrickMetaAncient(rand), 2);
		world.setBlock(i + 4, j + 15, k + 6, StructureGenHelper.blockChance90p(rand, Blocks.stonebrick), StructureGenHelper.stoneBrickMetaAncient(rand), 2);
		world.setBlock(i + 4, j + 15, k + 8, StructureGenHelper.blockChance90p(rand, Blocks.stonebrick), StructureGenHelper.stoneBrickMetaAncient(rand), 2);
		world.setBlock(i + 4, j + 15, k + 9, StructureGenHelper.blockChance90p(rand, Blocks.stonebrick), StructureGenHelper.stoneBrickMetaAncient(rand), 2);
		world.setBlock(i + 4, j + 15, k + 10, StructureGenHelper.blockChance90p(rand, Blocks.stonebrick), StructureGenHelper.stoneBrickMetaAncient(rand), 2);
		world.setBlock(i + 4, j + 16, k + 1, StructureGenHelper.blockChance90p(rand, Blocks.oak_stairs), 2, 2);
		world.setBlock(i + 4, j + 16, k + 3, StructureGenHelper.blockChance90p(rand, Blocks.planks), 0, 2);
		world.setBlock(i + 4, j + 16, k + 4, StructureGenHelper.blockChance90p(rand, Blocks.planks), 0, 2);
		world.setBlock(i + 4, j + 16, k + 5, StructureGenHelper.blockChance90p(rand, Blocks.stonebrick), StructureGenHelper.stoneBrickMetaAncient(rand), 2);
		world.setBlock(i + 4, j + 16, k + 6, Blocks.air);
		world.setBlock(i + 4, j + 16, k + 7, Blocks.air);
		world.setBlock(i + 4, j + 16, k + 8, Blocks.air);
		world.setBlock(i + 4, j + 16, k + 9, StructureGenHelper.blockChance90p(rand, Blocks.stonebrick), StructureGenHelper.stoneBrickMetaAncient(rand), 2);
		world.setBlock(i + 4, j + 17, k + 2, Blocks.air);
		world.setBlock(i + 4, j + 17, k + 3, StructureGenHelper.blockChance90p(rand, Blocks.planks), 0, 2);
		world.setBlock(i + 4, j + 17, k + 4, StructureGenHelper.blockChance90p(rand, Blocks.planks), 0, 2);
		world.setBlock(i + 4, j + 17, k + 5, StructureGenHelper.blockChance90p(rand, Blocks.stonebrick), StructureGenHelper.stoneBrickMetaAncient(rand), 2);
		world.setBlock(i + 4, j + 17, k + 6, Blocks.air);
		world.setBlock(i + 4, j + 17, k + 7, Blocks.air);
		world.setBlock(i + 4, j + 17, k + 8, Blocks.air);
		world.setBlock(i + 4, j + 17, k + 9, StructureGenHelper.blockChance90p(rand, Blocks.stonebrick), StructureGenHelper.stoneBrickMetaAncient(rand), 2);
		world.setBlock(i + 4, j + 18, k + 3, StructureGenHelper.blockChance90p(rand, Blocks.wooden_slab), 0, 2);
		world.setBlock(i + 4, j + 18, k + 5, StructureGenHelper.blockChance90p(rand, Blocks.stonebrick), StructureGenHelper.stoneBrickMetaAncient(rand), 2);
		world.setBlock(i + 4, j + 18, k + 6, StructureGenHelper.blockChance90p(rand, Blocks.stonebrick), StructureGenHelper.stoneBrickMetaAncient(rand), 2);
		world.setBlock(i + 4, j + 18, k + 7, StructureGenHelper.blockChance90p(rand, Blocks.stonebrick), StructureGenHelper.stoneBrickMetaAncient(rand), 2);
		world.setBlock(i + 4, j + 18, k + 8, StructureGenHelper.blockChance90p(rand, Blocks.stonebrick), StructureGenHelper.stoneBrickMetaAncient(rand), 2);
		world.setBlock(i + 4, j + 18, k + 9, StructureGenHelper.blockChance90p(rand, Blocks.stonebrick), StructureGenHelper.stoneBrickMetaAncient(rand), 2);
		world.setBlock(i + 4, j + 18, k + 10, StructureGenHelper.blockChance90p(rand, Blocks.oak_stairs), 5, 2);
		world.setBlock(i + 4, j + 18, k + 11, StructureGenHelper.blockChance90p(rand, Blocks.oak_stairs), 5, 2);
		world.setBlock(i + 4, j + 18, k + 12, StructureGenHelper.blockChance90p(rand, Blocks.oak_stairs), 5, 2);
		world.setBlock(i + 4, j + 19, k + 6, StructureGenHelper.blockChance90p(rand, Blocks.stonebrick), StructureGenHelper.stoneBrickMetaAncient(rand), 2);
		world.setBlock(i + 4, j + 19, k + 7, Blocks.air);
		world.setBlock(i + 4, j + 19, k + 8, Blocks.air);
		world.setBlock(i + 4, j + 19, k + 10, StructureGenHelper.blockChance90p(rand, Blocks.planks), 0, 2);
		world.setBlock(i + 4, j + 19, k + 11, StructureGenHelper.blockChance90p(rand, Blocks.planks), 0, 2);
		world.setBlock(i + 4, j + 19, k + 12, StructureGenHelper.blockChance90p(rand, Blocks.planks), 0, 2);
		world.setBlock(i + 4, j + 20, k + 6, StructureGenHelper.blockChance90p(rand, Blocks.stonebrick), StructureGenHelper.stoneBrickMetaAncient(rand), 2);
		world.setBlock(i + 4, j + 20, k + 7, Blocks.air);
		world.setBlock(i + 4, j + 20, k + 8, Blocks.air);
		world.setBlock(i + 4, j + 20, k + 10, StructureGenHelper.blockChance90p(rand, Blocks.planks), 0, 2);
		world.setBlock(i + 4, j + 20, k + 11, StructureGenHelper.blockChance90p(rand, Blocks.planks), 0, 2);
		world.setBlock(i + 4, j + 20, k + 12, StructureGenHelper.blockChance90p(rand, Blocks.planks), 0, 2);
		world.setBlock(i + 4, j + 21, k + 6, StructureGenHelper.blockChance90p(rand, Blocks.stonebrick), StructureGenHelper.stoneBrickMetaAncient(rand), 2);
		world.setBlock(i + 4, j + 21, k + 7, StructureGenHelper.blockChance90p(rand, Blocks.stonebrick), StructureGenHelper.stoneBrickMetaAncient(rand), 2);
		world.setBlock(i + 4, j + 21, k + 8, StructureGenHelper.blockChance90p(rand, Blocks.stonebrick), StructureGenHelper.stoneBrickMetaAncient(rand), 2);
		//world.scheduleBlockUpdate(i + 4, j + 21, k + 9, Blocks.daylight_detector, 10);
		world.setBlock(i + 4, j + 21, k + 10, StructureGenHelper.blockChance90p(rand, Blocks.planks), 0, 2);
		world.setBlock(i + 4, j + 21, k + 11, StructureGenHelper.blockChance90p(rand, Blocks.planks), 0, 2);
		world.setBlock(i + 4, j + 21, k + 12, StructureGenHelper.blockChance90p(rand, Blocks.planks), 0, 2);
		world.setBlock(i + 4, j + 22, k + 7, StructureGenHelper.blockChance90p(rand, Blocks.stonebrick), StructureGenHelper.stoneBrickMetaAncient(rand), 2);
		world.setBlock(i + 4, j + 22, k + 10, StructureGenHelper.blockChance90p(rand, Blocks.oak_stairs), 2, 2);
		world.setBlock(i + 4, j + 22, k + 11, StructureGenHelper.blockChance90p(rand, Blocks.oak_stairs), 1, 2);
		world.setBlock(i + 4, j + 22, k + 12, StructureGenHelper.blockChance90p(rand, Blocks.oak_stairs), 3, 2);
		world.setBlock(i + 4, j + 23, k + 7, StructureGenHelper.blockChance90p(rand, Blocks.stone_brick_stairs), 0, 2);
		world.setBlock(i + 4, j + 27, k + 5, StructureGenHelper.blockChance90p(rand, Blocks.stone_brick_stairs), 4, 2);
		world.setBlock(i + 4, j + 27, k + 6, StructureGenHelper.blockChance90p(rand, Blocks.stone_brick_stairs), 4, 2);
		world.setBlock(i + 4, j + 27, k + 7, StructureGenHelper.blockChance90p(rand, Blocks.stone_brick_stairs), 4, 2);
		world.setBlock(i + 4, j + 27, k + 8, StructureGenHelper.blockChance90p(rand, Blocks.stone_brick_stairs), 4, 2);
		world.setBlock(i + 4, j + 27, k + 9, StructureGenHelper.blockChance90p(rand, Blocks.stone_brick_stairs), 4, 2);
		world.setBlock(i + 4, j + 28, k + 5, StructureGenHelper.blockChance90p(rand, Blocks.stonebrick), StructureGenHelper.stoneBrickMetaAncient(rand), 2);
		world.setBlock(i + 4, j + 28, k + 6, StructureGenHelper.blockChance90p(rand, Blocks.stonebrick), StructureGenHelper.stoneBrickMetaAncient(rand), 2);
		world.setBlock(i + 4, j + 28, k + 7, StructureGenHelper.blockChance90p(rand, Blocks.stonebrick), StructureGenHelper.stoneBrickMetaAncient(rand), 2);
		world.setBlock(i + 4, j + 28, k + 8, StructureGenHelper.blockChance90p(rand, Blocks.stonebrick), StructureGenHelper.stoneBrickMetaAncient(rand), 2);
		world.setBlock(i + 4, j + 28, k + 9, StructureGenHelper.blockChance90p(rand, Blocks.stonebrick), StructureGenHelper.stoneBrickMetaAncient(rand), 2);
		world.setBlock(i + 4, j + 29, k + 5, StructureGenHelper.blockChance90p(rand, Blocks.stonebrick), StructureGenHelper.stoneBrickMetaAncient(rand), 2);
		world.setBlock(i + 4, j + 29, k + 6, Blocks.air);
		world.setBlock(i + 4, j + 29, k + 7, Blocks.air);
		world.setBlock(i + 4, j + 29, k + 8, Blocks.air);
		world.setBlock(i + 4, j + 29, k + 9, StructureGenHelper.blockChance90p(rand, Blocks.stonebrick), StructureGenHelper.stoneBrickMetaAncient(rand), 2);
		world.setBlock(i + 4, j + 30, k + 6, Blocks.air);
		world.setBlock(i + 4, j + 30, k + 7, Blocks.air);
		world.setBlock(i + 4, j + 30, k + 8, Blocks.air);
		world.setBlock(i + 5, j + 0, k + 2, StructureGenHelper.blockChance90p(rand, Blocks.stonebrick), StructureGenHelper.stoneBrickMetaAncient(rand), 2);
		world.setBlock(i + 5, j + 0, k + 3, StructureGenHelper.blockChance90p(rand, Blocks.stonebrick), StructureGenHelper.stoneBrickMetaAncient(rand), 2);
		world.setBlock(i + 5, j + 0, k + 4, StructureGenHelper.blockChance90p(rand, Blocks.stonebrick), StructureGenHelper.stoneBrickMetaAncient(rand), 2);
		world.setBlock(i + 5, j + 0, k + 5, StructureGenHelper.blockChance90p(rand, Blocks.stonebrick), StructureGenHelper.stoneBrickMetaAncient(rand), 2);
		world.setBlock(i + 5, j + 0, k + 6, StructureGenHelper.blockChance90p(rand, Blocks.stonebrick), StructureGenHelper.stoneBrickMetaAncient(rand), 2);
		world.setBlock(i + 5, j + 0, k + 7, StructureGenHelper.blockChance90p(rand, Blocks.stonebrick), StructureGenHelper.stoneBrickMetaAncient(rand), 2);
		world.setBlock(i + 5, j + 0, k + 8, StructureGenHelper.blockChance90p(rand, Blocks.stonebrick), StructureGenHelper.stoneBrickMetaAncient(rand), 2);
		world.setBlock(i + 5, j + 0, k + 9, StructureGenHelper.blockChance90p(rand, Blocks.stonebrick), StructureGenHelper.stoneBrickMetaAncient(rand), 2);
		world.setBlock(i + 5, j + 0, k + 10, StructureGenHelper.blockChance90p(rand, Blocks.stonebrick), StructureGenHelper.stoneBrickMetaAncient(rand), 2);
		world.setBlock(i + 5, j + 0, k + 11, StructureGenHelper.blockChance90p(rand, Blocks.stonebrick), StructureGenHelper.stoneBrickMetaAncient(rand), 2);
		world.setBlock(i + 5, j + 0, k + 12, StructureGenHelper.blockChance90p(rand, Blocks.stonebrick), StructureGenHelper.stoneBrickMetaAncient(rand), 2);
		world.setBlock(i + 5, j + 1, k + 2, StructureGenHelper.blockChance90p(rand, Blocks.stonebrick), StructureGenHelper.stoneBrickMetaAncient(rand), 2);
		world.setBlock(i + 5, j + 1, k + 3, StructureGenHelper.blockChance90p(rand, Blocks.stonebrick), StructureGenHelper.stoneBrickMetaAncient(rand), 2);
		world.setBlock(i + 5, j + 1, k + 4, StructureGenHelper.blockChance90p(rand, Blocks.stonebrick), StructureGenHelper.stoneBrickMetaAncient(rand), 2);
		world.setBlock(i + 5, j + 1, k + 5, BlockSpikes.instance, 0, 2);
		world.setBlock(i + 5, j + 1, k + 6, BlockSpikes.instance, 0, 2);
		world.setBlock(i + 5, j + 1, k + 7, BlockSpikes.instance, 0, 2);
		world.setBlock(i + 5, j + 1, k + 8, StructureGenHelper.blockChance90p(rand, Blocks.stonebrick), StructureGenHelper.stoneBrickMetaAncient(rand), 2);
		world.setBlock(i + 5, j + 1, k + 9, StructureGenHelper.blockChance90p(rand, Blocks.stonebrick), StructureGenHelper.stoneBrickMetaAncient(rand), 2);
		world.setBlock(i + 5, j + 1, k + 10, StructureGenHelper.blockChance90p(rand, Blocks.stonebrick), StructureGenHelper.stoneBrickMetaAncient(rand), 2);
		world.setBlock(i + 5, j + 1, k + 11, StructureGenHelper.blockChance90p(rand, Blocks.stonebrick), StructureGenHelper.stoneBrickMetaAncient(rand), 2);
		world.setBlock(i + 5, j + 1, k + 12, StructureGenHelper.blockChance90p(rand, Blocks.stonebrick), StructureGenHelper.stoneBrickMetaAncient(rand), 2);
		world.setBlock(i + 5, j + 2, k + 2, StructureGenHelper.blockChance90p(rand, Blocks.stonebrick), StructureGenHelper.stoneBrickMetaAncient(rand), 2);
		world.setBlock(i + 5, j + 2, k + 3, StructureGenHelper.blockChance90p(rand, Blocks.stonebrick), StructureGenHelper.stoneBrickMetaAncient(rand), 2);
		world.setBlock(i + 5, j + 2, k + 4, StructureGenHelper.blockChance90p(rand, Blocks.stonebrick), StructureGenHelper.stoneBrickMetaAncient(rand), 2);
		world.setBlock(i + 5, j + 2, k + 5, BlockIllusionary.instance, 0, 2);
		world.setBlock(i + 5, j + 2, k + 6, BlockIllusionary.instance, 0, 2);
		world.setBlock(i + 5, j + 2, k + 7, BlockIllusionary.instance, 0, 2);
		world.setBlock(i + 5, j + 2, k + 8, StructureGenHelper.blockChance90p(rand, Blocks.stonebrick), StructureGenHelper.stoneBrickMetaAncient(rand), 2);
		world.setBlock(i + 5, j + 2, k + 9, StructureGenHelper.blockChance90p(rand, Blocks.stonebrick), StructureGenHelper.stoneBrickMetaAncient(rand), 2);
		world.setBlock(i + 5, j + 2, k + 10, StructureGenHelper.blockChance90p(rand, Blocks.stonebrick), StructureGenHelper.stoneBrickMetaAncient(rand), 2);
		world.setBlock(i + 5, j + 2, k + 11, StructureGenHelper.blockChance90p(rand, Blocks.stonebrick), StructureGenHelper.stoneBrickMetaAncient(rand), 2);
		world.setBlock(i + 5, j + 2, k + 12, StructureGenHelper.blockChance90p(rand, Blocks.stonebrick), StructureGenHelper.stoneBrickMetaAncient(rand), 2);
		world.setBlock(i + 5, j + 3, k + 2, StructureGenHelper.blockChance90p(rand, Blocks.stonebrick), StructureGenHelper.stoneBrickMetaAncient(rand), 2);
		world.setBlock(i + 5, j + 3, k + 3, StructureGenHelper.blockChance90p(rand, Blocks.stonebrick), StructureGenHelper.stoneBrickMetaAncient(rand), 2);
		world.setBlock(i + 5, j + 3, k + 4, BlockTrap.instance, 3, 2);
		world.setBlockMetadataWithNotify(i + 5, j + 3, k + 4, 3, 2);
		world.setBlock(i + 5, j + 3, k + 5, Blocks.air);
		world.setBlock(i + 5, j + 3, k + 6, Blocks.air);
		world.setBlock(i + 5, j + 3, k + 7, Blocks.air);
		world.setBlock(i + 5, j + 3, k + 8, BlockTrap.instance, 2, 2);
		world.setBlockMetadataWithNotify(i + 5, j + 3, k + 8, 2, 2);
		world.setBlock(i + 5, j + 3, k + 9, Blocks.air);
		world.setBlock(i + 5, j + 3, k + 10, Blocks.air);
		world.setBlock(i + 5, j + 3, k + 11, Blocks.air);
		world.setBlock(i + 5, j + 3, k + 12, StructureGenHelper.blockChance90p(rand, Blocks.stonebrick), StructureGenHelper.stoneBrickMetaAncient(rand), 2);
		world.setBlock(i + 5, j + 4, k + 2, StructureGenHelper.blockChance90p(rand, Blocks.stonebrick), StructureGenHelper.stoneBrickMetaAncient(rand), 2);
		world.setBlock(i + 5, j + 4, k + 3, StructureGenHelper.blockChance90p(rand, Blocks.stonebrick), StructureGenHelper.stoneBrickMetaAncient(rand), 2);
		world.setBlock(i + 5, j + 4, k + 4, StructureGenHelper.blockChance90p(rand, Blocks.stonebrick), StructureGenHelper.stoneBrickMetaAncient(rand), 2);
		world.setBlock(i + 5, j + 4, k + 5, Blocks.air);
		world.setBlock(i + 5, j + 4, k + 6, Blocks.air);
		world.setBlock(i + 5, j + 4, k + 7, Blocks.air);
		world.setBlock(i + 5, j + 4, k + 8, StructureGenHelper.blockChance90p(rand, Blocks.stonebrick), StructureGenHelper.stoneBrickMetaAncient(rand), 2);
		world.setBlock(i + 5, j + 4, k + 9, Blocks.air);
		world.setBlock(i + 5, j + 4, k + 10, Blocks.air);
		world.setBlock(i + 5, j + 4, k + 11, Blocks.air);
		world.setBlock(i + 5, j + 4, k + 12, StructureGenHelper.blockChance90p(rand, Blocks.stonebrick), StructureGenHelper.stoneBrickMetaAncient(rand), 2);
		world.setBlock(i + 5, j + 5, k + 2, StructureGenHelper.blockChance90p(rand, Blocks.stonebrick), StructureGenHelper.stoneBrickMetaAncient(rand), 2);
		world.setBlock(i + 5, j + 5, k + 3, StructureGenHelper.blockChance90p(rand, Blocks.stonebrick), StructureGenHelper.stoneBrickMetaAncient(rand), 2);
		world.setBlock(i + 5, j + 5, k + 4, StructureGenHelper.blockChance90p(rand, Blocks.stonebrick), StructureGenHelper.stoneBrickMetaAncient(rand), 2);
		world.setBlock(i + 5, j + 5, k + 5, Blocks.air);
		world.setBlock(i + 5, j + 5, k + 6, Blocks.air);
		world.setBlock(i + 5, j + 5, k + 7, Blocks.air);
		world.setBlock(i + 5, j + 5, k + 8, StructureGenHelper.blockChance90p(rand, Blocks.stonebrick), StructureGenHelper.stoneBrickMetaAncient(rand), 2);
		world.setBlock(i + 5, j + 5, k + 9, Blocks.air);
		world.setBlock(i + 5, j + 5, k + 10, Blocks.air);
		world.setBlock(i + 5, j + 5, k + 11, Blocks.air);
		world.setBlock(i + 5, j + 5, k + 12, StructureGenHelper.blockChance90p(rand, Blocks.stonebrick), StructureGenHelper.stoneBrickMetaAncient(rand), 2);
		world.setBlock(i + 5, j + 6, k + 2, StructureGenHelper.blockChance90p(rand, Blocks.stonebrick), StructureGenHelper.stoneBrickMetaAncient(rand), 2);
		world.setBlock(i + 5, j + 6, k + 3, StructureGenHelper.blockChance90p(rand, Blocks.stonebrick), StructureGenHelper.stoneBrickMetaAncient(rand), 2);
		world.setBlock(i + 5, j + 6, k + 4, StructureGenHelper.blockChance90p(rand, Blocks.stonebrick), StructureGenHelper.stoneBrickMetaAncient(rand), 2);
		world.setBlock(i + 5, j + 6, k + 5, Blocks.air);
		world.setBlock(i + 5, j + 6, k + 6, Blocks.air);
		world.setBlock(i + 5, j + 6, k + 7, Blocks.air);
		world.setBlock(i + 5, j + 6, k + 8, StructureGenHelper.blockChance90p(rand, Blocks.stonebrick), StructureGenHelper.stoneBrickMetaAncient(rand), 2);
		world.setBlock(i + 5, j + 6, k + 9, Blocks.air);
		world.setBlock(i + 5, j + 6, k + 10, Blocks.air);
		world.setBlock(i + 5, j + 6, k + 11, Blocks.air);
		world.setBlock(i + 5, j + 6, k + 12, StructureGenHelper.blockChance90p(rand, Blocks.stonebrick), StructureGenHelper.stoneBrickMetaAncient(rand), 2);
		world.setBlock(i + 5, j + 7, k + 2, StructureGenHelper.blockChance90p(rand, Blocks.stonebrick), StructureGenHelper.stoneBrickMetaAncient(rand), 2);
		world.setBlock(i + 5, j + 7, k + 3, StructureGenHelper.blockChance90p(rand, Blocks.stonebrick), StructureGenHelper.stoneBrickMetaAncient(rand), 2);
		world.setBlock(i + 5, j + 7, k + 4, StructureGenHelper.blockChance90p(rand, Blocks.stonebrick), StructureGenHelper.stoneBrickMetaAncient(rand), 2);
		world.setBlock(i + 5, j + 7, k + 5, StructureGenHelper.blockChance90p(rand, Blocks.stonebrick), StructureGenHelper.stoneBrickMetaAncient(rand), 2);
		world.setBlock(i + 5, j + 7, k + 6, StructureGenHelper.blockChance90p(rand, Blocks.stonebrick), StructureGenHelper.stoneBrickMetaAncient(rand), 2);
		world.setBlock(i + 5, j + 7, k + 7, StructureGenHelper.blockChance90p(rand, Blocks.stonebrick), StructureGenHelper.stoneBrickMetaAncient(rand), 2);
		world.setBlock(i + 5, j + 7, k + 8, StructureGenHelper.blockChance90p(rand, Blocks.stonebrick), StructureGenHelper.stoneBrickMetaAncient(rand), 2);
		world.setBlock(i + 5, j + 7, k + 9, StructureGenHelper.blockChance90p(rand, Blocks.stonebrick), StructureGenHelper.stoneBrickMetaAncient(rand), 2);
		world.setBlock(i + 5, j + 7, k + 10, StructureGenHelper.blockChance90p(rand, Blocks.stonebrick), StructureGenHelper.stoneBrickMetaAncient(rand), 2);
		world.setBlock(i + 5, j + 7, k + 11, StructureGenHelper.blockChance90p(rand, Blocks.stonebrick), StructureGenHelper.stoneBrickMetaAncient(rand), 2);
		world.setBlock(i + 5, j + 7, k + 12, StructureGenHelper.blockChance90p(rand, Blocks.stonebrick), StructureGenHelper.stoneBrickMetaAncient(rand), 2);
		world.setBlock(i + 5, j + 8, k + 2, StructureGenHelper.blockChance90p(rand, Blocks.stonebrick), StructureGenHelper.stoneBrickMetaAncient(rand), 2);
		world.setBlock(i + 5, j + 8, k + 3, StructureGenHelper.blockChance90p(rand, Blocks.stonebrick), StructureGenHelper.stoneBrickMetaAncient(rand), 2);
		world.setBlock(i + 5, j + 8, k + 4, StructureGenHelper.randomBlock(rand, new Block[]{Blocks.anvil, Blocks.air, Blocks.air}), 0, 2);
		world.setBlock(i + 5, j + 8, k + 5, Blocks.air);
		world.setBlock(i + 5, j + 8, k + 6, Blocks.air);
		world.setBlock(i + 5, j + 8, k + 8, StructureGenHelper.randomBlock(rand, new Block[]{Blocks.bookshelf, Blocks.bookshelf, Blocks.air}), 0, 2);
		world.setBlock(i + 5, j + 8, k + 9, StructureGenHelper.randomBlock(rand, new Block[]{Blocks.bookshelf, Blocks.bookshelf, Blocks.air}), 0, 2);
		world.setBlock(i + 5, j + 8, k + 10, StructureGenHelper.randomBlock(rand, new Block[]{Blocks.bookshelf, Blocks.bookshelf, Blocks.air}), 0, 2);
		world.setBlock(i + 5, j + 8, k + 11, StructureGenHelper.blockChance90p(rand, Blocks.stonebrick), StructureGenHelper.stoneBrickMetaAncient(rand), 2);
		world.setBlock(i + 5, j + 8, k + 12, StructureGenHelper.blockChance90p(rand, Blocks.stonebrick), StructureGenHelper.stoneBrickMetaAncient(rand), 2);
		world.setBlock(i + 5, j + 9, k + 2, StructureGenHelper.blockChance90p(rand, Blocks.stonebrick), StructureGenHelper.stoneBrickMetaAncient(rand), 2);
		world.setBlock(i + 5, j + 9, k + 3, StructureGenHelper.blockChance90p(rand, Blocks.stonebrick), StructureGenHelper.stoneBrickMetaAncient(rand), 2);
		world.setBlock(i + 5, j + 9, k + 4, Blocks.air);
		world.setBlock(i + 5, j + 9, k + 5, Blocks.air);
		world.setBlock(i + 5, j + 9, k + 6, Blocks.air);
		world.setBlock(i + 5, j + 9, k + 8, StructureGenHelper.randomBlock(rand, new Block[]{Blocks.bookshelf, Blocks.air, Blocks.web}), 0, 2);
		world.setBlock(i + 5, j + 9, k + 9, StructureGenHelper.randomBlock(rand, new Block[]{Blocks.bookshelf, Blocks.air, Blocks.web}), 0, 2);
		world.setBlock(i + 5, j + 9, k + 10, StructureGenHelper.randomBlock(rand, new Block[]{Blocks.bookshelf, Blocks.air, Blocks.web}), 0, 2);
		world.setBlock(i + 5, j + 9, k + 11, StructureGenHelper.blockChance90p(rand, Blocks.stonebrick), StructureGenHelper.stoneBrickMetaAncient(rand), 2);
		world.setBlock(i + 5, j + 9, k + 12, StructureGenHelper.blockChance90p(rand, Blocks.stonebrick), StructureGenHelper.stoneBrickMetaAncient(rand), 2);
		world.setBlock(i + 5, j + 10, k + 1, StructureGenHelper.blockChance90p(rand, Blocks.oak_stairs), 6, 2);
		world.setBlock(i + 5, j + 10, k + 2, StructureGenHelper.blockChance90p(rand, Blocks.planks), 0, 2);
		world.setBlock(i + 5, j + 10, k + 3, StructureGenHelper.blockChance90p(rand, Blocks.stonebrick), StructureGenHelper.stoneBrickMetaAncient(rand), 2);
		world.setBlock(i + 5, j + 10, k + 4, StructureGenHelper.blockChance90p(rand, Blocks.stonebrick), StructureGenHelper.stoneBrickMetaAncient(rand), 2);
		world.setBlock(i + 5, j + 10, k + 5, StructureGenHelper.blockChance90p(rand, Blocks.stonebrick), StructureGenHelper.stoneBrickMetaAncient(rand), 2);
		world.setBlock(i + 5, j + 10, k + 6, StructureGenHelper.blockChance90p(rand, Blocks.stonebrick), StructureGenHelper.stoneBrickMetaAncient(rand), 2);
		world.setBlock(i + 5, j + 10, k + 7, StructureGenHelper.blockChance90p(rand, Blocks.stonebrick), StructureGenHelper.stoneBrickMetaAncient(rand), 2);
		world.setBlock(i + 5, j + 10, k + 8, StructureGenHelper.blockChance90p(rand, Blocks.stonebrick), StructureGenHelper.stoneBrickMetaAncient(rand), 2);
		world.setBlock(i + 5, j + 10, k + 9, StructureGenHelper.blockChance90p(rand, Blocks.stonebrick), StructureGenHelper.stoneBrickMetaAncient(rand), 2);
		world.setBlock(i + 5, j + 10, k + 10, StructureGenHelper.blockChance90p(rand, Blocks.stonebrick), StructureGenHelper.stoneBrickMetaAncient(rand), 2);
		world.setBlock(i + 5, j + 10, k + 11, StructureGenHelper.blockChance90p(rand, Blocks.stonebrick), StructureGenHelper.stoneBrickMetaAncient(rand), 2);
		world.setBlock(i + 5, j + 11, k + 0, StructureGenHelper.blockChance90p(rand, Blocks.oak_stairs), 6, 2);
		world.setBlock(i + 5, j + 11, k + 1, StructureGenHelper.blockChance90p(rand, Blocks.planks), 0, 2);
		world.setBlock(i + 5, j + 11, k + 2, StructureGenHelper.blockChance90p(rand, Blocks.planks), 0, 2);
		world.setBlock(i + 5, j + 11, k + 3, StructureGenHelper.blockChance90p(rand, Blocks.stonebrick), StructureGenHelper.stoneBrickMetaAncient(rand), 2);
		world.setBlock(i + 5, j + 11, k + 4, StructureGenHelper.blockChance90p(rand, Blocks.stonebrick), StructureGenHelper.stoneBrickMetaAncient(rand), 2);
		world.setBlock(i + 5, j + 11, k + 5, StructureGenHelper.blockChance90p(rand, Blocks.stonebrick), StructureGenHelper.stoneBrickMetaAncient(rand), 2);
		world.setBlock(i + 5, j + 11, k + 6, StructureGenHelper.blockChance90p(rand, Blocks.stonebrick), StructureGenHelper.stoneBrickMetaAncient(rand), 2);
		world.setBlock(i + 5, j + 11, k + 7, StructureGenHelper.blockChance90p(rand, Blocks.stonebrick), StructureGenHelper.stoneBrickMetaAncient(rand), 2);
		world.setBlock(i + 5, j + 11, k + 8, StructureGenHelper.blockChance90p(rand, Blocks.stonebrick), StructureGenHelper.stoneBrickMetaAncient(rand), 2);
		world.setBlock(i + 5, j + 11, k + 9, StructureGenHelper.blockChance90p(rand, Blocks.stonebrick), StructureGenHelper.stoneBrickMetaAncient(rand), 2);
		world.setBlock(i + 5, j + 11, k + 10, StructureGenHelper.blockChance90p(rand, Blocks.stonebrick), StructureGenHelper.stoneBrickMetaAncient(rand), 2);
		world.setBlock(i + 5, j + 11, k + 11, StructureGenHelper.blockChance90p(rand, Blocks.stonebrick), StructureGenHelper.stoneBrickMetaAncient(rand), 2);
		world.setBlock(i + 5, j + 12, k + 0, StructureGenHelper.blockChance90p(rand, Blocks.planks), 0, 2);
		world.setBlock(i + 5, j + 12, k + 1, StructureGenHelper.blockChance90p(rand, Blocks.stonebrick), StructureGenHelper.stoneBrickMetaAncient(rand), 2);
		//world.setBlock(i + 5, j + 12, k + 2, StructureGenHelper.blockChance90p(rand, Blocks.stonebrick), StructureGenHelper.stoneBrickMetaAncient(rand), 2);
		world.setBlock(i + 5, j + 12, k + 3, Blocks.air);
		world.setBlock(i + 5, j + 12, k + 4, Blocks.air);
		world.setBlock(i + 5, j + 12, k + 5, Blocks.air);
		world.setBlock(i + 5, j + 12, k + 6, StructureGenHelper.blockChance90p(rand, Blocks.stonebrick), StructureGenHelper.stoneBrickMetaAncient(rand), 2);
		world.setBlock(i + 5, j + 12, k + 7, StructureGenHelper.blockChance90p(rand, Blocks.stonebrick), StructureGenHelper.stoneBrickMetaAncient(rand), 2);
		world.setBlock(i + 5, j + 12, k + 8, StructureGenHelper.blockChance90p(rand, Blocks.stonebrick), StructureGenHelper.stoneBrickMetaAncient(rand), 2);
