package draco18s.artifacts.worldgen;

import java.util.Random;

import draco18s.artifacts.api.ArtifactsAPI;
import draco18s.artifacts.block.*;
import draco18s.artifacts.entity.TileEntityDisplayPedestal;
import draco18s.artifacts.item.ItemArtifact;

import net.minecraft.block.Block;
import net.minecraft.item.ItemStack;
import net.minecraft.nbt.NBTTagCompound;
import net.minecraft.tileentity.TileEntity;
import net.minecraft.tileentity.TileEntityChest;
import net.minecraft.tileentity.TileEntityMobSpawner;
import net.minecraft.util.WeightedRandomChestContent;
import net.minecraft.world.World;
import net.minecraft.world.gen.feature.WorldGenerator;
import net.minecraft.world.gen.structure.StructureBoundingBox;
import net.minecraft.world.gen.structure.StructureComponent;
import net.minecraftforge.common.ChestGenHooks;

public class StructureApprenticeTower extends WorldGenerator {

	protected StructureApprenticeTower() {
	}

	@Override
	public boolean generate(World world, Random random, int x, int y, int z) {
		for (z -= 8; y > 5 && (!world.isBlockOpaqueCube(x, y, z) || world.getBlockId(x, y, z) == Block.leaves.blockID); --y)
        {
            ;
        }

        if (y <= 61)
        {
            return false;
        }
        else
        {
        	build(world, random, x-3, y-2, z+1);
        }
		return false;
	}
	
	public boolean build(World world, Random rand, int i, int j, int k) {
		//System.out.println("Placing apprentice tower at (" + i + "," + k+ ")");
		world.setBlock(i + 0, j + 0, k + 2, Block.cobblestone.blockID, 0, 2);
		world.setBlock(i + 0, j + 0, k + 3, Block.cobblestone.blockID, 0, 2);
		world.setBlock(i + 0, j + 0, k + 4, Block.cobblestone.blockID, 0, 2);
		world.setBlock(i + 0, j + 1, k + 2, Block.cobblestone.blockID, 0, 2);
		world.setBlock(i + 0, j + 1, k + 3, Block.cobblestone.blockID, 0, 2);
		world.setBlock(i + 0, j + 1, k + 4, Block.cobblestone.blockID, 0, 2);
		world.setBlock(i + 0, j + 2, k + 2, Block.cobblestone.blockID, 0, 2);
		world.setBlock(i + 0, j + 2, k + 3, Block.cobblestone.blockID, 0, 2);
		world.setBlock(i + 0, j + 2, k + 4, Block.cobblestone.blockID, 0, 2);
		world.setBlock(i + 0, j + 3, k + 2, Block.cobblestone.blockID, 0, 2);
		world.setBlock(i + 0, j + 3, k + 3, Block.cobblestone.blockID, 0, 2);
		world.setBlock(i + 0, j + 3, k + 4, Block.cobblestone.blockID, 0, 2);
		world.setBlock(i + 0, j + 4, k + 2, Block.cobblestone.blockID, 0, 2);
		world.setBlock(i + 0, j + 4, k + 3, Block.cobblestone.blockID, 0, 2);
		world.setBlock(i + 0, j + 4, k + 4, Block.cobblestone.blockID, 0, 2);
		world.setBlock(i + 0, j + 5, k + 2, Block.cobblestone.blockID, 0, 2);
		world.setBlock(i + 0, j + 5, k + 3, Block.cobblestone.blockID, 0, 2);
		world.setBlock(i + 0, j + 5, k + 4, Block.cobblestone.blockID, 0, 2);
		world.setBlock(i + 0, j + 6, k + 2, Block.cobblestone.blockID, 0, 2);
		world.setBlock(i + 0, j + 6, k + 3, Block.cobblestone.blockID, 0, 2);
		world.setBlock(i + 0, j + 6, k + 4, Block.cobblestone.blockID, 0, 2);
		world.setBlock(i + 1, j + 0, k + 1, Block.cobblestone.blockID, 0, 2);
		world.setBlock(i + 1, j + 0, k + 2, Block.cobblestone.blockID, 0, 2);
		world.setBlock(i + 1, j + 0, k + 3, Block.cobblestone.blockID, 0, 2);
		world.setBlock(i + 1, j + 0, k + 4, Block.cobblestone.blockID, 0, 2);
		world.setBlock(i + 1, j + 0, k + 5, Block.cobblestone.blockID, 0, 2);
		world.setBlock(i + 1, j + 1, k + 1, Block.cobblestone.blockID, 0, 2);
		world.setBlock(i + 1, j + 1, k + 2, Block.cobblestone.blockID, 0, 2);
		world.setBlock(i + 1, j + 1, k + 3, Block.cobblestone.blockID, 0, 2);
		world.setBlock(i + 1, j + 1, k + 4, Block.cobblestone.blockID, 0, 2);
		world.setBlock(i + 1, j + 1, k + 5, Block.cobblestone.blockID, 0, 2);
		world.setBlock(i + 1, j + 2, k + 1, Block.cobblestone.blockID, 0, 2);
		world.setBlock(i + 1, j + 2, k + 2, Block.cobblestone.blockID, 0, 2);
		world.setBlock(i + 1, j + 2, k + 3, Block.cobblestone.blockID, 0, 2);
		world.setBlock(i + 1, j + 2, k + 4, Block.cobblestone.blockID, 0, 2);
		world.setBlock(i + 1, j + 2, k + 5, Block.cobblestone.blockID, 0, 2);
		world.setBlock(i + 1, j + 3, k + 1, Block.cobblestone.blockID, 0, 2);
		world.setBlock(i + 1, j + 3, k + 2, BlockInvisibleBlock.instance.blockID, 0, 2);
		world.setBlock(i + 1, j + 3, k + 3, 0);
		world.setBlock(i + 1, j + 3, k + 4, Block.bookShelf.blockID, 0, 2);
		world.setBlock(i + 1, j + 3, k + 5, Block.cobblestone.blockID, 0, 2);
		world.setBlock(i + 1, j + 4, k + 1, Block.cobblestone.blockID, 0, 2);
		world.setBlock(i + 1, j + 4, k + 2, BlockInvisibleBlock.instance.blockID, 0, 2);
		world.setBlock(i + 1, j + 4, k + 3, 0);
		world.setBlock(i + 1, j + 4, k + 4, Block.bookShelf.blockID, 0, 2);
		world.setBlock(i + 1, j + 4, k + 5, Block.cobblestone.blockID, 0, 2);
		world.setBlock(i + 1, j + 5, k + 1, Block.cobblestone.blockID, 0, 2);
		world.setBlock(i + 1, j + 5, k + 2, BlockInvisibleBlock.instance.blockID, 0, 2);
		world.setBlock(i + 1, j + 5, k + 3, 0);
		world.setBlock(i + 1, j + 5, k + 4, Block.web.blockID, 0, 2);
		world.setBlock(i + 1, j + 5, k + 5, Block.cobblestone.blockID, 0, 2);
		world.setBlock(i + 1, j + 6, k + 1, Block.cobblestone.blockID, 0, 2);
		world.setBlock(i + 1, j + 6, k + 2, Block.cobblestone.blockID, 0, 2);
		world.setBlock(i + 1, j + 6, k + 3, Block.cobblestone.blockID, 0, 2);
		world.setBlock(i + 1, j + 6, k + 4, Block.cobblestone.blockID, 0, 2);
		world.setBlock(i + 1, j + 6, k + 5, Block.cobblestone.blockID, 0, 2);
		world.setBlock(i + 1, j + 7, k + 2, Block.cobblestone.blockID, 0, 2);
		world.setBlock(i + 1, j + 7, k + 3, Block.cobblestone.blockID, 0, 2);
		world.setBlock(i + 1, j + 7, k + 4, Block.cobblestone.blockID, 0, 2);
		world.setBlock(i + 1, j + 8, k + 2, Block.cobblestone.blockID, 0, 2);
		world.setBlock(i + 1, j + 8, k + 3, Block.cobblestone.blockID, 0, 2);
		world.setBlock(i + 1, j + 8, k + 4, Block.cobblestone.blockID, 0, 2);
		world.setBlock(i + 1, j + 9, k + 2, Block.cobblestone.blockID, 0, 2);
		world.setBlock(i + 1, j + 9, k + 3, Block.cobblestone.blockID, 0, 2);
		world.setBlock(i + 1, j + 9, k + 4, Block.cobblestone.blockID, 0, 2);
		world.setBlock(i + 1, j + 10, k + 2, Block.cobblestone.blockID, 0, 2);
		world.setBlock(i + 1, j + 10, k + 3, Block.cobblestone.blockID, 0, 2);
		world.setBlock(i + 1, j + 10, k + 4, Block.cobblestone.blockID, 0, 2);
		world.setBlock(i + 1, j + 14, k + 2, Block.cobblestone.blockID, 0, 2);
		world.setBlock(i + 1, j + 14, k + 3, Block.cobblestone.blockID, 0, 2);
		world.setBlock(i + 1, j + 14, k + 4, Block.cobblestone.blockID, 0, 2);
		world.setBlock(i + 1, j + 15, k + 2, Block.cobblestone.blockID, 0, 2);
		world.setBlock(i + 1, j + 15, k + 3, Block.cobblestone.blockID, 0, 2);
		world.setBlock(i + 1, j + 15, k + 4, Block.cobblestone.blockID, 0, 2);
		world.setBlock(i + 1, j + 16, k + 2, Block.cobblestone.blockID, 0, 2);
		world.setBlock(i + 1, j + 16, k + 3, 0);
		world.setBlock(i + 1, j + 16, k + 4, Block.cobblestone.blockID, 0, 2);
		world.setBlock(i + 2, j + 0, k + 0, Block.cobblestone.blockID, 0, 2);
		world.setBlock(i + 2, j + 0, k + 1, Block.cobblestone.blockID, 0, 2);
		world.setBlock(i + 2, j + 0, k + 2, Block.cobblestone.blockID, 0, 2);
		world.setBlock(i + 2, j + 0, k + 3, Block.cobblestone.blockID, 0, 2);
		world.setBlock(i + 2, j + 0, k + 4, Block.cobblestone.blockID, 0, 2);
		world.setBlock(i + 2, j + 0, k + 5, Block.cobblestone.blockID, 0, 2);
		world.setBlock(i + 2, j + 0, k + 6, Block.cobblestone.blockID, 0, 2);
		world.setBlock(i + 2, j + 1, k + 0, Block.cobblestone.blockID, 0, 2);
		world.setBlock(i + 2, j + 1, k + 1, BlockSpikes.instance.blockID, 0, 2);
		world.setBlock(i + 2, j + 1, k + 2, BlockSpikes.instance.blockID, 0, 2);
		world.setBlock(i + 2, j + 1, k + 3, BlockSpikes.instance.blockID, 0, 2);
		world.setBlock(i + 2, j + 1, k + 4, Block.cobblestone.blockID, 0, 2);
		world.setBlock(i + 2, j + 1, k + 5, Block.cobblestone.blockID, 0, 2);
		world.setBlock(i + 2, j + 1, k + 6, Block.cobblestone.blockID, 0, 2);
		world.setBlock(i + 2, j + 2, k + 0, Block.cobblestone.blockID, 0, 2);
		world.setBlock(i + 2, j + 2, k + 1, BlockIllusionary.instance.blockID, 0, 2);
		world.setBlock(i + 2, j + 2, k + 2, BlockIllusionary.instance.blockID, 0, 2);
		world.setBlock(i + 2, j + 2, k + 3, BlockIllusionary.instance.blockID, 0, 2);
		world.setBlock(i + 2, j + 2, k + 4, Block.cobblestone.blockID, 0, 2);
		world.setBlock(i + 2, j + 2, k + 5, Block.cobblestone.blockID, 0, 2);
		world.setBlock(i + 2, j + 2, k + 6, Block.cobblestone.blockID, 0, 2);
		world.setBlock(i + 2, j + 3, k + 0, Block.cobblestone.blockID, 0, 2);
		world.setBlock(i + 2, j + 3, k + 1, 0);
		world.setBlock(i + 2, j + 3, k + 3, 0);
		world.setBlock(i + 2, j + 3, k + 4, 0);
		world.setBlock(i + 2, j + 3, k + 5, Block.bookShelf.blockID, 0, 2);
		world.setBlock(i + 2, j + 3, k + 6, Block.cobblestone.blockID, 0, 2);
		world.setBlock(i + 2, j + 4, k + 0, Block.cobblestone.blockID, 0, 2);
		world.setBlock(i + 2, j + 4, k + 1, 0);
		world.setBlock(i + 2, j + 4, k + 3, 0);
		world.setBlock(i + 2, j + 4, k + 4, 0);
		world.setBlock(i + 2, j + 4, k + 5, Block.bookShelf.blockID, 0, 2);
		world.setBlock(i + 2, j + 4, k + 6, Block.cobblestone.blockID, 0, 2);
		world.setBlock(i + 2, j + 5, k + 0, Block.cobblestone.blockID, 0, 2);
		world.setBlock(i + 2, j + 5, k + 1, 0);
		world.setBlock(i + 2, j + 5, k + 3, 0);
		world.setBlock(i + 2, j + 5, k + 4, 0);
		world.setBlock(i + 2, j + 5, k + 5, Block.web.blockID, 0, 2);
		world.setBlock(i + 2, j + 5, k + 6, Block.cobblestone.blockID, 0, 2);
		world.setBlock(i + 2, j + 6, k + 0, Block.cobblestone.blockID, 0, 2);
		world.setBlock(i + 2, j + 6, k + 1, Block.cobblestone.blockID, 0, 2);
		world.setBlock(i + 2, j + 6, k + 3, Block.cobblestone.blockID, 0, 2);
		world.setBlock(i + 2, j + 6, k + 4, Block.cobblestone.blockID, 0, 2);
		world.setBlock(i + 2, j + 6, k + 5, Block.cobblestone.blockID, 0, 2);
		world.setBlock(i + 2, j + 6, k + 6, Block.cobblestone.blockID, 0, 2);
		world.setBlock(i + 2, j + 7, k + 1, Block.cobblestone.blockID, 0, 2);
		world.setBlock(i + 2, j + 7, k + 2, 0);
		world.setBlock(i + 2, j + 7, k + 3, 0);
		world.setBlock(i + 2, j + 7, k + 4, 0);
		world.setBlock(i + 2, j + 7, k + 5, Block.cobblestone.blockID, 0, 2);
		world.setBlock(i + 2, j + 8, k + 1, Block.cobblestone.blockID, 0, 2);
		world.setBlock(i + 2, j + 8, k + 2, 0);
		world.setBlock(i + 2, j + 8, k + 3, 0);
		world.setBlock(i + 2, j + 8, k + 4, 0);
		world.setBlock(i + 2, j + 8, k + 5, Block.cobblestone.blockID, 0, 2);
		world.setBlock(i + 2, j + 9, k + 1, Block.cobblestone.blockID, 0, 2);
		world.setBlock(i + 2, j + 9, k + 2, 0);
		world.setBlock(i + 2, j + 9, k + 3, 0);
		world.setBlock(i + 2, j + 9, k + 4, Block.web.blockID, 0, 2);
		world.setBlock(i + 2, j + 9, k + 5, Block.cobblestone.blockID, 0, 2);
		world.setBlock(i + 2, j + 10, k + 1, Block.cobblestone.blockID, 0, 2);
		world.setBlock(i + 2, j + 10, k + 2, Block.cobblestone.blockID, 0, 2);
		world.setBlock(i + 2, j + 10, k + 3, Block.cobblestone.blockID, 0, 2);
		world.setBlock(i + 2, j + 10, k + 4, Block.cobblestone.blockID, 0, 2);
		world.setBlock(i + 2, j + 10, k + 5, Block.cobblestone.blockID, 0, 2);
		world.setBlock(i + 2, j + 11, k + 2, Block.cobblestone.blockID, 0, 2);
		world.setBlock(i + 2, j + 11, k + 3, Block.cobblestone.blockID, 0, 2);
		world.setBlock(i + 2, j + 11, k + 4, Block.cobblestone.blockID, 0, 2);
		world.setBlock(i + 2, j + 12, k + 2, Block.cobblestone.blockID, 0, 2);
		world.setBlock(i + 2, j + 12, k + 3, Block.cobblestone.blockID, 0, 2);
		world.setBlock(i + 2, j + 12, k + 4, Block.cobblestone.blockID, 0, 2);
		world.setBlock(i + 2, j + 13, k + 2, Block.cobblestone.blockID, 0, 2);
		world.setBlock(i + 2, j + 13, k + 3, Block.cobblestone.blockID, 0, 2);
		world.setBlock(i + 2, j + 13, k + 4, Block.cobblestone.blockID, 0, 2);
		world.setBlock(i + 2, j + 14, k + 1, Block.cobblestone.blockID, 0, 2);
		world.setBlock(i + 2, j + 14, k + 2, Block.cobblestone.blockID, 0, 2);
		world.setBlock(i + 2, j + 14, k + 3, Block.cobblestone.blockID, 0, 2);
		world.setBlock(i + 2, j + 14, k + 4, Block.cobblestone.blockID, 0, 2);
		world.setBlock(i + 2, j + 14, k + 5, Block.cobblestone.blockID, 0, 2);
		world.setBlock(i + 2, j + 15, k + 1, Block.cobblestone.blockID, 0, 2);
		world.setBlock(i + 2, j + 15, k + 2, 0);
		world.setBlock(i + 2, j + 15, k + 3, 0);
		world.setBlock(i + 2, j + 15, k + 4, 0);
		world.setBlock(i + 2, j + 15, k + 5, Block.cobblestone.blockID, 0, 2);
		world.setBlock(i + 2, j + 16, k + 1, Block.cobblestone.blockID, 0, 2);
		world.setBlock(i + 2, j + 16, k + 2, 0);
		world.setBlock(i + 2, j + 16, k + 3, 0);
		world.setBlock(i + 2, j + 16, k + 4, 0);
		world.setBlock(i + 2, j + 16, k + 5, Block.cobblestone.blockID, 0, 2);
		world.setBlock(i + 3, j + 0, k + 0, Block.cobblestone.blockID, 0, 2);
		world.setBlock(i + 3, j + 0, k + 1, Block.cobblestone.blockID, 0, 2);
		world.setBlock(i + 3, j + 0, k + 2, Block.cobblestone.blockID, 0, 2);
		world.setBlock(i + 3, j + 0, k + 3, Block.cobblestone.blockID, 0, 2);
		world.setBlock(i + 3, j + 0, k + 4, Block.cobblestone.blockID, 0, 2);
		world.setBlock(i + 3, j + 0, k + 5, Block.cobblestone.blockID, 0, 2);
		world.setBlock(i + 3, j + 0, k + 6, Block.cobblestone.blockID, 0, 2);
		world.setBlock(i + 3, j + 1, k + 0, Block.cobblestone.blockID, 0, 2);
		world.setBlock(i + 3, j + 1, k + 1, BlockSpikes.instance.blockID, 0, 2);
		world.setBlock(i + 3, j + 1, k + 2, BlockSpikes.instance.blockID, 0, 2);
		world.setBlock(i + 3, j + 1, k + 3, BlockSpikes.instance.blockID, 0, 2);
		world.setBlock(i + 3, j + 1, k + 4, Block.cobblestone.blockID, 0, 2);
		world.setBlock(i + 3, j + 1, k + 5, Block.cobblestone.blockID, 0, 2);
		world.setBlock(i + 3, j + 1, k + 6, Block.cobblestone.blockID, 0, 2);
		world.setBlock(i + 3, j + 2, k + 0, Block.cobblestone.blockID, 0, 2);
		world.setBlock(i + 3, j + 2, k + 1, BlockIllusionary.instance.blockID, 0, 2);
		world.setBlock(i + 3, j + 2, k + 2, BlockIllusionary.instance.blockID, 0, 2);
		world.setBlock(i + 3, j + 2, k + 3, BlockIllusionary.instance.blockID, 0, 2);
		world.setBlock(i + 3, j + 2, k + 4, Block.cobblestone.blockID, 0, 2);
		world.setBlock(i + 3, j + 2, k + 5, Block.cobblestone.blockID, 0, 2);
		world.setBlock(i + 3, j + 2, k + 6, Block.cobblestone.blockID, 0, 2);
		world.setBlock(i + 3, j + 3, k + 1, 0);
		world.setBlock(i + 3, j + 3, k + 2, 0);
		world.setBlock(i + 3, j + 3, k + 3, 0);
		world.setBlock(i + 3, j + 3, k + 4, 0);
		world.setBlock(i + 3, j + 3, k + 5, Block.workbench.blockID, 0, 2);
		world.setBlock(i + 3, j + 3, k + 6, Block.cobblestone.blockID, 0, 2);
		world.setBlock(i + 3, j + 4, k + 1, 0);
		world.setBlock(i + 3, j + 4, k + 2, 0);
		world.setBlock(i + 3, j + 4, k + 3, 0);
		world.setBlock(i + 3, j + 4, k + 4, 0);
		world.setBlock(i + 3, j + 4, k + 5, 0);
		world.setBlock(i + 3, j + 4, k + 6, Block.cobblestone.blockID, 0, 2);
		world.setBlock(i + 3, j + 5, k + 0, Block.cobblestone.blockID, 0, 2);
		world.setBlock(i + 3, j + 5, k + 1, 0);
		world.setBlock(i + 3, j + 5, k + 2, 0);
		world.setBlock(i + 3, j + 5, k + 3, 0);
		world.setBlock(i + 3, j + 5, k + 4, 0);
		world.setBlock(i + 3, j + 5, k + 5, 0);
		world.setBlock(i + 3, j + 5, k + 6, Block.cobblestone.blockID, 0, 2);
		world.setBlock(i + 3, j + 6, k + 0, Block.cobblestone.blockID, 0, 2);
		world.setBlock(i + 3, j + 6, k + 1, Block.cobblestone.blockID, 0, 2);
		world.setBlock(i + 3, j + 6, k + 2, Block.cobblestone.blockID, 0, 2);
		world.setBlock(i + 3, j + 6, k + 3, Block.cobblestone.blockID, 0, 2);
		world.setBlock(i + 3, j + 6, k + 4, Block.cobblestone.blockID, 0, 2);
		world.setBlock(i + 3, j + 6, k + 5, Block.cobblestone.blockID, 0, 2);
		world.setBlock(i + 3, j + 6, k + 6, Block.cobblestone.blockID, 0, 2);
		world.setBlock(i + 3, j + 7, k + 1, Block.cobblestone.blockID, 0, 2);
		world.setBlock(i + 3, j + 7, k + 2, 0);
		world.setBlock(i + 3, j + 7, k + 4, BlockInvisibleBlock.instance.blockID, 0, 2);
		world.setBlock(i + 3, j + 7, k + 5, Block.cobblestone.blockID, 0, 2);
		world.setBlock(i + 3, j + 8, k + 1, Block.cobblestone.blockID, 0, 2);
		world.setBlock(i + 3, j + 8, k + 2, 0);
		world.setBlock(i + 3, j + 8, k + 4, BlockInvisibleBlock.instance.blockID, 0, 2);
		world.setBlock(i + 3, j + 8, k + 5, Block.cobblestone.blockID, 0, 2);
		world.setBlock(i + 3, j + 9, k + 1, Block.cobblestone.blockID, 0, 2);
		world.setBlock(i + 3, j + 9, k + 2, 0);
		world.setBlock(i + 3, j + 9, k + 4, BlockInvisibleBlock.instance.blockID, 0, 2);
		world.setBlock(i + 3, j + 9, k + 5, Block.cobblestone.blockID, 0, 2);
		world.setBlock(i + 3, j + 10, k + 1, Block.cobblestone.blockID, 0, 2);
		world.setBlock(i + 3, j + 10, k + 2, Block.cobblestone.blockID, 0, 2);
		world.setBlock(i + 3, j + 10, k + 4, Block.cobblestone.blockID, 0, 2);
		world.setBlock(i + 3, j + 10, k + 5, Block.cobblestone.blockID, 0, 2);
		world.setBlock(i + 3, j + 11, k + 2, Block.cobblestone.blockID, 0, 2);
		world.setBlock(i + 3, j + 11, k + 4, Block.cobblestone.blockID, 0, 2);
		world.setBlock(i + 3, j + 12, k + 2, Block.cobblestone.blockID, 0, 2);
		world.setBlock(i + 3, j + 12, k + 4, Block.cobblestone.blockID, 0, 2);
		world.setBlock(i + 3, j + 13, k + 2, Block.cobblestone.blockID, 0, 2);
		world.setBlock(i + 3, j + 13, k + 4, Block.cobblestone.blockID, 0, 2);
		world.setBlock(i + 3, j + 14, k + 1, Block.cobblestone.blockID, 0, 2);
		world.setBlock(i + 3, j + 14, k + 2, Block.cobblestone.blockID, 0, 2);
		world.setBlock(i + 3, j + 14, k + 3, BlockIllusionary.instance.blockID, 0, 2);
		world.setBlock(i + 3, j + 14, k + 4, Block.cobblestone.blockID, 0, 2);
		world.setBlock(i + 3, j + 14, k + 5, Block.cobblestone.blockID, 0, 2);
		world.setBlock(i + 3, j + 15, k + 1, Block.cobblestone.blockID, 0, 2);
		world.setBlock(i + 3, j + 15, k + 2, 0);
		world.setBlock(i + 3, j + 15, k + 3, 0);
		world.setBlock(i + 3, j + 15, k + 4, Block.chest.blockID, 2, 2);
		world.setBlock(i + 3, j + 15, k + 5, Block.cobblestone.blockID, 0, 2);
		world.setBlock(i + 3, j + 16, k + 1, 0);
		world.setBlock(i + 3, j + 16, k + 2, 0);
		world.setBlock(i + 3, j + 16, k + 3, 0);
		world.setBlock(i + 3, j + 16, k + 4, 0);
		world.setBlock(i + 3, j + 16, k + 5, 0);
		world.setBlock(i + 4, j + 0, k + 0, Block.cobblestone.blockID, 0, 2);
		world.setBlock(i + 4, j + 0, k + 1, Block.cobblestone.blockID, 0, 2);
		world.setBlock(i + 4, j + 0, k + 2, Block.cobblestone.blockID, 0, 2);
		world.setBlock(i + 4, j + 0, k + 3, Block.cobblestone.blockID, 0, 2);
		world.setBlock(i + 4, j + 0, k + 4, Block.cobblestone.blockID, 0, 2);
		world.setBlock(i + 4, j + 0, k + 5, Block.cobblestone.blockID, 0, 2);
		world.setBlock(i + 4, j + 0, k + 6, Block.cobblestone.blockID, 0, 2);
		world.setBlock(i + 4, j + 1, k + 0, Block.cobblestone.blockID, 0, 2);
		world.setBlock(i + 4, j + 1, k + 1, BlockSpikes.instance.blockID, 0, 2);
		world.setBlock(i + 4, j + 1, k + 2, BlockSpikes.instance.blockID, 0, 2);
		world.setBlock(i + 4, j + 1, k + 3, BlockSpikes.instance.blockID, 0, 2);
		world.setBlock(i + 4, j + 1, k + 4, Block.cobblestone.blockID, 0, 2);
		world.setBlock(i + 4, j + 1, k + 5, Block.cobblestone.blockID, 0, 2);
		world.setBlock(i + 4, j + 1, k + 6, Block.cobblestone.blockID, 0, 2);
		world.setBlock(i + 4, j + 2, k + 0, Block.cobblestone.blockID, 0, 2);
		world.setBlock(i + 4, j + 2, k + 1, BlockIllusionary.instance.blockID, 0, 2);
		world.setBlock(i + 4, j + 2, k + 2, BlockIllusionary.instance.blockID, 0, 2);
		world.setBlock(i + 4, j + 2, k + 3, BlockIllusionary.instance.blockID, 0, 2);
		world.setBlock(i + 4, j + 2, k + 4, Block.cobblestone.blockID, 0, 2);
		world.setBlock(i + 4, j + 2, k + 5, Block.cobblestone.blockID, 0, 2);
		world.setBlock(i + 4, j + 2, k + 6, Block.cobblestone.blockID, 0, 2);
		world.setBlock(i + 4, j + 3, k + 0, Block.cobblestone.blockID, 0, 2);
		world.setBlock(i + 4, j + 3, k + 1, 0);
		world.setBlock(i + 4, j + 3, k + 2, 0);
		world.setBlock(i + 4, j + 3, k + 3, 0);
		world.setBlock(i + 4, j + 3, k + 4, 0);
		world.setBlock(i + 4, j + 3, k + 5, Block.bookShelf.blockID, 0, 2);
		world.setBlock(i + 4, j + 3, k + 6, Block.cobblestone.blockID, 0, 2);
		world.setBlock(i + 4, j + 4, k + 0, Block.cobblestone.blockID, 0, 2);
		world.setBlock(i + 4, j + 4, k + 1, 0);
		world.setBlock(i + 4, j + 4, k + 2, 0);
		world.setBlock(i + 4, j + 4, k + 3, 0);
		world.setBlock(i + 4, j + 4, k + 4, 0);
		world.setBlock(i + 4, j + 4, k + 5, Block.bookShelf.blockID, 0, 2);
		world.setBlock(i + 4, j + 4, k + 6, Block.cobblestone.blockID, 0, 2);
		world.setBlock(i + 4, j + 5, k + 0, Block.cobblestone.blockID, 0, 2);
		world.setBlock(i + 4, j + 5, k + 1, Block.web.blockID, 0, 2);
		world.setBlock(i + 4, j + 5, k + 2, 0);
		world.setBlock(i + 4, j + 5, k + 3, 0);
		world.setBlock(i + 4, j + 5, k + 4, 0);
		world.setBlock(i + 4, j + 5, k + 5, 0);
		world.setBlock(i + 4, j + 5, k + 6, Block.cobblestone.blockID, 0, 2);
		world.setBlock(i + 4, j + 6, k + 0, Block.cobblestone.blockID, 0, 2);
		world.setBlock(i + 4, j + 6, k + 1, Block.cobblestone.blockID, 0, 2);
		world.setBlock(i + 4, j + 6, k + 2, Block.cobblestone.blockID, 0, 2);
		world.setBlock(i + 4, j + 6, k + 3, Block.cobblestone.blockID, 0, 2);
		world.setBlock(i + 4, j + 6, k + 4, Block.cobblestone.blockID, 0, 2);
		world.setBlock(i + 4, j + 6, k + 5, Block.cobblestone.blockID, 0, 2);
		world.setBlock(i + 4, j + 6, k + 6, Block.cobblestone.blockID, 0, 2);
		world.setBlock(i + 4, j + 7, k + 1, Block.cobblestone.blockID, 0, 2);
		world.setBlock(i + 4, j + 7, k + 2, 0);
		world.setBlock(i + 4, j + 7, k + 3, 0);
		world.setBlock(i + 4, j + 7, k + 4, 0);
		world.setBlock(i + 4, j + 7, k + 5, Block.cobblestone.blockID, 0, 2);
		world.setBlock(i + 4, j + 8, k + 1, Block.cobblestone.blockID, 0, 2);
		world.setBlock(i + 4, j + 8, k + 2, 0);
		world.setBlock(i + 4, j + 8, k + 3, 0);
		world.setBlock(i + 4, j + 8, k + 4, 0);
		world.setBlock(i + 4, j + 8, k + 5, Block.cobblestone.blockID, 0, 2);
		world.setBlock(i + 4, j + 9, k + 1, Block.cobblestone.blockID, 0, 2);
		world.setBlock(i + 4, j + 9, k + 2, Block.web.blockID, 0, 2);
		world.setBlock(i + 4, j + 9, k + 3, Block.web.blockID, 0, 2);
		world.setBlock(i + 4, j + 9, k + 4, 0);
		world.setBlock(i + 4, j + 9, k + 5, Block.cobblestone.blockID, 0, 2);
		world.setBlock(i + 4, j + 10, k + 1, Block.cobblestone.blockID, 0, 2);
		world.setBlock(i + 4, j + 10, k + 2, Block.cobblestone.blockID, 0, 2);
		world.setBlock(i + 4, j + 10, k + 3, Block.cobblestone.blockID, 0, 2);
		world.setBlock(i + 4, j + 10, k + 4, Block.cobblestone.blockID, 0, 2);
		world.setBlock(i + 4, j + 10, k + 5, Block.cobblestone.blockID, 0, 2);
		world.setBlock(i + 4, j + 11, k + 2, Block.cobblestone.blockID, 0, 2);
		world.setBlock(i + 4, j + 11, k + 3, 0);
		world.setBlock(i + 4, j + 11, k + 4, Block.cobblestone.blockID, 0, 2);
		world.setBlock(i + 4, j + 12, k + 2, Block.cobblestone.blockID, 0, 2);
		world.setBlock(i + 4, j + 12, k + 3, 0);
		world.setBlock(i + 4, j + 12, k + 4, Block.cobblestone.blockID, 0, 2);
		world.setBlock(i + 4, j + 13, k + 2, Block.cobblestone.blockID, 0, 2);
		world.setBlock(i + 4, j + 13, k + 3, Block.cobblestone.blockID, 0, 2);
		world.setBlock(i + 4, j + 13, k + 4, Block.cobblestone.blockID, 0, 2);
		world.setBlock(i + 4, j + 14, k + 1, Block.cobblestone.blockID, 0, 2);
		world.setBlock(i + 4, j + 14, k + 2, Block.cobblestone.blockID, 0, 2);
		world.setBlock(i + 4, j + 14, k + 3, Block.cobblestone.blockID, 0, 2);
		world.setBlock(i + 4, j + 14, k + 4, Block.cobblestone.blockID, 0, 2);
		world.setBlock(i + 4, j + 14, k + 5, Block.cobblestone.blockID, 0, 2);
		world.setBlock(i + 4, j + 15, k + 1, Block.cobblestone.blockID, 0, 2);
		world.setBlock(i + 4, j + 15, k + 2, 0);
		world.setBlock(i + 4, j + 15, k + 3, 0);
		world.setBlock(i + 4, j + 15, k + 4, 0);
		world.setBlock(i + 4, j + 15, k + 5, Block.cobblestone.blockID, 0, 2);
		world.setBlock(i + 4, j + 16, k + 1, Block.cobblestone.blockID, 0, 2);
		world.setBlock(i + 4, j + 16, k + 2, 0);
		world.setBlock(i + 4, j + 16, k + 3, 0);
		world.setBlock(i + 4, j + 16, k + 4, 0);
		world.setBlock(i + 4, j + 16, k + 5, Block.cobblestone.blockID, 0, 2);
		world.setBlock(i + 5, j + 0, k + 1, Block.cobblestone.blockID, 0, 2);
		world.setBlock(i + 5, j + 0, k + 2, Block.cobblestone.blockID, 0, 2);
		world.setBlock(i + 5, j + 0, k + 3, Block.cobblestone.blockID, 0, 2);
		world.setBlock(i + 5, j + 0, k + 4, Block.cobblestone.blockID, 0, 2);
		world.setBlock(i + 5, j + 0, k + 5, Block.cobblestone.blockID, 0, 2);
		world.setBlock(i + 5, j + 1, k + 1, Block.cobblestone.blockID, 0, 2);
		world.setBlock(i + 5, j + 1, k + 2, Block.cobblestone.blockID, 0, 2);
		world.setBlock(i + 5, j + 1, k + 3, Block.cobblestone.blockID, 0, 2);
		world.setBlock(i + 5, j + 1, k + 4, Block.cobblestone.blockID, 0, 2);
		world.setBlock(i + 5, j + 1, k + 5, Block.cobblestone.blockID, 0, 2);
		world.setBlock(i + 5, j + 2, k + 1, Block.cobblestone.blockID, 0, 2);
		world.setBlock(i + 5, j + 2, k + 2, Block.cobblestone.blockID, 0, 2);
		world.setBlock(i + 5, j + 2, k + 3, Block.cobblestone.blockID, 0, 2);
		world.setBlock(i + 5, j + 2, k + 4, Block.cobblestone.blockID, 0, 2);
		world.setBlock(i + 5, j + 2, k + 5, Block.cobblestone.blockID, 0, 2);
		world.setBlock(i + 5, j + 3, k + 1, Block.cobblestone.blockID, 0, 2);
		world.setBlock(i + 5, j + 3, k + 2, 0);
		world.setBlock(i + 5, j + 3, k + 3, 0);
		world.setBlock(i + 5, j + 3, k + 4, Block.bookShelf.blockID, 0, 2);
		world.setBlock(i + 5, j + 3, k + 5, Block.cobblestone.blockID, 0, 2);
		world.setBlock(i + 5, j + 4, k + 1, Block.cobblestone.blockID, 0, 2);
		world.setBlock(i + 5, j + 4, k + 2, 0);
		world.setBlock(i + 5, j + 4, k + 3, 0);
		world.setBlock(i + 5, j + 4, k + 4, Block.bookShelf.blockID, 0, 2);
		world.setBlock(i + 5, j + 4, k + 5, Block.cobblestone.blockID, 0, 2);
		world.setBlock(i + 5, j + 5, k + 1, Block.cobblestone.blockID, 0, 2);
		world.setBlock(i + 5, j + 5, k + 2, 0);
		world.setBlock(i + 5, j + 5, k + 3, 0);
		world.setBlock(i + 5, j + 5, k + 4, Block.web.blockID, 0, 2);
		world.setBlock(i + 5, j + 5, k + 5, Block.cobblestone.blockID, 0, 2);
		world.setBlock(i + 5, j + 6, k + 1, Block.cobblestone.blockID, 0, 2);
		world.setBlock(i + 5, j + 6, k + 2, Block.cobblestone.blockID, 0, 2);
		world.setBlock(i + 5, j + 6, k + 3, Block.cobblestone.blockID, 0, 2);
		world.setBlock(i + 5, j + 6, k + 4, Block.cobblestone.blockID, 0, 2);
		world.setBlock(i + 5, j + 6, k + 5, Block.cobblestone.blockID, 0, 2);
		world.setBlock(i + 5, j + 7, k + 2, Block.cobblestone.blockID, 0, 2);
		world.setBlock(i + 5, j + 7, k + 3, Block.cobblestone.blockID, 0, 2);
		world.setBlock(i + 5, j + 7, k + 4, Block.cobblestone.blockID, 0, 2);
		world.setBlock(i + 5, j + 8, k + 2, Block.cobblestone.blockID, 0, 2);
		world.setBlock(i + 5, j + 8, k + 3, Block.cobblestone.blockID, 0, 2);
		world.setBlock(i + 5, j + 8, k + 4, Block.cobblestone.blockID, 0, 2);
		world.setBlock(i + 5, j + 9, k + 2, Block.cobblestone.blockID, 0, 2);
		world.setBlock(i + 5, j + 9, k + 3, Block.cobblestone.blockID, 0, 2);
		world.setBlock(i + 5, j + 9, k + 4, Block.cobblestone.blockID, 0, 2);
		world.setBlock(i + 5, j + 10, k + 2, Block.cobblestone.blockID, 0, 2);
		world.setBlock(i + 5, j + 10, k + 3, Block.cobblestone.blockID, 0, 2);
		world.setBlock(i + 5, j + 10, k + 4, Block.cobblestone.blockID, 0, 2);
		world.setBlock(i + 5, j + 11, k + 2, Block.fence.blockID, 0, 2);
		world.setBlock(i + 5, j + 11, k + 3, 0);
		world.setBlock(i + 5, j + 11, k + 4, Block.fence.blockID, 0, 2);
		world.setBlock(i + 5, j + 12, k + 3, 0);
		world.setBlock(i + 5, j + 14, k + 2, Block.cobblestone.blockID, 0, 2);
		world.setBlock(i + 5, j + 14, k + 3, Block.cobblestone.blockID, 0, 2);
		world.setBlock(i + 5, j + 14, k + 4, Block.cobblestone.blockID, 0, 2);
		world.setBlock(i + 5, j + 15, k + 2, Block.cobblestone.blockID, 0, 2);
		world.setBlock(i + 5, j + 15, k + 3, Block.cobblestone.blockID, 0, 2);
		world.setBlock(i + 5, j + 15, k + 4, Block.cobblestone.blockID, 0, 2);
		world.setBlock(i + 5, j + 16, k + 2, Block.cobblestone.blockID, 0, 2);
		world.setBlock(i + 5, j + 16, k + 3, 0);
		world.setBlock(i + 5, j + 16, k + 4, Block.cobblestone.blockID, 0, 2);
		world.setBlock(i + 6, j + 0, k + 2, Block.cobblestone.blockID, 0, 2);
		world.setBlock(i + 6, j + 0, k + 3, Block.cobblestone.blockID, 0, 2);
		world.setBlock(i + 6, j + 0, k + 4, Block.cobblestone.blockID, 0, 2);
		world.setBlock(i + 6, j + 1, k + 2, Block.cobblestone.blockID, 0, 2);
		world.setBlock(i + 6, j + 1, k + 3, Block.cobblestone.blockID, 0, 2);
		world.setBlock(i + 6, j + 1, k + 4, Block.cobblestone.blockID, 0, 2);
		world.setBlock(i + 6, j + 2, k + 2, Block.cobblestone.blockID, 0, 2);
		world.setBlock(i + 6, j + 2, k + 3, Block.cobblestone.blockID, 0, 2);
		world.setBlock(i + 6, j + 2, k + 4, Block.cobblestone.blockID, 0, 2);
		world.setBlock(i + 6, j + 3, k + 2, Block.cobblestone.blockID, 0, 2);
		world.setBlock(i + 6, j + 3, k + 3, Block.cobblestone.blockID, 0, 2);
		world.setBlock(i + 6, j + 3, k + 4, Block.cobblestone.blockID, 0, 2);
		world.setBlock(i + 6, j + 4, k + 2, Block.cobblestone.blockID, 0, 2);
		world.setBlock(i + 6, j + 4, k + 3, Block.cobblestone.blockID, 0, 2);
		world.setBlock(i + 6, j + 4, k + 4, Block.cobblestone.blockID, 0, 2);
		world.setBlock(i + 6, j + 5, k + 2, Block.cobblestone.blockID, 0, 2);
		world.setBlock(i + 6, j + 5, k + 3, Block.cobblestone.blockID, 0, 2);
		world.setBlock(i + 6, j + 5, k + 4, Block.cobblestone.blockID, 0, 2);
		world.setBlock(i + 6, j + 6, k + 2, Block.cobblestone.blockID, 0, 2);
		world.setBlock(i + 6, j + 6, k + 3, Block.cobblestone.blockID, 0, 2);
		world.setBlock(i + 6, j + 6, k + 4, Block.cobblestone.blockID, 0, 2);
		world.setBlock(i + 6, j + 10, k + 2, 0);
		world.setBlock(i + 6, j + 10, k + 3, BlockIllusionary.instance.blockID, 0, 2);
		world.setBlock(i + 6, j + 10, k + 4, 0);
		world.setBlock(i + 6, j + 11, k + 2, Block.fence.blockID, 0, 2);
		world.setBlock(i + 6, j + 11, k + 3, 0);
		world.setBlock(i + 6, j + 11, k + 4, Block.fence.blockID, 0, 2);
		world.setBlock(i + 6, j + 12, k + 3, 0);
		world.setBlock(i + 7, j + 10, k + 2, 0);
		world.setBlock(i + 7, j + 10, k + 3, BlockIllusionary.instance.blockID, 0, 2);
		world.setBlock(i + 7, j + 10, k + 4, 0);
		world.setBlock(i + 7, j + 11, k + 2, Block.fence.blockID, 0, 2);
		world.setBlock(i + 7, j + 11, k + 3, 0);
		world.setBlock(i + 7, j + 11, k + 4, Block.fence.blockID, 0, 2);
		world.setBlock(i + 7, j + 12, k + 0, 0);
		world.setBlock(i + 7, j + 12, k + 1, 0);
		world.setBlock(i + 7, j + 12, k + 2, 0);
		world.setBlock(i + 7, j + 12, k + 3, 0);
		world.setBlock(i + 7, j + 12, k + 4, 0);
		world.setBlock(i + 7, j + 12, k + 5, 0);
		world.setBlock(i + 8, j + 8, k + 1, 0);
		world.setBlock(i + 8, j + 8, k + 2, 0);
		world.setBlock(i + 8, j + 8, k + 3, 0);
		world.setBlock(i + 8, j + 8, k + 4, 0);
		world.setBlock(i + 8, j + 9, k + 1, 0);
		world.setBlock(i + 8, j + 9, k + 2, 0);
		world.setBlock(i + 8, j + 9, k + 3, 0);
		world.setBlock(i + 8, j + 9, k + 4, 0);
		world.setBlock(i + 8, j + 10, k + 0, 0);
		world.setBlock(i + 8, j + 10, k + 1, 0);
		world.setBlock(i + 8, j + 10, k + 2, 0);
		world.setBlock(i + 8, j + 10, k + 3, BlockIllusionary.instance.blockID, 0, 2);
		world.setBlock(i + 8, j + 10, k + 4, 0);
		world.setBlock(i + 8, j + 10, k + 5, 0);
		world.setBlock(i + 8, j + 11, k + 0, 0);
		world.setBlock(i + 8, j + 11, k + 1, 0);
		world.setBlock(i + 8, j + 11, k + 2, Block.cobblestone.blockID, 0, 2);
		world.setBlock(i + 8, j + 11, k + 3, 0);
		world.setBlock(i + 8, j + 11, k + 4, Block.fence.blockID, 0, 2);
		world.setBlock(i + 8, j + 11, k + 5, 0);
		world.setBlock(i + 8, j + 12, k + 0, 0);
		world.setBlock(i + 8, j + 12, k + 1, 0);
		world.setBlock(i + 8, j + 12, k + 2, Block.cobblestone.blockID, 0, 2);
		world.setBlock(i + 8, j + 12, k + 3, 0);
		world.setBlock(i + 8, j + 12, k + 4, 0);
		world.setBlock(i + 8, j + 12, k + 5, 0);
		world.setBlock(i + 8, j + 13, k + 2, Block.cobblestone.blockID, 0, 2);
		world.setBlock(i + 8, j + 13, k + 3, Block.cobblestone.blockID, 0, 2);
		world.setBlock(i + 8, j + 14, k + 1, Block.stairsWoodOak.blockID, 2, 2);
		world.setBlock(i + 8, j + 14, k + 2, Block.stairsWoodOak.blockID, 0, 2);
		world.setBlock(i + 8, j + 14, k + 3, Block.stairsWoodOak.blockID, 0, 2);
		world.setBlock(i + 8, j + 14, k + 4, Block.stairsWoodOak.blockID, 0, 2);
		world.setBlock(i + 9, j + 8, k + 1, 0);
		world.setBlock(i + 9, j + 8, k + 2, 0);
		world.setBlock(i + 9, j + 8, k + 3, 0);
		world.setBlock(i + 9, j + 8, k + 4, 0);
		world.setBlock(i + 9, j + 9, k + 1, 0);
		world.setBlock(i + 9, j + 9, k + 2, Block.stairsCobblestone.blockID, 6, 2);
		world.setBlock(i + 9, j + 9, k + 3, Block.stairsCobblestone.blockID, 4, 2);
		world.setBlock(i + 9, j + 9, k + 4, 0);
		world.setBlock(i + 9, j + 10, k + 0, 0);
		world.setBlock(i + 9, j + 10, k + 1, Block.stairsCobblestone.blockID, 6, 2);
		world.setBlock(i + 9, j + 10, k + 2, Block.cobblestone.blockID, 0, 2);
		world.setBlock(i + 9, j + 10, k + 3, Block.cobblestone.blockID, 0, 2);
		world.setBlock(i + 9, j + 10, k + 4, Block.stairsCobblestone.blockID, 7, 2);
		world.setBlock(i + 9, j + 10, k + 5, 0);
		world.setBlock(i + 9, j + 11, k + 0, 0);
		world.setBlock(i + 9, j + 11, k + 1, Block.cobblestone.blockID, 0, 2);
		world.setBlock(i + 9, j + 11, k + 2, BlockPedestal.instance.blockID, 0, 2);
		world.setBlock(i + 9, j + 11, k + 3, 0);
		world.setBlock(i + 9, j + 11, k + 4, Block.cobblestone.blockID, 0, 2);
		world.setBlock(i + 9, j + 11, k + 5, 0);
		world.setBlock(i + 9, j + 12, k + 0, 0);
		world.setBlock(i + 9, j + 12, k + 1, Block.cobblestone.blockID, 0, 2);
		world.setBlock(i + 9, j + 12, k + 2, 0);
		world.setBlock(i + 9, j + 12, k + 3, 0);
		world.setBlock(i + 9, j + 12, k + 4, Block.cobblestone.blockID, 0, 2);
		world.setBlock(i + 9, j + 12, k + 5, 0);
		world.setBlock(i + 9, j + 13, k + 1, Block.cobblestone.blockID, 0, 2);
		world.setBlock(i + 9, j + 13, k + 2, Block.cobblestone.blockID, 0, 2);
		world.setBlock(i + 9, j + 13, k + 3, Block.cobblestone.blockID, 0, 2);
		world.setBlock(i + 9, j + 13, k + 4, Block.cobblestone.blockID, 0, 2);
		world.setBlock(i + 9, j + 14, k + 1, Block.stairsWoodOak.blockID, 2, 2);
		world.setBlock(i + 9, j + 14, k + 2, Block.cobblestone.blockID, 0, 2);
		world.setBlock(i + 9, j + 14, k + 3, Block.cobblestone.blockID, 0, 2);
		world.setBlock(i + 9, j + 14, k + 4, Block.stairsWoodOak.blockID, 3, 2);
		world.setBlock(i + 9, j + 15, k + 2, Block.stairsWoodOak.blockID, 2, 2);
		world.setBlock(i + 9, j + 15, k + 3, Block.stairsWoodOak.blockID, 0, 2);
		world.setBlock(i + 10, j + 8, k + 1, 0);
		world.setBlock(i + 10, j + 8, k + 2, 0);
		world.setBlock(i + 10, j + 8, k + 3, 0);
		world.setBlock(i + 10, j + 8, k + 4, 0);
		world.setBlock(i + 10, j + 9, k + 1, 0);
		world.setBlock(i + 10, j + 9, k + 2, Block.stairsCobblestone.blockID, 5, 2);
		world.setBlock(i + 10, j + 9, k + 3, Block.stairsCobblestone.blockID, 7, 2);
		world.setBlock(i + 10, j + 9, k + 4, 0);
		world.setBlock(i + 10, j + 10, k + 0, 0);
		world.setBlock(i + 10, j + 10, k + 1, Block.stairsCobblestone.blockID, 6, 2);
		world.setBlock(i + 10, j + 10, k + 2, Block.cobblestone.blockID, 0, 2);
		world.setBlock(i + 10, j + 10, k + 3, Block.cobblestone.blockID, 0, 2);
		world.setBlock(i + 10, j + 10, k + 4, Block.stairsCobblestone.blockID, 7, 2);
		world.setBlock(i + 10, j + 10, k + 5, 0);
		world.setBlock(i + 10, j + 11, k + 0, 0);
		world.setBlock(i + 10, j + 11, k + 1, Block.cobblestone.blockID, 0, 2);
		world.setBlock(i + 10, j + 11, k + 2, Block.bed.blockID, 10, 2);
		world.setBlock(i + 10, j + 11, k + 3, Block.bed.blockID, 2, 2);
		world.setBlock(i + 10, j + 11, k + 4, Block.cobblestone.blockID, 0, 2);
		world.setBlock(i + 10, j + 11, k + 5, 0);
		world.setBlock(i + 10, j + 12, k + 0, 0);
		world.setBlock(i + 10, j + 12, k + 1, Block.cobblestone.blockID, 0, 2);
		world.setBlock(i + 10, j + 12, k + 2, 0);
		world.setBlock(i + 10, j + 12, k + 3, 0);
		world.setBlock(i + 10, j + 12, k + 4, Block.cobblestone.blockID, 0, 2);
		world.setBlock(i + 10, j + 12, k + 5, 0);
		world.setBlock(i + 10, j + 13, k + 1, Block.cobblestone.blockID, 0, 2);
		world.setBlock(i + 10, j + 13, k + 2, Block.glowStone.blockID, 0, 2);
		world.setBlock(i + 10, j + 13, k + 3, Block.cobblestone.blockID, 0, 2);
		world.setBlock(i + 10, j + 13, k + 4, Block.cobblestone.blockID, 0, 2);
		world.setBlock(i + 10, j + 14, k + 1, Block.stairsWoodOak.blockID, 2, 2);
		world.setBlock(i + 10, j + 14, k + 2, Block.cobblestone.blockID, 0, 2);
		world.setBlock(i + 10, j + 14, k + 3, Block.cobblestone.blockID, 0, 2);
		world.setBlock(i + 10, j + 14, k + 4, Block.stairsWoodOak.blockID, 3, 2);
		world.setBlock(i + 10, j + 15, k + 2, Block.stairsWoodOak.blockID, 1, 2);
		world.setBlock(i + 10, j + 15, k + 3, Block.stairsWoodOak.blockID, 3, 2);
		world.setBlock(i + 11, j + 8, k + 1, 0);
		world.setBlock(i + 11, j + 8, k + 2, 0);
		world.setBlock(i + 11, j + 8, k + 3, 0);
		world.setBlock(i + 11, j + 8, k + 4, 0);
		world.setBlock(i + 11, j + 9, k + 1, 0);
		world.setBlock(i + 11, j + 9, k + 2, 0);
		world.setBlock(i + 11, j + 9, k + 3, 0);
		world.setBlock(i + 11, j + 9, k + 4, 0);
		world.setBlock(i + 11, j + 10, k + 0, 0);
		world.setBlock(i + 11, j + 10, k + 1, 0);
		world.setBlock(i + 11, j + 10, k + 2, Block.stairsCobblestone.blockID, 5, 2);
		world.setBlock(i + 11, j + 10, k + 3, Block.stairsCobblestone.blockID, 5, 2);
		world.setBlock(i + 11, j + 10, k + 4, 0);
		world.setBlock(i + 11, j + 10, k + 5, 0);
		world.setBlock(i + 11, j + 11, k + 0, 0);
		world.setBlock(i + 11, j + 11, k + 1, 0);
		world.setBlock(i + 11, j + 11, k + 2, Block.cobblestone.blockID, 0, 2);
		world.setBlock(i + 11, j + 11, k + 3, Block.cobblestone.blockID, 0, 2);
		world.setBlock(i + 11, j + 11, k + 4, 0);
		world.setBlock(i + 11, j + 11, k + 5, 0);
		world.setBlock(i + 11, j + 12, k + 0, 0);
		world.setBlock(i + 11, j + 12, k + 1, 0);
		world.setBlock(i + 11, j + 12, k + 2, Block.cobblestone.blockID, 0, 2);
		world.setBlock(i + 11, j + 12, k + 3, Block.cobblestone.blockID, 0, 2);
		world.setBlock(i + 11, j + 12, k + 4, 0);
		world.setBlock(i + 11, j + 12, k + 5, 0);
		world.setBlock(i + 11, j + 13, k + 2, Block.cobblestone.blockID, 0, 2);
		world.setBlock(i + 11, j + 13, k + 3, Block.cobblestone.blockID, 0, 2);
		world.setBlock(i + 11, j + 14, k + 1, Block.stairsWoodOak.blockID, 1, 2);
		world.setBlock(i + 11, j + 14, k + 2, Block.stairsWoodOak.blockID, 1, 2);
		world.setBlock(i + 11, j + 14, k + 3, Block.stairsWoodOak.blockID, 1, 2);
		world.setBlock(i + 11, j + 14, k + 4, Block.stairsWoodOak.blockID, 3, 2);
		world.setBlock(i + 2, j + 3, k + 2, Block.ladder.blockID, 5, 2);
		world.setBlock(i + 2, j + 4, k + 2, Block.ladder.blockID, 5, 2);
		world.setBlock(i + 2, j + 5, k + 2, Block.ladder.blockID, 5, 2);
		world.setBlock(i + 2, j + 6, k + 2, Block.ladder.blockID, 5, 2);
		world.setBlock(i + 3, j + 3, k + 0, Block.doorIron.blockID, 1, 2);
		world.setBlock(i + 3, j + 4, k + 0, Block.doorIron.blockID, 8, 2);
		world.setBlockToAir(i+3, j+3, k-1);
		world.setBlockToAir(i+3, j+4, k-1);
		world.setBlock(i + 3, j + 7, k + 3, Block.ladder.blockID, 2, 2);
		world.setBlock(i + 3, j + 8, k + 3, Block.ladder.blockID, 2, 2);
		world.setBlock(i + 3, j + 9, k + 3, Block.ladder.blockID, 2, 2);
		world.setBlock(i + 3, j + 10, k + 3, Block.ladder.blockID, 2, 2);
		world.setBlock(i + 3, j + 11, k + 3, Block.ladder.blockID, 2, 2);
		world.setBlock(i + 3, j + 12, k + 3, Block.ladder.blockID, 2, 2);
		world.setBlock(i + 3, j + 13, k + 3, Block.torchWood.blockID, 4, 2);
		TileEntity te = world.getBlockTileEntity(i + 9, j + 11, k + 2); 
		if(te instanceof TileEntityDisplayPedestal) {
			TileEntityDisplayPedestal ted = (TileEntityDisplayPedestal)te;
			ted.setInventorySlotContents(0, ArtifactsAPI.artifacts.generateRandomArtifact());
			ted.rotation = 180;
		}
		TileEntityChest tileentitychest = (TileEntityChest)world.getBlockTileEntity(i + 3, j + 15, k + 4);
		if (tileentitychest != null)
        {
            ChestGenHooks info = ChestGenHooks.getInfo(ChestGenHooks.PYRAMID_JUNGLE_CHEST);
            WeightedRandomChestContent.generateChestContents(rand, info.getItems(rand), tileentitychest, info.getCount(rand));
        }
		basement(world, i, j, k);
		return true;
	}
	
	private void basement(World world, int i, int j, int k) {
		boolean noair = false;
		int y = -1;
		do {
			noair = false;
			for(int x = 0; x <= 6; x++) {
				for(int z = 0; z <= 6; z++) {
					//5,y,4
					int d = (x-3)*(x-3)+(z-3)*(z-3);
					if(d <= 10) {
						if(!world.isBlockOpaqueCube(i+x, j+y, z+k) || world.getBlockId(i+x, j+y, z+k) == Block.leaves.blockID) {
							noair=true;
							world.setBlock(i+x, j+y, z+k, Block.cobblestone.blockID, 0, 2);
						}
					}
				}
			}
			y--;
		} while(noair && (j+y) >= 0);
	}
}
