package draco18s.artifacts.worldgen;
import java.util.Random;

import draco18s.artifacts.block.*;
import draco18s.artifacts.entity.TileEntityDisplayPedestal;
import draco18s.artifacts.entity.TileEntityTrap;
import draco18s.artifacts.item.*;

import net.minecraft.block.Block;
import net.minecraft.entity.item.EntityPainting;
import net.minecraft.item.Item;
import net.minecraft.item.ItemStack;
import net.minecraft.nbt.NBTTagCompound;
import net.minecraft.tileentity.*;
import net.minecraft.util.WeightedRandomChestContent;
import net.minecraft.world.World;
import net.minecraft.world.gen.feature.WorldGenerator;
import net.minecraftforge.common.ChestGenHooks;

public class StructureMasterTower extends WorldGenerator
{
	public StructureMasterTower() { }

	@Override
	public boolean generate(World world, Random random, int x, int y, int z) {
		for (z -= 8; y > 5 && (!world.isBlockOpaqueCube(x, y, z) || world.getBlockId(x, y, z) == Block.leaves.blockID); --y)
        {
            ;
        }

        if (y <= 61)
        {
            return false;
        }
        else
        {
        	build(world, random, x-6, y-2, z-12);
        }
		return false;
	}
	
	public boolean build(World world, Random rand, int i, int j, int k) {
		//System.out.println("Master tower at (" + i + "," + k + ")");
		world.setBlock(i + 0, j + 18, k + 9, Block.stairsWoodOak.blockID, 4, 3);
		world.setBlock(i + 0, j + 18, k + 10, Block.stairsWoodOak.blockID, 4, 3);
		world.setBlock(i + 0, j + 18, k + 11, Block.stairsWoodOak.blockID, 4, 3);
		world.setBlock(i + 0, j + 18, k + 12, Block.stairsWoodOak.blockID, 4, 3);
		world.setBlock(i + 0, j + 19, k + 9, Block.planks.blockID);
		world.setBlock(i + 0, j + 19, k + 10, Block.planks.blockID);
		world.setBlock(i + 0, j + 19, k + 11, Block.planks.blockID);
		world.setBlock(i + 0, j + 19, k + 12, Block.planks.blockID);
		world.setBlock(i + 0, j + 20, k + 9, Block.planks.blockID);
		world.setBlock(i + 0, j + 20, k + 10, Block.thinGlass.blockID);
		world.setBlock(i + 0, j + 20, k + 11, Block.thinGlass.blockID);
		world.setBlock(i + 0, j + 20, k + 12, Block.planks.blockID);
		world.setBlock(i + 0, j + 21, k + 9, Block.planks.blockID);
		world.setBlock(i + 0, j + 21, k + 10, Block.planks.blockID);
		world.setBlock(i + 0, j + 21, k + 11, Block.planks.blockID);
		world.setBlock(i + 0, j + 21, k + 12, Block.planks.blockID);
		world.setBlock(i + 0, j + 22, k + 9, Block.stairsWoodOak.blockID, 2, 3);
		world.setBlock(i + 0, j + 22, k + 10, Block.stairsWoodOak.blockID);
		world.setBlock(i + 0, j + 22, k + 11, Block.stairsWoodOak.blockID);
		world.setBlock(i + 0, j + 22, k + 12, Block.stairsWoodOak.blockID);
		world.setBlock(i + 1, j + 0, k + 6, Block.stoneBrick.blockID);
		world.setBlock(i + 1, j + 0, k + 7, Block.stoneBrick.blockID);
		world.setBlock(i + 1, j + 0, k + 8, Block.stoneBrick.blockID);
		world.setBlock(i + 1, j + 1, k + 6, Block.stoneBrick.blockID);
		world.setBlock(i + 1, j + 1, k + 7, Block.stoneBrick.blockID);
		world.setBlock(i + 1, j + 1, k + 8, Block.stoneBrick.blockID);
		world.setBlock(i + 1, j + 2, k + 6, Block.stoneBrick.blockID);
		world.setBlock(i + 1, j + 2, k + 7, Block.stoneBrick.blockID);
		world.setBlock(i + 1, j + 2, k + 8, Block.stoneBrick.blockID);
		world.setBlock(i + 1, j + 3, k + 6, Block.stoneBrick.blockID);
		world.setBlock(i + 1, j + 3, k + 7, Block.stoneBrick.blockID);
		world.setBlock(i + 1, j + 3, k + 8, Block.stoneBrick.blockID);
		world.setBlock(i + 1, j + 4, k + 6, Block.stoneBrick.blockID);
		world.setBlock(i + 1, j + 4, k + 7, Block.fenceIron.blockID);
		world.setBlock(i + 1, j + 4, k + 8, Block.stoneBrick.blockID);
		world.setBlock(i + 1, j + 5, k + 6, Block.stoneBrick.blockID);
		world.setBlock(i + 1, j + 5, k + 7, Block.stoneBrick.blockID);
		world.setBlock(i + 1, j + 5, k + 8, Block.stoneBrick.blockID);
		world.setBlock(i + 1, j + 6, k + 6, Block.stoneBrick.blockID);
		world.setBlock(i + 1, j + 6, k + 7, Block.stoneBrick.blockID);
		world.setBlock(i + 1, j + 6, k + 8, Block.stoneBrick.blockID);
		world.setBlock(i + 1, j + 7, k + 6, Block.stoneBrick.blockID);
		world.setBlock(i + 1, j + 7, k + 7, Block.stoneBrick.blockID);
		world.setBlock(i + 1, j + 7, k + 8, Block.stoneBrick.blockID);
		world.setBlock(i + 1, j + 8, k + 6, Block.stoneBrick.blockID);
		world.setBlock(i + 1, j + 8, k + 7, Block.stoneBrick.blockID);
		world.setBlock(i + 1, j + 8, k + 8, Block.stoneBrick.blockID);
		world.setBlock(i + 1, j + 9, k + 6, Block.stoneBrick.blockID);
		world.setBlock(i + 1, j + 9, k + 7, Block.stoneBrick.blockID);
		world.setBlock(i + 1, j + 9, k + 8, Block.stoneBrick.blockID);
		world.setBlock(i + 1, j + 10, k + 7, Block.stoneBrick.blockID);
		world.setBlock(i + 1, j + 11, k + 2, Block.stairsWoodOak.blockID, 4, 3);
		world.setBlock(i + 1, j + 11, k + 3, Block.stairsWoodOak.blockID, 4, 3);
		world.setBlock(i + 1, j + 11, k + 4, Block.stairsWoodOak.blockID, 4, 3);
		world.setBlock(i + 1, j + 11, k + 7, Block.stairsStoneBrick.blockID);
		world.setBlock(i + 1, j + 12, k + 2, Block.planks.blockID);
		world.setBlock(i + 1, j + 12, k + 3, Block.planks.blockID);
		world.setBlock(i + 1, j + 12, k + 4, Block.planks.blockID);
		world.setBlock(i + 1, j + 13, k + 2, Block.planks.blockID);
		world.setBlock(i + 1, j + 13, k + 3, Block.planks.blockID);
		world.setBlock(i + 1, j + 13, k + 4, Block.planks.blockID);
		world.setBlock(i + 1, j + 14, k + 2, Block.planks.blockID);
		world.setBlock(i + 1, j + 14, k + 3, Block.planks.blockID);
		world.setBlock(i + 1, j + 14, k + 4, Block.planks.blockID);
		world.setBlock(i + 1, j + 15, k + 1, Block.stairsWoodOak.blockID, 2, 3);
		world.setBlock(i + 1, j + 15, k + 2, Block.stairsWoodOak.blockID);
		world.setBlock(i + 1, j + 15, k + 3, Block.stairsWoodOak.blockID);
		world.setBlock(i + 1, j + 15, k + 4, Block.stairsWoodOak.blockID);
		world.setBlock(i + 1, j + 15, k + 5, Block.stairsWoodOak.blockID, 3, 3);
		world.setBlock(i + 1, j + 17, k + 9, Block.stairsWoodOak.blockID, 4, 3);
		world.setBlock(i + 1, j + 17, k + 10, Block.stairsWoodOak.blockID, 4, 3);
		world.setBlock(i + 1, j + 17, k + 11, Block.stairsWoodOak.blockID, 4, 3);
		world.setBlock(i + 1, j + 17, k + 12, Block.stairsWoodOak.blockID, 4, 3);
		world.setBlock(i + 1, j + 18, k + 8, Block.stairsWoodOak.blockID, 6, 3);
		world.setBlock(i + 1, j + 18, k + 9, Block.planks.blockID);
		world.setBlock(i + 1, j + 18, k + 10, Block.planks.blockID);
		world.setBlock(i + 1, j + 18, k + 11, Block.planks.blockID);
		world.setBlock(i + 1, j + 18, k + 12, Block.planks.blockID);
		world.setBlock(i + 1, j + 18, k + 13, Block.stairsWoodOak.blockID, 7, 3);
		world.setBlock(i + 1, j + 19, k + 8, Block.planks.blockID);
		world.setBlock(i + 1, j + 19, k + 9, 0);
		world.setBlock(i + 1, j + 19, k + 10, 0);
		world.setBlock(i + 1, j + 19, k + 11, 0);
		world.setBlock(i + 1, j + 19, k + 12, 0);
		world.setBlock(i + 1, j + 19, k + 13, Block.planks.blockID);
		world.setBlock(i + 1, j + 20, k + 8, Block.planks.blockID);
		world.setBlock(i + 1, j + 20, k + 9, 0);
		world.setBlock(i + 1, j + 20, k + 10, 0);
		world.setBlock(i + 1, j + 20, k + 11, 0);
		world.setBlock(i + 1, j + 20, k + 12, 0);
		world.setBlock(i + 1, j + 20, k + 13, Block.planks.blockID);
		world.setBlock(i + 1, j + 21, k + 8, Block.planks.blockID);
		world.setBlock(i + 1, j + 21, k + 9, Block.planks.blockID);
		world.setBlock(i + 1, j + 21, k + 10, Block.planks.blockID);
		world.setBlock(i + 1, j + 21, k + 11, Block.planks.blockID);
		world.setBlock(i + 1, j + 21, k + 12, Block.planks.blockID);
		world.setBlock(i + 1, j + 21, k + 13, Block.planks.blockID);
		world.setBlock(i + 1, j + 22, k + 8, Block.stairsWoodOak.blockID, 2, 3);
		world.setBlock(i + 1, j + 22, k + 9, Block.stairsWoodOak.blockID);
		world.setBlock(i + 1, j + 22, k + 10, Block.planks.blockID);
		world.setBlock(i + 1, j + 22, k + 11, Block.planks.blockID);
		world.setBlock(i + 1, j + 22, k + 12, Block.stairsWoodOak.blockID, 3, 3);
		world.setBlock(i + 1, j + 22, k + 13, Block.stairsWoodOak.blockID);
		world.setBlock(i + 1, j + 23, k + 10, Block.woodSingleSlab.blockID);
		world.setBlock(i + 1, j + 23, k + 11, Block.stairsWoodOak.blockID);
		world.setBlock(i + 2, j + 0, k + 4, Block.stoneBrick.blockID);
		world.setBlock(i + 2, j + 0, k + 5, Block.stoneBrick.blockID);
		world.setBlock(i + 2, j + 0, k + 6, Block.stoneBrick.blockID);
		world.setBlock(i + 2, j + 0, k + 7, Block.stoneBrick.blockID);
		world.setBlock(i + 2, j + 0, k + 8, Block.stoneBrick.blockID);
		world.setBlock(i + 2, j + 0, k + 9, Block.stoneBrick.blockID);
		world.setBlock(i + 2, j + 0, k + 10, Block.stoneBrick.blockID);
		world.setBlock(i + 2, j + 1, k + 4, Block.stoneBrick.blockID);
		world.setBlock(i + 2, j + 1, k + 5, Block.stoneBrick.blockID);
		world.setBlock(i + 2, j + 1, k + 6, Block.stoneBrick.blockID);
		world.setBlock(i + 2, j + 1, k + 7, Block.stoneBrick.blockID);
		world.setBlock(i + 2, j + 1, k + 8, Block.stoneBrick.blockID);
		world.setBlock(i + 2, j + 1, k + 9, Block.stoneBrick.blockID);
		world.setBlock(i + 2, j + 1, k + 10, Block.stoneBrick.blockID);
		world.setBlock(i + 2, j + 2, k + 4, Block.stoneBrick.blockID);
		world.setBlock(i + 2, j + 2, k + 5, Block.stoneBrick.blockID);
		world.setBlock(i + 2, j + 2, k + 6, Block.stoneBrick.blockID);
		world.setBlock(i + 2, j + 2, k + 7, Block.stoneBrick.blockID);
		world.setBlock(i + 2, j + 2, k + 8, Block.stoneBrick.blockID);
		world.setBlock(i + 2, j + 2, k + 9, Block.stoneBrick.blockID);
		world.setBlock(i + 2, j + 2, k + 10, Block.stoneBrick.blockID);
		world.setBlock(i + 2, j + 3, k + 4, Block.stoneBrick.blockID);
		world.setBlock(i + 2, j + 3, k + 5, Block.stoneBrick.blockID);
		world.setBlock(i + 2, j + 3, k + 7, 0);
		world.setBlock(i + 2, j + 3, k + 8, Block.stoneBrick.blockID);
		world.setBlock(i + 2, j + 3, k + 9, Block.stoneBrick.blockID);
		world.setBlock(i + 2, j + 3, k + 10, Block.stoneBrick.blockID);
		world.setBlock(i + 2, j + 4, k + 4, Block.stoneBrick.blockID);
		world.setBlock(i + 2, j + 4, k + 5, Block.stoneBrick.blockID);
		world.setBlock(i + 2, j + 4, k + 7, 0);
		world.setBlock(i + 2, j + 4, k + 8, Block.stoneBrick.blockID);
		world.setBlock(i + 2, j + 4, k + 9, Block.stoneBrick.blockID);
		world.setBlock(i + 2, j + 4, k + 10, Block.stoneBrick.blockID);
		world.setBlock(i + 2, j + 5, k + 4, Block.stoneBrick.blockID);
		world.setBlock(i + 2, j + 5, k + 5, Block.stoneBrick.blockID);
		world.setBlock(i + 2, j + 5, k + 7, 0);
		world.setBlock(i + 2, j + 5, k + 8, Block.stoneBrick.blockID);
		world.setBlock(i + 2, j + 5, k + 9, Block.stoneBrick.blockID);
		world.setBlock(i + 2, j + 5, k + 10, Block.stoneBrick.blockID);
		world.setBlock(i + 2, j + 6, k + 4, Block.stoneBrick.blockID);
		world.setBlock(i + 2, j + 6, k + 5, Block.stoneBrick.blockID);
		world.setBlock(i + 2, j + 6, k + 7, 0);
		world.setBlock(i + 2, j + 6, k + 8, Block.stoneBrick.blockID);
		world.setBlock(i + 2, j + 6, k + 9, Block.stoneBrick.blockID);
		world.setBlock(i + 2, j + 6, k + 10, Block.stoneBrick.blockID);
		world.setBlock(i + 2, j + 7, k + 4, Block.stoneBrick.blockID);
		world.setBlock(i + 2, j + 7, k + 5, Block.stoneBrick.blockID);
		world.setBlock(i + 2, j + 7, k + 7, Block.stoneBrick.blockID);
		world.setBlock(i + 2, j + 7, k + 8, Block.stoneBrick.blockID);
		world.setBlock(i + 2, j + 7, k + 9, Block.stoneBrick.blockID);
		world.setBlock(i + 2, j + 7, k + 10, Block.stoneBrick.blockID);
		world.setBlock(i + 2, j + 8, k + 5, Block.stoneBrick.blockID);
		world.setBlock(i + 2, j + 8, k + 6, 0);
		world.setBlock(i + 2, j + 8, k + 7, Block.stoneBrick.blockID);
		world.setBlock(i + 2, j + 8, k + 8, Block.stoneBrick.blockID);
		world.setBlock(i + 2, j + 8, k + 9, Block.stoneBrick.blockID);
		world.setBlock(i + 2, j + 9, k + 5, Block.stoneBrick.blockID);
		world.setBlock(i + 2, j + 9, k + 6, 0);
		world.setBlock(i + 2, j + 9, k + 7, Block.glowStone.blockID);
		world.setBlock(i + 2, j + 9, k + 8, Block.stoneBrick.blockID);
		world.setBlock(i + 2, j + 9, k + 9, Block.stoneBrick.blockID);
		world.setBlock(i + 2, j + 10, k + 2, Block.stairsWoodOak.blockID, 6, 3);
		world.setBlock(i + 2, j + 10, k + 3, Block.stairsWoodOak.blockID, 4, 3);
		world.setBlock(i + 2, j + 10, k + 4, Block.stairsWoodOak.blockID, 4, 3);
		world.setBlock(i + 2, j + 10, k + 5, Block.stoneBrick.blockID);
		world.setBlock(i + 2, j + 10, k + 6, Block.stoneBrick.blockID);
		world.setBlock(i + 2, j + 10, k + 7, Block.stoneBrick.blockID);
		world.setBlock(i + 2, j + 10, k + 8, Block.stoneBrick.blockID);
		world.setBlock(i + 2, j + 10, k + 9, Block.stoneBrick.blockID);
		world.setBlock(i + 2, j + 11, k + 1, Block.stairsWoodOak.blockID, 6, 3);
		world.setBlock(i + 2, j + 11, k + 2, Block.planks.blockID);
		world.setBlock(i + 2, j + 11, k + 3, Block.planks.blockID);
		world.setBlock(i + 2, j + 11, k + 4, Block.planks.blockID);
		world.setBlock(i + 2, j + 11, k + 5, Block.stoneBrick.blockID);
		world.setBlock(i + 2, j + 11, k + 6, Block.stoneBrick.blockID);
		world.setBlock(i + 2, j + 11, k + 7, Block.stoneBrick.blockID);
		world.setBlock(i + 2, j + 11, k + 8, Block.stoneBrick.blockID);
		world.setBlock(i + 2, j + 11, k + 9, Block.stoneBrick.blockID);
		world.setBlock(i + 2, j + 12, k + 1, Block.planks.blockID);
		world.setBlock(i + 2, j + 12, k + 2, Block.planks.blockID);
		world.setBlock(i + 2, j + 12, k + 3, BlockPedestal.instance.blockID);
		TileEntityDisplayPedestal tedd;
		TileEntity te = world.getBlockTileEntity(i + 2, j + 12, k + 3); 
		if(te instanceof TileEntityDisplayPedestal) {
			tedd = (TileEntityDisplayPedestal)te;
			tedd.setInventorySlotContents(0, FactoryArtifact.applyRandomEffects(new ItemStack(ItemArtifact.instance)));
			tedd.rotation = 90;
		}
		world.setBlock(i + 2, j + 12, k + 4, 0);
		world.setBlock(i + 2, j + 12, k + 5, Block.planks.blockID);
		world.setBlock(i + 2, j + 12, k + 6, Block.stoneBrick.blockID);
		world.setBlock(i + 2, j + 12, k + 7, Block.stoneBrick.blockID);
		world.setBlock(i + 2, j + 12, k + 8, Block.stoneBrick.blockID);
		world.setBlock(i + 2, j + 13, k + 1, Block.planks.blockID);
		world.setBlock(i + 2, j + 13, k + 2, Block.planks.blockID);
		world.setBlock(i + 2, j + 13, k + 3, 0);
		world.setBlock(i + 2, j + 13, k + 4, 0);
		world.setBlock(i + 2, j + 13, k + 5, Block.planks.blockID);
		world.setBlock(i + 2, j + 13, k + 6, Block.stoneBrick.blockID);
		world.setBlock(i + 2, j + 13, k + 7, Block.stoneBrick.blockID);
		world.setBlock(i + 2, j + 13, k + 8, Block.stoneBrick.blockID);
		world.setBlock(i + 2, j + 14, k + 1, Block.planks.blockID);
		world.setBlock(i + 2, j + 14, k + 2, Block.planks.blockID);
		world.setBlock(i + 2, j + 14, k + 3, 0);
		world.setBlock(i + 2, j + 14, k + 4, 0);
		world.setBlock(i + 2, j + 14, k + 5, Block.planks.blockID);
		world.setBlock(i + 2, j + 14, k + 6, Block.stoneBrick.blockID);
		world.setBlock(i + 2, j + 14, k + 7, Block.stoneBrick.blockID);
		world.setBlock(i + 2, j + 14, k + 8, Block.stoneBrick.blockID);
		world.setBlock(i + 2, j + 15, k + 0, Block.stairsWoodOak.blockID);
		world.setBlock(i + 2, j + 15, k + 1, Block.stairsWoodOak.blockID);
		world.setBlock(i + 2, j + 15, k + 2, Block.planks.blockID);
		world.setBlock(i + 2, j + 15, k + 3, Block.planks.blockID);
		world.setBlock(i + 2, j + 15, k + 4, Block.planks.blockID);
		world.setBlock(i + 2, j + 15, k + 5, Block.stairsWoodOak.blockID, 3, 3);
		world.setBlock(i + 2, j + 15, k + 7, Block.stoneBrick.blockID);
		world.setBlock(i + 2, j + 16, k + 2, Block.stairsWoodOak.blockID, 2, 3);
		world.setBlock(i + 2, j + 16, k + 3, Block.stairsWoodOak.blockID);
		world.setBlock(i + 2, j + 16, k + 4, Block.stairsWoodOak.blockID);
		world.setBlock(i + 2, j + 16, k + 7, Block.stairsStoneBrick.blockID);
		world.setBlock(i + 2, j + 17, k + 9, Block.stairsWoodOak.blockID, 6, 3);
		world.setBlock(i + 2, j + 17, k + 10, Block.planks.blockID);
		world.setBlock(i + 2, j + 17, k + 11, Block.planks.blockID);
		world.setBlock(i + 2, j + 17, k + 12, Block.stairsWoodOak.blockID, 7, 3);
		world.setBlock(i + 2, j + 18, k + 8, Block.stairsWoodOak.blockID, 6, 3);
		world.setBlock(i + 2, j + 18, k + 9, Block.planks.blockID);
		world.setBlock(i + 2, j + 18, k + 10, Block.planks.blockID);
		world.setBlock(i + 2, j + 18, k + 11, Block.planks.blockID);
		world.setBlock(i + 2, j + 18, k + 12, Block.planks.blockID);
		world.setBlock(i + 2, j + 18, k + 13, Block.stairsWoodOak.blockID, 7, 3);
		world.setBlock(i + 2, j + 19, k + 8, Block.planks.blockID);
		world.setBlock(i + 2, j + 19, k + 9, 0);
		world.setBlock(i + 2, j + 19, k + 10, 0);
		world.setBlock(i + 2, j + 19, k + 11, 0);
		world.setBlock(i + 2, j + 19, k + 12, Block.chest.blockID, 2, 3);
		world.setBlockMetadataWithNotify(i + 2, j + 19, k + 12, 2, 3);
		te = world.getBlockTileEntity(i + 2, j + 19, k + 12);
		if(te instanceof TileEntityChest) {
			/*TileEntityChest tec = (TileEntityChest)te;
			ChestGenHooks info = ChestGenHooks.getInfo(ChestGenHooks.PYRAMID_DESERT_CHEST);
            WeightedRandomChestContent.generateChestContents(rand, info.getItems(rand), tec, info.getCount(rand));*/
		}
		world.setBlock(i + 2, j + 19, k + 13, Block.planks.blockID);
		world.setBlock(i + 2, j + 20, k + 8, Block.planks.blockID);
		world.setBlock(i + 2, j + 20, k + 9, 0);
		world.setBlock(i + 2, j + 20, k + 10, 0);
		world.setBlock(i + 2, j + 20, k + 11, 0);
		world.setBlock(i + 2, j + 20, k + 12, 0);
		world.setBlock(i + 2, j + 20, k + 13, Block.planks.blockID);
		world.setBlock(i + 2, j + 21, k + 8, Block.planks.blockID);
		world.setBlock(i + 2, j + 21, k + 9, Block.planks.blockID);
		world.setBlock(i + 2, j + 21, k + 10, Block.redstoneLampIdle.blockID);
		world.setBlock(i + 2, j + 21, k + 11, Block.planks.blockID);
		world.setBlock(i + 2, j + 21, k + 12, Block.planks.blockID);
		world.setBlock(i + 2, j + 21, k + 13, Block.planks.blockID);
		world.setBlock(i + 2, j + 22, k + 8, Block.stairsWoodOak.blockID, 2, 3);
		world.setBlock(i + 2, j + 22, k + 9, Block.planks.blockID);
		world.setBlock(i + 2, j + 22, k + 11, Block.planks.blockID);
		world.setBlock(i + 2, j + 22, k + 12, Block.planks.blockID);
		world.setBlock(i + 2, j + 22, k + 13, Block.stairsWoodOak.blockID, 3, 3);
		world.setBlock(i + 2, j + 23, k + 9, Block.woodSingleSlab.blockID);
		world.setBlock(i + 2, j + 23, k + 10, Block.stairsWoodOak.blockID, 7, 3);
		world.setBlock(i + 2, j + 23, k + 12, Block.stairsWoodOak.blockID, 3, 3);
		//world.scheduleBlockUpdate(i + 2, j + 24, k + 11, Block.daylightSensor.blockID, 10);
		world.setBlock(i + 3, j + 0, k + 4, Block.stoneBrick.blockID);
		world.setBlock(i + 3, j + 0, k + 5, Block.stoneBrick.blockID);
		world.setBlock(i + 3, j + 0, k + 6, Block.stoneBrick.blockID);
		world.setBlock(i + 3, j + 0, k + 7, Block.stoneBrick.blockID);
		world.setBlock(i + 3, j + 0, k + 8, Block.stoneBrick.blockID);
		world.setBlock(i + 3, j + 0, k + 9, Block.stoneBrick.blockID);
		world.setBlock(i + 3, j + 0, k + 10, Block.stoneBrick.blockID);
		world.setBlock(i + 3, j + 1, k + 3, Block.stoneBrick.blockID);
		world.setBlock(i + 3, j + 1, k + 4, Block.stoneBrick.blockID);
		world.setBlock(i + 3, j + 1, k + 5, BlockSpikes.instance.blockID);
		world.setBlock(i + 3, j + 1, k + 6, BlockSpikes.instance.blockID);
		world.setBlock(i + 3, j + 1, k + 7, BlockSpikes.instance.blockID);
		world.setBlock(i + 3, j + 1, k + 8, Block.stoneBrick.blockID);
		world.setBlock(i + 3, j + 1, k + 9, Block.stoneBrick.blockID);
		world.setBlock(i + 3, j + 1, k + 10, Block.stoneBrick.blockID);
		world.setBlock(i + 3, j + 1, k + 11, Block.stoneBrick.blockID);
		world.setBlock(i + 3, j + 2, k + 3, Block.stoneBrick.blockID);
		world.setBlock(i + 3, j + 2, k + 4, Block.stoneBrick.blockID);
		world.setBlock(i + 3, j + 2, k + 5, BlockIllusionary.instance.blockID);
		world.setBlock(i + 3, j + 2, k + 6, BlockIllusionary.instance.blockID);
		world.setBlock(i + 3, j + 2, k + 7, BlockIllusionary.instance.blockID);
		world.setBlock(i + 3, j + 2, k + 8, Block.stoneBrick.blockID);
		world.setBlock(i + 3, j + 2, k + 9, Block.stoneBrick.blockID);
		world.setBlock(i + 3, j + 2, k + 10, Block.stoneBrick.blockID);
		world.setBlock(i + 3, j + 2, k + 11, Block.stoneBrick.blockID);
		world.setBlock(i + 3, j + 3, k + 3, Block.stoneBrick.blockID);
		world.setBlock(i + 3, j + 3, k + 4, BlockTrap.instance.blockID, 3, 3);
		te = world.getBlockTileEntity(i + 3, j + 3, k + 4); 
		TileEntityTrap ted;
		if(te instanceof TileEntityTrap) {
			ted = (TileEntityTrap)te;
			ted.addItem(new ItemStack(Item.swordDiamond, 1, 1000));
		}
		world.setBlockMetadataWithNotify(i + 3, j + 3, k + 4, 3, 3);
		world.setBlock(i + 3, j + 3, k + 5, 0);
		world.setBlock(i + 3, j + 3, k + 6, 0);
		world.setBlock(i + 3, j + 3, k + 7, 0);
		world.setBlock(i + 3, j + 3, k + 8, BlockTrap.instance.blockID, 2, 3);
		te = world.getBlockTileEntity(i + 3, j + 3, k + 8); 
		if(te instanceof TileEntityTrap) {
			ted = (TileEntityTrap)te;
			ted.addItem(new ItemStack(Item.swordDiamond, 1, 1000));
		}
		world.setBlockMetadataWithNotify(i + 3, j + 3, k + 8, 2, 3);
		world.setBlock(i + 3, j + 3, k + 9, Block.stoneBrick.blockID);
		world.setBlock(i + 3, j + 3, k + 10, Block.stoneBrick.blockID);
		world.setBlock(i + 3, j + 3, k + 11, Block.stoneBrick.blockID);
		world.setBlock(i + 3, j + 4, k + 3, Block.stoneBrick.blockID);
		world.setBlock(i + 3, j + 4, k + 4, Block.stoneBrick.blockID);
		world.setBlock(i + 3, j + 4, k + 5, 0);
		world.setBlock(i + 3, j + 4, k + 6, 0);
		world.setBlock(i + 3, j + 4, k + 7, 0);
		world.setBlock(i + 3, j + 4, k + 8, Block.stoneBrick.blockID);
		world.setBlock(i + 3, j + 4, k + 9, Block.stoneBrick.blockID);
		world.setBlock(i + 3, j + 4, k + 10, Block.stoneBrick.blockID);
		world.setBlock(i + 3, j + 4, k + 11, Block.stoneBrick.blockID);
		world.setBlock(i + 3, j + 5, k + 3, Block.stoneBrick.blockID);
		world.setBlock(i + 3, j + 5, k + 4, Block.stoneBrick.blockID);
		world.setBlock(i + 3, j + 5, k + 5, 0);
		world.setBlock(i + 3, j + 5, k + 6, 0);
		world.setBlock(i + 3, j + 5, k + 7, 0);
		world.setBlock(i + 3, j + 5, k + 8, Block.stoneBrick.blockID);
		world.setBlock(i + 3, j + 5, k + 9, Block.stoneBrick.blockID);
		world.setBlock(i + 3, j + 5, k + 10, Block.stoneBrick.blockID);
		world.setBlock(i + 3, j + 5, k + 11, Block.stoneBrick.blockID);
		world.setBlock(i + 3, j + 6, k + 3, Block.stoneBrick.blockID);
		world.setBlock(i + 3, j + 6, k + 4, Block.stoneBrick.blockID);
		world.setBlock(i + 3, j + 6, k + 5, 0);
		world.setBlock(i + 3, j + 6, k + 6, 0);
		world.setBlock(i + 3, j + 6, k + 7, 0);
		world.setBlock(i + 3, j + 6, k + 8, Block.stoneBrick.blockID);
		world.setBlock(i + 3, j + 6, k + 9, Block.stoneBrick.blockID);
		world.setBlock(i + 3, j + 6, k + 10, Block.stoneBrick.blockID);
		world.setBlock(i + 3, j + 6, k + 11, Block.stoneBrick.blockID);
		world.setBlock(i + 3, j + 7, k + 3, Block.stoneBrick.blockID);
		world.setBlock(i + 3, j + 7, k + 4, Block.stoneBrick.blockID);
		world.setBlock(i + 3, j + 7, k + 5, Block.stoneBrick.blockID);
		world.setBlock(i + 3, j + 7, k + 6, Block.stoneBrick.blockID);
		world.setBlock(i + 3, j + 7, k + 7, BlockTrap.instance.blockID, 1, 3);
		world.setBlockMetadataWithNotify(i + 3, j + 7, k + 7, 1, 3);
		te = world.getBlockTileEntity(i + 3, j + 7, k + 7); 
		if(te instanceof TileEntityTrap) {
			ted = (TileEntityTrap)te;
			ted.addItem(new ItemStack(Item.arrow, 32));
		}
		world.setBlock(i + 3, j + 8, k + 7, BlockInvisiblePressurePlate.obsidian.blockID);
		world.setBlock(i + 3, j + 7, k + 8, Block.stoneBrick.blockID);
		world.setBlock(i + 3, j + 7, k + 9, Block.stoneBrick.blockID);
		world.setBlock(i + 3, j + 7, k + 10, Block.stoneBrick.blockID);
		world.setBlock(i + 3, j + 7, k + 11, Block.stoneBrick.blockID);
		world.setBlock(i + 3, j + 8, k + 4, Block.stoneBrick.blockID);
		world.setBlock(i + 3, j + 8, k + 5, Block.stoneBrick.blockID);
		world.setBlock(i + 3, j + 8, k + 6, 0);
		//world.setBlock(i + 3, j + 8, k + 7, 0);
		world.setBlock(i + 3, j + 8, k + 9, Block.stoneBrick.blockID);
		world.setBlock(i + 3, j + 8, k + 10, Block.stoneBrick.blockID);
		world.setBlock(i + 3, j + 9, k + 4, Block.stoneBrick.blockID);
		world.setBlock(i + 3, j + 9, k + 5, Block.stoneBrick.blockID);
		world.setBlock(i + 3, j + 9, k + 6, 0);
		world.setBlock(i + 3, j + 9, k + 7, 0);
		world.setBlock(i + 3, j + 9, k + 9, Block.stoneBrick.blockID);
		world.setBlock(i + 3, j + 9, k + 10, Block.stoneBrick.blockID);
		world.setBlock(i + 3, j + 10, k + 1, Block.stairsWoodOak.blockID, 4, 3);
		world.setBlock(i + 3, j + 10, k + 2, Block.stairsWoodOak.blockID, 4, 3);
		world.setBlock(i + 3, j + 10, k + 3, Block.planks.blockID);
		world.setBlock(i + 3, j + 10, k + 4, Block.stoneBrick.blockID);
		world.setBlock(i + 3, j + 10, k + 5, Block.stoneBrick.blockID);
		world.setBlock(i + 3, j + 10, k + 6, 0);
		world.setBlock(i + 3, j + 10, k + 7, 0);
		world.setBlock(i + 3, j + 10, k + 9, Block.stoneBrick.blockID);
		world.setBlock(i + 3, j + 10, k + 10, Block.stoneBrick.blockID);
		world.setBlock(i + 3, j + 11, k + 0, Block.stairsWoodOak.blockID, 6, 3);
		world.setBlock(i + 3, j + 11, k + 1, Block.planks.blockID);
		world.setBlock(i + 3, j + 11, k + 2, Block.planks.blockID);
		world.setBlock(i + 3, j + 11, k + 3, Block.planks.blockID);
		world.setBlock(i + 3, j + 11, k + 5, Block.stoneBrick.blockID);
		world.setBlock(i + 3, j + 11, k + 6, Block.stoneBrick.blockID);
		world.setBlock(i + 3, j + 11, k + 7, Block.stoneBrick.blockID);
		world.setBlock(i + 3, j + 11, k + 9, Block.stoneBrick.blockID);
		world.setBlock(i + 3, j + 12, k + 0, Block.planks.blockID);
		world.setBlock(i + 3, j + 12, k + 1, Block.stoneBrick.blockID);
		world.setBlock(i + 3, j + 12, k + 2, Block.planks.blockID);
		world.setBlock(i + 3, j + 12, k + 3, 0);
		world.setBlock(i + 3, j + 12, k + 4, 0);
		world.setBlock(i + 3, j + 12, k + 5, Block.stoneBrick.blockID);
		world.setBlock(i + 3, j + 12, k + 6, Block.stoneBrick.blockID);
		world.setBlock(i + 3, j + 12, k + 7, 0);
		world.setBlock(i + 3, j + 12, k + 8, 0);
		world.setBlock(i + 3, j + 12, k + 9, Block.stoneBrick.blockID);
		world.setBlock(i + 3, j + 13, k + 0, Block.planks.blockID);
		world.setBlock(i + 3, j + 13, k + 1, Block.stoneBrick.blockID);
		world.setBlock(i + 3, j + 13, k + 2, Block.planks.blockID);
		world.setBlock(i + 3, j + 13, k + 3, 0);
		world.setBlock(i + 3, j + 13, k + 4, 0);
		world.setBlock(i + 3, j + 13, k + 5, Block.stoneBrick.blockID);
		world.setBlock(i + 3, j + 13, k + 6, Block.stoneBrick.blockID);
		world.setBlock(i + 3, j + 13, k + 7, 0);
		//world.setBlock(i + 3, j + 13, k + 8, Block.stoneBrick.blockID);
		world.setBlock(i + 3, j + 13, k + 9, Block.stoneBrick.blockID);
		world.setBlock(i + 3, j + 14, k + 0, Block.planks.blockID);
		world.setBlock(i + 3, j + 14, k + 2, Block.planks.blockID);
		world.setBlock(i + 3, j + 14, k + 3, 0);
		world.setBlock(i + 3, j + 14, k + 4, 0);
		world.setBlock(i + 3, j + 14, k + 5, Block.stoneBrick.blockID);
		world.setBlock(i + 3, j + 14, k + 6, Block.stoneBrick.blockID);
		world.setBlock(i + 3, j + 14, k + 7, 0);
		world.setBlock(i + 3, j + 14, k + 8, 0);
		world.setBlock(i + 3, j + 14, k + 9, Block.stoneBrick.blockID);
		world.setBlock(i + 3, j + 15, k + 0, Block.stairsWoodOak.blockID, 2, 3);
		world.setBlock(i + 3, j + 14, k + 1, Block.planks.blockID, 15, 3);
		world.setBlock(i + 3, j + 15, k + 1, Block.redstoneWire.blockID);
		//world.scheduleBlockUpdate(i + 3, j + 15, k + 1, Block.daylightSensor.blockID, 10);
		world.setBlock(i + 4, j + 15, k + 2, Block.planks.blockID);
		world.setBlock(i + 4, j + 16, k + 2, Block.redstoneWire.blockID);
		world.setBlock(i + 3, j + 15, k + 2, Block.torchRedstoneIdle.blockID, 2, 3);
		world.setBlock(i + 3, j + 15, k + 3, Block.planks.blockID);
		world.setBlock(i + 3, j + 15, k + 4, Block.planks.blockID);
		world.setBlock(i + 3, j + 15, k + 5, Block.stoneBrick.blockID);
		world.setBlock(i + 3, j + 15, k + 6, Block.stoneBrick.blockID);
		world.setBlock(i + 3, j + 15, k + 7, Block.stoneBrick.blockID);
		world.setBlock(i + 3, j + 15, k + 8, Block.stoneBrick.blockID);
		world.setBlock(i + 3, j + 15, k + 9, Block.stoneBrick.blockID);
		world.setBlock(i + 3, j + 16, k + 1, Block.stairsWoodOak.blockID, 2, 3);
		world.setBlock(i + 3, j + 16, k + 2, Block.stairsWoodOak.blockID);
		world.setBlock(i + 3, j + 16, k + 3, Block.planks.blockID);
		world.setBlock(i + 3, j + 16, k + 4, Block.stairsWoodOak.blockID, 3, 3);
		world.setBlock(i + 3, j + 16, k + 5, Block.stairsWoodOak.blockID);
		world.setBlock(i + 3, j + 16, k + 6, Block.stoneBrick.blockID);
		world.setBlock(i + 3, j + 16, k + 7, Block.stoneBrick.blockID);
		world.setBlock(i + 3, j + 16, k + 8, Block.stoneBrick.blockID);
		world.setBlock(i + 3, j + 17, k + 3, Block.stairsWoodOak.blockID);
		world.setBlock(i + 3, j + 17, k + 6, Block.stoneBrick.blockID);
		world.setBlock(i + 3, j + 17, k + 7, Block.stoneBrick.blockID);
		world.setBlock(i + 3, j + 17, k + 8, Block.stoneBrick.blockID);
		world.setBlock(i + 3, j + 17, k + 9, Block.stairsWoodOak.blockID, 6, 3);
		world.setBlock(i + 3, j + 17, k + 10, Block.stairsWoodOak.blockID, 5, 3);
		world.setBlock(i + 3, j + 17, k + 11, Block.stairsWoodOak.blockID, 5, 3);
		world.setBlock(i + 3, j + 17, k + 12, Block.stairsWoodOak.blockID, 7, 3);
		world.setBlock(i + 3, j + 18, k + 7, Block.stoneBrick.blockID);
		world.setBlock(i + 3, j + 18, k + 8, Block.planks.blockID);
		world.setBlock(i + 3, j + 18, k + 9, Block.planks.blockID);
		world.setBlock(i + 3, j + 18, k + 10, Block.planks.blockID);
		world.setBlock(i + 3, j + 18, k + 11, Block.planks.blockID);
		world.setBlock(i + 3, j + 18, k + 12, Block.planks.blockID);
		world.setBlock(i + 3, j + 18, k + 13, Block.stairsWoodOak.blockID, 7, 3);
		world.setBlock(i + 3, j + 19, k + 7, Block.planks.blockID);
		world.setBlock(i + 3, j + 19, k + 8, Block.planks.blockID);
		world.setBlock(i + 3, j + 19, k + 9, 0);
		world.setBlock(i + 3, j + 19, k + 10, 0);
		world.setBlock(i + 3, j + 19, k + 11, 0);
		world.setBlock(i + 3, j + 19, k + 12, 0);
		world.setBlock(i + 3, j + 19, k + 13, Block.planks.blockID);
		world.setBlock(i + 3, j + 20, k + 7, Block.planks.blockID);
		world.setBlock(i + 3, j + 20, k + 8, Block.planks.blockID);
		world.setBlock(i + 3, j + 20, k + 9, 0);
		world.setBlock(i + 3, j + 20, k + 10, 0);
		world.setBlock(i + 3, j + 20, k + 11, 0);
		world.setBlock(i + 3, j + 20, k + 12, 0);
		world.setBlock(i + 3, j + 20, k + 13, Block.planks.blockID);
		world.setBlock(i + 3, j + 21, k + 7, Block.stairsWoodOak.blockID, 2, 3);
		world.setBlock(i + 3, j + 21, k + 8, Block.planks.blockID);
		world.setBlock(i + 3, j + 21, k + 9, Block.planks.blockID);
		world.setBlock(i + 3, j + 21, k + 10, Block.planks.blockID);
		world.setBlock(i + 3, j + 21, k + 11, Block.planks.blockID);
		world.setBlock(i + 3, j + 21, k + 12, Block.planks.blockID);
		world.setBlock(i + 3, j + 21, k + 13, Block.planks.blockID);
		world.setBlock(i + 3, j + 22, k + 8, Block.stairsWoodOak.blockID, 2, 3);
		world.setBlock(i + 3, j + 22, k + 9, Block.stairsWoodOak.blockID, 1, 3);
		world.setBlock(i + 3, j + 22, k + 10, Block.planks.blockID);
		world.setBlock(i + 3, j + 22, k + 11, Block.planks.blockID);
		world.setBlock(i + 3, j + 22, k + 12, Block.stairsWoodOak.blockID, 1, 3);
		world.setBlock(i + 3, j + 22, k + 13, Block.stairsWoodOak.blockID, 3, 3);
		world.setBlock(i + 3, j + 23, k + 10, Block.stairsWoodOak.blockID, 1, 3);
		world.setBlock(i + 3, j + 23, k + 11, Block.stairsWoodOak.blockID, 1, 3);
		world.setBlock(i + 3, j + 28, k + 6, Block.stairsStoneBrick.blockID, 4, 3);
		world.setBlock(i + 3, j + 28, k + 7, Block.stairsStoneBrick.blockID, 4, 3);
		world.setBlock(i + 3, j + 28, k + 8, Block.stairsStoneBrick.blockID, 4, 3);
		world.setBlock(i + 3, j + 29, k + 6, Block.stoneBrick.blockID);
		world.setBlock(i + 3, j + 29, k + 7, Block.stoneBrick.blockID);
		world.setBlock(i + 3, j + 29, k + 8, Block.stoneBrick.blockID);
		world.setBlock(i + 3, j + 30, k + 6, Block.stairsStoneBrick.blockID, 3, 3);
		world.setBlock(i + 3, j + 30, k + 8, Block.stairsStoneBrick.blockID, 2, 3);
		world.setBlock(i + 4, j + 0, k + 3, Block.stoneBrick.blockID);
		world.setBlock(i + 4, j + 0, k + 4, Block.stoneBrick.blockID);
		world.setBlock(i + 4, j + 0, k + 5, Block.stoneBrick.blockID);
		world.setBlock(i + 4, j + 0, k + 6, Block.stoneBrick.blockID);
		world.setBlock(i + 4, j + 0, k + 7, Block.stoneBrick.blockID);
		world.setBlock(i + 4, j + 0, k + 8, Block.stoneBrick.blockID);
		world.setBlock(i + 4, j + 0, k + 9, Block.stoneBrick.blockID);
		world.setBlock(i + 4, j + 0, k + 10, Block.stoneBrick.blockID);
		world.setBlock(i + 4, j + 0, k + 11, Block.stoneBrick.blockID);
		world.setBlock(i + 4, j + 1, k + 3, Block.stoneBrick.blockID);
		world.setBlock(i + 4, j + 1, k + 4, Block.stoneBrick.blockID);
		world.setBlock(i + 4, j + 1, k + 5, BlockSpikes.instance.blockID);
		world.setBlock(i + 4, j + 1, k + 6, BlockSpikes.instance.blockID);
		world.setBlock(i + 4, j + 1, k + 7, BlockSpikes.instance.blockID);
		world.setBlock(i + 4, j + 1, k + 8, Block.stoneBrick.blockID);
		world.setBlock(i + 4, j + 1, k + 9, Block.stoneBrick.blockID);
		world.setBlock(i + 4, j + 1, k + 10, Block.stoneBrick.blockID);
		world.setBlock(i + 4, j + 1, k + 11, Block.stoneBrick.blockID);
		world.setBlock(i + 4, j + 2, k + 3, Block.stoneBrick.blockID);
		world.setBlock(i + 4, j + 2, k + 4, BlockIllusionary.instance.blockID);
		world.setBlock(i + 4, j + 2, k + 5, BlockIllusionary.instance.blockID);
		world.setBlock(i + 4, j + 2, k + 6, BlockIllusionary.instance.blockID);
		world.setBlock(i + 4, j + 2, k + 7, BlockIllusionary.instance.blockID);
		world.setBlock(i + 4, j + 2, k + 8, BlockIllusionary.instance.blockID);
		world.setBlock(i + 4, j + 2, k + 9, Block.stoneBrick.blockID);
		world.setBlock(i + 4, j + 2, k + 10, Block.stoneBrick.blockID);
		world.setBlock(i + 4, j + 2, k + 11, Block.stoneBrick.blockID);
		world.setBlock(i + 4, j + 3, k + 3, Block.stoneBrick.blockID);
		world.setBlock(i + 4, j + 3, k + 4, Block.tripWireSource.blockID);
		world.setBlock(i + 4, j + 3, k + 8, Block.tripWireSource.blockID, 2, 3);
		world.setBlock(i + 4, j + 3, k + 9, Block.stoneBrick.blockID);
		world.setBlock(i + 4, j + 3, k + 10, Block.stoneBrick.blockID);
		world.setBlock(i + 4, j + 3, k + 11, Block.stoneBrick.blockID);
		world.setBlock(i + 4, j + 4, k + 3, Block.stoneBrick.blockID);
		world.setBlock(i + 4, j + 4, k + 4, BlockTrap.instance.blockID, 3, 3);
		te = world.getBlockTileEntity(i + 4, j + 4, k + 4); 
		if(te instanceof TileEntityTrap) {
			ted = (TileEntityTrap)te;
			ted.addItem(new ItemStack(Item.potion, 8, 16384+8204));
		}
		world.setBlockMetadataWithNotify(i + 4, j + 4, k + 4, 3, 3);
		world.setBlock(i + 4, j + 4, k + 5, 0);
		world.setBlock(i + 4, j + 4, k + 6, 0);
		world.setBlock(i + 4, j + 4, k + 7, 0);
		world.setBlock(i + 4, j + 4, k + 8, BlockTrap.instance.blockID, 2, 3);
		te = world.getBlockTileEntity(i + 4, j + 4, k + 8); 
		if(te instanceof TileEntityTrap) {
			ted = (TileEntityTrap)te;
			ted.addItem(new ItemStack(Item.potion, 8, 16384+8234));
		}
		world.setBlockMetadataWithNotify(i + 4, j + 4, k + 8, 2, 3);
		world.setBlock(i + 4, j + 4, k + 9, Block.stoneBrick.blockID);
		world.setBlock(i + 4, j + 4, k + 10, Block.stoneBrick.blockID);
		world.setBlock(i + 4, j + 4, k + 11, Block.stoneBrick.blockID);
		world.setBlock(i + 4, j + 5, k + 3, Block.stoneBrick.blockID);
		world.setBlock(i + 4, j + 5, k + 4, Block.stoneBrick.blockID);
		world.setBlock(i + 4, j + 5, k + 5, 0);
		world.setBlock(i + 4, j + 5, k + 6, 0);
		world.setBlock(i + 4, j + 5, k + 7, 0);
		world.setBlock(i + 4, j + 5, k + 8, Block.stoneBrick.blockID);
		world.setBlock(i + 4, j + 5, k + 9, Block.stoneBrick.blockID);
		world.setBlock(i + 4, j + 5, k + 10, Block.stoneBrick.blockID);
		world.setBlock(i + 4, j + 5, k + 11, Block.stoneBrick.blockID);
		world.setBlock(i + 4, j + 6, k + 3, Block.stoneBrick.blockID);
		world.setBlock(i + 4, j + 6, k + 4, Block.stoneBrick.blockID);
		world.setBlock(i + 4, j + 6, k + 5, 0);
		world.setBlock(i + 4, j + 6, k + 6, 0);
		world.setBlock(i + 4, j + 6, k + 7, 0);
		world.setBlock(i + 4, j + 6, k + 8, Block.stoneBrick.blockID);
		world.setBlock(i + 4, j + 6, k + 9, Block.stoneBrick.blockID);
		world.setBlock(i + 4, j + 6, k + 10, Block.stoneBrick.blockID);
		world.setBlock(i + 4, j + 6, k + 11, Block.stoneBrick.blockID);
		world.setBlock(i + 4, j + 7, k + 3, Block.stoneBrick.blockID);
		world.setBlock(i + 4, j + 7, k + 4, Block.stoneBrick.blockID);
		world.setBlock(i + 4, j + 7, k + 5, Block.stoneBrick.blockID);
		world.setBlock(i + 4, j + 7, k + 6, Block.stoneBrick.blockID);
		world.setBlock(i + 4, j + 7, k + 7, Block.stoneBrick.blockID);
		world.setBlock(i + 4, j + 7, k + 8, Block.stoneBrick.blockID);
		world.setBlock(i + 4, j + 7, k + 9, Block.stoneBrick.blockID);
		world.setBlock(i + 4, j + 7, k + 10, Block.stoneBrick.blockID);
		world.setBlock(i + 4, j + 7, k + 11, Block.stoneBrick.blockID);
		world.setBlock(i + 4, j + 8, k + 3, Block.stoneBrick.blockID);
		world.setBlock(i + 4, j + 8, k + 4, Block.stoneBrick.blockID);
		world.setBlock(i + 4, j + 8, k + 5, Block.stoneBrick.blockID);
		world.setBlock(i + 4, j + 8, k + 6, Block.stoneBrick.blockID);
		world.setBlock(i + 4, j + 8, k + 7, Block.stoneBrick.blockID);
		world.setBlock(i + 4, j + 8, k + 8, Block.stoneBrick.blockID);
		world.setBlock(i + 4, j + 8, k + 9, Block.stoneBrick.blockID);
		world.setBlock(i + 4, j + 8, k + 10, Block.stoneBrick.blockID);
		world.setBlock(i + 4, j + 8, k + 11, Block.stoneBrick.blockID);
		world.setBlock(i + 4, j + 9, k + 3, Block.stoneBrick.blockID);
		world.setBlock(i + 4, j + 9, k + 4, Block.stoneBrick.blockID);
		world.setBlock(i + 4, j + 9, k + 5, Block.stoneBrick.blockID);
		world.setBlock(i + 4, j + 9, k + 6, Block.stoneBrick.blockID);
		world.setBlock(i + 4, j + 9, k + 7, Block.stoneBrick.blockID);
		world.setBlock(i + 4, j + 9, k + 8, Block.stoneBrick.blockID);
		world.setBlock(i + 4, j + 9, k + 9, Block.stoneBrick.blockID);
		world.setBlock(i + 4, j + 9, k + 10, Block.stoneBrick.blockID);
		world.setBlock(i + 4, j + 9, k + 11, Block.stoneBrick.blockID);
		world.setBlock(i + 4, j + 10, k + 1, Block.stairsWoodOak.blockID, 6, 3);
		world.setBlock(i + 4, j + 10, k + 2, Block.planks.blockID);
		world.setBlock(i + 4, j + 10, k + 3, Block.stoneBrick.blockID);
		world.setBlock(i + 4, j + 10, k + 4, Block.stoneBrick.blockID);
		world.setBlock(i + 4, j + 10, k + 5, Block.stoneBrick.blockID);
		world.setBlock(i + 4, j + 10, k + 6, Block.stoneBrick.blockID);
		world.setBlock(i + 4, j + 10, k + 7, Block.stoneBrick.blockID);
		world.setBlock(i + 4, j + 10, k + 8, Block.stoneBrick.blockID);
		world.setBlock(i + 4, j + 10, k + 9, Block.stoneBrick.blockID);
		world.setBlock(i + 4, j + 10, k + 10, Block.stoneBrick.blockID);
		world.setBlock(i + 4, j + 10, k + 11, Block.stoneBrick.blockID);
		world.setBlock(i + 4, j + 11, k + 0, Block.stairsWoodOak.blockID, 6, 3);
		world.setBlock(i + 4, j + 11, k + 1, Block.planks.blockID);
		world.setBlock(i + 4, j + 11, k + 2, Block.planks.blockID);
		world.setBlock(i + 4, j + 11, k + 3, Block.stoneBrick.blockID);
		world.setBlock(i + 4, j + 11, k + 4, Block.stoneBrick.blockID);
		world.setBlock(i + 4, j + 11, k + 5, Block.stoneBrick.blockID);
		world.setBlock(i + 4, j + 11, k + 6, Block.stoneBrick.blockID);
		world.setBlock(i + 4, j + 11, k + 7, Block.stoneBrick.blockID);
		world.setBlock(i + 4, j + 11, k + 8, Block.stoneBrick.blockID);
		world.setBlock(i + 4, j + 11, k + 9, Block.stoneBrick.blockID);
		world.setBlock(i + 4, j + 11, k + 10, Block.stoneBrick.blockID);
		world.setBlock(i + 4, j + 11, k + 11, Block.stoneBrick.blockID);
		world.setBlock(i + 4, j + 12, k + 0, Block.planks.blockID);
		world.setBlock(i + 4, j + 12, k + 1, Block.stoneBrick.blockID);
		world.setBlock(i + 4, j + 12, k + 2, Block.planks.blockID);
		world.setBlock(i + 4, j + 12, k + 3, 0);
		world.setBlock(i + 4, j + 12, k + 4, Block.stoneBrick.blockID);
		world.setBlock(i + 4, j + 12, k + 5, Block.stoneBrick.blockID);
		world.setBlock(i + 4, j + 12, k + 6, Block.stoneBrick.blockID);
		world.setBlock(i + 4, j + 12, k + 8, Block.glowStone.blockID);
		world.setBlock(i + 4, j + 12, k + 9, Block.stoneBrick.blockID);
		world.setBlock(i + 4, j + 12, k + 10, Block.stoneBrick.blockID);
		world.setBlock(i + 4, j + 13, k + 0, Block.planks.blockID);
		world.setBlock(i + 4, j + 13, k + 2, Block.planks.blockID);
		world.setBlock(i + 4, j + 13, k + 3, 0);
		world.setBlock(i + 4, j + 13, k + 4, Block.redstoneLampIdle.blockID);
		world.setBlock(i + 4, j + 13, k + 5, Block.stoneBrick.blockID);
		world.setBlock(i + 4, j + 13, k + 6, Block.stoneBrick.blockID);
		world.setBlock(i + 4, j + 13, k + 9, Block.stoneBrick.blockID);
		world.setBlock(i + 4, j + 13, k + 10, Block.stoneBrick.blockID);
		world.setBlock(i + 4, j + 14, k + 0, Block.planks.blockID);
		world.setBlock(i + 4, j + 14, k + 1, Block.torchRedstoneIdle.blockID, 1, 3);
		world.setBlock(i + 4, j + 14, k + 2, Block.planks.blockID);
		world.setBlock(i + 4, j + 14, k + 3, 0);
		world.setBlock(i + 4, j + 14, k + 4, Block.stoneBrick.blockID);
		world.setBlock(i + 4, j + 14, k + 5, Block.stoneBrick.blockID);
		world.setBlock(i + 4, j + 14, k + 6, Block.stoneBrick.blockID);
		world.setBlock(i + 4, j + 14, k + 8, Block.stoneBrick.blockID);
		world.setBlock(i + 4, j + 14, k + 9, Block.stoneBrick.blockID);
		world.setBlock(i + 4, j + 14, k + 10, Block.stoneBrick.blockID);
		world.setBlock(i + 4, j + 15, k + 0, Block.stairsWoodOak.blockID, 2, 3);
		world.setBlock(i + 4, j + 15, k + 1, 0);
		world.setBlock(i + 4, j + 15, k + 3, Block.planks.blockID);
		world.setBlock(i + 4, j + 15, k + 4, Block.stoneBrick.blockID);
		world.setBlock(i + 4, j + 15, k + 5, Block.stoneBrick.blockID);
		world.setBlock(i + 4, j + 15, k + 6, Block.stoneBrick.blockID);
		world.setBlock(i + 4, j + 15, k + 8, Block.stoneBrick.blockID);
		world.setBlock(i + 4, j + 15, k + 9, Block.stoneBrick.blockID);
		world.setBlock(i + 4, j + 15, k + 10, Block.stoneBrick.blockID);
		world.setBlock(i + 4, j + 16, k + 1, Block.stairsWoodOak.blockID, 2, 3);
		world.setBlock(i + 4, j + 16, k + 3, Block.planks.blockID);
		world.setBlock(i + 4, j + 16, k + 4, Block.planks.blockID);
		world.setBlock(i + 4, j + 16, k + 5, Block.stoneBrick.blockID);
		world.setBlock(i + 4, j + 16, k + 6, 0);
		world.setBlock(i + 4, j + 16, k + 7, 0);
		world.setBlock(i + 4, j + 16, k + 8, 0);
		world.setBlock(i + 4, j + 16, k + 9, Block.stoneBrick.blockID);
		world.setBlock(i + 4, j + 17, k + 2, Block.daylightSensor.blockID);
		world.setBlock(i + 4, j + 17, k + 3, Block.planks.blockID);
		world.setBlock(i + 4, j + 17, k + 4, Block.planks.blockID);
		world.setBlock(i + 4, j + 17, k + 5, Block.stoneBrick.blockID);
		world.setBlock(i + 4, j + 17, k + 6, 0);
		world.setBlock(i + 4, j + 17, k + 7, 0);
		world.setBlock(i + 4, j + 17, k + 8, 0);
		world.setBlock(i + 4, j + 17, k + 9, Block.stoneBrick.blockID);
		world.setBlock(i + 4, j + 18, k + 3, Block.woodSingleSlab.blockID);
		world.setBlock(i + 4, j + 18, k + 5, Block.stoneBrick.blockID);
		world.setBlock(i + 4, j + 18, k + 6, Block.stoneBrick.blockID);
		world.setBlock(i + 4, j + 18, k + 7, Block.stoneBrick.blockID);
		world.setBlock(i + 4, j + 18, k + 8, Block.stoneBrick.blockID);
		world.setBlock(i + 4, j + 18, k + 9, Block.stoneBrick.blockID);
		world.setBlock(i + 4, j + 18, k + 10, Block.stairsWoodOak.blockID, 5, 3);
		world.setBlock(i + 4, j + 18, k + 11, Block.stairsWoodOak.blockID, 5, 3);
		world.setBlock(i + 4, j + 18, k + 12, Block.stairsWoodOak.blockID, 5, 3);
		world.setBlock(i + 4, j + 19, k + 6, Block.stoneBrick.blockID);
		world.setBlock(i + 4, j + 19, k + 7, 0);
		world.setBlock(i + 4, j + 19, k + 8, 0);
		world.setBlock(i + 4, j + 19, k + 10, Block.planks.blockID);
		world.setBlock(i + 4, j + 19, k + 11, Block.planks.blockID);
		world.setBlock(i + 4, j + 19, k + 12, Block.planks.blockID);
		world.setBlock(i + 4, j + 20, k + 6, Block.stoneBrick.blockID);
		world.setBlock(i + 4, j + 20, k + 7, 0);
		world.setBlock(i + 4, j + 20, k + 8, 0);
		world.setBlock(i + 4, j + 20, k + 10, Block.planks.blockID);
		world.setBlock(i + 4, j + 20, k + 11, Block.planks.blockID);
		world.setBlock(i + 4, j + 20, k + 12, Block.planks.blockID);
		world.setBlock(i + 4, j + 21, k + 6, Block.stoneBrick.blockID);
		world.setBlock(i + 4, j + 21, k + 7, Block.stoneBrick.blockID);
		world.setBlock(i + 4, j + 21, k + 8, Block.stoneBrick.blockID);
		//world.scheduleBlockUpdate(i + 4, j + 21, k + 9, Block.daylightSensor.blockID, 10);
		world.setBlock(i + 4, j + 21, k + 10, Block.planks.blockID);
		world.setBlock(i + 4, j + 21, k + 11, Block.planks.blockID);
		world.setBlock(i + 4, j + 21, k + 12, Block.planks.blockID);
		world.setBlock(i + 4, j + 22, k + 7, Block.stoneBrick.blockID);
		world.setBlock(i + 4, j + 22, k + 10, Block.stairsWoodOak.blockID, 2, 3);
		world.setBlock(i + 4, j + 22, k + 11, Block.stairsWoodOak.blockID, 1, 3);
		world.setBlock(i + 4, j + 22, k + 12, Block.stairsWoodOak.blockID, 3, 3);
		world.setBlock(i + 4, j + 23, k + 7, Block.stairsStoneBrick.blockID);
		world.setBlock(i + 4, j + 27, k + 5, Block.stairsStoneBrick.blockID, 4, 3);
		world.setBlock(i + 4, j + 27, k + 6, Block.stairsStoneBrick.blockID, 4, 3);
		world.setBlock(i + 4, j + 27, k + 7, Block.stairsStoneBrick.blockID, 4, 3);
		world.setBlock(i + 4, j + 27, k + 8, Block.stairsStoneBrick.blockID, 4, 3);
		world.setBlock(i + 4, j + 27, k + 9, Block.stairsStoneBrick.blockID, 4, 3);
		world.setBlock(i + 4, j + 28, k + 5, Block.stoneBrick.blockID);
		world.setBlock(i + 4, j + 28, k + 6, Block.stoneBrick.blockID);
		world.setBlock(i + 4, j + 28, k + 7, Block.stoneBrick.blockID);
		world.setBlock(i + 4, j + 28, k + 8, Block.stoneBrick.blockID);
		world.setBlock(i + 4, j + 28, k + 9, Block.stoneBrick.blockID);
		world.setBlock(i + 4, j + 29, k + 5, Block.stoneBrick.blockID);
		world.setBlock(i + 4, j + 29, k + 6, 0);
		world.setBlock(i + 4, j + 29, k + 7, 0);
		world.setBlock(i + 4, j + 29, k + 8, 0);
		world.setBlock(i + 4, j + 29, k + 9, Block.stoneBrick.blockID);
		world.setBlock(i + 4, j + 30, k + 6, 0);
		world.setBlock(i + 4, j + 30, k + 7, 0);
		world.setBlock(i + 4, j + 30, k + 8, 0);
		world.setBlock(i + 5, j + 0, k + 2, Block.stoneBrick.blockID);
		world.setBlock(i + 5, j + 0, k + 3, Block.stoneBrick.blockID);
		world.setBlock(i + 5, j + 0, k + 4, Block.stoneBrick.blockID);
		world.setBlock(i + 5, j + 0, k + 5, Block.stoneBrick.blockID);
		world.setBlock(i + 5, j + 0, k + 6, Block.stoneBrick.blockID);
		world.setBlock(i + 5, j + 0, k + 7, Block.stoneBrick.blockID);
		world.setBlock(i + 5, j + 0, k + 8, Block.stoneBrick.blockID);
		world.setBlock(i + 5, j + 0, k + 9, Block.stoneBrick.blockID);
		world.setBlock(i + 5, j + 0, k + 10, Block.stoneBrick.blockID);
		world.setBlock(i + 5, j + 0, k + 11, Block.stoneBrick.blockID);
		world.setBlock(i + 5, j + 0, k + 12, Block.stoneBrick.blockID);
		world.setBlock(i + 5, j + 1, k + 2, Block.stoneBrick.blockID);
		world.setBlock(i + 5, j + 1, k + 3, Block.stoneBrick.blockID);
		world.setBlock(i + 5, j + 1, k + 4, Block.stoneBrick.blockID);
		world.setBlock(i + 5, j + 1, k + 5, BlockSpikes.instance.blockID);
		world.setBlock(i + 5, j + 1, k + 6, BlockSpikes.instance.blockID);
		world.setBlock(i + 5, j + 1, k + 7, BlockSpikes.instance.blockID);
		world.setBlock(i + 5, j + 1, k + 8, Block.stoneBrick.blockID);
		world.setBlock(i + 5, j + 1, k + 9, Block.stoneBrick.blockID);
		world.setBlock(i + 5, j + 1, k + 10, Block.stoneBrick.blockID);
		world.setBlock(i + 5, j + 1, k + 11, Block.stoneBrick.blockID);
		world.setBlock(i + 5, j + 1, k + 12, Block.stoneBrick.blockID);
		world.setBlock(i + 5, j + 2, k + 2, Block.stoneBrick.blockID);
		world.setBlock(i + 5, j + 2, k + 3, Block.stoneBrick.blockID);
		world.setBlock(i + 5, j + 2, k + 4, Block.stoneBrick.blockID);
		world.setBlock(i + 5, j + 2, k + 5, BlockIllusionary.instance.blockID);
		world.setBlock(i + 5, j + 2, k + 6, BlockIllusionary.instance.blockID);
		world.setBlock(i + 5, j + 2, k + 7, BlockIllusionary.instance.blockID);
		world.setBlock(i + 5, j + 2, k + 8, Block.stoneBrick.blockID);
		world.setBlock(i + 5, j + 2, k + 9, Block.stoneBrick.blockID);
		world.setBlock(i + 5, j + 2, k + 10, Block.stoneBrick.blockID);
		world.setBlock(i + 5, j + 2, k + 11, Block.stoneBrick.blockID);
		world.setBlock(i + 5, j + 2, k + 12, Block.stoneBrick.blockID);
		world.setBlock(i + 5, j + 3, k + 2, Block.stoneBrick.blockID);
		world.setBlock(i + 5, j + 3, k + 3, Block.stoneBrick.blockID);
		world.setBlock(i + 5, j + 3, k + 4, BlockTrap.instance.blockID, 3, 3);
		world.setBlockMetadataWithNotify(i + 5, j + 3, k + 4, 3, 3);
		world.setBlock(i + 5, j + 3, k + 5, 0);
		world.setBlock(i + 5, j + 3, k + 6, 0);
		world.setBlock(i + 5, j + 3, k + 7, 0);
		world.setBlock(i + 5, j + 3, k + 8, BlockTrap.instance.blockID, 2, 3);
		world.setBlockMetadataWithNotify(i + 5, j + 3, k + 8, 2, 3);
		world.setBlock(i + 5, j + 3, k + 9, 0);
		world.setBlock(i + 5, j + 3, k + 10, 0);
		world.setBlock(i + 5, j + 3, k + 11, 0);
		world.setBlock(i + 5, j + 3, k + 12, Block.stoneBrick.blockID);
		world.setBlock(i + 5, j + 4, k + 2, Block.stoneBrick.blockID);
		world.setBlock(i + 5, j + 4, k + 3, Block.stoneBrick.blockID);
		world.setBlock(i + 5, j + 4, k + 4, Block.stoneBrick.blockID);
		world.setBlock(i + 5, j + 4, k + 5, 0);
		world.setBlock(i + 5, j + 4, k + 6, 0);
		world.setBlock(i + 5, j + 4, k + 7, 0);
		world.setBlock(i + 5, j + 4, k + 8, Block.stoneBrick.blockID);
		world.setBlock(i + 5, j + 4, k + 9, 0);
		world.setBlock(i + 5, j + 4, k + 10, 0);
		world.setBlock(i + 5, j + 4, k + 11, 0);
		world.setBlock(i + 5, j + 4, k + 12, Block.stoneBrick.blockID);
		world.setBlock(i + 5, j + 5, k + 2, Block.stoneBrick.blockID);
		world.setBlock(i + 5, j + 5, k + 3, Block.stoneBrick.blockID);
		world.setBlock(i + 5, j + 5, k + 4, Block.stoneBrick.blockID);
		world.setBlock(i + 5, j + 5, k + 5, 0);
		world.setBlock(i + 5, j + 5, k + 6, 0);
		world.setBlock(i + 5, j + 5, k + 7, 0);
		world.setBlock(i + 5, j + 5, k + 8, Block.stoneBrick.blockID);
		world.setBlock(i + 5, j + 5, k + 9, 0);
		world.setBlock(i + 5, j + 5, k + 10, 0);
		world.setBlock(i + 5, j + 5, k + 11, 0);
		world.setBlock(i + 5, j + 5, k + 12, Block.stoneBrick.blockID);
		world.setBlock(i + 5, j + 6, k + 2, Block.stoneBrick.blockID);
		world.setBlock(i + 5, j + 6, k + 3, Block.stoneBrick.blockID);
		world.setBlock(i + 5, j + 6, k + 4, Block.stoneBrick.blockID);
		world.setBlock(i + 5, j + 6, k + 5, 0);
		world.setBlock(i + 5, j + 6, k + 6, 0);
		world.setBlock(i + 5, j + 6, k + 7, 0);
		world.setBlock(i + 5, j + 6, k + 8, Block.stoneBrick.blockID);
		world.setBlock(i + 5, j + 6, k + 9, 0);
		world.setBlock(i + 5, j + 6, k + 10, 0);
		world.setBlock(i + 5, j + 6, k + 11, 0);
		world.setBlock(i + 5, j + 6, k + 12, Block.stoneBrick.blockID);
		world.setBlock(i + 5, j + 7, k + 2, Block.stoneBrick.blockID);
		world.setBlock(i + 5, j + 7, k + 3, Block.stoneBrick.blockID);
		world.setBlock(i + 5, j + 7, k + 4, Block.stoneBrick.blockID);
		world.setBlock(i + 5, j + 7, k + 5, Block.stoneBrick.blockID);
		world.setBlock(i + 5, j + 7, k + 6, Block.stoneBrick.blockID);
		world.setBlock(i + 5, j + 7, k + 7, Block.stoneBrick.blockID);
		world.setBlock(i + 5, j + 7, k + 8, Block.stoneBrick.blockID);
		world.setBlock(i + 5, j + 7, k + 9, Block.stoneBrick.blockID);
		world.setBlock(i + 5, j + 7, k + 10, Block.stoneBrick.blockID);
		world.setBlock(i + 5, j + 7, k + 11, Block.stoneBrick.blockID);
		world.setBlock(i + 5, j + 7, k + 12, Block.stoneBrick.blockID);
		world.setBlock(i + 5, j + 8, k + 2, Block.stoneBrick.blockID);
		world.setBlock(i + 5, j + 8, k + 3, Block.stoneBrick.blockID);
		world.setBlock(i + 5, j + 8, k + 4, Block.anvil.blockID);
		world.setBlock(i + 5, j + 8, k + 5, 0);
		world.setBlock(i + 5, j + 8, k + 6, 0);
		world.setBlock(i + 5, j + 8, k + 8, Block.bookShelf.blockID);
		world.setBlock(i + 5, j + 8, k + 9, Block.bookShelf.blockID);
		world.setBlock(i + 5, j + 8, k + 10, Block.bookShelf.blockID);
		world.setBlock(i + 5, j + 8, k + 11, Block.stoneBrick.blockID);
		world.setBlock(i + 5, j + 8, k + 12, Block.stoneBrick.blockID);
		world.setBlock(i + 5, j + 9, k + 2, Block.stoneBrick.blockID);
		world.setBlock(i + 5, j + 9, k + 3, Block.stoneBrick.blockID);
		world.setBlock(i + 5, j + 9, k + 4, 0);
		world.setBlock(i + 5, j + 9, k + 5, 0);
		world.setBlock(i + 5, j + 9, k + 6, 0);
		world.setBlock(i + 5, j + 9, k + 8, Block.bookShelf.blockID);
		world.setBlock(i + 5, j + 9, k + 9, Block.bookShelf.blockID);
		world.setBlock(i + 5, j + 9, k + 10, Block.bookShelf.blockID);
		world.setBlock(i + 5, j + 9, k + 11, Block.stoneBrick.blockID);
		world.setBlock(i + 5, j + 9, k + 12, Block.stoneBrick.blockID);
		world.setBlock(i + 5, j + 10, k + 1, Block.stairsWoodOak.blockID, 6, 3);
		world.setBlock(i + 5, j + 10, k + 2, Block.planks.blockID);
		world.setBlock(i + 5, j + 10, k + 3, Block.stoneBrick.blockID);
		world.setBlock(i + 5, j + 10, k + 4, Block.stoneBrick.blockID);
		world.setBlock(i + 5, j + 10, k + 5, Block.stoneBrick.blockID);
		world.setBlock(i + 5, j + 10, k + 6, Block.stoneBrick.blockID);
		world.setBlock(i + 5, j + 10, k + 7, Block.stoneBrick.blockID);
		world.setBlock(i + 5, j + 10, k + 8, Block.stoneBrick.blockID);
		world.setBlock(i + 5, j + 10, k + 9, Block.stoneBrick.blockID);
		world.setBlock(i + 5, j + 10, k + 10, Block.stoneBrick.blockID);
		world.setBlock(i + 5, j + 10, k + 11, Block.stoneBrick.blockID);
		world.setBlock(i + 5, j + 11, k + 0, Block.stairsWoodOak.blockID, 6, 3);
		world.setBlock(i + 5, j + 11, k + 1, Block.planks.blockID);
		world.setBlock(i + 5, j + 11, k + 2, Block.planks.blockID);
		world.setBlock(i + 5, j + 11, k + 3, Block.stoneBrick.blockID);
		world.setBlock(i + 5, j + 11, k + 4, Block.stoneBrick.blockID);
		world.setBlock(i + 5, j + 11, k + 5, Block.stoneBrick.blockID);
		world.setBlock(i + 5, j + 11, k + 6, Block.stoneBrick.blockID);
		world.setBlock(i + 5, j + 11, k + 7, Block.stoneBrick.blockID);
		world.setBlock(i + 5, j + 11, k + 8, Block.stoneBrick.blockID);
		world.setBlock(i + 5, j + 11, k + 9, Block.stoneBrick.blockID);
		world.setBlock(i + 5, j + 11, k + 10, Block.stoneBrick.blockID);
		world.setBlock(i + 5, j + 11, k + 11, Block.stoneBrick.blockID);
		world.setBlock(i + 5, j + 12, k + 0, Block.planks.blockID);
		world.setBlock(i + 5, j + 12, k + 1, Block.pistonStickyBase.blockID, 3, 3);
		//world.setBlock(i + 5, j + 12, k + 2, Block.stoneBrick.blockID);
		world.setBlock(i + 5, j + 12, k + 3, 0);
		world.setBlock(i + 5, j + 12, k + 4, 0);
		world.setBlock(i + 5, j + 12, k + 5, 0);
		world.setBlock(i + 5, j + 12, k + 6, Block.stoneBrick.blockID);
		world.setBlock(i + 5, j + 12, k + 7, Block.stoneBrick.blockID);
		world.setBlock(i + 5, j + 12, k + 8, Block.stoneBrick.blockID);
		world.setBlock(i + 5, j + 12, k + 9, Block.stoneBrick.blockID);
		world.setBlock(i + 5, j + 12, k + 10, Block.stoneBrick.blockID);
		world.setBlock(i + 5, j + 12, k + 11, Block.stoneBrick.blockID);
		world.setBlock(i + 5, j + 13, k + 0, Block.planks.blockID);
		world.setBlock(i + 5, j + 13, k + 1, Block.pistonStickyBase.blockID, 3, 3);
		//world.setBlock(i + 5, j + 13, k + 2, Block.stoneBrick.blockID);
		world.setBlock(i + 5, j + 13, k + 3, 0);
		world.setBlock(i + 5, j + 13, k + 5, 0);
		world.setBlock(i + 5, j + 13, k + 6, Block.stoneBrick.blockID);
		world.setBlock(i + 5, j + 13, k + 7, Block.stoneBrick.blockID);
		world.setBlock(i + 5, j + 13, k + 8, Block.pistonStickyBase.blockID, 12, 3);
		world.setBlock(i + 4, j + 13, k + 8, Block.pistonExtension.blockID, 12, 3);
		world.setBlock(i + 5, j + 13, k + 9, Block.stoneBrick.blockID);
		world.setBlock(i + 5, j + 13, k + 10, Block.stoneBrick.blockID);
		world.setBlock(i + 5, j + 13, k + 11, Block.stoneBrick.blockID);
		world.setBlock(i + 5, j + 14, k + 0, Block.planks.blockID);
		world.setBlock(i + 5, j + 14, k + 1, Block.stoneBrick.blockID);
		world.setBlock(i + 5, j + 14, k + 2, Block.stoneBrick.blockID);
		world.setBlock(i + 5, j + 14, k + 3, Block.stoneBrick.blockID);
		world.setBlock(i + 5, j + 14, k + 4, Block.stoneBrick.blockID);
		world.setBlock(i + 5, j + 14, k + 5, Block.stoneBrick.blockID);
		world.setBlock(i + 5, j + 14, k + 6, Block.stoneBrick.blockID);
		world.setBlock(i + 5, j + 14, k + 7, Block.stoneBrick.blockID);
		world.setBlock(i + 5, j + 14, k + 8, Block.stoneBrick.blockID);
		world.setBlock(i + 5, j + 14, k + 9, Block.stoneBrick.blockID);
		world.setBlock(i + 5, j + 14, k + 10, Block.stoneBrick.blockID);
		world.setBlock(i + 5, j + 14, k + 11, Block.stoneBrick.blockID);
		world.setBlock(i + 5, j + 15, k + 0, Block.stairsWoodOak.blockID, 2, 3);
		world.setBlock(i + 5, j + 15, k + 1, Block.planks.blockID);
		world.setBlock(i + 5, j + 15, k + 2, Block.planks.blockID);
		world.setBlock(i + 5, j + 15, k + 3, Block.stoneBrick.blockID);
		world.setBlock(i + 5, j + 15, k + 5, Block.stoneBrick.blockID);
		world.setBlock(i + 5, j + 15, k + 6, Block.stoneBrick.blockID);
		world.setBlock(i + 5, j + 15, k + 7, BlockTrap.instance.blockID, 1, 3);
		world.setBlockMetadataWithNotify(i + 5, j + 15, k + 7, 1, 3);
		te = world.getBlockTileEntity(i + 5, j + 15, k + 7);
		if(te instanceof TileEntityTrap) {
			ted = (TileEntityTrap)te;
			ted.addItem(new ItemStack(Item.arrow, 32));
		}
		world.setBlock(i + 5, j + 16, k + 7, BlockInvisiblePressurePlate.obsidian.blockID);
		world.setBlock(i + 5, j + 15, k + 8, Block.stoneBrick.blockID);
		world.setBlock(i + 5, j + 15, k + 9, Block.stoneBrick.blockID);
		world.setBlock(i + 5, j + 15, k + 10, Block.stoneBrick.blockID);
		world.setBlock(i + 5, j + 16, k + 1, Block.stairsWoodOak.blockID, 2, 3);
		world.setBlock(i + 5, j + 16, k + 2, Block.stairsWoodOak.blockID, 1, 3);
		world.setBlock(i + 5, j + 16, k + 3, Block.planks.blockID);
		world.setBlock(i + 5, j + 16, k + 4, Block.stoneBrick.blockID);
		world.setBlock(i + 5, j + 16, k + 5, Block.stoneBrick.blockID);
		world.setBlock(i + 5, j + 16, k + 6, 0);
		//world.setBlock(i + 5, j + 16, k + 7, 0);
		world.setBlock(i + 5, j + 16, k + 9, Block.stoneBrick.blockID);
		world.setBlock(i + 5, j + 16, k + 10, Block.stoneBrick.blockID);
		world.setBlock(i + 5, j + 17, k + 3, Block.stairsWoodOak.blockID, 1, 3);
		world.setBlock(i + 5, j + 17, k + 4, Block.stoneBrick.blockID);
		world.setBlock(i + 5, j + 17, k + 5, Block.stoneBrick.blockID);
		world.setBlock(i + 5, j + 17, k + 6, 0);
		world.setBlock(i + 5, j + 17, k + 7, 0);
		world.setBlock(i + 5, j + 17, k + 9, Block.stoneBrick.blockID);
		world.setBlock(i + 5, j + 17, k + 10, Block.stoneBrick.blockID);
		world.setBlock(i + 5, j + 18, k + 5, Block.stoneBrick.blockID);
		world.setBlock(i + 5, j + 18, k + 6, Block.stoneBrick.blockID);
		world.setBlock(i + 5, j + 18, k + 7, Block.stoneBrick.blockID);
		world.setBlock(i + 5, j + 18, k + 9, Block.stoneBrick.blockID);
		world.setBlock(i + 5, j + 19, k + 5, Block.stoneBrick.blockID);
		world.setBlock(i + 5, j + 19, k + 6, 0);
		world.setBlock(i + 5, j + 19, k + 7, 0);
		world.setBlock(i + 5, j + 19, k + 8, 0);
		world.setBlock(i + 5, j + 19, k + 9, Block.stoneBrick.blockID);
		world.setBlock(i + 5, j + 20, k + 5, Block.stoneBrick.blockID);
		world.setBlock(i + 5, j + 20, k + 6, 0);
		world.setBlock(i + 5, j + 20, k + 7, 0);
		world.setBlock(i + 5, j + 20, k + 8, 0);
		world.setBlock(i + 5, j + 20, k + 9, Block.stoneBrick.blockID);
		world.setBlock(i + 5, j + 21, k + 5, Block.stoneBrick.blockID);
		world.setBlock(i + 5, j + 21, k + 6, Block.stoneBrick.blockID);
		world.setBlock(i + 5, j + 21, k + 7, Block.stoneBrick.blockID);
		world.setBlock(i + 5, j + 21, k + 8, Block.stoneBrick.blockID);
		world.setBlock(i + 5, j + 21, k + 9, Block.stoneBrick.blockID);
		world.setBlock(i + 5, j + 22, k + 6, Block.stoneBrick.blockID);
		world.setBlock(i + 5, j + 22, k + 7, Block.stoneBrick.blockID);
		world.setBlock(i + 5, j + 23, k + 6, Block.stoneBrick.blockID);
		world.setBlock(i + 5, j + 23, k + 7, Block.stoneBrick.blockID);
		world.setBlock(i + 5, j + 23, k + 8, Block.stoneBrick.blockID);
		world.setBlock(i + 5, j + 24, k + 6, Block.stoneBrick.blockID);
		world.setBlock(i + 5, j + 24, k + 7, Block.stoneBrick.blockID);
		world.setBlock(i + 5, j + 24, k + 8, Block.stoneBrick.blockID);
		world.setBlock(i + 5, j + 25, k + 6, Block.stoneBrick.blockID);
		world.setBlock(i + 5, j + 25, k + 7, Block.stoneBrick.blockID);
		world.setBlock(i + 5, j + 25, k + 8, Block.stoneBrick.blockID);
		world.setBlock(i + 5, j + 26, k + 6, Block.stoneBrick.blockID);
		world.setBlock(i + 5, j + 26, k + 7, Block.stoneBrick.blockID);
		world.setBlock(i + 5, j + 26, k + 8, Block.stoneBrick.blockID);
		world.setBlock(i + 5, j + 27, k + 5, Block.stairsStoneBrick.blockID, 6, 3);
		world.setBlock(i + 5, j + 27, k + 6, Block.stoneBrick.blockID);
		world.setBlock(i + 5, j + 27, k + 7, Block.stoneBrick.blockID);
		world.setBlock(i + 5, j + 27, k + 8, Block.stoneBrick.blockID);
		world.setBlock(i + 5, j + 27, k + 9, Block.stairsStoneBrick.blockID, 7, 3);
		world.setBlock(i + 5, j + 28, k + 4, Block.stairsStoneBrick.blockID, 6, 3);
		world.setBlock(i + 5, j + 28, k + 5, Block.stoneBrick.blockID);
		world.setBlock(i + 5, j + 28, k + 6, Block.stoneBrick.blockID);
		world.setBlock(i + 5, j + 28, k + 7, Block.stoneBrick.blockID);
		world.setBlock(i + 5, j + 28, k + 8, Block.stoneBrick.blockID);
		world.setBlock(i + 5, j + 28, k + 9, Block.stoneBrick.blockID);
		world.setBlock(i + 5, j + 28, k + 10, Block.stairsStoneBrick.blockID, 7, 3);
		world.setBlock(i + 5, j + 29, k + 4, Block.stoneBrick.blockID);
		world.setBlock(i + 5, j + 29, k + 5, 0);
		world.setBlock(i + 5, j + 29, k + 6, Block.fence.blockID);
		world.setBlock(i + 5, j + 29, k + 7, 0);
		world.setBlock(i + 5, j + 29, k + 8, Block.fence.blockID);
		world.setBlock(i + 5, j + 29, k + 9, 0);
		world.setBlock(i + 5, j + 29, k + 10, Block.stoneBrick.blockID);
		world.setBlock(i + 5, j + 30, k + 4, Block.stairsStoneBrick.blockID, 1, 3);
		world.setBlock(i + 5, j + 30, k + 5, 0);
		world.setBlock(i + 5, j + 30, k + 6, Block.fence.blockID);
		world.setBlock(i + 5, j + 30, k + 7, 0);
		world.setBlock(i + 5, j + 30, k + 8, Block.fence.blockID);
		world.setBlock(i + 5, j + 30, k + 9, 0);
		world.setBlock(i + 5, j + 30, k + 10, Block.stairsStoneBrick.blockID, 1, 3);
		world.setBlock(i + 5, j + 31, k + 6, Block.fence.blockID);
		world.setBlock(i + 5, j + 31, k + 7, 0);
		world.setBlock(i + 5, j + 31, k + 8, Block.fence.blockID);
		world.setBlock(i + 5, j + 32, k + 6, Block.stairsWoodOak.blockID, 2, 3);
		world.setBlock(i + 5, j + 32, k + 7, Block.stairsWoodOak.blockID);
		world.setBlock(i + 5, j + 32, k + 8, Block.stairsWoodOak.blockID, 3, 3);
		world.setBlock(i + 6, j + 0, k + 2, Block.stoneBrick.blockID);
		world.setBlock(i + 6, j + 0, k + 3, Block.stoneBrick.blockID);
		world.setBlock(i + 6, j + 0, k + 4, Block.stoneBrick.blockID);
		world.setBlock(i + 6, j + 0, k + 5, Block.stoneBrick.blockID);
		world.setBlock(i + 6, j + 0, k + 6, Block.stoneBrick.blockID);
		world.setBlock(i + 6, j + 0, k + 7, Block.stoneBrick.blockID);
		world.setBlock(i + 6, j + 0, k + 8, Block.stoneBrick.blockID);
		world.setBlock(i + 6, j + 0, k + 9, Block.stoneBrick.blockID);
		world.setBlock(i + 6, j + 0, k + 10, Block.stoneBrick.blockID);
		world.setBlock(i + 6, j + 0, k + 11, Block.stoneBrick.blockID);
		world.setBlock(i + 6, j + 0, k + 12, Block.stoneBrick.blockID);
		world.setBlock(i + 6, j + 1, k + 2, Block.stoneBrick.blockID);
		world.setBlock(i + 6, j + 1, k + 3, Block.stoneBrick.blockID);
		world.setBlock(i + 6, j + 1, k + 4, Block.stoneBrick.blockID);
		world.setBlock(i + 6, j + 1, k + 5, Block.stoneBrick.blockID);
		world.setBlock(i + 6, j + 1, k + 6, Block.stoneBrick.blockID);
		world.setBlock(i + 6, j + 1, k + 7, Block.stoneBrick.blockID);
		world.setBlock(i + 6, j + 1, k + 8, Block.stoneBrick.blockID);
		world.setBlock(i + 6, j + 1, k + 9, Block.stoneBrick.blockID);
		world.setBlock(i + 6, j + 1, k + 10, Block.stoneBrick.blockID);
		world.setBlock(i + 6, j + 1, k + 11, Block.stoneBrick.blockID);
		world.setBlock(i + 6, j + 1, k + 12, Block.stoneBrick.blockID);
		world.setBlock(i + 6, j + 2, k + 2, Block.stoneBrick.blockID);
		world.setBlock(i + 6, j + 2, k + 3, Block.stoneBrick.blockID);
		world.setBlock(i + 6, j + 2, k + 4, Block.stoneBrick.blockID);
		world.setBlock(i + 6, j + 2, k + 5, Block.stoneBrick.blockID);
		world.setBlock(i + 6, j + 2, k + 6, Block.stoneBrick.blockID);
		world.setBlock(i + 6, j + 2, k + 7, Block.stoneBrick.blockID);
		world.setBlock(i + 6, j + 2, k + 8, Block.stoneBrick.blockID);
		world.setBlock(i + 6, j + 2, k + 9, Block.stoneBrick.blockID);
		world.setBlock(i + 6, j + 2, k + 10, Block.stoneBrick.blockID);
		world.setBlock(i + 6, j + 2, k + 11, Block.stoneBrick.blockID);
		world.setBlock(i + 6, j + 2, k + 12, Block.stoneBrick.blockID);
		world.setBlock(i + 6, j + 3, k + 2, Block.stoneBrick.blockID);
		world.setBlock(i + 6, j + 3, k + 3, Block.stoneBrick.blockID);
		world.setBlock(i + 6, j + 3, k + 4, Block.stoneBrick.blockID);
		world.setBlock(i + 6, j + 3, k + 5, BlockPedestal.instance.blockID);
		te = world.getBlockTileEntity(i + 6, j + 3, k + 5); 
		if(te instanceof TileEntityDisplayPedestal) {
			tedd = (TileEntityDisplayPedestal)te;
			tedd.setInventorySlotContents(0, FactoryArtifact.applyRandomEffects(new ItemStack(ItemArtifact.instance)));
			tedd.rotation = 270;
		}
		world.setBlock(i + 6, j + 3, k + 6, BlockPedestal.instance.blockID);
		te = world.getBlockTileEntity(i + 6, j + 3, k + 6); 
		if(te instanceof TileEntityDisplayPedestal) {
			tedd = (TileEntityDisplayPedestal)te;
			tedd.setInventorySlotContents(0, FactoryArtifact.applyRandomEffects(new ItemStack(ItemArtifact.instance)));
			tedd.rotation = 270;
		}
		world.setBlock(i + 6, j + 3, k + 7, BlockPedestal.instance.blockID);
		te = world.getBlockTileEntity(i + 6, j + 3, k + 7); 
		if(te instanceof TileEntityDisplayPedestal) {
			tedd = (TileEntityDisplayPedestal)te;
			tedd.setInventorySlotContents(0, FactoryArtifact.applyRandomEffects(new ItemStack(ItemArtifact.instance)));
			tedd.rotation = 270;
		}
		world.setBlock(i + 6, j + 3, k + 8, Block.stoneBrick.blockID);
		world.setBlock(i + 6, j + 3, k + 9, 0);
		world.setBlock(i + 6, j + 3, k + 10, 0);
		world.setBlock(i + 6, j + 3, k + 11, 0);
		world.setBlock(i + 6, j + 4, k + 2, Block.stoneBrick.blockID);
		world.setBlock(i + 6, j + 4, k + 3, Block.stoneBrick.blockID);
		world.setBlock(i + 6, j + 4, k + 4, Block.stoneBrick.blockID);
		world.setBlock(i + 6, j + 4, k + 5, 0);
		world.setBlock(i + 6, j + 4, k + 6, 0);
		world.setBlock(i + 6, j + 4, k + 7, 0);
		world.setBlock(i + 6, j + 4, k + 8, Block.stoneBrick.blockID);
		world.setBlock(i + 6, j + 4, k + 9, 0);
		world.setBlock(i + 6, j + 4, k + 10, 0);
		world.setBlock(i + 6, j + 4, k + 11, 0);
		world.setBlock(i + 6, j + 5, k + 2, Block.stoneBrick.blockID);
		world.setBlock(i + 6, j + 5, k + 3, Block.stoneBrick.blockID);
		world.setBlock(i + 6, j + 5, k + 4, Block.stoneBrick.blockID);
		world.setBlock(i + 6, j + 5, k + 6, 0);
		world.setBlock(i + 6, j + 5, k + 8, Block.stoneBrick.blockID);
		world.setBlock(i + 6, j + 5, k + 9, 0);
		world.setBlock(i + 6, j + 5, k + 10, 0);
		world.setBlock(i + 6, j + 5, k + 11, 0);
		world.setBlock(i + 6, j + 5, k + 12, Block.stoneBrick.blockID);
		world.setBlock(i + 6, j + 6, k + 2, Block.stoneBrick.blockID);
		world.setBlock(i + 6, j + 6, k + 3, Block.stoneBrick.blockID);
		world.setBlock(i + 6, j + 6, k + 4, Block.stoneBrick.blockID);
		world.setBlock(i + 6, j + 6, k + 5, 0);
		world.setBlock(i + 6, j + 6, k + 6, 0);
		world.setBlock(i + 6, j + 6, k + 7, 0);
		world.setBlock(i + 6, j + 6, k + 8, Block.stoneBrick.blockID);
		world.setBlock(i + 6, j + 6, k + 9, 0);
		world.setBlock(i + 6, j + 6, k + 10, 0);
		world.setBlock(i + 6, j + 6, k + 11, 0);
		world.setBlock(i + 6, j + 6, k + 12, Block.stoneBrick.blockID);
		world.setBlock(i + 6, j + 7, k + 2, Block.stoneBrick.blockID);
		world.setBlock(i + 6, j + 7, k + 3, Block.stoneBrick.blockID);
		world.setBlock(i + 6, j + 7, k + 4, Block.stoneBrick.blockID);
		world.setBlock(i + 6, j + 7, k + 5, Block.stoneBrick.blockID);
		world.setBlock(i + 6, j + 7, k + 6, Block.stoneBrick.blockID);
		world.setBlock(i + 6, j + 7, k + 7, Block.stoneBrick.blockID);
		world.setBlock(i + 6, j + 7, k + 8, Block.stoneBrick.blockID);
		world.setBlock(i + 6, j + 7, k + 9, Block.stoneBrick.blockID);
		world.setBlock(i + 6, j + 7, k + 10, Block.stoneBrick.blockID);
		world.setBlock(i + 6, j + 7, k + 11, Block.stoneBrick.blockID);
		world.setBlock(i + 6, j + 7, k + 12, Block.stoneBrick.blockID);
		world.setBlock(i + 6, j + 8, k + 2, Block.stoneBrick.blockID);
		world.setBlock(i + 6, j + 8, k + 3, Block.stoneBrick.blockID);
		world.setBlock(i + 6, j + 8, k + 4, Block.workbench.blockID);
		world.setBlock(i + 6, j + 8, k + 5, 0);
		world.setBlock(i + 6, j + 8, k + 6, 0);
		world.setBlock(i + 6, j + 8, k + 7, 0);
		world.setBlock(i + 6, j + 8, k + 8, 0);
		world.setBlock(i + 6, j + 8, k + 9, 0);
		world.setBlock(i + 6, j + 8, k + 10, Block.bookShelf.blockID);
		world.setBlock(i + 6, j + 8, k + 11, Block.stoneBrick.blockID);
		world.setBlock(i + 6, j + 8, k + 12, Block.stoneBrick.blockID);
		world.setBlock(i + 6, j + 9, k + 2, Block.stoneBrick.blockID);
		world.setBlock(i + 6, j + 9, k + 3, 0);
		world.setBlock(i + 6, j + 9, k + 4, 0);
		world.setBlock(i + 6, j + 9, k + 5, 0);
		world.setBlock(i + 6, j + 9, k + 6, 0);
		world.setBlock(i + 6, j + 9, k + 7, 0);
		world.setBlock(i + 6, j + 9, k + 8, 0);
		world.setBlock(i + 6, j + 9, k + 9, 0);
		world.setBlock(i + 6, j + 9, k + 10, Block.bookShelf.blockID);
		world.setBlock(i + 6, j + 9, k + 11, Block.stoneBrick.blockID);
		world.setBlock(i + 6, j + 9, k + 12, Block.stoneBrick.blockID);
		world.setBlock(i + 6, j + 10, k + 2, Block.stoneBrick.blockID);
		world.setBlock(i + 6, j + 10, k + 3, Block.stoneBrick.blockID);
		world.setBlock(i + 6, j + 10, k + 4, Block.stoneBrick.blockID);
		world.setBlock(i + 6, j + 10, k + 5, Block.stoneBrick.blockID);
		world.setBlock(i + 6, j + 10, k + 6, Block.stoneBrick.blockID);
		world.setBlock(i + 6, j + 10, k + 7, Block.stoneBrick.blockID);
		world.setBlock(i + 6, j + 10, k + 8, Block.stoneBrick.blockID);
		world.setBlock(i + 6, j + 10, k + 9, Block.stoneBrick.blockID);
		world.setBlock(i + 6, j + 10, k + 10, Block.stoneBrick.blockID);
		world.setBlock(i + 6, j + 10, k + 11, Block.stoneBrick.blockID);
		world.setBlock(i + 6, j + 10, k + 12, Block.stoneBrick.blockID);
		world.setBlock(i + 6, j + 11, k + 1, Block.stairsWoodOak.blockID, 5, 3);
		world.setBlock(i + 6, j + 11, k + 2, Block.planks.blockID);
		world.setBlock(i + 6, j + 11, k + 3, Block.stoneBrick.blockID);
		world.setBlock(i + 6, j + 11, k + 4, Block.stoneBrick.blockID);
		world.setBlock(i + 6, j + 11, k + 5, Block.stoneBrick.blockID);
		world.setBlock(i + 6, j + 11, k + 6, Block.stoneBrick.blockID);
		world.setBlock(i + 6, j + 11, k + 7, Block.stoneBrick.blockID);
		world.setBlock(i + 6, j + 11, k + 8, Block.stoneBrick.blockID);
		world.setBlock(i + 6, j + 11, k + 9, Block.stoneBrick.blockID);
		world.setBlock(i + 6, j + 11, k + 10, Block.stoneBrick.blockID);
		world.setBlock(i + 6, j + 11, k + 11, Block.stoneBrick.blockID);
		world.setBlock(i + 6, j + 11, k + 12, Block.stairsStoneBrick.blockID, 3, 3);
		world.setBlock(i + 6, j + 12, k + 1, Block.planks.blockID);
		world.setBlock(i + 6, j + 12, k + 2, Block.planks.blockID);
		world.setBlock(i + 6, j + 12, k + 3, Block.stoneBrick.blockID);
		world.setBlock(i + 6, j + 12, k + 4, 0);
		world.setBlock(i + 6, j + 12, k + 5, 0);
		world.setBlock(i + 6, j + 12, k + 11, Block.stoneBrick.blockID);
		world.setBlock(i + 6, j + 13, k + 1, Block.planks.blockID);
		world.setBlock(i + 6, j + 13, k + 2, Block.planks.blockID);
		world.setBlock(i + 6, j + 13, k + 3, Block.stoneBrick.blockID);
		world.setBlock(i + 6, j + 13, k + 4, 0);
		world.setBlock(i + 6, j + 13, k + 5, 0);
		world.setBlock(i + 6, j + 13, k + 7, 0);
		world.setBlock(i + 6, j + 13, k + 8, 0);
		world.setBlock(i + 6, j + 13, k + 9, 0);
		world.setBlock(i + 6, j + 13, k + 10, 0);
		world.setBlock(i + 6, j + 13, k + 11, Block.fenceIron.blockID);
		world.setBlock(i + 6, j + 14, k + 1, Block.planks.blockID);
		world.setBlock(i + 6, j + 14, k + 2, Block.planks.blockID);
		world.setBlock(i + 6, j + 14, k + 3, Block.stoneBrick.blockID);
		world.setBlock(i + 6, j + 14, k + 4, Block.stoneBrick.blockID);
		world.setBlock(i + 6, j + 14, k + 5, Block.stoneBrick.blockID);
		world.setBlock(i + 6, j + 14, k + 6, Block.stoneBrick.blockID);
		world.setBlock(i + 6, j + 14, k + 7, 0);
		world.setBlock(i + 6, j + 14, k + 10, 0);
		world.setBlock(i + 6, j + 14, k + 11, Block.fenceIron.blockID);
		world.setBlock(i + 6, j + 15, k + 0, Block.stairsWoodOak.blockID, 1, 3);
		world.setBlock(i + 6, j + 15, k + 1, Block.stairsWoodOak.blockID, 1, 3);
		world.setBlock(i + 6, j + 15, k + 2, Block.planks.blockID);
		world.setBlock(i + 6, j + 15, k + 3, Block.stoneBrick.blockID);
		world.setBlock(i + 6, j + 15, k + 6, Block.stoneBrick.blockID);
		world.setBlock(i + 6, j + 15, k + 7, Block.glowStone.blockID);
		world.setBlock(i + 6, j + 15, k + 8, Block.stoneBrick.blockID);
		world.setBlock(i + 6, j + 15, k + 9, Block.stoneBrick.blockID);
		world.setBlock(i + 6, j + 15, k + 10, Block.stoneBrick.blockID);
		world.setBlock(i + 6, j + 15, k + 11, Block.stoneBrick.blockID);
		world.setBlock(i + 6, j + 16, k + 2, Block.stairsWoodOak.blockID, 2, 3);
		world.setBlock(i + 6, j + 16, k + 3, Block.stairsWoodOak.blockID, 1, 3);
		world.setBlock(i + 6, j + 16, k + 4, Block.stoneBrick.blockID);
		world.setBlock(i + 6, j + 16, k + 5, Block.stoneBrick.blockID);
		world.setBlock(i + 6, j + 16, k + 7, Block.stoneBrick.blockID);
		world.setBlock(i + 6, j + 16, k + 8, Block.fenceIron.blockID);
		world.setBlock(i + 6, j + 16, k + 9, Block.stoneBrick.blockID);
		world.setBlock(i + 6, j + 16, k + 10, Block.stoneBrick.blockID);
		world.setBlock(i + 6, j + 16, k + 11, Block.stairsStoneBrick.blockID, 3, 3);
		world.setBlock(i + 6, j + 17, k + 4, Block.stoneBrick.blockID);
		world.setBlock(i + 6, j + 17, k + 5, Block.stoneBrick.blockID);
		world.setBlock(i + 6, j + 17, k + 7, Block.stoneBrick.blockID);
		world.setBlock(i + 6, j + 17, k + 8, Block.fenceIron.blockID);
		world.setBlock(i + 6, j + 17, k + 9, Block.stoneBrick.blockID);
		world.setBlock(i + 6, j + 17, k + 10, Block.stoneBrick.blockID);
		world.setBlock(i + 6, j + 18, k + 4, Block.stoneBrick.blockID);
		world.setBlock(i + 6, j + 18, k + 5, Block.stoneBrick.blockID);
		world.setBlock(i + 6, j + 18, k + 6, Block.stoneBrick.blockID);
		world.setBlock(i + 6, j + 18, k + 7, Block.stoneBrick.blockID);
		world.setBlock(i + 6, j + 18, k + 8, Block.stoneBrick.blockID);
		world.setBlock(i + 6, j + 18, k + 9, Block.stoneBrick.blockID);
		world.setBlock(i + 6, j + 18, k + 10, Block.stoneBrick.blockID);
		world.setBlock(i + 6, j + 19, k + 4, Block.stairsStoneBrick.blockID, 2, 3);
		world.setBlock(i + 6, j + 19, k + 5, Block.stoneBrick.blockID);
		world.setBlock(i + 6, j + 19, k + 6, 0);
		world.setBlock(i + 6, j + 19, k + 8, 0);
		world.setBlock(i + 6, j + 19, k + 9, Block.stoneBrick.blockID);
		world.setBlock(i + 6, j + 19, k + 10, Block.stairsStoneBrick.blockID, 3, 3);
		world.setBlock(i + 6, j + 20, k + 5, Block.fenceIron.blockID);
		world.setBlock(i + 6, j + 20, k + 6, 0);
		world.setBlock(i + 6, j + 20, k + 8, 0);
		world.setBlock(i + 6, j + 20, k + 9, Block.fenceIron.blockID);
		world.setBlock(i + 6, j + 21, k + 5, Block.stoneBrick.blockID);
		world.setBlock(i + 6, j + 21, k + 6, Block.stoneBrick.blockID);
		world.setBlock(i + 6, j + 21, k + 8, Block.stoneBrick.blockID);
		world.setBlock(i + 6, j + 21, k + 9, Block.stoneBrick.blockID);
		world.setBlock(i + 6, j + 22, k + 5, Block.stoneBrick.blockID);
		world.setBlock(i + 6, j + 22, k + 6, Block.stoneBrick.blockID);
		world.setBlock(i + 6, j + 22, k + 8, Block.stoneBrick.blockID);
		world.setBlock(i + 6, j + 22, k + 9, Block.stoneBrick.blockID);
		world.setBlock(i + 6, j + 23, k + 5, Block.stairsStoneBrick.blockID, 2, 3);
		world.setBlock(i + 6, j + 23, k + 6, Block.stoneBrick.blockID);
		world.setBlock(i + 6, j + 23, k + 8, Block.stoneBrick.blockID);
		world.setBlock(i + 6, j + 23, k + 9, Block.stairsStoneBrick.blockID, 3, 3);
		world.setBlock(i + 6, j + 24, k + 6, Block.stoneBrick.blockID);
		world.setBlock(i + 6, j + 24, k + 8, Block.stoneBrick.blockID);
		world.setBlock(i + 6, j + 25, k + 6, Block.stoneBrick.blockID);
		world.setBlock(i + 6, j + 25, k + 8, Block.stoneBrick.blockID);
		world.setBlock(i + 6, j + 26, k + 6, Block.stoneBrick.blockID);
		world.setBlock(i + 6, j + 26, k + 8, Block.stoneBrick.blockID);
		world.setBlock(i + 6, j + 27, k + 5, Block.stairsStoneBrick.blockID, 6, 3);
		world.setBlock(i + 6, j + 27, k + 6, Block.stoneBrick.blockID);
		world.setBlock(i + 6, j + 27, k + 8, Block.stoneBrick.blockID);
		world.setBlock(i + 6, j + 27, k + 9, Block.stairsStoneBrick.blockID, 7, 3);
		world.setBlock(i + 6, j + 28, k + 4, Block.stairsStoneBrick.blockID, 6, 3);
		world.setBlock(i + 6, j + 28, k + 5, Block.stoneBrick.blockID);
		world.setBlock(i + 6, j + 28, k + 6, Block.stoneBrick.blockID);
		world.setBlock(i + 6, j + 28, k + 8, Block.stoneBrick.blockID);
		world.setBlock(i + 6, j + 28, k + 9, Block.stoneBrick.blockID);
		world.setBlock(i + 6, j + 28, k + 10, Block.stairsStoneBrick.blockID, 7, 3);
		world.setBlock(i + 6, j + 29, k + 4, Block.stoneBrick.blockID);
		world.setBlock(i + 6, j + 29, k + 5, 0);
		world.setBlock(i + 6, j + 29, k + 6, 0);
		world.setBlock(i + 6, j + 29, k + 7, 0);
		world.setBlock(i + 6, j + 29, k + 8, 0);
		world.setBlock(i + 6, j + 29, k + 9, 0);
		world.setBlock(i + 6, j + 29, k + 10, Block.stoneBrick.blockID);
		world.setBlock(i + 6, j + 30, k + 5, 0);
		world.setBlock(i + 6, j + 30, k + 6, 0);
		world.setBlock(i + 6, j + 30, k + 7, 0);
		world.setBlock(i + 6, j + 30, k + 8, 0);
		world.setBlock(i + 6, j + 30, k + 9, 0);
		world.setBlock(i + 6, j + 31, k + 6, 0);
		world.setBlock(i + 6, j + 31, k + 7, 0);
		world.setBlock(i + 6, j + 31, k + 8, 0);
		world.setBlock(i + 6, j + 32, k + 6, Block.stairsWoodOak.blockID, 2, 3);
		world.setBlock(i + 6, j + 32, k + 7, Block.glowStone.blockID);
		world.setBlock(i + 6, j + 32, k + 8, Block.stairsWoodOak.blockID, 3, 3);
		world.setBlock(i + 7, j + 0, k + 2, Block.stoneBrick.blockID);
		world.setBlock(i + 7, j + 0, k + 3, Block.stoneBrick.blockID);
		world.setBlock(i + 7, j + 0, k + 4, Block.stoneBrick.blockID);
		world.setBlock(i + 7, j + 0, k + 5, Block.stoneBrick.blockID);
		world.setBlock(i + 7, j + 0, k + 6, Block.stoneBrick.blockID);
		world.setBlock(i + 7, j + 0, k + 7, Block.stoneBrick.blockID);
		world.setBlock(i + 7, j + 0, k + 8, Block.stoneBrick.blockID);
		world.setBlock(i + 7, j + 0, k + 9, Block.stoneBrick.blockID);
		world.setBlock(i + 7, j + 0, k + 10, Block.stoneBrick.blockID);
		world.setBlock(i + 7, j + 0, k + 11, Block.stoneBrick.blockID);
		world.setBlock(i + 7, j + 0, k + 12, Block.stoneBrick.blockID);
		world.setBlock(i + 7, j + 1, k + 2, Block.stoneBrick.blockID);
		world.setBlock(i + 7, j + 1, k + 3, Block.stoneBrick.blockID);
		world.setBlock(i + 7, j + 1, k + 4, Block.stoneBrick.blockID);
		world.setBlock(i + 7, j + 1, k + 5, Block.stoneBrick.blockID);
		world.setBlock(i + 7, j + 1, k + 6, Block.stoneBrick.blockID);
		world.setBlock(i + 7, j + 1, k + 7, Block.stoneBrick.blockID);
		world.setBlock(i + 7, j + 1, k + 8, Block.stoneBrick.blockID);
		world.setBlock(i + 7, j + 1, k + 9, Block.stoneBrick.blockID);
		world.setBlock(i + 7, j + 1, k + 10, Block.stoneBrick.blockID);
		world.setBlock(i + 7, j + 1, k + 11, Block.stoneBrick.blockID);
		world.setBlock(i + 7, j + 1, k + 12, Block.stoneBrick.blockID);
		world.setBlock(i + 7, j + 2, k + 2, Block.stoneBrick.blockID);
		world.setBlock(i + 7, j + 2, k + 3, Block.stoneBrick.blockID);
		world.setBlock(i + 7, j + 2, k + 4, Block.stoneBrick.blockID);
		world.setBlock(i + 7, j + 2, k + 5, Block.stoneBrick.blockID);
		world.setBlock(i + 7, j + 2, k + 6, Block.stoneBrick.blockID);
		world.setBlock(i + 7, j + 2, k + 7, Block.stoneBrick.blockID);
		world.setBlock(i + 7, j + 2, k + 8, Block.stoneBrick.blockID);
		world.setBlock(i + 7, j + 2, k + 9, Block.stoneBrick.blockID);
		world.setBlock(i + 7, j + 2, k + 10, Block.stoneBrick.blockID);
		world.setBlock(i + 7, j + 2, k + 11, Block.stoneBrick.blockID);
		world.setBlock(i + 7, j + 2, k + 12, Block.stoneBrick.blockID);
		world.setBlock(i + 7, j + 3, k + 2, Block.stoneBrick.blockID);
		world.setBlock(i + 7, j + 3, k + 3, Block.stoneBrick.blockID);
		world.setBlock(i + 7, j + 3, k + 4, Block.stoneBrick.blockID);
		world.setBlock(i + 7, j + 3, k + 5, Block.stoneBrick.blockID);
		world.setBlock(i + 7, j + 3, k + 6, Block.stoneBrick.blockID);
		world.setBlock(i + 7, j + 3, k + 7, Block.stoneBrick.blockID);
		world.setBlock(i + 7, j + 3, k + 8, Block.stoneBrick.blockID);
		world.setBlock(i + 7, j + 3, k + 9, 0);
		world.setBlock(i + 7, j + 3, k + 10, 0);
		world.setBlock(i + 7, j + 3, k + 11, 0);
		world.setBlock(i + 7, j + 3, k + 12, Block.stoneBrick.blockID);
		world.setBlock(i + 7, j + 4, k + 2, Block.stoneBrick.blockID);
		world.setBlock(i + 7, j + 4, k + 3, Block.stoneBrick.blockID);
		world.setBlock(i + 7, j + 4, k + 4, Block.stoneBrick.blockID);
		world.setBlock(i + 7, j + 4, k + 5, Block.stoneBrick.blockID);
		world.setBlock(i + 7, j + 4, k + 6, Block.stoneBrick.blockID);
		world.setBlock(i + 7, j + 4, k + 7, Block.stoneBrick.blockID);
		world.setBlock(i + 7, j + 4, k + 8, Block.stoneBrick.blockID);
		world.setBlock(i + 7, j + 4, k + 9, 0);
		world.setBlock(i + 7, j + 4, k + 10, 0);
		world.setBlock(i + 7, j + 4, k + 11, 0);
		world.setBlock(i + 7, j + 4, k + 12, Block.stoneBrick.blockID);
		world.setBlock(i + 7, j + 5, k + 2, Block.stoneBrick.blockID);
		world.setBlock(i + 7, j + 5, k + 3, Block.stoneBrick.blockID);
		world.setBlock(i + 7, j + 5, k + 4, Block.stoneBrick.blockID);
		world.setBlock(i + 7, j + 5, k + 5, Block.stoneBrick.blockID);
		world.setBlock(i + 7, j + 5, k + 6, Block.stoneBrick.blockID);
		world.setBlock(i + 7, j + 5, k + 7, Block.stoneBrick.blockID);
		world.setBlock(i + 7, j + 5, k + 8, Block.stoneBrick.blockID);
		world.setBlock(i + 7, j + 5, k + 9, 0);
		world.setBlock(i + 7, j + 5, k + 10, 0);
		world.setBlock(i + 7, j + 5, k + 11, 0);
		world.setBlock(i + 7, j + 5, k + 12, Block.stoneBrick.blockID);
		world.setBlock(i + 7, j + 6, k + 2, Block.stoneBrick.blockID);
		world.setBlock(i + 7, j + 6, k + 3, Block.stoneBrick.blockID);
		world.setBlock(i + 7, j + 6, k + 4, Block.stoneBrick.blockID);
		world.setBlock(i + 7, j + 6, k + 5, Block.stoneBrick.blockID);
		world.setBlock(i + 7, j + 6, k + 6, Block.stoneBrick.blockID);
		world.setBlock(i + 7, j + 6, k + 7, Block.stoneBrick.blockID);
		world.setBlock(i + 7, j + 6, k + 8, Block.stoneBrick.blockID);
		world.setBlock(i + 7, j + 6, k + 9, 0);
		world.setBlock(i + 7, j + 6, k + 10, 0);
		world.setBlock(i + 7, j + 6, k + 11, 0);
		world.setBlock(i + 7, j + 6, k + 12, Block.stoneBrick.blockID);
		world.setBlock(i + 7, j + 7, k + 2, Block.stoneBrick.blockID);
		world.setBlock(i + 7, j + 7, k + 3, Block.stoneBrick.blockID);
		world.setBlock(i + 7, j + 7, k + 4, Block.stoneBrick.blockID);
		world.setBlock(i + 7, j + 7, k + 5, Block.stoneBrick.blockID);
		world.setBlock(i + 7, j + 7, k + 6, Block.stoneBrick.blockID);
		world.setBlock(i + 7, j + 7, k + 7, Block.stoneBrick.blockID);
		world.setBlock(i + 7, j + 7, k + 8, Block.stoneBrick.blockID);
		world.setBlock(i + 7, j + 7, k + 9, Block.stoneBrick.blockID);
		world.setBlock(i + 7, j + 7, k + 10, Block.stoneBrick.blockID);
		world.setBlock(i + 7, j + 7, k + 11, Block.stoneBrick.blockID);
		world.setBlock(i + 7, j + 7, k + 12, Block.stoneBrick.blockID);
		world.setBlock(i + 7, j + 8, k + 2, Block.stoneBrick.blockID);
		world.setBlock(i + 7, j + 8, k + 3, Block.stoneBrick.blockID);
		world.setBlock(i + 7, j + 8, k + 4, Block.furnaceIdle.blockID, 3, 3);
		world.setBlockMetadataWithNotify(i + 7, j + 8, k + 4, 3, 3);
		world.setBlock(i + 7, j + 8, k + 5, 0);
		world.setBlock(i + 7, j + 8, k + 6, 0);
		world.setBlock(i + 7, j + 8, k + 7, 0);
		world.setBlock(i + 7, j + 8, k + 8, Block.enchantmentTable.blockID);
		world.setBlock(i + 7, j + 8, k + 9, 0);
		world.setBlock(i + 7, j + 8, k + 10, Block.bookShelf.blockID);
		world.setBlock(i + 7, j + 8, k + 11, Block.stoneBrick.blockID);
		world.setBlock(i + 7, j + 8, k + 12, Block.stoneBrick.blockID);
		world.setBlock(i + 7, j + 9, k + 2, Block.stoneBrick.blockID);
		world.setBlock(i + 7, j + 9, k + 3, Block.stoneBrick.blockID);
		world.setBlock(i + 7, j + 9, k + 4, 0);
		world.setBlock(i + 7, j + 9, k + 5, 0);
		world.setBlock(i + 7, j + 9, k + 6, 0);
		world.setBlock(i + 7, j + 9, k + 8, 0);
		world.setBlock(i + 7, j + 9, k + 9, 0);
		world.setBlock(i + 7, j + 9, k + 10, Block.bookShelf.blockID);
		world.setBlock(i + 7, j + 9, k + 11, Block.stoneBrick.blockID);
		world.setBlock(i + 7, j + 9, k + 12, Block.stoneBrick.blockID);
		world.setBlock(i + 7, j + 10, k + 2, Block.planks.blockID);
		world.setBlock(i + 7, j + 10, k + 3, Block.stoneBrick.blockID);
		world.setBlock(i + 7, j + 10, k + 4, Block.stoneBrick.blockID);
		world.setBlock(i + 7, j + 10, k + 5, Block.stoneBrick.blockID);
		world.setBlock(i + 7, j + 10, k + 6, Block.stoneBrick.blockID);
		world.setBlock(i + 7, j + 10, k + 7, Block.redstoneLampActive.blockID);
		world.setBlock(i + 7, j + 10, k + 8, Block.stoneBrick.blockID);
		world.setBlock(i + 7, j + 10, k + 9, Block.stoneBrick.blockID);
		world.setBlock(i + 7, j + 10, k + 10, Block.stoneBrick.blockID);
		world.setBlock(i + 7, j + 10, k + 11, Block.stoneBrick.blockID);
		world.setBlock(i + 7, j + 11, k + 2, Block.planks.blockID);
		world.setBlock(i + 7, j + 11, k + 3, Block.stoneBrick.blockID);
		world.setBlock(i + 7, j + 11, k + 4, Block.stoneBrick.blockID);
		world.setBlock(i + 7, j + 11, k + 5, Block.stoneBrick.blockID);
		world.setBlock(i + 7, j + 11, k + 6, Block.stoneBrick.blockID);
		world.setBlock(i + 7, j + 11, k + 7, Block.stoneBrick.blockID);
		world.setBlock(i + 7, j + 11, k + 8, Block.stoneBrick.blockID);
		world.setBlock(i + 7, j + 11, k + 9, Block.stoneBrick.blockID);
		world.setBlock(i + 7, j + 11, k + 10, Block.stoneBrick.blockID);
		world.setBlock(i + 7, j + 11, k + 11, Block.stoneBrick.blockID);
		world.setBlock(i + 7, j + 12, k + 2, Block.planks.blockID);
		world.setBlock(i + 7, j + 12, k + 3, Block.stoneBrick.blockID);
		world.setBlock(i + 7, j + 12, k + 5, Block.bed.blockID, 2, 3);
		world.setBlock(i + 7, j + 12, k + 4, Block.bed.blockID, 10, 3);
		world.setBlock(i + 7, j + 12, k + 6, Block.stoneBrick.blockID);
		world.setBlock(i + 7, j + 12, k + 11, Block.stoneBrick.blockID);
		world.setBlock(i + 7, j + 13, k + 2, Block.planks.blockID);
		world.setBlock(i + 7, j + 13, k + 3, Block.stoneBrick.blockID);
		world.setBlock(i + 7, j + 13, k + 4, 0);
		world.setBlock(i + 7, j + 13, k + 5, 0);
		world.setBlock(i + 7, j + 13, k + 6, Block.stoneBrick.blockID);
		world.setBlock(i + 7, j + 13, k + 7, 0);
		world.setBlock(i + 7, j + 13, k + 8, 0);
		world.setBlock(i + 7, j + 13, k + 9, 0);
		world.setBlock(i + 7, j + 13, k + 10, 0);
		world.setBlock(i + 7, j + 13, k + 11, Block.stoneBrick.blockID);
		world.setBlock(i + 7, j + 14, k + 2, Block.planks.blockID);
		world.setBlock(i + 7, j + 14, k + 3, Block.stoneBrick.blockID);
		world.setBlock(i + 7, j + 14, k + 4, Block.stoneBrick.blockID);
		world.setBlock(i + 7, j + 14, k + 5, Block.stoneBrick.blockID);
		world.setBlock(i + 7, j + 14, k + 6, Block.stoneBrick.blockID);
		world.setBlock(i + 7, j + 14, k + 7, 0);
		world.setBlock(i + 7, j + 14, k + 8, 0);
		world.setBlock(i + 7, j + 14, k + 9, 0);
		world.setBlock(i + 7, j + 14, k + 10, 0);
		world.setBlock(i + 7, j + 14, k + 11, Block.stoneBrick.blockID);
		world.setBlock(i + 7, j + 15, k + 1, Block.stairsWoodOak.blockID, 2, 3);
		world.setBlock(i + 7, j + 15, k + 2, Block.stairsWoodOak.blockID, 1, 3);
		world.setBlock(i + 7, j + 15, k + 3, Block.stairsWoodOak.blockID, 1, 3);
		world.setBlock(i + 7, j + 15, k + 4, Block.stoneBrick.blockID);
		world.setBlock(i + 7, j + 15, k + 5, Block.stoneBrick.blockID);
		world.setBlock(i + 7, j + 15, k + 6, Block.stoneBrick.blockID);
		world.setBlock(i + 7, j + 15, k + 7, Block.stoneBrick.blockID);
		world.setBlock(i + 7, j + 15, k + 8, Block.stoneBrick.blockID);
		world.setBlock(i + 7, j + 15, k + 9, Block.stoneBrick.blockID);
		world.setBlock(i + 7, j + 15, k + 10, Block.stoneBrick.blockID);
		world.setBlock(i + 7, j + 15, k + 11, Block.stairsWoodOak.blockID);
		world.setBlock(i + 7, j + 15, k + 12, Block.stairsWoodOak.blockID);
		world.setBlock(i + 7, j + 16, k + 4, Block.stoneBrick.blockID);
		world.setBlock(i + 7, j + 16, k + 5, Block.stoneBrick.blockID);
		world.setBlock(i + 7, j + 16, k + 6, 0);
		world.setBlock(i + 7, j + 16, k + 7, 0);
		world.setBlock(i + 7, j + 16, k + 8, 0);
		world.setBlock(i + 7, j + 16, k + 9, Block.stoneBrick.blockID);
		world.setBlock(i + 7, j + 16, k + 10, Block.stoneBrick.blockID);
		world.setBlock(i + 7, j + 17, k + 4, Block.stoneBrick.blockID);
		world.setBlock(i + 7, j + 17, k + 5, Block.stoneBrick.blockID);
		world.setBlock(i + 7, j + 17, k + 6, 0);
		world.setBlock(i + 7, j + 17, k + 7, 0);
		world.setBlock(i + 7, j + 17, k + 8, 0);
		world.setBlock(i + 7, j + 17, k + 9, Block.glowStone.blockID);
		world.setBlock(i + 7, j + 17, k + 10, Block.stoneBrick.blockID);
		world.setBlock(i + 7, j + 18, k + 5, Block.stoneBrick.blockID);
		world.setBlock(i + 7, j + 18, k + 6, Block.stoneBrick.blockID);
		world.setBlock(i + 7, j + 18, k + 7, Block.stoneBrick.blockID);
		world.setBlock(i + 7, j + 18, k + 8, Block.stoneBrick.blockID);
		world.setBlock(i + 7, j + 18, k + 9, Block.stoneBrick.blockID);
		world.setBlock(i + 7, j + 19, k + 5, Block.stoneBrick.blockID);
		world.setBlock(i + 7, j + 19, k + 6, Block.stoneBrick.blockID);
		world.setBlock(i + 7, j + 19, k + 7, Block.stoneBrick.blockID);
		world.setBlock(i + 7, j + 19, k + 8, Block.stoneBrick.blockID);
		world.setBlock(i + 7, j + 19, k + 9, Block.stoneBrick.blockID);
		world.setBlock(i + 7, j + 20, k + 5, Block.stoneBrick.blockID);
		world.setBlock(i + 7, j + 20, k + 6, Block.stoneBrick.blockID);
		world.setBlock(i + 7, j + 20, k + 7, Block.stoneBrick.blockID);
		world.setBlock(i + 7, j + 20, k + 8, Block.stoneBrick.blockID);
		world.setBlock(i + 7, j + 20, k + 9, Block.stoneBrick.blockID);
		world.setBlock(i + 7, j + 21, k + 5, Block.stoneBrick.blockID);
		world.setBlock(i + 7, j + 21, k + 6, Block.stoneBrick.blockID);
		world.setBlock(i + 7, j + 21, k + 7, Block.stoneBrick.blockID);
		world.setBlock(i + 7, j + 21, k + 8, Block.stoneBrick.blockID);
		world.setBlock(i + 7, j + 21, k + 9, Block.stoneBrick.blockID);
		world.setBlock(i + 7, j + 22, k + 6, Block.stoneBrick.blockID);
		world.setBlock(i + 7, j + 22, k + 7, Block.stoneBrick.blockID);
		world.setBlock(i + 7, j + 22, k + 8, Block.stoneBrick.blockID);
		world.setBlock(i + 7, j + 23, k + 6, Block.stoneBrick.blockID);
		world.setBlock(i + 7, j + 23, k + 7, Block.stoneBrick.blockID);
		world.setBlock(i + 7, j + 23, k + 8, Block.stoneBrick.blockID);
		world.setBlock(i + 7, j + 24, k + 6, Block.stoneBrick.blockID);
		world.setBlock(i + 7, j + 24, k + 7, Block.stoneBrick.blockID);
		world.setBlock(i + 7, j + 24, k + 8, Block.stoneBrick.blockID);
		world.setBlock(i + 7, j + 25, k + 6, Block.stoneBrick.blockID);
		world.setBlock(i + 7, j + 25, k + 7, Block.stoneBrick.blockID);
		world.setBlock(i + 7, j + 25, k + 8, Block.stoneBrick.blockID);
		world.setBlock(i + 7, j + 26, k + 6, Block.stoneBrick.blockID);
		world.setBlock(i + 7, j + 26, k + 7, Block.stoneBrick.blockID);
		world.setBlock(i + 7, j + 26, k + 8, Block.stoneBrick.blockID);
		world.setBlock(i + 7, j + 27, k + 5, Block.stairsStoneBrick.blockID, 6, 3);
		world.setBlock(i + 7, j + 27, k + 6, Block.stoneBrick.blockID);
		world.setBlock(i + 7, j + 27, k + 7, Block.stoneBrick.blockID);
		world.setBlock(i + 7, j + 27, k + 8, Block.stoneBrick.blockID);
		world.setBlock(i + 7, j + 27, k + 9, Block.stairsStoneBrick.blockID, 7, 3);
		world.setBlock(i + 7, j + 28, k + 4, Block.stairsStoneBrick.blockID, 6, 3);
		world.setBlock(i + 7, j + 28, k + 5, Block.stoneBrick.blockID);
		world.setBlock(i + 7, j + 28, k + 6, Block.stoneBrick.blockID);
		world.setBlock(i + 7, j + 28, k + 7, Block.stoneBrick.blockID);
		world.setBlock(i + 7, j + 28, k + 8, Block.stoneBrick.blockID);
		world.setBlock(i + 7, j + 28, k + 9, Block.stoneBrick.blockID);
		world.setBlock(i + 7, j + 28, k + 10, Block.stairsStoneBrick.blockID, 7, 3);
		world.setBlock(i + 7, j + 29, k + 4, Block.stoneBrick.blockID);
		world.setBlock(i + 7, j + 29, k + 5, 0);
		world.setBlock(i + 7, j + 29, k + 6, Block.fence.blockID);
		world.setBlock(i + 7, j + 29, k + 7, 0);
		world.setBlock(i + 7, j + 29, k + 8, Block.fence.blockID);
		world.setBlock(i + 7, j + 29, k + 9, 0);
		world.setBlock(i + 7, j + 29, k + 10, Block.stoneBrick.blockID);
		world.setBlock(i + 7, j + 30, k + 4, Block.stairsStoneBrick.blockID);
		world.setBlock(i + 7, j + 30, k + 5, 0);
		world.setBlock(i + 7, j + 30, k + 6, Block.fence.blockID);
		world.setBlock(i + 7, j + 30, k + 7, 0);
		world.setBlock(i + 7, j + 30, k + 8, Block.fence.blockID);
		world.setBlock(i + 7, j + 30, k + 9, 0);
		world.setBlock(i + 7, j + 30, k + 10, Block.stairsStoneBrick.blockID);
		world.setBlock(i + 7, j + 31, k + 6, Block.fence.blockID);
		world.setBlock(i + 7, j + 31, k + 7, 0);
		world.setBlock(i + 7, j + 31, k + 8, Block.fence.blockID);
		world.setBlock(i + 7, j + 32, k + 6, Block.stairsWoodOak.blockID, 1, 3);
		world.setBlock(i + 7, j + 32, k + 7, Block.stairsWoodOak.blockID, 1, 3);
		world.setBlock(i + 7, j + 32, k + 8, Block.stairsWoodOak.blockID, 3, 3);
		world.setBlock(i + 8, j + 0, k + 3, Block.stoneBrick.blockID);
		world.setBlock(i + 8, j + 0, k + 4, Block.stoneBrick.blockID);
		world.setBlock(i + 8, j + 0, k + 5, Block.stoneBrick.blockID);
		world.setBlock(i + 8, j + 0, k + 6, Block.stoneBrick.blockID);
		world.setBlock(i + 8, j + 0, k + 7, Block.stoneBrick.blockID);
		world.setBlock(i + 8, j + 0, k + 8, Block.stoneBrick.blockID);
		world.setBlock(i + 8, j + 0, k + 9, Block.stoneBrick.blockID);
		world.setBlock(i + 8, j + 0, k + 10, Block.stoneBrick.blockID);
		world.setBlock(i + 8, j + 0, k + 11, Block.stoneBrick.blockID);
		world.setBlock(i + 8, j + 1, k + 3, Block.stoneBrick.blockID);
		world.setBlock(i + 8, j + 1, k + 4, Block.stoneBrick.blockID);
		world.setBlock(i + 8, j + 1, k + 5, Block.stoneBrick.blockID);
		world.setBlock(i + 8, j + 1, k + 6, Block.stoneBrick.blockID);
		world.setBlock(i + 8, j + 1, k + 7, Block.stoneBrick.blockID);
		world.setBlock(i + 8, j + 1, k + 8, Block.stoneBrick.blockID);
		world.setBlock(i + 8, j + 1, k + 9, Block.stoneBrick.blockID);
		world.setBlock(i + 8, j + 1, k + 10, Block.stoneBrick.blockID);
		world.setBlock(i + 8, j + 1, k + 11, Block.stoneBrick.blockID);
		world.setBlock(i + 8, j + 2, k + 3, Block.stoneBrick.blockID);
		world.setBlock(i + 8, j + 2, k + 4, Block.stoneBrick.blockID);
		world.setBlock(i + 8, j + 2, k + 5, Block.stoneBrick.blockID);
		world.setBlock(i + 8, j + 2, k + 6, Block.stoneBrick.blockID);
		world.setBlock(i + 8, j + 2, k + 7, Block.stoneBrick.blockID);
		world.setBlock(i + 8, j + 2, k + 8, Block.stoneBrick.blockID);
		world.setBlock(i + 8, j + 2, k + 9, Block.stoneBrick.blockID);
		world.setBlock(i + 8, j + 2, k + 10, Block.stoneBrick.blockID);
		world.setBlock(i + 8, j + 2, k + 11, Block.stoneBrick.blockID);
		world.setBlock(i + 8, j + 3, k + 3, Block.stoneBrick.blockID);
		world.setBlock(i + 8, j + 3, k + 4, Block.stoneBrick.blockID);
		world.setBlock(i + 8, j + 3, k + 5, Block.stoneBrick.blockID);
		world.setBlock(i + 8, j + 3, k + 7, 0);
		world.setBlock(i + 8, j + 3, k + 8, Block.web.blockID);
		world.setBlock(i + 8, j + 3, k + 9, 0);
		world.setBlock(i + 8, j + 3, k + 10, 0);
		world.setBlock(i + 8, j + 3, k + 11, Block.stoneBrick.blockID);
		world.setBlock(i + 8, j + 4, k + 3, Block.stoneBrick.blockID);
		world.setBlock(i + 8, j + 4, k + 4, Block.stoneBrick.blockID);
		world.setBlock(i + 8, j + 4, k + 5, Block.stoneBrick.blockID);
		world.setBlock(i + 8, j + 4, k + 7, 0);
		world.setBlock(i + 8, j + 4, k + 8, 0);
		world.setBlock(i + 8, j + 4, k + 9, Block.web.blockID);
		world.setBlock(i + 8, j + 4, k + 10, 0);
		world.setBlock(i + 8, j + 4, k + 11, Block.stoneBrick.blockID);
		world.setBlock(i + 8, j + 5, k + 3, Block.stoneBrick.blockID);
		world.setBlock(i + 8, j + 5, k + 4, Block.stoneBrick.blockID);
		world.setBlock(i + 8, j + 5, k + 5, Block.stoneBrick.blockID);
		world.setBlock(i + 8, j + 5, k + 7, 0);
		world.setBlock(i + 8, j + 5, k + 8, 0);
		world.setBlock(i + 8, j + 5, k + 9, 0);
		world.setBlock(i + 8, j + 5, k + 10, 0);
		world.setBlock(i + 8, j + 5, k + 11, Block.stoneBrick.blockID);
		world.setBlock(i + 8, j + 6, k + 3, Block.stoneBrick.blockID);
		world.setBlock(i + 8, j + 6, k + 4, Block.stoneBrick.blockID);
		world.setBlock(i + 8, j + 6, k + 5, Block.stoneBrick.blockID);
		world.setBlock(i + 8, j + 6, k + 7, 0);
		world.setBlock(i + 8, j + 6, k + 8, 0);
		world.setBlock(i + 8, j + 6, k + 9, 0);
		world.setBlock(i + 8, j + 6, k + 10, 0);
		world.setBlock(i + 8, j + 6, k + 11, Block.stoneBrick.blockID);
		world.setBlock(i + 8, j + 7, k + 3, Block.stoneBrick.blockID);
		world.setBlock(i + 8, j + 7, k + 4, Block.stoneBrick.blockID);
		world.setBlock(i + 8, j + 7, k + 5, Block.stoneBrick.blockID);
		world.setBlock(i + 8, j + 7, k + 7, Block.stoneBrick.blockID);
		world.setBlock(i + 8, j + 7, k + 8, Block.stoneBrick.blockID);
		world.setBlock(i + 8, j + 7, k + 9, Block.stoneBrick.blockID);
		world.setBlock(i + 8, j + 7, k + 10, Block.stoneBrick.blockID);
		world.setBlock(i + 8, j + 7, k + 11, Block.stoneBrick.blockID);
		world.setBlock(i + 8, j + 8, k + 3, Block.stoneBrick.blockID);
		world.setBlock(i + 8, j + 8, k + 4, Block.chest.blockID);
		te = world.getBlockTileEntity(i + 8, j + 8, k + 4);
		if(te instanceof TileEntityChest) {
			TileEntityChest tec = (TileEntityChest)te;
			ChestGenHooks info = ChestGenHooks.getInfo(ChestGenHooks.PYRAMID_DESERT_CHEST);
            WeightedRandomChestContent.generateChestContents(rand, info.getItems(rand), tec, info.getCount(rand));
		}
		world.setBlock(i + 8, j + 8, k + 5, 0);
		world.setBlock(i + 8, j + 8, k + 6, 0);
		world.setBlock(i + 8, j + 8, k + 7, 0);
		world.setBlock(i + 8, j + 8, k + 8, 0);
		world.setBlock(i + 8, j + 8, k + 9, 0);
		world.setBlock(i + 8, j + 8, k + 10, Block.bookShelf.blockID);
		world.setBlock(i + 8, j + 8, k + 11, Block.stoneBrick.blockID);
		world.setBlock(i + 8, j + 9, k + 3, Block.stoneBrick.blockID);

		generate2(world, rand, i, j, k);
		return true;
	}

