package draco18s.artifacts.worldgen;

import java.util.Random;

import draco18s.artifacts.block.*;
import draco18s.artifacts.entity.*;
import draco18s.artifacts.item.*;

import net.minecraft.block.Block;
import net.minecraft.item.Item;
import net.minecraft.item.ItemStack;
import net.minecraft.nbt.NBTTagCompound;
import net.minecraft.tileentity.TileEntity;
import net.minecraft.tileentity.TileEntityChest;
import net.minecraft.tileentity.TileEntityMobSpawner;
import net.minecraft.util.WeightedRandomChestContent;
import net.minecraft.world.World;
import net.minecraft.world.gen.feature.WorldGenerator;
import net.minecraft.world.gen.structure.StructureBoundingBox;
import net.minecraft.world.gen.structure.StructureComponent;
import net.minecraftforge.common.ChestGenHooks;

public class StructureJourneymanTower extends WorldGenerator {

	protected StructureJourneymanTower() {
	}

	@Override
	public boolean generate(World world, Random random, int x, int y, int z) {
		for (z -= 8; y > 5 && (!world.isBlockOpaqueCube(x, y, z) || world.getBlockId(x, y, z) == Block.leaves.blockID); --y)
        {
            ;
        }

        if (y <= 61)
        {
            return false;
        }
        else
        {
        	build(world, random, x-5, y, z);
        }
		return false;
	}
	
	public boolean build(World world, Random rand, int i, int j, int k) {
		//System.out.println("Placing journeyman tower at (" + i + "," + k+ ")");
		world.setBlock(i + 0, j + 11, k + 1, Block.stairsCobblestone.blockID, 4, 3);
		world.setBlock(i + 0, j + 11, k + 2, Block.stairsCobblestone.blockID, 4, 3);
		world.setBlock(i + 0, j + 11, k + 3, Block.stairsCobblestone.blockID, 4, 3);
		world.setBlock(i + 0, j + 12, k + 1, Block.cobblestone.blockID);
		world.setBlock(i + 0, j + 12, k + 3, Block.cobblestone.blockID);
		world.setBlock(i + 1, j + 0, k + 3, Block.cobblestone.blockID);
		world.setBlock(i + 1, j + 0, k + 4, Block.cobblestone.blockID);
		world.setBlock(i + 1, j + 0, k + 5, Block.cobblestone.blockID);
		world.setBlock(i + 1, j + 1, k + 3, Block.cobblestone.blockID);
		world.setBlock(i + 1, j + 1, k + 4, Block.cobblestone.blockID);
		world.setBlock(i + 1, j + 1, k + 5, Block.cobblestone.blockID);
		world.setBlock(i + 1, j + 2, k + 3, Block.cobblestone.blockID);
		world.setBlock(i + 1, j + 2, k + 4, Block.cobblestone.blockID);
		world.setBlock(i + 1, j + 2, k + 5, Block.cobblestone.blockID);
		world.setBlock(i + 1, j + 3, k + 3, Block.cobblestone.blockID);
		world.setBlock(i + 1, j + 3, k + 4, Block.cobblestone.blockID);
		world.setBlock(i + 1, j + 3, k + 5, Block.cobblestone.blockID);
		world.setBlock(i + 1, j + 4, k + 3, Block.cobblestone.blockID);
		world.setBlock(i + 1, j + 4, k + 4, Block.cobblestone.blockID);
		world.setBlock(i + 1, j + 4, k + 5, Block.cobblestone.blockID);
		//world.setBlock(i + 1, j + 9, k + 2, Block.stairsCobblestone.blockID, 4, 3);
		//world.setBlock(i + 1, j + 9, k + 3, Block.stairsCobblestone.blockID, 4, 3);
		world.setBlock(i + 1, j + 10, k + 1, Block.stairsCobblestone.blockID, 6, 3);
		world.setBlock(i + 1, j + 10, k + 2, Block.stairsCobblestone.blockID, 4, 3);
		world.setBlock(i + 1, j + 10, k + 3, Block.stairsCobblestone.blockID, 4, 3);
		world.setBlock(i + 1, j + 11, k + 0, Block.stairsCobblestone.blockID, 6, 3);
		world.setBlock(i + 1, j + 11, k + 1, 0);
		world.setBlock(i + 1, j + 11, k + 2, 0);
		world.setBlock(i + 1, j + 11, k + 3, 0);
		world.setBlock(i + 1, j + 11, k + 4, Block.stairsCobblestone.blockID, 7, 3);
		world.setBlock(i + 1, j + 12, k + 0, Block.cobblestone.blockID);
		world.setBlock(i + 1, j + 12, k + 1, 0);
		world.setBlock(i + 1, j + 12, k + 2, 0);
		world.setBlock(i + 1, j + 12, k + 3, 0);
		world.setBlock(i + 1, j + 12, k + 4, Block.cobblestone.blockID);
		world.setBlock(i + 1, j + 13, k + 1, 0);
		world.setBlock(i + 1, j + 13, k + 2, 0);
		world.setBlock(i + 1, j + 13, k + 3, 0);
		world.setBlock(i + 2, j + 0, k + 2, Block.cobblestone.blockID);
		world.setBlock(i + 2, j + 0, k + 3, Block.cobblestone.blockID);
		world.setBlock(i + 2, j + 0, k + 4, Block.cobblestone.blockID);
		world.setBlock(i + 2, j + 0, k + 5, Block.cobblestone.blockID);
		world.setBlock(i + 2, j + 0, k + 6, Block.cobblestone.blockID);
		world.setBlock(i + 2, j + 1, k + 2, Block.cobblestone.blockID);
		world.setBlock(i + 2, j + 1, k + 3, 0);
		world.setBlock(i + 2, j + 1, k + 4, 0);
		world.setBlock(i + 2, j + 2, k + 5, 0);
		world.setBlock(i + 2, j + 1, k + 6, Block.cobblestone.blockID);
		world.setBlock(i + 2, j + 2, k + 6, BlockTrap.instance.blockID, 4, 3);
		world.setBlockMetadataWithNotify(i + 2, j + 2, k + 6, 2, 3);
		TileEntity te = world.getBlockTileEntity(i + 2, j + 2, k + 6); 
		TileEntityTrap ted;
		if(te instanceof TileEntityTrap) {
			ted = (TileEntityTrap)te;
			//PlaceTraps.addTrapItem(ted);
			ted.addItem(new ItemStack(Item.swordIron));
		}
		world.setBlock(i + 2, j + 2, k + 2, Block.cobblestone.blockID);
		world.setBlock(i + 2, j + 2, k + 3, 0);
		world.setBlock(i + 2, j + 2, k + 4, 0);
		//world.setBlock(i + 2, j + 2, k + 6, Block.cobblestone.blockID);
		world.setBlock(i + 2, j + 3, k + 2, Block.cobblestone.blockID);
		world.setBlock(i + 2, j + 3, k + 3, Block.web.blockID);
		world.setBlock(i + 2, j + 3, k + 4, 0);
		world.setBlock(i + 2, j + 3, k + 5, 0);
		world.setBlock(i + 2, j + 3, k + 6, Block.cobblestone.blockID);
		world.setBlock(i + 2, j + 4, k + 2, Block.cobblestone.blockID);
		world.setBlock(i + 2, j + 4, k + 3, Block.cobblestone.blockID);
		world.setBlock(i + 2, j + 4, k + 4, Block.cobblestone.blockID);
		world.setBlock(i + 2, j + 4, k + 5, Block.cobblestone.blockID);
		world.setBlock(i + 2, j + 4, k + 6, Block.cobblestone.blockID);
		world.setBlock(i + 2, j + 5, k + 2, Block.cobblestone.blockID);
		world.setBlock(i + 2, j + 5, k + 3, Block.cobblestone.blockID);
		world.setBlock(i + 2, j + 5, k + 4, Block.cobblestone.blockID);
		world.setBlock(i + 2, j + 5, k + 5, Block.cobblestone.blockID);
		world.setBlock(i + 2, j + 5, k + 6, Block.cobblestone.blockID);
		world.setBlock(i + 2, j + 6, k + 2, Block.cobblestone.blockID);
		world.setBlock(i + 2, j + 6, k + 3, Block.cobblestone.blockID);
		world.setBlock(i + 2, j + 6, k + 4, Block.cobblestone.blockID);
		world.setBlock(i + 2, j + 6, k + 5, Block.cobblestone.blockID);
		world.setBlock(i + 2, j + 6, k + 6, Block.cobblestone.blockID);
		world.setBlock(i + 2, j + 7, k + 3, Block.cobblestone.blockID);
		world.setBlock(i + 2, j + 7, k + 4, Block.cobblestone.blockID);
		world.setBlock(i + 2, j + 7, k + 5, Block.cobblestone.blockID);
		world.setBlock(i + 2, j + 8, k + 3, Block.cobblestone.blockID);
		world.setBlock(i + 2, j + 8, k + 4, Block.cobblestone.blockID);
		world.setBlock(i + 2, j + 8, k + 5, Block.cobblestone.blockID);
		world.setBlock(i + 2, j + 8, k + 7, Block.stairsCobblestone.blockID, 4, 3);
		world.setBlock(i + 2, j + 8, k + 8, Block.stairsCobblestone.blockID, 4, 3);
		//world.setBlock(i + 2, j + 9, k + 2, Block.stairsCobblestone.blockID, 6, 3);
		world.setBlock(i + 2, j + 9, k + 3, Block.cobblestone.blockID);
		world.setBlock(i + 2, j + 9, k + 7, Block.cobblestone.blockID);
		/*te = world.getBlockTileEntity(i + 2, j + 9, k + 7); 
		if(te instanceof TileEntityTrap) {
			ted = (TileEntityTrap)te;
			PlaceTraps.addTrapItem(ted);
		}*/
		world.setBlock(i + 2, j + 9, k + 8, Block.cobblestone.blockID);
		world.setBlock(i + 2, j + 10, k + 1, Block.stairsCobblestone.blockID, 6, 3);
		world.setBlock(i + 2, j + 10, k + 2, Block.cobblestone.blockID);
		world.setBlock(i + 2, j + 10, k + 3, Block.cobblestone.blockID);
		world.setBlock(i + 2, j + 10, k + 7, Block.cobblestone.blockID);
		world.setBlock(i + 2, j + 10, k + 8, Block.cobblestone.blockID);
		world.setBlock(i + 2, j + 11, k + 0, Block.stairsCobblestone.blockID, 6, 3);
		world.setBlock(i + 2, j + 11, k + 1, 0);
		world.setBlock(i + 2, j + 11, k + 2, 0);
		world.setBlock(i + 2, j + 11, k + 3, 0);
		world.setBlock(i + 2, j + 11, k + 4, Block.stairsCobblestone.blockID, 7, 3);
		world.setBlock(i + 2, j + 11, k + 6, Block.stairsWoodBirch.blockID, 2, 3);
		world.setBlock(i + 2, j + 11, k + 7, Block.stairsWoodBirch.blockID);
		world.setBlock(i + 2, j + 11, k + 8, Block.stairsWoodBirch.blockID);
		world.setBlock(i + 2, j + 11, k + 9, Block.stairsWoodBirch.blockID, 3, 3);
		world.setBlock(i + 2, j + 12, k + 1, 0);
		world.setBlock(i + 2, j + 12, k + 2, 0);
		world.setBlock(i + 2, j + 12, k + 3, 0);
		world.setBlock(i + 2, j + 13, k + 1, 0);
		world.setBlock(i + 2, j + 13, k + 2, 0);
		world.setBlock(i + 2, j + 13, k + 3, 0);
		world.setBlock(i + 3, j + 0, k + 1, Block.cobblestone.blockID);
		world.setBlock(i + 3, j + 0, k + 2, Block.cobblestone.blockID);
		world.setBlock(i + 3, j + 0, k + 3, Block.cobblestone.blockID);
		world.setBlock(i + 3, j + 0, k + 4, Block.cobblestone.blockID);
		world.setBlock(i + 3, j + 0, k + 5, Block.cobblestone.blockID);
		world.setBlock(i + 3, j + 0, k + 6, Block.cobblestone.blockID);
		world.setBlock(i + 3, j + 0, k + 7, Block.cobblestone.blockID);
		world.setBlock(i + 3, j + 1, k + 1, Block.cobblestone.blockID);
		world.setBlock(i + 3, j + 1, k + 2, 0);
		world.setBlock(i + 3, j + 1, k + 3, 0);
		world.setBlock(i + 3, j + 1, k + 4, 0);
		world.setBlock(i + 3, j + 1, k + 6, BlockInvisibleBlock.instance.blockID);
		world.setBlock(i + 3, j + 1, k + 7, Block.cobblestone.blockID);
		world.setBlock(i + 3, j + 2, k + 1, Block.cobblestone.blockID);
		world.setBlock(i + 3, j + 2, k + 2, 0);
		world.setBlock(i + 3, j + 2, k + 3, 0);
		world.setBlock(i + 3, j + 2, k + 4, 0);
		world.setBlock(i + 3, j + 2, k + 6, BlockInvisibleBlock.instance.blockID);
		world.setBlock(i + 3, j + 2, k + 7, Block.cobblestone.blockID);
		world.setBlock(i + 3, j + 3, k + 1, Block.cobblestone.blockID);
		world.setBlock(i + 3, j + 3, k + 2, 0);
		world.setBlock(i + 3, j + 3, k + 3, 0);
		world.setBlock(i + 3, j + 3, k + 4, 0);
		world.setBlock(i + 3, j + 3, k + 6, BlockInvisibleBlock.instance.blockID);
		world.setBlock(i + 3, j + 3, k + 7, Block.cobblestone.blockID);
		world.setBlock(i + 3, j + 4, k + 1, Block.cobblestone.blockID);
		world.setBlock(i + 3, j + 4, k + 2, Block.cobblestone.blockID);
		world.setBlock(i + 3, j + 4, k + 3, Block.cobblestone.blockID);
		world.setBlock(i + 3, j + 4, k + 4, Block.cobblestone.blockID);
		world.setBlock(i + 3, j + 4, k + 6, Block.cobblestone.blockID);
		world.setBlock(i + 3, j + 4, k + 7, Block.cobblestone.blockID);
		world.setBlock(i + 3, j + 5, k + 1, Block.cobblestone.blockID);
		world.setBlock(i + 3, j + 5, k + 2, Block.cobblestone.blockID);
		world.setBlock(i + 3, j + 5, k + 3, 0);
		world.setBlock(i + 3, j + 5, k + 4, 0);
		world.setBlock(i + 3, j + 5, k + 5, 0);
		world.setBlock(i + 3, j + 5, k + 6, Block.cobblestone.blockID);
		world.setBlock(i + 3, j + 5, k + 7, Block.cobblestone.blockID);
		world.setBlock(i + 3, j + 6, k + 1, Block.cobblestone.blockID);
		world.setBlock(i + 3, j + 6, k + 2, Block.cobblestone.blockID);
		world.setBlock(i + 3, j + 6, k + 3, 0);
		world.setBlock(i + 3, j + 6, k + 4, 0);
		world.setBlock(i + 3, j + 6, k + 5, 0);
		world.setBlock(i + 3, j + 6, k + 6, Block.cobblestone.blockID);
		world.setBlock(i + 3, j + 6, k + 7, Block.cobblestone.blockID);
		world.setBlock(i + 3, j + 7, k + 2, Block.cobblestone.blockID);
		world.setBlock(i + 3, j + 7, k + 3, 0);
		world.setBlock(i + 3, j + 7, k + 4, 0);
		world.setBlock(i + 3, j + 7, k + 5, 0);
		world.setBlock(i + 3, j + 7, k + 6, Block.cobblestone.blockID);
		world.setBlock(i + 3, j + 7, k + 7, Block.cobblestone.blockID);
		world.setBlock(i + 3, j + 7, k + 8, Block.stairsCobblestone.blockID, 4, 3);
		world.setBlock(i + 3, j + 8, k + 2, Block.cobblestone.blockID);
		world.setBlock(i + 3, j + 8, k + 3, Block.cobblestone.blockID);
		world.setBlock(i + 3, j + 8, k + 4, Block.cobblestone.blockID);
		world.setBlock(i + 3, j + 8, k + 5, Block.cobblestone.blockID);
		world.setBlock(i + 3, j + 8, k + 6, Block.cobblestone.blockID);
		world.setBlock(i + 3, j + 8, k + 7, Block.cobblestone.blockID);
		world.setBlock(i + 3, j + 8, k + 8, Block.cobblestone.blockID);
		world.setBlock(i + 3, j + 8, k + 9, Block.stairsCobblestone.blockID, 7, 3);
		world.setBlock(i + 3, j + 9, k + 2, Block.cobblestone.blockID);
		world.setBlock(i + 3, j + 10, k + 3, BlockTrap.instance.blockID, 5, 3);
		world.setBlockMetadataWithNotify(i + 3, j + 10, k + 3, 5, 3);
		te = world.getBlockTileEntity(i + 3, j + 10, k + 3);
		if(te instanceof TileEntityTrap) {
			ted = (TileEntityTrap)te;
			//PlaceTraps.addTrapItem(ted);
			ted.addItem(new ItemStack(Item.swordIron));
		}
		world.setBlock(i + 3, j + 9, k + 4, Block.cobblestone.blockID);
		world.setBlock(i + 3, j + 9, k + 5, Block.cobblestone.blockID);
		world.setBlock(i + 3, j + 9, k + 6, Block.cobblestone.blockID);
		world.setBlock(i + 3, j + 9, k + 7, 0);
		world.setBlock(i + 3, j + 9, k + 8, Block.chest.blockID, 2, 3);//trapped chest
		te = world.getBlockTileEntity(i + 3, j + 9, k + 8);
		if(te instanceof TileEntityChest) {
			TileEntityChest tec = (TileEntityChest)te;
			ChestGenHooks info = ChestGenHooks.getInfo(ChestGenHooks.DUNGEON_CHEST);
            WeightedRandomChestContent.generateChestContents(rand, info.getItems(rand), tec, info.getCount(rand));
		}
		world.setBlock(i + 3, j + 9, k + 9, Block.cobblestone.blockID);
		world.setBlock(i + 3, j + 10, k + 1, Block.stairsCobblestone.blockID, 6, 3);
		world.setBlock(i + 3, j + 10, k + 2, Block.cobblestone.blockID);
		world.setBlock(i + 3, j + 9, k + 3, Block.cobblestone.blockID);
		world.setBlock(i + 3, j + 10, k + 4, Block.cobblestone.blockID);
		world.setBlock(i + 3, j + 10, k + 5, Block.cobblestone.blockID);
		world.setBlock(i + 3, j + 10, k + 6, Block.cobblestone.blockID);
		world.setBlock(i + 3, j + 10, k + 7, 0);
		world.setBlock(i + 3, j + 10, k + 8, 0);
		world.setBlock(i + 3, j + 10, k + 9, Block.cobblestone.blockID);
		world.setBlock(i + 3, j + 11, k + 0, Block.stairsCobblestone.blockID, 6, 3);
		world.setBlock(i + 3, j + 11, k + 1, 0);
		world.setBlock(i + 3, j + 11, k + 2, Block.stairsCobblestone.blockID);
		world.setBlock(i + 3, j + 11, k + 3, Block.stairsCobblestone.blockID);
		world.setBlock(i + 3, j + 11, k + 4, Block.cobblestone.blockID);
		world.setBlock(i + 3, j + 11, k + 5, Block.stairsCobblestone.blockID);
		world.setBlock(i + 3, j + 11, k + 6, Block.stairsCobblestone.blockID);
		world.setBlock(i + 3, j + 11, k + 7, 0);
		world.setBlock(i + 3, j + 11, k + 8, 0);
		world.setBlock(i + 3, j + 11, k + 9, Block.stairsWoodBirch.blockID, 3, 3);
		world.setBlock(i + 3, j + 12, k + 0, Block.cobblestone.blockID);
		world.setBlock(i + 3, j + 12, k + 1, 0);
		world.setBlock(i + 3, j + 12, k + 2, 0);
		world.setBlock(i + 3, j + 12, k + 3, 0);
		world.setBlock(i + 3, j + 12, k + 4, Block.cobblestone.blockID);
		world.setBlock(i + 3, j + 12, k + 7, Block.stairsWoodBirch.blockID);
		world.setBlock(i + 3, j + 12, k + 8, Block.stairsWoodBirch.blockID, 3, 3);
		world.setBlock(i + 3, j + 13, k + 1, 0);
		world.setBlock(i + 3, j + 13, k + 2, 0);
		world.setBlock(i + 3, j + 13, k + 3, 0);
		world.setBlock(i + 3, j + 17, k + 4, Block.cobblestone.blockID);
		world.setBlock(i + 3, j + 17, k + 5, Block.cobblestone.blockID);
		world.setBlock(i + 3, j + 17, k + 6, Block.cobblestone.blockID);
		world.setBlock(i + 3, j + 18, k + 4, Block.cobblestone.blockID);
		world.setBlock(i + 3, j + 18, k + 6, Block.cobblestone.blockID);
		world.setBlock(i + 4, j + 0, k + 0, Block.cobblestone.blockID);
		world.setBlock(i + 4, j + 0, k + 1, Block.cobblestone.blockID);
		world.setBlock(i + 4, j + 0, k + 2, Block.cobblestone.blockID);
		world.setBlock(i + 4, j + 0, k + 3, Block.cobblestone.blockID);
		world.setBlock(i + 4, j + 0, k + 4, Block.cobblestone.blockID);
		world.setBlock(i + 4, j + 0, k + 5, Block.cobblestone.blockID);
		world.setBlock(i + 4, j + 0, k + 6, Block.cobblestone.blockID);
		world.setBlock(i + 4, j + 0, k + 7, Block.cobblestone.blockID);
		world.setBlock(i + 4, j + 0, k + 8, Block.cobblestone.blockID);
		world.setBlock(i + 4, j + 1, k + 0, Block.cobblestone.blockID);
		world.setBlock(i + 4, j + 1, k + 1, Block.web.blockID);
		world.setBlock(i + 4, j + 1, k + 2, 0);
		world.setBlock(i + 4, j + 1, k + 3, 0);
		world.setBlock(i + 4, j + 1, k + 4, 0);
		world.setBlock(i + 4, j + 1, k + 5, 0);
		world.setBlock(i + 4, j + 1, k + 6, 0);
		world.setBlock(i + 4, j + 1, k + 7, 0);
		world.setBlock(i + 4, j + 1, k + 8, Block.cobblestone.blockID);
		world.setBlock(i + 4, j + 2, k + 0, Block.cobblestone.blockID);
		world.setBlock(i + 4, j + 2, k + 1, Block.web.blockID);
		world.setBlock(i + 4, j + 2, k + 2, 0);
		world.setBlock(i + 4, j + 2, k + 3, 0);
		world.setBlock(i + 4, j + 2, k + 4, 0);
		world.setBlock(i + 4, j + 2, k + 5, 0);
		world.setBlock(i + 4, j + 2, k + 6, 0);
		world.setBlock(i + 4, j + 2, k + 7, 0);
		world.setBlock(i + 4, j + 2, k + 8, Block.cobblestone.blockID);
		world.setBlock(i + 4, j + 3, k + 0, Block.cobblestone.blockID);
		world.setBlock(i + 4, j + 3, k + 1, Block.web.blockID);
		world.setBlock(i + 4, j + 3, k + 2, 0);
		world.setBlock(i + 4, j + 3, k + 3, 0);
		world.setBlock(i + 4, j + 3, k + 4, 0);
		world.setBlock(i + 4, j + 3, k + 5, 0);
		world.setBlock(i + 4, j + 3, k + 6, Block.web.blockID);
		world.setBlock(i + 4, j + 3, k + 7, Block.web.blockID);
		world.setBlock(i + 4, j + 3, k + 8, Block.cobblestone.blockID);
		world.setBlock(i + 4, j + 4, k + 0, Block.cobblestone.blockID);
		world.setBlock(i + 4, j + 4, k + 1, Block.cobblestone.blockID);
		world.setBlock(i + 4, j + 4, k + 2, Block.cobblestone.blockID);
		world.setBlock(i + 4, j + 4, k + 3, Block.cobblestone.blockID);
		world.setBlock(i + 4, j + 4, k + 4, Block.cobblestone.blockID);
		world.setBlock(i + 4, j + 4, k + 5, Block.cobblestone.blockID);
		world.setBlock(i + 4, j + 4, k + 6, Block.cobblestone.blockID);
		world.setBlock(i + 4, j + 4, k + 7, Block.cobblestone.blockID);
		world.setBlock(i + 4, j + 4, k + 8, Block.cobblestone.blockID);
		world.setBlock(i + 4, j + 5, k + 1, Block.cobblestone.blockID);
		world.setBlock(i + 4, j + 5, k + 2, BlockInvisibleBlock.instance.blockID);
		world.setBlock(i + 4, j + 5, k + 4, 0);
		world.setBlock(i + 4, j + 5, k + 5, 0);
		world.setBlock(i + 4, j + 5, k + 6, Block.workbench.blockID);
		world.setBlock(i + 4, j + 5, k + 7, Block.cobblestone.blockID);
		world.setBlock(i + 4, j + 6, k + 1, Block.cobblestone.blockID);
		world.setBlock(i + 4, j + 6, k + 2, BlockInvisibleBlock.instance.blockID);
		world.setBlock(i + 4, j + 6, k + 4, 0);
		world.setBlock(i + 4, j + 6, k + 5, 0);
		world.setBlock(i + 4, j + 6, k + 6, 0);
		world.setBlock(i + 4, j + 6, k + 7, Block.cobblestone.blockID);
		world.setBlock(i + 4, j + 7, k + 1, Block.cobblestone.blockID);
		world.setBlock(i + 4, j + 7, k + 2, BlockInvisibleBlock.instance.blockID);
		world.setBlock(i + 4, j + 7, k + 4, 0);
		world.setBlock(i + 4, j + 7, k + 5, 0);
		world.setBlock(i + 4, j + 7, k + 6, 0);
		world.setBlock(i + 4, j + 7, k + 7, Block.cobblestone.blockID);
		world.setBlock(i + 4, j + 7, k + 8, Block.stairsCobblestone.blockID, 7, 3);
		world.setBlock(i + 4, j + 8, k + 1, Block.cobblestone.blockID);
		world.setBlock(i + 4, j + 8, k + 2, Block.cobblestone.blockID);
		world.setBlock(i + 4, j + 8, k + 4, Block.cobblestone.blockID);
		world.setBlock(i + 4, j + 8, k + 5, Block.cobblestone.blockID);
		world.setBlock(i + 4, j + 8, k + 6, Block.cobblestone.blockID);
		world.setBlock(i + 4, j + 8, k + 7, Block.cobblestone.blockID);
		world.setBlock(i + 4, j + 8, k + 8, Block.cobblestone.blockID);
		world.setBlock(i + 4, j + 8, k + 9, Block.stairsCobblestone.blockID, 7, 3);
		world.setBlock(i + 4, j + 9, k + 2, Block.cobblestone.blockID);
		world.setBlock(i + 4, j + 9, k + 4, 0);
		world.setBlock(i + 4, j + 9, k + 5, 0);
		world.setBlock(i + 4, j + 9, k + 7, 0);
		world.setBlock(i + 4, j + 9, k + 9, Block.cobblestone.blockID);
		world.setBlock(i + 4, j + 10, k + 2, Block.cobblestone.blockID);
		world.setBlock(i + 4, j + 10, k + 3, 0);
		world.setBlock(i + 4, j + 10, k + 4, 0);
		world.setBlock(i + 4, j + 10, k + 5, 0);
		world.setBlock(i + 4, j + 10, k + 7, 0);
		world.setBlock(i + 4, j + 10, k + 8, 0);
		world.setBlock(i + 4, j + 10, k + 9, Block.thinGlass.blockID);
		world.setBlock(i + 4, j + 11, k + 1, Block.stairsCobblestone.blockID, 5, 3);
		world.setBlock(i + 4, j + 11, k + 2, Block.cobblestone.blockID);
		world.setBlock(i + 4, j + 11, k + 3, 0);
		world.setBlock(i + 4, j + 11, k + 4, 0);
		world.setBlock(i + 4, j + 11, k + 5, 0);
		world.setBlock(i + 4, j + 11, k + 6, Block.cobblestone.blockID);
		world.setBlock(i + 4, j + 11, k + 7, 0);
		world.setBlock(i + 4, j + 11, k + 8, 0);
		world.setBlock(i + 4, j + 11, k + 9, Block.stairsWoodBirch.blockID, 3, 3);
		world.setBlock(i + 4, j + 12, k + 1, Block.cobblestone.blockID);
		world.setBlock(i + 4, j + 12, k + 2, Block.stairsCobblestone.blockID);
		world.setBlock(i + 4, j + 12, k + 3, Block.stairsCobblestone.blockID);
		world.setBlock(i + 4, j + 12, k + 4, Block.cobblestone.blockID);
		world.setBlock(i + 4, j + 12, k + 5, Block.cobblestone.blockID);
		world.setBlock(i + 4, j + 12, k + 6, Block.cobblestone.blockID);
		world.setBlock(i + 4, j + 12, k + 7, Block.planks.blockID, 2, 3);
		world.setBlock(i + 4, j + 12, k + 8, Block.stairsWoodBirch.blockID, 3, 3);
		world.setBlock(i + 4, j + 13, k + 1, Block.cobblestone.blockID);
		world.setBlock(i + 4, j + 13, k + 2, 0);
		world.setBlock(i + 4, j + 13, k + 3, 0);
		world.setBlock(i + 4, j + 13, k + 4, Block.cobblestone.blockID);
		world.setBlock(i + 4, j + 13, k + 5, Block.cobblestone.blockID);
		world.setBlock(i + 4, j + 13, k + 6, Block.cobblestone.blockID);
		world.setBlock(i + 4, j + 13, k + 7, Block.woodSingleSlab.blockID, 2, 3);
		world.setBlock(i + 4, j + 14, k + 2, 0);
		world.setBlock(i + 4, j + 14, k + 3, 0);
		world.setBlock(i + 4, j + 14, k + 4, Block.cobblestone.blockID);
		world.setBlock(i + 4, j + 14, k + 5, Block.cobblestone.blockID);
		world.setBlock(i + 4, j + 14, k + 6, Block.cobblestone.blockID);
		world.setBlock(i + 4, j + 15, k + 4, Block.cobblestone.blockID);
		world.setBlock(i + 4, j + 15, k + 5, Block.cobblestone.blockID);
		world.setBlock(i + 4, j + 15, k + 6, Block.cobblestone.blockID);
		world.setBlock(i + 4, j + 16, k + 4, Block.cobblestone.blockID);
		world.setBlock(i + 4, j + 16, k + 5, Block.cobblestone.blockID);
		world.setBlock(i + 4, j + 16, k + 6, Block.cobblestone.blockID);
		world.setBlock(i + 4, j + 17, k + 3, Block.cobblestone.blockID);
		world.setBlock(i + 4, j + 17, k + 4, 0);
		world.setBlock(i + 4, j + 17, k + 5, 0);
		world.setBlock(i + 4, j + 17, k + 6, 0);
		world.setBlock(i + 4, j + 17, k + 7, Block.cobblestone.blockID);
		world.setBlock(i + 4, j + 18, k + 3, Block.cobblestone.blockID);
		world.setBlock(i + 4, j + 18, k + 4, 0);
		world.setBlock(i + 4, j + 18, k + 5, 0);
		world.setBlock(i + 4, j + 18, k + 6, 0);
		world.setBlock(i + 4, j + 18, k + 7, Block.cobblestone.blockID);
		world.setBlock(i + 5, j + 0, k + 0, Block.cobblestone.blockID);
		world.setBlock(i + 5, j + 0, k + 1, Block.cobblestone.blockID);
		world.setBlock(i + 5, j + 0, k + 2, Block.cobblestone.blockID);
		world.setBlock(i + 5, j + 0, k + 3, Block.cobblestone.blockID);
		world.setBlock(i + 5, j + 0, k + 4, Block.cobblestone.blockID);
		world.setBlock(i + 5, j + 0, k + 5, Block.cobblestone.blockID);
		world.setBlock(i + 5, j + 0, k + 6, Block.cobblestone.blockID);
		world.setBlock(i + 5, j + 0, k + 7, Block.cobblestone.blockID);
		world.setBlock(i + 5, j + 0, k + 8, Block.cobblestone.blockID);
		world.setBlock(i + 5, j + 1, k + 1, 0);
		world.setBlock(i + 5, j + 1, k + 2, 0);
		world.setBlock(i + 5, j + 1, k + 3, 0);
		world.setBlock(i + 5, j + 1, k + 4, 0);
		world.setBlock(i + 5, j + 1, k + 5, 0);
		world.setBlock(i + 5, j + 1, k + 6, 0);
		world.setBlock(i + 5, j + 1, k + 7, 0);
		world.setBlock(i + 5, j + 1, k + 8, Block.cobblestone.blockID);
		world.setBlock(i + 5, j + 2, k + 1, 0);
		world.setBlock(i + 5, j + 2, k + 2, 0);
		world.setBlock(i + 5, j + 2, k + 3, 0);
		world.setBlock(i + 5, j + 2, k + 4, 0);
		world.setBlock(i + 5, j + 2, k + 5, 0);
		world.setBlock(i + 5, j + 2, k + 6, 0);
		world.setBlock(i + 5, j + 2, k + 7, 0);
		world.setBlock(i + 5, j + 2, k + 8, Block.cobblestone.blockID);
		world.setBlock(i + 5, j + 3, k + 0, Block.cobblestone.blockID);
		world.setBlock(i + 5, j + 3, k + 1, Block.web.blockID);
		world.setBlock(i + 5, j + 3, k + 2, 0);
		world.setBlock(i + 5, j + 3, k + 3, 0);
		world.setBlock(i + 5, j + 3, k + 4, 0);
		world.setBlock(i + 5, j + 3, k + 5, 0);
		world.setBlock(i + 5, j + 3, k + 6, 0);
		world.setBlock(i + 5, j + 3, k + 7, 0);
		world.setBlock(i + 5, j + 3, k + 8, Block.cobblestone.blockID);
		world.setBlock(i + 5, j + 4, k + 0, Block.cobblestone.blockID);
		world.setBlock(i + 5, j + 4, k + 1, Block.cobblestone.blockID);
		world.setBlock(i + 5, j + 4, k + 2, Block.cobblestone.blockID);
		world.setBlock(i + 5, j + 4, k + 3, Block.cobblestone.blockID);
		world.setBlock(i + 5, j + 4, k + 4, Block.cobblestone.blockID);
		world.setBlock(i + 5, j + 4, k + 5, Block.cobblestone.blockID);
		world.setBlock(i + 5, j + 4, k + 6, Block.cobblestone.blockID);
		world.setBlock(i + 5, j + 4, k + 7, Block.cobblestone.blockID);
		world.setBlock(i + 5, j + 4, k + 8, Block.cobblestone.blockID);
		world.setBlock(i + 5, j + 5, k + 1, Block.cobblestone.blockID);
		world.setBlock(i + 5, j + 5, k + 2, 0);
		world.setBlock(i + 5, j + 5, k + 3, 0);
		world.setBlock(i + 5, j + 5, k + 4, 0);
		world.setBlock(i + 5, j + 5, k + 5, 0);
		world.setBlock(i + 5, j + 5, k + 6, Block.anvil.blockID);
		world.setBlock(i + 5, j + 5, k + 7, Block.cobblestone.blockID);
		world.setBlock(i + 5, j + 6, k + 1, Block.cobblestone.blockID);
		world.setBlock(i + 5, j + 6, k + 2, 0);
		world.setBlock(i + 5, j + 6, k + 3, 0);
		world.setBlock(i + 5, j + 6, k + 4, 0);
		world.setBlock(i + 5, j + 6, k + 5, 0);
		world.setBlock(i + 5, j + 6, k + 6, 0);
		world.setBlock(i + 5, j + 6, k + 7, Block.cobblestone.blockID);
		world.setBlock(i + 5, j + 7, k + 1, Block.cobblestone.blockID);
		world.setBlock(i + 5, j + 7, k + 2, 0);
		world.setBlock(i + 5, j + 7, k + 3, 0);
		world.setBlock(i + 5, j + 7, k + 4, 0);
		world.setBlock(i + 5, j + 7, k + 5, 0);
		world.setBlock(i + 5, j + 7, k + 6, 0);
		world.setBlock(i + 5, j + 7, k + 7, Block.cobblestone.blockID);
		world.setBlock(i + 5, j + 7, k + 8, Block.stairsCobblestone.blockID, 7, 3);
		world.setBlock(i + 5, j + 8, k + 1, Block.cobblestone.blockID);
		world.setBlock(i + 5, j + 8, k + 2, Block.cobblestone.blockID);
		world.setBlock(i + 5, j + 8, k + 3, Block.cobblestone.blockID);
		world.setBlock(i + 5, j + 8, k + 4, Block.cobblestone.blockID);
		world.setBlock(i + 5, j + 8, k + 5, Block.cobblestone.blockID);
		world.setBlock(i + 5, j + 8, k + 6, Block.cobblestone.blockID);
		world.setBlock(i + 5, j + 8, k + 7, Block.cobblestone.blockID);
		world.setBlock(i + 5, j + 8, k + 8, Block.cobblestone.blockID);
		world.setBlock(i + 5, j + 8, k + 9, Block.stairsCobblestone.blockID, 7, 3);
		world.setBlock(i + 5, j + 9, k + 2, Block.cobblestone.blockID);
		world.setBlock(i + 5, j + 9, k + 3, 0);
		world.setBlock(i + 5, j + 9, k + 4, 0);
		world.setBlock(i + 5, j + 9, k + 6, Block.cobblestone.blockID);
		world.setBlock(i + 5, j + 9, k + 7, Block.redstoneLampActive.blockID);
		world.setBlock(i + 5, j + 9, k + 9, Block.cobblestone.blockID);
		world.setBlock(i + 5, j + 10, k + 2, Block.fenceIron.blockID);
		world.setBlock(i + 5, j + 10, k + 3, 0);
		world.setBlock(i + 5, j + 10, k + 4, 0);
		world.setBlock(i + 5, j + 10, k + 6, Block.cobblestone.blockID);
		world.setBlock(i + 5, j + 10, k + 8, 0);
		world.setBlock(i + 5, j + 10, k + 9, Block.cobblestone.blockID);
		world.setBlock(i + 5, j + 11, k + 2, Block.cobblestone.blockID);
		world.setBlock(i + 5, j + 11, k + 3, 0);
		world.setBlock(i + 5, j + 11, k + 4, 0);
		world.setBlock(i + 5, j + 11, k + 6, Block.cobblestone.blockID);
		world.setBlock(i + 5, j + 11, k + 7, 0);
		world.setBlock(i + 5, j + 11, k + 8, 0);
		world.setBlock(i + 5, j + 11, k + 9, Block.stairsWoodBirch.blockID, 3, 3);
		world.setBlock(i + 5, j + 12, k + 2, Block.cobblestone.blockID);
		world.setBlock(i + 5, j + 12, k + 3, Block.cobblestone.blockID);
		world.setBlock(i + 5, j + 12, k + 4, Block.cobblestone.blockID);
		world.setBlock(i + 5, j + 12, k + 6, Block.cobblestone.blockID);
		world.setBlock(i + 5, j + 12, k + 7, Block.stairsWoodBirch.blockID, 1, 3);
		world.setBlock(i + 5, j + 12, k + 8, Block.stairsWoodBirch.blockID, 1, 3);
		world.setBlock(i + 5, j + 13, k + 1, Block.stairsCobblestone.blockID, 6, 3);
		world.setBlock(i + 5, j + 13, k + 2, 0);
		world.setBlock(i + 5, j + 13, k + 3, 0);
		world.setBlock(i + 5, j + 13, k + 4, 0);
		world.setBlock(i + 5, j + 13, k + 6, Block.cobblestone.blockID);
		world.setBlock(i + 5, j + 14, k + 2, 0);
		world.setBlock(i + 5, j + 14, k + 3, 0);
		world.setBlock(i + 5, j + 14, k + 4, 0);
		world.setBlock(i + 5, j + 14, k + 6, Block.cobblestone.blockID);
		world.setBlock(i + 5, j + 15, k + 4, Block.cobblestone.blockID);
		world.setBlock(i + 5, j + 15, k + 6, Block.cobblestone.blockID);
		world.setBlock(i + 5, j + 16, k + 4, Block.cobblestone.blockID);
		world.setBlock(i + 5, j + 16, k + 5, BlockIllusionary.instance.blockID);
		world.setBlock(i + 5, j + 16, k + 6, Block.cobblestone.blockID);
		world.setBlock(i + 5, j + 17, k + 3, Block.cobblestone.blockID);
		world.setBlock(i + 5, j + 17, k + 4, Block.chest.blockID, 3, 3);
		te = world.getBlockTileEntity(i + 5, j + 17, k + 4);
		if(te instanceof TileEntityChest) {
			TileEntityChest tec = (TileEntityChest)te;
			ChestGenHooks info = ChestGenHooks.getInfo(ChestGenHooks.PYRAMID_JUNGLE_CHEST);
            WeightedRandomChestContent.generateChestContents(rand, info.getItems(rand), tec, info.getCount(rand));
		}
		world.setBlock(i + 5, j + 17, k + 5, 0);
		world.setBlock(i + 5, j + 17, k + 6, 0);
		world.setBlock(i + 5, j + 17, k + 7, Block.cobblestone.blockID);
		world.setBlock(i + 5, j + 18, k + 4, 0);
		world.setBlock(i + 5, j + 18, k + 5, 0);
		world.setBlock(i + 5, j + 18, k + 6, 0);
		world.setBlock(i + 6, j + 0, k + 0, Block.cobblestone.blockID);
		world.setBlock(i + 6, j + 0, k + 1, Block.cobblestone.blockID);
		world.setBlock(i + 6, j + 0, k + 2, Block.cobblestone.blockID);
		world.setBlock(i + 6, j + 0, k + 3, Block.cobblestone.blockID);
		world.setBlock(i + 6, j + 0, k + 4, Block.cobblestone.blockID);
		world.setBlock(i + 6, j + 0, k + 5, Block.cobblestone.blockID);
		world.setBlock(i + 6, j + 0, k + 6, Block.cobblestone.blockID);
		world.setBlock(i + 6, j + 0, k + 7, Block.cobblestone.blockID);
		world.setBlock(i + 6, j + 0, k + 8, Block.cobblestone.blockID);
		world.setBlock(i + 6, j + 1, k + 0, Block.cobblestone.blockID);
		world.setBlock(i + 6, j + 1, k + 1, 0);
		world.setBlock(i + 6, j + 1, k + 2, 0);
		world.setBlock(i + 6, j + 1, k + 3, 0);
		world.setBlock(i + 6, j + 1, k + 4, 0);
		world.setBlock(i + 6, j + 1, k + 5, 0);
		world.setBlock(i + 6, j + 1, k + 6, 0);
		world.setBlock(i + 6, j + 1, k + 7, 0);
		world.setBlock(i + 6, j + 1, k + 8, Block.cobblestone.blockID);
		world.setBlock(i + 6, j + 2, k + 0, Block.cobblestone.blockID);
		world.setBlock(i + 6, j + 2, k + 1, 0);
		world.setBlock(i + 6, j + 2, k + 2, 0);
		world.setBlock(i + 6, j + 2, k + 3, 0);
		world.setBlock(i + 6, j + 2, k + 4, 0);
		world.setBlock(i + 6, j + 2, k + 5, 0);
		world.setBlock(i + 6, j + 2, k + 6, 0);
		world.setBlock(i + 6, j + 2, k + 7, 0);
		world.setBlock(i + 6, j + 2, k + 8, Block.cobblestone.blockID);
		world.setBlock(i + 6, j + 3, k + 0, Block.cobblestone.blockID);
		world.setBlock(i + 6, j + 3, k + 1, 0);
		world.setBlock(i + 6, j + 3, k + 2, 0);
		world.setBlock(i + 6, j + 3, k + 3, 0);
		world.setBlock(i + 6, j + 3, k + 4, 0);
		world.setBlock(i + 6, j + 3, k + 5, 0);
		world.setBlock(i + 6, j + 3, k + 6, 0);
		world.setBlock(i + 6, j + 3, k + 7, 0);
		world.setBlock(i + 6, j + 3, k + 8, Block.cobblestone.blockID);
		world.setBlock(i + 6, j + 4, k + 0, Block.cobblestone.blockID);
		world.setBlock(i + 6, j + 4, k + 1, Block.cobblestone.blockID);
		world.setBlock(i + 6, j + 4, k + 2, Block.cobblestone.blockID);
		world.setBlock(i + 6, j + 4, k + 3, Block.cobblestone.blockID);
		world.setBlock(i + 6, j + 4, k + 4, Block.cobblestone.blockID);
		world.setBlock(i + 6, j + 4, k + 5, Block.cobblestone.blockID);
		world.setBlock(i + 6, j + 4, k + 6, Block.cobblestone.blockID);
		world.setBlock(i + 6, j + 4, k + 7, Block.cobblestone.blockID);
		world.setBlock(i + 6, j + 4, k + 8, Block.cobblestone.blockID);
		world.setBlock(i + 6, j + 5, k + 1, Block.cobblestone.blockID);
		world.setBlock(i + 6, j + 5, k + 2, 0);
		world.setBlock(i + 6, j + 5, k + 3, 0);
		world.setBlock(i + 6, j + 5, k + 4, 0);
		world.setBlock(i + 6, j + 5, k + 5, 0);
		world.setBlock(i + 6, j + 5, k + 6, 0);
		world.setBlock(i + 6, j + 5, k + 7, Block.cobblestone.blockID);
		world.setBlock(i + 6, j + 6, k + 1, Block.cobblestone.blockID);
		world.setBlock(i + 6, j + 6, k + 2, 0);
		world.setBlock(i + 6, j + 6, k + 3, 0);
		world.setBlock(i + 6, j + 6, k + 4, 0);
		world.setBlock(i + 6, j + 6, k + 5, 0);
		world.setBlock(i + 6, j + 6, k + 6, 0);
		world.setBlock(i + 6, j + 6, k + 7, Block.cobblestone.blockID);
		world.setBlock(i + 6, j + 7, k + 1, Block.cobblestone.blockID);
		world.setBlock(i + 6, j + 7, k + 2, 0);
		world.setBlock(i + 6, j + 7, k + 3, 0);
		world.setBlock(i + 6, j + 7, k + 4, 0);
		world.setBlock(i + 6, j + 7, k + 5, 0);
		world.setBlock(i + 6, j + 7, k + 6, 0);
		world.setBlock(i + 6, j + 7, k + 7, Block.cobblestone.blockID);
		world.setBlock(i + 6, j + 8, k + 1, Block.cobblestone.blockID);
		world.setBlock(i + 6, j + 8, k + 2, Block.cobblestone.blockID);
		world.setBlock(i + 6, j + 8, k + 3, Block.cobblestone.blockID);
		world.setBlock(i + 6, j + 8, k + 4, Block.cobblestone.blockID);
		world.setBlock(i + 6, j + 8, k + 5, Block.cobblestone.blockID);
		world.setBlock(i + 6, j + 8, k + 6, Block.cobblestone.blockID);
		world.setBlock(i + 6, j + 8, k + 7, Block.cobblestone.blockID);
		world.setBlock(i + 6, j + 8, k + 8, Block.stairsCobblestone.blockID, 5, 3);
		world.setBlock(i + 6, j + 9, k + 2, Block.cobblestone.blockID);
		world.setBlock(i + 6, j + 9, k + 3, 0);
		world.setBlock(i + 6, j + 9, k + 4, 0);
		world.setBlock(i + 6, j + 9, k + 6, Block.cobblestone.blockID);
		world.setBlock(i + 6, j + 9, k + 7, Block.cobblestone.blockID);
		world.setBlock(i + 6, j + 9, k + 8, Block.cobblestone.blockID);
		world.setBlock(i + 6, j + 10, k + 2, Block.cobblestone.blockID);
		world.setBlock(i + 6, j + 10, k + 3, 0);
		world.setBlock(i + 6, j + 10, k + 4, 0);
		world.setBlock(i + 6, j + 10, k + 5, 0);
		world.setBlock(i + 6, j + 10, k + 6, BlockTrap.instance.blockID, 4, 3);
		world.setBlockMetadataWithNotify(i + 6, j + 10, k + 6, 2, 3);
		te = world.getBlockTileEntity(i + 6, j + 10, k + 6); 
		if(te instanceof TileEntityTrap) {
			ted = (TileEntityTrap)te;
			//PlaceTraps.addTrapItem(ted);
			ted.addItem(new ItemStack(Item.swordIron));
		}
		world.setBlock(i + 6, j + 10, k + 7, Block.cobblestone.blockID);
		world.setBlock(i + 6, j + 10, k + 8, Block.cobblestone.blockID);
		world.setBlock(i + 6, j + 11, k + 2, Block.cobblestone.blockID);
		world.setBlock(i + 6, j + 11, k + 3, 0);
		world.setBlock(i + 6, j + 11, k + 4, 0);
		world.setBlock(i + 6, j + 11, k + 5, 0);
		world.setBlock(i + 6, j + 11, k + 6, Block.cobblestone.blockID);
		world.setBlock(i + 6, j + 11, k + 7, Block.stairsWoodBirch.blockID, 1, 3);
		world.setBlock(i + 6, j + 11, k + 8, Block.stairsWoodBirch.blockID, 1, 3);
		world.setBlock(i + 6, j + 11, k + 9, Block.stairsWoodBirch.blockID, 1, 3);
		world.setBlock(i + 6, j + 12, k + 2, Block.cobblestone.blockID);
		world.setBlock(i + 6, j + 12, k + 3, Block.cobblestone.blockID);
		world.setBlock(i + 6, j + 12, k + 4, Block.cobblestone.blockID);
		world.setBlock(i + 6, j + 12, k + 5, Block.cobblestone.blockID);
		world.setBlock(i + 6, j + 12, k + 6, Block.cobblestone.blockID);
		world.setBlock(i + 6, j + 13, k + 1, Block.stairsCobblestone.blockID, 6, 3);
		world.setBlock(i + 6, j + 13, k + 2, 0);
		world.setBlock(i + 6, j + 13, k + 3, 0);
		world.setBlock(i + 6, j + 13, k + 4, Block.cobblestone.blockID);
		world.setBlock(i + 6, j + 13, k + 5, Block.cobblestone.blockID);
		world.setBlock(i + 6, j + 13, k + 6, Block.cobblestone.blockID);
		world.setBlock(i + 6, j + 14, k + 2, 0);
		world.setBlock(i + 6, j + 14, k + 3, 0);
		world.setBlock(i + 6, j + 14, k + 4, Block.cobblestone.blockID);
		world.setBlock(i + 6, j + 14, k + 5, Block.cobblestone.blockID);
		world.setBlock(i + 6, j + 14, k + 6, Block.cobblestone.blockID);
		world.setBlock(i + 6, j + 15, k + 4, Block.cobblestone.blockID);
		world.setBlock(i + 6, j + 15, k + 5, Block.cobblestone.blockID);
		world.setBlock(i + 6, j + 15, k + 6, Block.cobblestone.blockID);
		world.setBlock(i + 6, j + 16, k + 4, Block.cobblestone.blockID);
		world.setBlock(i + 6, j + 16, k + 5, Block.cobblestone.blockID);
		world.setBlock(i + 6, j + 16, k + 6, Block.cobblestone.blockID);
		world.setBlock(i + 6, j + 17, k + 3, Block.cobblestone.blockID);
		world.setBlock(i + 6, j + 17, k + 4, 0);
		world.setBlock(i + 6, j + 17, k + 5, 0);
		world.setBlock(i + 6, j + 17, k + 6, 0);
		world.setBlock(i + 6, j + 17, k + 7, Block.cobblestone.blockID);
		world.setBlock(i + 6, j + 18, k + 3, Block.cobblestone.blockID);
		world.setBlock(i + 6, j + 18, k + 4, 0);
		world.setBlock(i + 6, j + 18, k + 5, 0);
		world.setBlock(i + 6, j + 18, k + 6, 0);
		world.setBlock(i + 6, j + 18, k + 7, Block.cobblestone.blockID);
		world.setBlock(i + 7, j + 0, k + 1, Block.cobblestone.blockID);
		world.setBlock(i + 7, j + 0, k + 2, Block.cobblestone.blockID);
		world.setBlock(i + 7, j + 0, k + 3, Block.cobblestone.blockID);
		world.setBlock(i + 7, j + 0, k + 4, Block.cobblestone.blockID);
		world.setBlock(i + 7, j + 0, k + 5, Block.cobblestone.blockID);
		world.setBlock(i + 7, j + 0, k + 6, Block.cobblestone.blockID);
		world.setBlock(i + 7, j + 0, k + 7, Block.cobblestone.blockID);
		world.setBlock(i + 7, j + 1, k + 1, Block.cobblestone.blockID);
		world.setBlock(i + 7, j + 1, k + 2, 0);
		world.setBlock(i + 7, j + 1, k + 3, 0);
		world.setBlock(i + 7, j + 1, k + 4, 0);
		world.setBlock(i + 7, j + 1, k + 5, 0);
		world.setBlock(i + 7, j + 1, k + 6, Block.web.blockID);
		world.setBlock(i + 7, j + 1, k + 7, Block.cobblestone.blockID);
		world.setBlock(i + 7, j + 2, k + 1, Block.cobblestone.blockID);
		world.setBlock(i + 7, j + 2, k + 2, 0);
		world.setBlock(i + 7, j + 2, k + 3, 0);
		world.setBlock(i + 7, j + 2, k + 4, 0);
		world.setBlock(i + 7, j + 2, k + 5, 0);
		world.setBlock(i + 7, j + 2, k + 6, Block.web.blockID);
		world.setBlock(i + 7, j + 2, k + 7, Block.cobblestone.blockID);
		world.setBlock(i + 7, j + 3, k + 1, Block.cobblestone.blockID);
		world.setBlock(i + 7, j + 3, k + 2, 0);
		world.setBlock(i + 7, j + 3, k + 3, 0);
		world.setBlock(i + 7, j + 3, k + 4, 0);
		world.setBlock(i + 7, j + 3, k + 5, 0);
		world.setBlock(i + 7, j + 3, k + 6, Block.web.blockID);
		world.setBlock(i + 7, j + 3, k + 7, Block.cobblestone.blockID);
		world.setBlock(i + 7, j + 4, k + 1, Block.cobblestone.blockID);
		world.setBlock(i + 7, j + 4, k + 2, Block.cobblestone.blockID);
		world.setBlock(i + 7, j + 4, k + 3, Block.cobblestone.blockID);
		world.setBlock(i + 7, j + 4, k + 4, Block.cobblestone.blockID);
		world.setBlock(i + 7, j + 4, k + 5, Block.cobblestone.blockID);
		world.setBlock(i + 7, j + 4, k + 6, Block.cobblestone.blockID);
		world.setBlock(i + 7, j + 4, k + 7, Block.cobblestone.blockID);
		world.setBlock(i + 7, j + 5, k + 1, Block.cobblestone.blockID);
		world.setBlock(i + 7, j + 5, k + 2, Block.cobblestone.blockID);
		world.setBlock(i + 7, j + 5, k + 3, BlockPedestal.instance.blockID);
		te = world.getBlockTileEntity(i + 7, j + 5, k + 3); 
		if(te instanceof TileEntityDisplayPedestal) {
			TileEntityDisplayPedestal tedd = (TileEntityDisplayPedestal)te;
			tedd.setInventorySlotContents(0, FactoryArtifact.applyRandomEffects(new ItemStack(ItemArtifact.instance)));
			tedd.rotation = 180;
		}
		world.setBlock(i + 7, j + 5, k + 4, 0);
		world.setBlock(i + 7, j + 5, k + 5, 0);
		world.setBlock(i + 7, j + 5, k + 6, 0);
		world.setBlock(i + 7, j + 5, k + 7, Block.cobblestone.blockID);
		world.setBlock(i + 7, j + 6, k + 1, Block.cobblestone.blockID);
		world.setBlock(i + 7, j + 6, k + 2, Block.cobblestone.blockID);
		world.setBlock(i + 7, j + 6, k + 3, 0);
		world.setBlock(i + 7, j + 6, k + 4, 0);
		world.setBlock(i + 7, j + 6, k + 5, 0);
		world.setBlock(i + 7, j + 6, k + 6, 0);
		world.setBlock(i + 7, j + 6, k + 7, Block.cobblestone.blockID);
		world.setBlock(i + 7, j + 7, k + 2, Block.cobblestone.blockID);
		world.setBlock(i + 7, j + 7, k + 3, 0);
		world.setBlock(i + 7, j + 7, k + 4, 0);
		world.setBlock(i + 7, j + 7, k + 5, 0);
		world.setBlock(i + 7, j + 7, k + 6, 0);
		world.setBlock(i + 7, j + 7, k + 7, Block.cobblestone.blockID);
		world.setBlock(i + 7, j + 8, k + 2, Block.cobblestone.blockID);
		world.setBlock(i + 7, j + 8, k + 3, Block.cobblestone.blockID);
		world.setBlock(i + 7, j + 8, k + 4, Block.cobblestone.blockID);
		world.setBlock(i + 7, j + 8, k + 5, Block.cobblestone.blockID);
		world.setBlock(i + 7, j + 8, k + 6, Block.cobblestone.blockID);
		world.setBlock(i + 7, j + 9, k + 2, Block.cobblestone.blockID);
		world.setBlock(i + 7, j + 9, k + 3, Block.cobblestone.blockID);
		world.setBlock(i + 7, j + 9, k + 4, Block.cobblestone.blockID);
		world.setBlock(i + 7, j + 9, k + 5, Block.cobblestone.blockID);
		world.setBlock(i + 7, j + 9, k + 6, Block.cobblestone.blockID);
		world.setBlock(i + 7, j + 10, k + 2, Block.cobblestone.blockID);
		world.setBlock(i + 7, j + 10, k + 3, Block.cobblestone.blockID);
		world.setBlock(i + 7, j + 10, k + 4, Block.cobblestone.blockID);
		world.setBlock(i + 7, j + 10, k + 5, Block.cobblestone.blockID);
		world.setBlock(i + 7, j + 10, k + 6, Block.cobblestone.blockID);
		world.setBlock(i + 7, j + 11, k + 3, Block.cobblestone.blockID);
		world.setBlock(i + 7, j + 11, k + 4, Block.cobblestone.blockID);
		world.setBlock(i + 7, j + 11, k + 5, Block.cobblestone.blockID);
		world.setBlock(i + 7, j + 12, k + 3, Block.cobblestone.blockID);
		world.setBlock(i + 7, j + 12, k + 4, Block.cobblestone.blockID);
		world.setBlock(i + 7, j + 12, k + 5, Block.cobblestone.blockID);
		world.setBlock(i + 7, j + 13, k + 2, Block.cobblestone.blockID);
		world.setBlock(i + 7, j + 13, k + 3, 0);
		world.setBlock(i + 7, j + 13, k + 4, 0);
		world.setBlock(i + 7, j + 13, k + 5, 0);
		world.setBlock(i + 7, j + 13, k + 6, Block.stairsCobblestone.blockID, 7, 3);
		world.setBlock(i + 7, j + 14, k + 3, 0);
		world.setBlock(i + 7, j + 14, k + 4, 0);
		world.setBlock(i + 7, j + 14, k + 5, 0);
		world.setBlock(i + 7, j + 17, k + 4, Block.cobblestone.blockID);
		world.setBlock(i + 7, j + 17, k + 5, Block.cobblestone.blockID);
		world.setBlock(i + 7, j + 17, k + 6, Block.cobblestone.blockID);
		world.setBlock(i + 7, j + 18, k + 4, Block.cobblestone.blockID);
		world.setBlock(i + 7, j + 18, k + 6, Block.cobblestone.blockID);
		world.setBlock(i + 8, j + 0, k + 2, Block.cobblestone.blockID);
		world.setBlock(i + 8, j + 0, k + 3, Block.cobblestone.blockID);
		world.setBlock(i + 8, j + 0, k + 4, Block.cobblestone.blockID);
		world.setBlock(i + 8, j + 0, k + 5, Block.cobblestone.blockID);
		world.setBlock(i + 8, j + 0, k + 6, Block.cobblestone.blockID);
		world.setBlock(i + 8, j + 1, k + 2, Block.cobblestone.blockID);
		world.setBlock(i + 8, j + 1, k + 3, 0);
		world.setBlock(i + 8, j + 1, k + 4, 0);
		world.setBlock(i + 8, j + 1, k + 5, 0);
		world.setBlock(i + 8, j + 1, k + 6, Block.cobblestone.blockID);
		world.setBlock(i + 8, j + 2, k + 2, Block.cobblestone.blockID);
		world.setBlock(i + 8, j + 2, k + 3, 0);
		world.setBlock(i + 8, j + 2, k + 4, 0);
		world.setBlock(i + 8, j + 2, k + 5, 0);
		world.setBlock(i + 8, j + 2, k + 6, Block.cobblestone.blockID);
		world.setBlock(i + 8, j + 3, k + 2, Block.cobblestone.blockID);
		world.setBlock(i + 8, j + 3, k + 3, 0);
		world.setBlock(i + 8, j + 3, k + 4, 0);
		world.setBlock(i + 8, j + 3, k + 5, Block.web.blockID);
		world.setBlock(i + 8, j + 3, k + 6, Block.cobblestone.blockID);
		world.setBlock(i + 8, j + 4, k + 2, Block.cobblestone.blockID);
		world.setBlock(i + 8, j + 4, k + 3, Block.cobblestone.blockID);
		world.setBlock(i + 8, j + 4, k + 4, Block.cobblestone.blockID);
		world.setBlock(i + 8, j + 4, k + 5, Block.cobblestone.blockID);
		world.setBlock(i + 8, j + 4, k + 6, Block.cobblestone.blockID);
		world.setBlock(i + 8, j + 5, k + 2, Block.cobblestone.blockID);
		world.setBlock(i + 8, j + 5, k + 3, Block.cobblestone.blockID);
		world.setBlock(i + 8, j + 5, k + 4, 0);
		world.setBlock(i + 8, j + 5, k + 5, 0);
		world.setBlock(i + 8, j + 5, k + 6, 0);
		world.setBlock(i + 8, j + 5, k + 7, Block.cobblestone.blockID);
		world.setBlock(i + 8, j + 6, k + 2, Block.cobblestone.blockID);
		world.setBlock(i + 8, j + 6, k + 3, Block.cobblestone.blockID);
		world.setBlock(i + 8, j + 6, k + 4, 0);
		world.setBlock(i + 8, j + 6, k + 5, 0);
		world.setBlock(i + 8, j + 6, k + 6, 0);
		world.setBlock(i + 8, j + 6, k + 7, Block.cobblestone.blockID);
		world.setBlock(i + 8, j + 7, k + 3, Block.cobblestone.blockID);
		world.setBlock(i + 8, j + 7, k + 4, 0);
		world.setBlock(i + 8, j + 7, k + 5, 0);
		world.setBlock(i + 8, j + 7, k + 6, 0);
		world.setBlock(i + 8, j + 7, k + 7, Block.cobblestone.blockID);
		world.setBlock(i + 8, j + 8, k + 3, Block.cobblestone.blockID);
		world.setBlock(i + 8, j + 8, k + 4, Block.cobblestone.blockID);
		world.setBlock(i + 8, j + 8, k + 5, Block.cobblestone.blockID);
		world.setBlock(i + 8, j + 8, k + 6, Block.cobblestone.blockID);
		world.setBlock(i + 8, j + 13, k + 3, Block.stairsCobblestone.blockID, 5, 3);
		world.setBlock(i + 8, j + 13, k + 4, Block.stairsCobblestone.blockID, 5, 3);
		world.setBlock(i + 8, j + 13, k + 5, Block.stairsCobblestone.blockID, 5, 3);
		world.setBlock(i + 9, j + 0, k + 3, Block.cobblestone.blockID);
		world.setBlock(i + 9, j + 0, k + 4, Block.cobblestone.blockID);
		world.setBlock(i + 9, j + 0, k + 5, Block.cobblestone.blockID);
		world.setBlock(i + 9, j + 1, k + 3, Block.cobblestone.blockID);
		world.setBlock(i + 9, j + 1, k + 4, Block.cobblestone.blockID);
		world.setBlock(i + 9, j + 1, k + 5, Block.cobblestone.blockID);
		world.setBlock(i + 9, j + 2, k + 3, Block.cobblestone.blockID);
		world.setBlock(i + 9, j + 2, k + 4, Block.cobblestone.blockID);
		world.setBlock(i + 9, j + 2, k + 5, Block.cobblestone.blockID);
		world.setBlock(i + 9, j + 3, k + 3, Block.cobblestone.blockID);
		world.setBlock(i + 9, j + 3, k + 4, Block.cobblestone.blockID);
		world.setBlock(i + 9, j + 3, k + 5, Block.cobblestone.blockID);
		world.setBlock(i + 9, j + 4, k + 3, Block.cobblestone.blockID);
		world.setBlock(i + 9, j + 4, k + 4, Block.cobblestone.blockID);
		world.setBlock(i + 9, j + 4, k + 5, Block.cobblestone.blockID);
		world.setBlock(i + 9, j + 4, k + 6, Block.cobblestone.blockID);
		world.setBlock(i + 9, j + 4, k + 7, Block.stairsCobblestone.blockID, 7, 3);
		world.setBlock(i + 9, j + 5, k + 4, BlockTrap.instance.blockID, 3, 3);
		te = world.getBlockTileEntity(i + 9, j + 5, k + 4); 
		if(te instanceof TileEntityTrap) {
			ted = (TileEntityTrap)te;
			//PlaceTraps.addTrapItem(ted);
			ted.addItem(new ItemStack(Item.arrow, 32));
		}
		world.setBlock(i + 9, j + 5, k + 7, BlockTrap.instance.blockID, 2, 3);
		world.setBlockMetadataWithNotify(i + 9, j + 5, k + 7, 2, 3);
		te = world.getBlockTileEntity(i + 9, j + 5, k + 7); 
		if(te instanceof TileEntityTrap) {
			ted = (TileEntityTrap)te;
			//PlaceTraps.addTrapItem(ted);
			ted.addItem(new ItemStack(Item.arrow, 32));
		}
		world.setBlock(i + 9, j + 6, k + 4, Block.cobblestone.blockID);
		world.setBlock(i + 9, j + 6, k + 5, 0);
		world.setBlock(i + 9, j + 6, k + 6, 0);
		world.setBlock(i + 9, j + 6, k + 7, Block.cobblestone.blockID);
		world.setBlock(i + 9, j + 7, k + 4, Block.cobblestone.blockID);
		world.setBlock(i + 9, j + 7, k + 5, 0);
		world.setBlock(i + 9, j + 7, k + 6, 0);
		world.setBlock(i + 9, j + 7, k + 7, Block.cobblestone.blockID);
		world.setBlock(i + 9, j + 8, k + 5, Block.cobblestone.blockID);
		world.setBlock(i + 9, j + 8, k + 6, Block.cobblestone.blockID);
		world.setBlock(i + 9, j + 8, k + 7, Block.cobblestone.blockID);
		world.setBlock(i + 10, j + 4, k + 5, Block.stairsCobblestone.blockID, 6, 3);
		world.setBlock(i + 10, j + 4, k + 6, Block.cobblestone.blockID);
		world.setBlock(i + 10, j + 4, k + 7, Block.stairsCobblestone.blockID, 7, 3);
		world.setBlock(i + 10, j + 5, k + 4, Block.stairsCobblestone.blockID, 6, 3);
		world.setBlock(i + 10, j + 5, k + 5, 0);
		world.setBlock(i + 10, j + 5, k + 6, 0);
		world.setBlock(i + 10, j + 5, k + 7, 0);
		world.setBlock(i + 10, j + 5, k + 8, Block.stairsCobblestone.blockID, 7, 3);
		world.setBlock(i + 10, j + 6, k + 4, Block.cobblestone.blockID);
		world.setBlock(i + 10, j + 6, k + 5, 0);
		world.setBlock(i + 10, j + 6, k + 6, 0);
		world.setBlock(i + 10, j + 6, k + 7, 0);
		world.setBlock(i + 10, j + 6, k + 8, Block.cobblestone.blockID);
		world.setBlock(i + 10, j + 7, k + 4, Block.cobblestone.blockID);
		world.setBlock(i + 10, j + 7, k + 5, 0);
		world.setBlock(i + 10, j + 7, k + 6, 0);
		world.setBlock(i + 10, j + 7, k + 7, 0);
		world.setBlock(i + 10, j + 7, k + 8, Block.cobblestone.blockID);
		world.setBlock(i + 10, j + 8, k + 4, Block.cobblestone.blockID);
		world.setBlock(i + 10, j + 8, k + 5, Block.stairsWoodBirch.blockID, 5, 3);
		world.setBlock(i + 10, j + 8, k + 6, Block.stairsWoodBirch.blockID, 5, 3);
		world.setBlock(i + 10, j + 8, k + 7, Block.stairsWoodBirch.blockID, 5, 3);
		world.setBlock(i + 10, j + 8, k + 8, Block.cobblestone.blockID);
		world.setBlock(i + 10, j + 9, k + 4, Block.stairsWoodBirch.blockID);
		world.setBlock(i + 10, j + 9, k + 5, Block.stairsWoodBirch.blockID);
		world.setBlock(i + 10, j + 9, k + 6, Block.stairsWoodBirch.blockID);
		world.setBlock(i + 10, j + 9, k + 7, Block.stairsWoodBirch.blockID);
		world.setBlock(i + 10, j + 9, k + 8, Block.stairsWoodBirch.blockID, 3, 3);
		world.setBlock(i + 11, j + 4, k + 5, Block.stairsCobblestone.blockID, 6, 3);
		world.setBlock(i + 11, j + 4, k + 6, Block.cobblestone.blockID);
		world.setBlock(i + 11, j + 4, k + 7, Block.stairsCobblestone.blockID, 7, 3);
		world.setBlock(i + 11, j + 5, k + 4, Block.stairsCobblestone.blockID, 6, 3);
		world.setBlock(i + 11, j + 5, k + 5, 0);
		world.setBlock(i + 11, j + 5, k + 6, Block.enchantmentTable.blockID);
		world.setBlock(i + 11, j + 5, k + 7, 0);
		world.setBlock(i + 11, j + 5, k + 8, Block.stairsCobblestone.blockID, 7, 3);
		world.setBlock(i + 11, j + 6, k + 4, Block.fenceIron.blockID);
		world.setBlock(i + 11, j + 6, k + 5, 0);
		world.setBlock(i + 11, j + 6, k + 6, 0);
		world.setBlock(i + 11, j + 6, k + 7, 0);
		world.setBlock(i + 11, j + 6, k + 8, Block.fenceIron.blockID);
		world.setBlock(i + 11, j + 7, k + 4, Block.fenceIron.blockID);
		world.setBlock(i + 11, j + 7, k + 5, 0);
		world.setBlock(i + 11, j + 7, k + 6, 0);
		world.setBlock(i + 11, j + 7, k + 7, 0);
		world.setBlock(i + 11, j + 7, k + 8, Block.fenceIron.blockID);
		world.setBlock(i + 11, j + 8, k + 4, Block.cobblestone.blockID);
		world.setBlock(i + 11, j + 8, k + 5, 0);
		world.setBlock(i + 11, j + 8, k + 6, 0);
		world.setBlock(i + 11, j + 8, k + 7, 0);
		world.setBlock(i + 11, j + 8, k + 8, Block.cobblestone.blockID);
		world.setBlock(i + 11, j + 9, k + 4, Block.stairsWoodBirch.blockID, 2, 3);
		world.setBlock(i + 11, j + 9, k + 5, BlockIllusionary.instance.blockID);
		world.setBlock(i + 11, j + 9, k + 6, BlockIllusionary.instance.blockID);
		world.setBlock(i + 11, j + 9, k + 7, BlockIllusionary.instance.blockID);
		world.setBlock(i + 11, j + 9, k + 8, Block.stairsWoodBirch.blockID, 3, 3);
		world.setBlock(i + 11, j + 10, k + 5, Block.stairsWoodBirch.blockID);
		world.setBlock(i + 11, j + 10, k + 6, Block.stairsWoodBirch.blockID);
		world.setBlock(i + 11, j + 10, k + 7, Block.stairsWoodBirch.blockID, 3, 3);
		world.setBlock(i + 12, j + 4, k + 5, Block.stairsCobblestone.blockID, 6, 3);
		world.setBlock(i + 12, j + 4, k + 6, Block.cobblestone.blockID);
		world.setBlock(i + 12, j + 4, k + 7, Block.stairsCobblestone.blockID, 7, 3);
		world.setBlock(i + 12, j + 5, k + 4, Block.stairsCobblestone.blockID, 6, 3);
		world.setBlock(i + 12, j + 5, k + 5, 0);
		world.setBlock(i + 12, j + 5, k + 6, 0);
		world.setBlock(i + 12, j + 5, k + 7, 0);
		world.setBlock(i + 12, j + 5, k + 8, Block.stairsCobblestone.blockID, 7, 3);
		world.setBlock(i + 12, j + 6, k + 4, Block.cobblestone.blockID);
		world.setBlock(i + 12, j + 6, k + 5, 0);
		world.setBlock(i + 12, j + 6, k + 6, 0);
		world.setBlock(i + 12, j + 6, k + 7, 0);
		world.setBlock(i + 12, j + 6, k + 8, Block.cobblestone.blockID);
		world.setBlock(i + 12, j + 7, k + 4, Block.cobblestone.blockID);
		world.setBlock(i + 12, j + 7, k + 5, 0);
		world.setBlock(i + 12, j + 7, k + 6, 0);
		world.setBlock(i + 12, j + 7, k + 7, 0);
		world.setBlock(i + 12, j + 7, k + 8, Block.cobblestone.blockID);
		world.setBlock(i + 12, j + 8, k + 4, Block.cobblestone.blockID);
		world.setBlock(i + 12, j + 8, k + 5, 0);
		world.setBlock(i + 12, j + 8, k + 6, 0);
		world.setBlock(i + 12, j + 8, k + 7, 0);
		world.setBlock(i + 12, j + 8, k + 8, Block.cobblestone.blockID);
		world.setBlock(i + 12, j + 9, k + 4, Block.stairsWoodBirch.blockID, 2, 3);
		world.setBlock(i + 12, j + 9, k + 5, BlockIllusionary.instance.blockID);
		world.setBlock(i + 12, j + 9, k + 6, BlockIllusionary.instance.blockID);
		world.setBlock(i + 12, j + 9, k + 7, BlockIllusionary.instance.blockID);
		world.setBlock(i + 12, j + 9, k + 8, Block.stairsWoodBirch.blockID, 3, 3);
		world.setBlock(i + 12, j + 10, k + 5, Block.stairsWoodBirch.blockID, 2, 3);
		world.setBlock(i + 12, j + 10, k + 6, Block.chest.blockID, 4, 3);
		te = world.getBlockTileEntity(i + 12, j + 10, k + 6);
		if(te instanceof TileEntityChest) {
			TileEntityChest tec = (TileEntityChest)te;
			ChestGenHooks info = ChestGenHooks.getInfo(ChestGenHooks.PYRAMID_DESERT_CHEST);
            WeightedRandomChestContent.generateChestContents(rand, info.getItems(rand), tec, info.getCount(rand));
		}
		world.setBlock(i + 12, j + 10, k + 7, Block.stairsWoodBirch.blockID, 3, 3);
		world.setBlock(i + 12, j + 11, k + 6, Block.woodSingleSlab.blockID, 2, 3);
		world.setBlock(i + 13, j + 4, k + 5, Block.stairsCobblestone.blockID, 5, 3);
		world.setBlock(i + 13, j + 4, k + 6, Block.stairsCobblestone.blockID, 5, 3);
		world.setBlock(i + 13, j + 4, k + 7, Block.stairsCobblestone.blockID, 7, 3);
		world.setBlock(i + 13, j + 5, k + 4, Block.stairsCobblestone.blockID, 6, 3);
		world.setBlock(i + 13, j + 5, k + 5, Block.bookShelf.blockID);
		world.setBlock(i + 13, j + 5, k + 6, Block.bookShelf.blockID);
		world.setBlock(i + 13, j + 5, k + 7, Block.bookShelf.blockID);
		world.setBlock(i + 13, j + 5, k + 8, Block.stairsCobblestone.blockID, 7, 3);
		world.setBlock(i + 13, j + 6, k + 4, Block.cobblestone.blockID);
		world.setBlock(i + 13, j + 6, k + 5, Block.bookShelf.blockID);
		world.setBlock(i + 13, j + 6, k + 6, Block.bookShelf.blockID);
		world.setBlock(i + 13, j + 6, k + 7, Block.bookShelf.blockID);
		world.setBlock(i + 13, j + 6, k + 8, Block.cobblestone.blockID);
		world.setBlock(i + 13, j + 7, k + 4, Block.cobblestone.blockID);
		world.setBlock(i + 13, j + 7, k + 5, Block.bookShelf.blockID);
		world.setBlock(i + 13, j + 7, k + 6, Block.bookShelf.blockID);
		world.setBlock(i + 13, j + 7, k + 7, Block.bookShelf.blockID);
		world.setBlock(i + 13, j + 7, k + 8, Block.cobblestone.blockID);
		world.setBlock(i + 13, j + 8, k + 4, Block.cobblestone.blockID);
		world.setBlock(i + 13, j + 8, k + 5, Block.bookShelf.blockID);
		world.setBlock(i + 13, j + 8, k + 6, Block.bookShelf.blockID);
		world.setBlock(i + 13, j + 8, k + 7, Block.bookShelf.blockID);
		world.setBlock(i + 13, j + 8, k + 8, Block.cobblestone.blockID);
		world.setBlock(i + 13, j + 9, k + 4, Block.stairsWoodBirch.blockID, 2, 3);
		world.setBlock(i + 13, j + 9, k + 5, Block.planks.blockID, 2, 3);
		world.setBlock(i + 13, j + 9, k + 6, Block.planks.blockID, 2, 3);
		world.setBlock(i + 13, j + 9, k + 7, Block.planks.blockID, 2, 3);
		world.setBlock(i + 13, j + 9, k + 8, Block.stairsWoodBirch.blockID, 3, 3);
		world.setBlock(i + 13, j + 10, k + 5, Block.stairsWoodBirch.blockID, 2, 3);
		world.setBlock(i + 13, j + 10, k + 6, Block.stairsWoodBirch.blockID, 1, 3);
		world.setBlock(i + 13, j + 10, k + 7, Block.stairsWoodBirch.blockID, 1, 3);
		world.setBlock(i + 14, j + 5, k + 5, Block.stairsCobblestone.blockID, 5, 3);
		world.setBlock(i + 14, j + 5, k + 6, Block.stairsCobblestone.blockID, 5, 3);
		world.setBlock(i + 14, j + 5, k + 7, Block.stairsCobblestone.blockID, 5, 3);
		world.setBlock(i + 14, j + 6, k + 5, Block.cobblestone.blockID);
		world.setBlock(i + 14, j + 6, k + 6, Block.cobblestone.blockID);
		world.setBlock(i + 14, j + 6, k + 7, Block.cobblestone.blockID);
		world.setBlock(i + 14, j + 7, k + 5, Block.cobblestone.blockID);
		world.setBlock(i + 14, j + 7, k + 6, Block.cobblestone.blockID);
		world.setBlock(i + 14, j + 7, k + 7, Block.cobblestone.blockID);
		world.setBlock(i + 14, j + 8, k + 5, Block.cobblestone.blockID);
		world.setBlock(i + 14, j + 8, k + 6, Block.cobblestone.blockID);
		world.setBlock(i + 14, j + 8, k + 7, Block.cobblestone.blockID);
		world.setBlock(i + 14, j + 9, k + 4, Block.stairsWoodBirch.blockID, 2, 3);
		world.setBlock(i + 14, j + 9, k + 5, Block.stairsWoodBirch.blockID, 1, 3);
		world.setBlock(i + 14, j + 9, k + 6, Block.stairsWoodBirch.blockID, 1, 3);
		world.setBlock(i + 14, j + 9, k + 7, Block.stairsWoodBirch.blockID, 1, 3);
		world.setBlock(i + 14, j + 9, k + 8, Block.stairsWoodBirch.blockID, 1, 3);
		world.setBlock(i + 0, j + 13, k + 1, Block.torchWood.blockID, 5, 3);
		world.setBlock(i + 2, j + 1, k + 5, BlockWallPlate.instance.blockID, 2, 3);
		world.setBlock(i + 3, j + 1, k + 5, Block.ladder.blockID, 2, 3);
		world.setBlock(i + 3, j + 2, k + 5, Block.ladder.blockID, 2, 3);
		world.setBlock(i + 3, j + 3, k + 5, Block.ladder.blockID, 2, 3);
		world.setBlock(i + 3, j + 4, k + 5, Block.ladder.blockID, 2, 3);
		world.setBlock(i + 4, j + 5, k + 3, Block.ladder.blockID, 3, 3);
		world.setBlock(i + 4, j + 6, k + 3, Block.ladder.blockID, 3, 3);
		world.setBlock(i + 4, j + 7, k + 3, Block.ladder.blockID, 3, 3);
		world.setBlock(i + 4, j + 8, k + 3, Block.ladder.blockID, 3, 3);
		world.setBlock(i + 4, j + 9, k + 3, BlockWallPlate.instance.blockID, 3, 3);
		world.setBlock(i + 4, j + 9, k + 6, Block.doorWood.blockID, 1, 3);
		world.setBlock(i + 4, j + 10, k + 6, Block.doorWood.blockID, 8, 3);
		world.setBlock(i + 5, j + 1, k + 0, Block.doorIron.blockID, 1, 3);
		world.setBlock(i + 5, j + 2, k + 0, Block.doorIron.blockID, 8, 3);
		world.setBlock(i + 5, j + 9, k + 5, Block.ladder.blockID, 2, 3);
		world.setBlock(i + 5, j + 10, k + 5, Block.ladder.blockID, 2, 3);
		world.setBlock(i + 5, j + 10, k + 7, Block.lever.blockID, 14, 3);
		world.setBlock(i + 5, j + 11, k + 5, Block.ladder.blockID, 2, 3);
		world.setBlock(i + 5, j + 12, k + 5, Block.ladder.blockID, 2, 3);
		world.setBlock(i + 5, j + 13, k + 5, Block.ladder.blockID, 2, 3);
		world.setBlock(i + 5, j + 14, k + 5, Block.ladder.blockID, 2, 3);
		world.setBlock(i + 5, j + 15, k + 5, Block.torchWood.blockID, 4, 3);
		world.setBlock(i + 6, j + 9, k + 5, BlockWallPlate.instance.blockID, 2, 3);
		world.setBlock(i + 7, j + 14, k + 2, Block.torchWood.blockID, 5, 3);
		world.setBlock(i + 9, j + 5, k + 5, BlockInvisiblePressurePlate.obsidian.blockID);
		world.setBlock(i + 9, j + 5, k + 6, BlockInvisiblePressurePlate.obsidian.blockID);

		world.setBlock(i + 4, j + 9, k + 8, Block.bed.blockID, 3, 3);
		world.setBlock(i + 5, j + 9, k + 8, Block.bed.blockID, 11, 3);
		
		basement(world, i, j, k);
		return true;
	}
	
	private void basement(World world, int i, int j, int k) {
		boolean noair = false;
		int y = -1;
		do {
			noair = false;
			for(int x = 1; x <= 9; x++) {
				for(int z = 0; z <= 8; z++) {
					//5,y,4
					int d = (x-5)*(x-5)+(z-4)*(z-4);
					if(d <= 17) {
						if(!world.isBlockOpaqueCube(i+x, j+y, z+k) || world.getBlockId(i+x, j+y, z+k) == Block.leaves.blockID) {
							noair=true;
							world.setBlock(i+x, j+y, z+k, Block.cobblestone.blockID);
						}
					}
				}
			}
			y--;
		} while(noair && (j+y) >= 0);
		if(y >= -7 && world.rand.nextBoolean()) {
			y = -8;
		}
		if(y < -7) {
			y++;
			int yy = 3;
			for(; yy <= 5; yy++) {
				for(int x = 3; x <= 7; x++) {
					for(int z = 2; z <= 6; z++) {
						world.setBlockToAir(i+x, j+y+yy, k+z);
					}
				}
			}
			world.setBlock(i+5, j+y+6, k+4, Block.mobSpawner.blockID);
			TileEntityMobSpawner tileentitymobspawner = (TileEntityMobSpawner)world.getBlockTileEntity(i+5, j+y+6, k+4);

            if (tileentitymobspawner != null)
            {
                tileentitymobspawner.getSpawnerLogic().setMobID("artifacts.EntClayGolem");
                NBTTagCompound nbt = new NBTTagCompound();
                tileentitymobspawner.writeToNBT(nbt);
                nbt.setShort("MinSpawnDelay",(short)800);
                nbt.setShort("MaxSpawnDelay",(short)2400);
                tileentitymobspawner.readFromNBT(nbt);
            }
			for(yy=3;yy*-1>y;yy++) {
				world.setBlock(i+7, j+y+yy, k+6, Block.ladder.blockID, 2, 3);
			}
			world.setBlock(i+7, j+y+yy, k+6, Block.ladder.blockID, 2, 3);
			world.setBlock(i+7, j+y+yy+1, k+6, Block.trapdoor.blockID, 2, 3);
		}
	}
}
